{"market":"0x5977c69bca02e6cc150855b0faec463b38be463f141ec37ea5c8a1a1e986e0d3","asset_id":"103575991306220918671611575108050794364462782362354955892418399227289531345027","bids":[],"asks":[{"price":"0.999","size":"270"},{"price":"0.998","size":"60"},{"price":"0.99","size":"8146.4"},{"price":"0.98","size":"4061.8"},{"price":"0.97","size":"2960.5"},{"price":"0.96","size":"2724.52"},{"price":"0.95","size":"2640"},{"price":"0.94","size":"2505"},{"price":"0.93","size":"2505"},{"price":"0.92","size":"2505"},{"price":"0.91","size":"2505"},{"price":"0.9","size":"2515"},{"price":"0.89","size":"5"},{"price":"0.88","size":"10"},{"price":"0.87","size":"5"},{"price":"0.86","size":"5"},{"price":"0.85","size":"10"},{"price":"0.84","size":"5"},{"price":"0.83","size":"5"},{"price":"0.82","size":"5"},{"price":"0.81","size":"380"},{"price":"0.8","size":"420"},{"price":"0.79","size":"380"},{"price":"0.78","size":"380"},{"price":"0.77","size":"380"},{"price":"0.76","size":"380"},{"price":"0.75","size":"413.5"},{"price":"0.74","size":"380"},{"price":"0.73","size":"380"},{"price":"0.72","size":"403.14"},{"price":"0.71","size":"380"},{"price":"0.7","size":"606.69"},{"price":"0.69","size":"380"},{"price":"0.68","size":"385"},{"price":"0.67","size":"380"},{"price":"0.66","size":"385"},{"price":"0.65","size":"398.93"},{"price":"0.64","size":"394.18"},{"price":"0.63","size":"403.13"},{"price":"0.62","size":"380"},{"price":"0.61","size":"374.09"},{"price":"0.6","size":"39"},{"price":"0.59","size":"5"},{"price":"0.58","size":"28.41"},{"price":"0.57","size":"10"},{"price":"0.56","size":"16"},{"price":"0.55","size":"319.33"},{"price":"0.54","size":"10"},{"price":"0.53","size":"15"},{"price":"0.52","size":"88.05"},{"price":"0.51","size":"5"},{"price":"0.5","size":"25"},{"price":"0.49","size":"107.65"},{"price":"0.48","size":"43"},{"price":"0.47","size":"380"},{"price":"0.46","size":"380"},{"price":"0.45","size":"380"},{"price":"0.44","size":"395"},{"price":"0.43","size":"385"},{"price":"0.42","size":"385"},{"price":"0.41","size":"390"},{"price":"0.4","size":"396"},{"price":"0.39","size":"385"},{"price":"0.38","size":"380"},{"price":"0.37","size":"400.24"},{"price":"0.36","size":"516.18"},{"price":"0.35","size":"530.75"},{"price":"0.34","size":"510.37"},{"price":"0.33","size":"298.95"},{"price":"0.32","size":"490.24"},{"price":"0.31","size":"474.01"},{"price":"0.3","size":"677.5"},{"price":"0.29","size":"682.74"},{"price":"0.28","size":"582.84"},{"price":"0.27","size":"414.37"},{"price":"0.26","size":"490.67"},{"price":"0.252","size":"5"},{"price":"0.25","size":"820.01"},{"price":"0.24","size":"659.24"},{"price":"0.23","size":"470"},{"price":"0.22","size":"389.97"},{"price":"0.21","size":"385"},{"price":"0.2","size":"385"},{"price":"0.19","size":"484.75"},{"price":"0.18","size":"393"},{"price":"0.17","size":"428.78"},{"price":"0.16","size":"396.56"},{"price":"0.15","size":"406.25"},{"price":"0.14","size":"905.94"},{"price":"0.13","size":"380"},{"price":"0.12","size":"1391.36"},{"price":"0.11","size":"1390"},{"price":"0.1","size":"424.19"},{"price":"0.09","size":"380"},{"price":"0.08","size":"594.2"},{"price":"0.07","size":"454"},{"price":"0.06","size":"802.08"},{"price":"0.05","size":"436.43"},{"price":"0.04","size":"594.7"},{"price":"0.03","size":"903"},{"price":"0.021","size":"700"},{"price":"0.02","size":"1138.45"},{"price":"0.01","size":"1490.24"},{"price":"0.009","size":"948.75"},{"price":"0.005","size":"200"},{"price":"0.002","size":"0.06"},{"price":"0.001","size":"87.07"}],"hash":"07b44ef3bbf6633b7766cd0d6a9e3281ecf2441b","timestamp":"1768359576884","event_type":"book"}
{"market":"0x5977c69bca02e6cc150855b0faec463b38be463f141ec37ea5c8a1a1e986e0d3","asset_id":"110222991870854778724082971333105906777328061970448875974576460135015541883929","bids":[{"price":"0.001","size":"270"},{"price":"0.002","size":"60"},{"price":"0.01","size":"8146.4"},{"price":"0.02","size":"4061.8"},{"price":"0.03","size":"2960.5"},{"price":"0.04","size":"2724.52"},{"price":"0.05","size":"2640"},{"price":"0.06","size":"2505"},{"price":"0.07","size":"2505"},{"price":"0.08","size":"2505"},{"price":"0.09","size":"2505"},{"price":"0.1","size":"2515"},{"price":"0.11","size":"5"},{"price":"0.12","size":"10"},{"price":"0.13","size":"5"},{"price":"0.14","size":"5"},{"price":"0.15","size":"10"},{"price":"0.16","size":"5"},{"price":"0.17","size":"5"},{"price":"0.18","size":"5"},{"price":"0.19","size":"380"},{"price":"0.2","size":"420"},{"price":"0.21","size":"380"},{"price":"0.22","size":"380"},{"price":"0.23","size":"380"},{"price":"0.24","size":"380"},{"price":"0.25","size":"413.5"},{"price":"0.26","size":"380"},{"price":"0.27","size":"380"},{"price":"0.28","size":"403.14"},{"price":"0.29","size":"380"},{"price":"0.3","size":"606.69"},{"price":"0.31","size":"380"},{"price":"0.32","size":"385"},{"price":"0.33","size":"380"},{"price":"0.34","size":"385"},{"price":"0.35","size":"398.93"},{"price":"0.36","size":"394.18"},{"price":"0.37","size":"403.13"},{"price":"0.38","size":"380"},{"price":"0.39","size":"374.09"},{"price":"0.4","size":"39"},{"price":"0.41","size":"5"},{"price":"0.42","size":"28.41"},{"price":"0.43","size":"10"},{"price":"0.44","size":"16"},{"price":"0.45","size":"319.33"},{"price":"0.46","size":"10"},{"price":"0.47","size":"15"},{"price":"0.48","size":"88.05"},{"price":"0.49","size":"5"},{"price":"0.5","size":"25"},{"price":"0.51","size":"107.65"},{"price":"0.52","size":"43"},{"price":"0.53","size":"380"},{"price":"0.54","size":"380"},{"price":"0.55","size":"380"},{"price":"0.56","size":"395"},{"price":"0.57","size":"385"},{"price":"0.58","size":"385"},{"price":"0.59","size":"390"},{"price":"0.6","size":"396"},{"price":"0.61","size":"385"},{"price":"0.62","size":"380"},{"price":"0.63","size":"400.24"},{"price":"0.64","size":"516.18"},{"price":"0.65","size":"530.75"},{"price":"0.66","size":"510.37"},{"price":"0.67","size":"298.95"},{"price":"0.68","size":"490.24"},{"price":"0.69","size":"474.01"},{"price":"0.7","size":"677.5"},{"price":"0.71","size":"682.74"},{"price":"0.72","size":"582.84"},{"price":"0.73","size":"414.37"},{"price":"0.74","size":"490.67"},{"price":"0.748","size":"5"},{"price":"0.75","size":"820.01"},{"price":"0.76","size":"659.24"},{"price":"0.77","size":"470"},{"price":"0.78","size":"389.97"},{"price":"0.79","size":"385"},{"price":"0.8","size":"385"},{"price":"0.81","size":"484.75"},{"price":"0.82","size":"393"},{"price":"0.83","size":"428.78"},{"price":"0.84","size":"396.56"},{"price":"0.85","size":"406.25"},{"price":"0.86","size":"905.94"},{"price":"0.87","size":"380"},{"price":"0.88","size":"1391.36"},{"price":"0.89","size":"1390"},{"price":"0.9","size":"424.19"},{"price":"0.91","size":"380"},{"price":"0.92","size":"594.2"},{"price":"0.93","size":"454"},{"price":"0.94","size":"802.08"},{"price":"0.95","size":"436.43"},{"price":"0.96","size":"594.7"},{"price":"0.97","size":"903"},{"price":"0.979","size":"700"},{"price":"0.98","size":"1138.45"},{"price":"0.99","size":"1490.24"},{"price":"0.991","size":"948.75"},{"price":"0.995","size":"200"},{"price":"0.998","size":"0.06"},{"price":"0.999","size":"87.07"}],"asks":[],"hash":"873387907d306fe8a6b785cfd0a786ab8d953a39","timestamp":"1768359576884","event_type":"book"}
{"market":"0x5977c69bca02e6cc150855b0faec463b38be463f141ec37ea5c8a1a1e986e0d3","asset_id":"110222991870854778724082971333105906777328061970448875974576460135015541883929","price":"0.999","size":"1.01","fee_rate_bps":"1000","side":"SELL","timestamp":"1768359576913","event_type":"last_trade_price","transaction_hash":"0x817af3332f8051e4e2eaba6b31dfefdfe80671dc3eb8bad8e24eb2bbda7bcd21"}
{"market":"0x5977c69bca02e6cc150855b0faec463b38be463f141ec37ea5c8a1a1e986e0d3","price_changes":[{"asset_id":"110222991870854778724082971333105906777328061970448875974576460135015541883929","price":"0.99","size":"1501.24","side":"BUY","hash":"8eabf59d9722ad60fd191f71927e7ac2a8e3c9be","best_bid":"0.999","best_ask":"1"},{"asset_id":"103575991306220918671611575108050794364462782362354955892418399227289531345027","price":"0.01","size":"1501.24","side":"SELL","hash":"6c3a4198ee1aa8d623f82268612b588fef078315","best_bid":"0","best_ask":"0.001"}],"timestamp":"1768359577034","event_type":"price_change"}
{"market":"0x5977c69bca02e6cc150855b0faec463b38be463f141ec37ea5c8a1a1e986e0d3","price_changes":[{"asset_id":"110222991870854778724082971333105906777328061970448875974576460135015541883929","price":"0.83","size":"418.78","side":"BUY","hash":"917008058803073aac7fc7c527525c1aa11c3ef7","best_bid":"0.999","best_ask":"1"},{"asset_id":"103575991306220918671611575108050794364462782362354955892418399227289531345027","price":"0.17","size":"418.78","side":"SELL","hash":"3bac2457efe405a6cca5024bfe15cb775e01e6ca","best_bid":"0","best_ask":"0.001"}],"timestamp":"1768359577142","event_type":"price_change"}
{"market":"0x5977c69bca02e6cc150855b0faec463b38be463f141ec37ea5c8a1a1e986e0d3","price_changes":[{"asset_id":"110222991870854778724082971333105906777328061970448875974576460135015541883929","price":"0.83","size":"428.78","side":"BUY","hash":"1af205dadad703bc9c2f3e0399c58e4bcff22ab8","best_bid":"0.999","best_ask":"1"},{"asset_id":"103575991306220918671611575108050794364462782362354955892418399227289531345027","price":"0.17","size":"428.78","side":"SELL","hash":"96eacec388f3d33bd1ec73c2b14f53c4f2e1a4a5","best_bid":"0","best_ask":"0.001"}],"timestamp":"1768359577165","event_type":"price_change"}
{"market":"0x5977c69bca02e6cc150855b0faec463b38be463f141ec37ea5c8a1a1e986e0d3","price_changes":[{"asset_id":"110222991870854778724082971333105906777328061970448875974576460135015541883929","price":"0.979","size":"0","side":"BUY","hash":"7a0c9162cea311c834542e0ef3066d4a92aaaa18","best_bid":"0.999","best_ask":"1"},{"asset_id":"103575991306220918671611575108050794364462782362354955892418399227289531345027","price":"0.021","size":"0","side":"SELL","hash":"67325d186c3bc4ddb62f4a365625e9f894027143","best_bid":"0","best_ask":"0.001"}],"timestamp":"1768359577785","event_type":"price_change"}
{"market":"0x5977c69bca02e6cc150855b0faec463b38be463f141ec37ea5c8a1a1e986e0d3","price_changes":[{"asset_id":"110222991870854778724082971333105906777328061970448875974576460135015541883929","price":"0.83","size":"418.78","side":"BUY","hash":"78c3ac359d6e5d077d2643beb5b24642b0eab772","best_bid":"0.999","best_ask":"1"},{"asset_id":"103575991306220918671611575108050794364462782362354955892418399227289531345027","price":"0.17","size":"418.78","side":"SELL","hash":"4a7cd612c8e209a7fab102ad24bf4d9523bc9606","best_bid":"0","best_ask":"0.001"}],"timestamp":"1768359578244","event_type":"price_change"}
{"market":"0x5977c69bca02e6cc150855b0faec463b38be463f141ec37ea5c8a1a1e986e0d3","price_changes":[{"asset_id":"110222991870854778724082971333105906777328061970448875974576460135015541883929","price":"0.83","size":"428.78","side":"BUY","hash":"56e57f7434883bb4425a3c4903d7d4e08150648c","best_bid":"0.999","best_ask":"1"},{"asset_id":"103575991306220918671611575108050794364462782362354955892418399227289531345027","price":"0.17","size":"428.78","side":"SELL","hash":"3f080b388d60907c9018a2a66dfa9f8c67c9eb82","best_bid":"0","best_ask":"0.001"}],"timestamp":"1768359578271","event_type":"price_change"}
{"market":"0x5977c69bca02e6cc150855b0faec463b38be463f141ec37ea5c8a1a1e986e0d3","price_changes":[{"asset_id":"110222991870854778724082971333105906777328061970448875974576460135015541883929","price":"0.99","size":"1551.24","side":"BUY","hash":"89d5ad199713aa71895c83bafa63adc390d7793a","best_bid":"0.999","best_ask":"1"},{"asset_id":"103575991306220918671611575108050794364462782362354955892418399227289531345027","price":"0.01","size":"1551.24","side":"SELL","hash":"c96820b2a8088d55c024b7654799448e94312e03","best_bid":"0","best_ask":"0.001"}],"timestamp":"1768359579002","event_type":"price_change"}
{"market":"0x5977c69bca02e6cc150855b0faec463b38be463f141ec37ea5c8a1a1e986e0d3","asset_id":"103575991306220918671611575108050794364462782362354955892418399227289531345027","price":"0.006","size":"542.997777","fee_rate_bps":"1000","side":"BUY","timestamp":"1768359579200","event_type":"last_trade_price","transaction_hash":"0x6a8b61b96b6c6c2c96adc709eb955fc6e64a02f612dd3a1816c40b0fb4d189c4"}
{"market":"0x5977c69bca02e6cc150855b0faec463b38be463f141ec37ea5c8a1a1e986e0d3","price_changes":[{"asset_id":"110222991870854778724082971333105906777328061970448875974576460135015541883929","price":"0.991","size":"692.88","side":"BUY","hash":"d2ba815cbb6aea81ab147a34d568ea451d7fec01","best_bid":"0.991","best_ask":"1"},{"asset_id":"103575991306220918671611575108050794364462782362354955892418399227289531345027","price":"0.009","size":"692.88","side":"SELL","hash":"b62c53cf544f0025e59e0e8655a7895ee7db69b1","best_bid":"0","best_ask":"0.009"}],"timestamp":"1768359579168","event_type":"price_change"}
{"market":"0x5977c69bca02e6cc150855b0faec463b38be463f141ec37ea5c8a1a1e986e0d3","price_changes":[{"asset_id":"110222991870854778724082971333105906777328061970448875974576460135015541883929","price":"0.999","size":"0","side":"BUY","hash":"d2ba815cbb6aea81ab147a34d568ea451d7fec01","best_bid":"0.991","best_ask":"1"},{"asset_id":"103575991306220918671611575108050794364462782362354955892418399227289531345027","price":"0.001","size":"0","side":"SELL","hash":"b62c53cf544f0025e59e0e8655a7895ee7db69b1","best_bid":"0","best_ask":"0.009"}],"timestamp":"1768359579168","event_type":"price_change"}
{"market":"0x5977c69bca02e6cc150855b0faec463b38be463f141ec37ea5c8a1a1e986e0d3","price_changes":[{"asset_id":"110222991870854778724082971333105906777328061970448875974576460135015541883929","price":"0.998","size":"0","side":"BUY","hash":"d2ba815cbb6aea81ab147a34d568ea451d7fec01","best_bid":"0.991","best_ask":"1"},{"asset_id":"103575991306220918671611575108050794364462782362354955892418399227289531345027","price":"0.002","size":"0","side":"SELL","hash":"b62c53cf544f0025e59e0e8655a7895ee7db69b1","best_bid":"0","best_ask":"0.009"}],"timestamp":"1768359579168","event_type":"price_change"}
{"market":"0x5977c69bca02e6cc150855b0faec463b38be463f141ec37ea5c8a1a1e986e0d3","price_changes":[{"asset_id":"110222991870854778724082971333105906777328061970448875974576460135015541883929","price":"0.995","size":"0","side":"BUY","hash":"d2ba815cbb6aea81ab147a34d568ea451d7fec01","best_bid":"0.991","best_ask":"1"},{"asset_id":"103575991306220918671611575108050794364462782362354955892418399227289531345027","price":"0.005","size":"0","side":"SELL","hash":"b62c53cf544f0025e59e0e8655a7895ee7db69b1","best_bid":"0","best_ask":"0.009"}],"timestamp":"1768359579168","event_type":"price_change"}
{"market":"0x5977c69bca02e6cc150855b0faec463b38be463f141ec37ea5c8a1a1e986e0d3","asset_id":"103575991306220918671611575108050794364462782362354955892418399227289531345027","bids":[],"asks":[{"price":"0.999","size":"270"},{"price":"0.998","size":"60"},{"price":"0.99","size":"8146.4"},{"price":"0.98","size":"4061.8"},{"price":"0.97","size":"2960.5"},{"price":"0.96","size":"2724.52"},{"price":"0.95","size":"2640"},{"price":"0.94","size":"2505"},{"price":"0.93","size":"2505"},{"price":"0.92","size":"2505"},{"price":"0.91","size":"2505"},{"price":"0.9","size":"2515"},{"price":"0.89","size":"5"},{"price":"0.88","size":"10"},{"price":"0.87","size":"5"},{"price":"0.86","size":"5"},{"price":"0.85","size":"10"},{"price":"0.84","size":"5"},{"price":"0.83","size":"5"},{"price":"0.82","size":"5"},{"price":"0.81","size":"380"},{"price":"0.8","size":"420"},{"price":"0.79","size":"380"},{"price":"0.78","size":"380"},{"price":"0.77","size":"380"},{"price":"0.76","size":"380"},{"price":"0.75","size":"413.5"},{"price":"0.74","size":"380"},{"price":"0.73","size":"380"},{"price":"0.72","size":"403.14"},{"price":"0.71","size":"380"},{"price":"0.7","size":"606.69"},{"price":"0.69","size":"380"},{"price":"0.68","size":"385"},{"price":"0.67","size":"380"},{"price":"0.66","size":"385"},{"price":"0.65","size":"398.93"},{"price":"0.64","size":"394.18"},{"price":"0.63","size":"403.13"},{"price":"0.62","size":"380"},{"price":"0.61","size":"374.09"},{"price":"0.6","size":"39"},{"price":"0.59","size":"5"},{"price":"0.58","size":"28.41"},{"price":"0.57","size":"10"},{"price":"0.56","size":"16"},{"price":"0.55","size":"319.33"},{"price":"0.54","size":"10"},{"price":"0.53","size":"15"},{"price":"0.52","size":"88.05"},{"price":"0.51","size":"5"},{"price":"0.5","size":"25"},{"price":"0.49","size":"107.65"},{"price":"0.48","size":"43"},{"price":"0.47","size":"380"},{"price":"0.46","size":"380"},{"price":"0.45","size":"380"},{"price":"0.44","size":"395"},{"price":"0.43","size":"385"},{"price":"0.42","size":"385"},{"price":"0.41","size":"390"},{"price":"0.4","size":"396"},{"price":"0.39","size":"385"},{"price":"0.38","size":"380"},{"price":"0.37","size":"400.24"},{"price":"0.36","size":"516.18"},{"price":"0.35","size":"530.75"},{"price":"0.34","size":"510.37"},{"price":"0.33","size":"298.95"},{"price":"0.32","size":"490.24"},{"price":"0.31","size":"474.01"},{"price":"0.3","size":"677.5"},{"price":"0.29","size":"682.74"},{"price":"0.28","size":"582.84"},{"price":"0.27","size":"414.37"},{"price":"0.26","size":"490.67"},{"price":"0.252","size":"5"},{"price":"0.25","size":"820.01"},{"price":"0.24","size":"659.24"},{"price":"0.23","size":"470"},{"price":"0.22","size":"389.97"},{"price":"0.21","size":"385"},{"price":"0.2","size":"385"},{"price":"0.19","size":"484.75"},{"price":"0.18","size":"393"},{"price":"0.17","size":"428.78"},{"price":"0.16","size":"396.56"},{"price":"0.15","size":"406.25"},{"price":"0.14","size":"905.94"},{"price":"0.13","size":"380"},{"price":"0.12","size":"1391.36"},{"price":"0.11","size":"1390"},{"price":"0.1","size":"424.19"},{"price":"0.09","size":"380"},{"price":"0.08","size":"594.2"},{"price":"0.07","size":"454"},{"price":"0.06","size":"802.08"},{"price":"0.05","size":"436.43"},{"price":"0.04","size":"594.7"},{"price":"0.03","size":"903"},{"price":"0.02","size":"1138.45"},{"price":"0.01","size":"1551.24"},{"price":"0.009","size":"692.88"}],"hash":"b62c53cf544f0025e59e0e8655a7895ee7db69b1","timestamp":"1768359579168","event_type":"book"}
{"market":"0x5977c69bca02e6cc150855b0faec463b38be463f141ec37ea5c8a1a1e986e0d3","asset_id":"110222991870854778724082971333105906777328061970448875974576460135015541883929","bids":[{"price":"0.001","size":"270"},{"price":"0.002","size":"60"},{"price":"0.01","size":"8146.4"},{"price":"0.02","size":"4061.8"},{"price":"0.03","size":"2960.5"},{"price":"0.04","size":"2724.52"},{"price":"0.05","size":"2640"},{"price":"0.06","size":"2505"},{"price":"0.07","size":"2505"},{"price":"0.08","size":"2505"},{"price":"0.09","size":"2505"},{"price":"0.1","size":"2515"},{"price":"0.11","size":"5"},{"price":"0.12","size":"10"},{"price":"0.13","size":"5"},{"price":"0.14","size":"5"},{"price":"0.15","size":"10"},{"price":"0.16","size":"5"},{"price":"0.17","size":"5"},{"price":"0.18","size":"5"},{"price":"0.19","size":"380"},{"price":"0.2","size":"420"},{"price":"0.21","size":"380"},{"price":"0.22","size":"380"},{"price":"0.23","size":"380"},{"price":"0.24","size":"380"},{"price":"0.25","size":"413.5"},{"price":"0.26","size":"380"},{"price":"0.27","size":"380"},{"price":"0.28","size":"403.14"},{"price":"0.29","size":"380"},{"price":"0.3","size":"606.69"},{"price":"0.31","size":"380"},{"price":"0.32","size":"385"},{"price":"0.33","size":"380"},{"price":"0.34","size":"385"},{"price":"0.35","size":"398.93"},{"price":"0.36","size":"394.18"},{"price":"0.37","size":"403.13"},{"price":"0.38","size":"380"},{"price":"0.39","size":"374.09"},{"price":"0.4","size":"39"},{"price":"0.41","size":"5"},{"price":"0.42","size":"28.41"},{"price":"0.43","size":"10"},{"price":"0.44","size":"16"},{"price":"0.45","size":"319.33"},{"price":"0.46","size":"10"},{"price":"0.47","size":"15"},{"price":"0.48","size":"88.05"},{"price":"0.49","size":"5"},{"price":"0.5","size":"25"},{"price":"0.51","size":"107.65"},{"price":"0.52","size":"43"},{"price":"0.53","size":"380"},{"price":"0.54","size":"380"},{"price":"0.55","size":"380"},{"price":"0.56","size":"395"},{"price":"0.57","size":"385"},{"price":"0.58","size":"385"},{"price":"0.59","size":"390"},{"price":"0.6","size":"396"},{"price":"0.61","size":"385"},{"price":"0.62","size":"380"},{"price":"0.63","size":"400.24"},{"price":"0.64","size":"516.18"},{"price":"0.65","size":"530.75"},{"price":"0.66","size":"510.37"},{"price":"0.67","size":"298.95"},{"price":"0.68","size":"490.24"},{"price":"0.69","size":"474.01"},{"price":"0.7","size":"677.5"},{"price":"0.71","size":"682.74"},{"price":"0.72","size":"582.84"},{"price":"0.73","size":"414.37"},{"price":"0.74","size":"490.67"},{"price":"0.748","size":"5"},{"price":"0.75","size":"820.01"},{"price":"0.76","size":"659.24"},{"price":"0.77","size":"470"},{"price":"0.78","size":"389.97"},{"price":"0.79","size":"385"},{"price":"0.8","size":"385"},{"price":"0.81","size":"484.75"},{"price":"0.82","size":"393"},{"price":"0.83","size":"428.78"},{"price":"0.84","size":"396.56"},{"price":"0.85","size":"406.25"},{"price":"0.86","size":"905.94"},{"price":"0.87","size":"380"},{"price":"0.88","size":"1391.36"},{"price":"0.89","size":"1390"},{"price":"0.9","size":"424.19"},{"price":"0.91","size":"380"},{"price":"0.92","size":"594.2"},{"price":"0.93","size":"454"},{"price":"0.94","size":"802.08"},{"price":"0.95","size":"436.43"},{"price":"0.96","size":"594.7"},{"price":"0.97","size":"903"},{"price":"0.98","size":"1138.45"},{"price":"0.99","size":"1551.24"},{"price":"0.991","size":"692.88"}],"asks":[],"hash":"d2ba815cbb6aea81ab147a34d568ea451d7fec01","timestamp":"1768359579168","event_type":"book"}
{"market":"0x5977c69bca02e6cc150855b0faec463b38be463f141ec37ea5c8a1a1e986e0d3","price_changes":[{"asset_id":"110222991870854778724082971333105906777328061970448875974576460135015541883929","price":"0.98","size":"1128.45","side":"BUY","hash":"66a7dffb3b12c3e1c80ec56219f92b5e5f2a52ba","best_bid":"0.991","best_ask":"1"},{"asset_id":"103575991306220918671611575108050794364462782362354955892418399227289531345027","price":"0.02","size":"1128.45","side":"SELL","hash":"bbd092fa789b8df626a86b969b2c9b0554c2c046","best_bid":"0","best_ask":"0.009"}],"timestamp":"1768359579275","event_type":"price_change"}
{"market":"0x5977c69bca02e6cc150855b0faec463b38be463f141ec37ea5c8a1a1e986e0d3","price_changes":[{"asset_id":"110222991870854778724082971333105906777328061970448875974576460135015541883929","price":"0.93","size":"464","side":"BUY","hash":"79250de01bdbebc370db5311ad3b70abc66198a6","best_bid":"0.991","best_ask":"1"},{"asset_id":"103575991306220918671611575108050794364462782362354955892418399227289531345027","price":"0.07","size":"464","side":"SELL","hash":"f9bb9b37e6c1da0712767df4dece7f595b5637be","best_bid":"0","best_ask":"0.009"}],"timestamp":"1768359579276","event_type":"price_change"}
{"market":"0x5977c69bca02e6cc150855b0faec463b38be463f141ec37ea5c8a1a1e986e0d3","price_changes":[{"asset_id":"110222991870854778724082971333105906777328061970448875974576460135015541883929","price":"0.82","size":"380","side":"BUY","hash":"6f2edd8a109012c64c130c734937d35f6826e03b","best_bid":"0.991","best_ask":"1"},{"asset_id":"103575991306220918671611575108050794364462782362354955892418399227289531345027","price":"0.18","size":"380","side":"SELL","hash":"d351dfb5cd79f71f7148cb7780f0b81e1ebaa8aa","best_bid":"0","best_ask":"0.009"}],"timestamp":"1768359579307","event_type":"price_change"}
{"market":"0x5977c69bca02e6cc150855b0faec463b38be463f141ec37ea5c8a1a1e986e0d3","price_changes":[{"asset_id":"110222991870854778724082971333105906777328061970448875974576460135015541883929","price":"0.83","size":"418.78","side":"BUY","hash":"90b53915dd90432f90cd7a2505a22fcd837ae623","best_bid":"0.991","best_ask":"1"},{"asset_id":"103575991306220918671611575108050794364462782362354955892418399227289531345027","price":"0.17","size":"418.78","side":"SELL","hash":"64293e90f01d8d1d10b73f263f82e2b7b66de80f","best_bid":"0","best_ask":"0.009"}],"timestamp":"1768359579353","event_type":"price_change"}
{"market":"0x5977c69bca02e6cc150855b0faec463b38be463f141ec37ea5c8a1a1e986e0d3","price_changes":[{"asset_id":"110222991870854778724082971333105906777328061970448875974576460135015541883929","price":"0.83","size":"428.78","side":"BUY","hash":"c80c9226c6b62ef2796781d578b6b3c5df23579b","best_bid":"0.991","best_ask":"1"},{"asset_id":"103575991306220918671611575108050794364462782362354955892418399227289531345027","price":"0.17","size":"428.78","side":"SELL","hash":"87c9c21c70eb12b3049cad743329c2030591e78a","best_bid":"0","best_ask":"0.009"}],"timestamp":"1768359579379","event_type":"price_change"}
{"market":"0x5977c69bca02e6cc150855b0faec463b38be463f141ec37ea5c8a1a1e986e0d3","price_changes":[{"asset_id":"110222991870854778724082971333105906777328061970448875974576460135015541883929","price":"0.81","size":"497.75","side":"BUY","hash":"b46e6a59b137eccc0dc9e8989d6cadf7ad183dde","best_bid":"0.991","best_ask":"1"},{"asset_id":"103575991306220918671611575108050794364462782362354955892418399227289531345027","price":"0.19","size":"497.75","side":"SELL","hash":"be8a5d6de0d2cad61a725522d70f1a5c114619ce","best_bid":"0","best_ask":"0.009"}],"timestamp":"1768359579395","event_type":"price_change"}
{"market":"0x5977c69bca02e6cc150855b0faec463b38be463f141ec37ea5c8a1a1e986e0d3","price_changes":[{"asset_id":"110222991870854778724082971333105906777328061970448875974576460135015541883929","price":"0.748","size":"0","side":"BUY","hash":"840eb8a394a435e14666754b9aab1cb1392dfa03","best_bid":"0.991","best_ask":"1"},{"asset_id":"103575991306220918671611575108050794364462782362354955892418399227289531345027","price":"0.252","size":"0","side":"SELL","hash":"6dfb5960f01763e6153691de46aa7fa2207d9e92","best_bid":"0","best_ask":"0.009"}],"timestamp":"1768359579947","event_type":"price_change"}
PONG
{"market":"0x5977c69bca02e6cc150855b0faec463b38be463f141ec37ea5c8a1a1e986e0d3","price_changes":[{"asset_id":"103575991306220918671611575108050794364462782362354955892418399227289531345027","price":"0.07","size":"458.5","side":"SELL","hash":"dac96c4db9cdbc316295e196fa93bf66993e6286","best_bid":"0","best_ask":"0.009"},{"asset_id":"110222991870854778724082971333105906777328061970448875974576460135015541883929","price":"0.93","size":"458.5","side":"BUY","hash":"5878722f54cd6366444d35c10038d9b170164dec","best_bid":"0.991","best_ask":"1"}],"timestamp":"1768359580166","event_type":"price_change"}
{"market":"0x5977c69bca02e6cc150855b0faec463b38be463f141ec37ea5c8a1a1e986e0d3","price_changes":[{"asset_id":"103575991306220918671611575108050794364462782362354955892418399227289531345027","price":"0.07","size":"453","side":"SELL","hash":"227d60987e64979f81021bbf0d799c30bc4bd666","best_bid":"0","best_ask":"0.009"},{"asset_id":"110222991870854778724082971333105906777328061970448875974576460135015541883929","price":"0.93","size":"453","side":"BUY","hash":"8e9dc84ea9b9e7abcdd81e3d5413bd703dbe4b55","best_bid":"0.991","best_ask":"1"}],"timestamp":"1768359580318","event_type":"price_change"}
{"market":"0x5977c69bca02e6cc150855b0faec463b38be463f141ec37ea5c8a1a1e986e0d3","price_changes":[{"asset_id":"110222991870854778724082971333105906777328061970448875974576460135015541883929","price":"0.83","size":"418.78","side":"BUY","hash":"42198fbd5f6c4541ef524419d6a3c4ac52f1ee61","best_bid":"0.991","best_ask":"1"},{"asset_id":"103575991306220918671611575108050794364462782362354955892418399227289531345027","price":"0.17","size":"418.78","side":"SELL","hash":"671e5b9b08784117bde92789169c28ce436bfa6f","best_bid":"0","best_ask":"0.009"}],"timestamp":"1768359580441","event_type":"price_change"}
{"market":"0x5977c69bca02e6cc150855b0faec463b38be463f141ec37ea5c8a1a1e986e0d3","price_changes":[{"asset_id":"110222991870854778724082971333105906777328061970448875974576460135015541883929","price":"0.83","size":"428.78","side":"BUY","hash":"fd0b6c12a7847f1b42baeeff16136e73132d5600","best_bid":"0.991","best_ask":"1"},{"asset_id":"103575991306220918671611575108050794364462782362354955892418399227289531345027","price":"0.17","size":"428.78","side":"SELL","hash":"ef8d1ee5487a2328b9ac592cf9294f6c9aedb580","best_bid":"0","best_ask":"0.009"}],"timestamp":"1768359580467","event_type":"price_change"}
{"market":"0x5977c69bca02e6cc150855b0faec463b38be463f141ec37ea5c8a1a1e986e0d3","price_changes":[{"asset_id":"110222991870854778724082971333105906777328061970448875974576460135015541883929","price":"0.741","size":"5","side":"BUY","hash":"3cf43870f9dc21e4f6d4cda5c841d06f15cb6ffe","best_bid":"0.991","best_ask":"1"},{"asset_id":"103575991306220918671611575108050794364462782362354955892418399227289531345027","price":"0.259","size":"5","side":"SELL","hash":"853fa032e592a7084208b32c2725a386ac3d01ca","best_bid":"0","best_ask":"0.009"}],"timestamp":"1768359580927","event_type":"price_change"}
{"market":"0x5977c69bca02e6cc150855b0faec463b38be463f141ec37ea5c8a1a1e986e0d3","price_changes":[{"asset_id":"110222991870854778724082971333105906777328061970448875974576460135015541883929","price":"0.83","size":"418.78","side":"BUY","hash":"371b91cf69f835a0ec6bbaf94249d3de18bbde77","best_bid":"0.991","best_ask":"1"},{"asset_id":"103575991306220918671611575108050794364462782362354955892418399227289531345027","price":"0.17","size":"418.78","side":"SELL","hash":"c4a87dc5e2ab54630f5627b4e227696aeda0205c","best_bid":"0","best_ask":"0.009"}],"timestamp":"1768359581554","event_type":"price_change"}
{"market":"0x5977c69bca02e6cc150855b0faec463b38be463f141ec37ea5c8a1a1e986e0d3","price_changes":[{"asset_id":"110222991870854778724082971333105906777328061970448875974576460135015541883929","price":"0.83","size":"428.78","side":"BUY","hash":"5a0d4032b55932af012e94515fade3bd862fc868","best_bid":"0.991","best_ask":"1"},{"asset_id":"103575991306220918671611575108050794364462782362354955892418399227289531345027","price":"0.17","size":"428.78","side":"SELL","hash":"4ab6b4e1c3ed4175d8819a5860de5d2c9520094f","best_bid":"0","best_ask":"0.009"}],"timestamp":"1768359581589","event_type":"price_change"}
{"market":"0x5977c69bca02e6cc150855b0faec463b38be463f141ec37ea5c8a1a1e986e0d3","price_changes":[{"asset_id":"110222991870854778724082971333105906777328061970448875974576460135015541883929","price":"0.98","size":"1828.45","side":"BUY","hash":"1202e9d31f34f96b891c9a72273f55816452e30b","best_bid":"0.991","best_ask":"1"},{"asset_id":"103575991306220918671611575108050794364462782362354955892418399227289531345027","price":"0.02","size":"1828.45","side":"SELL","hash":"c6f5c5c0999621f02a1c48b98235f280b5fda326","best_bid":"0","best_ask":"0.009"}],"timestamp":"1768359581794","event_type":"price_change"}
{"market":"0x5977c69bca02e6cc150855b0faec463b38be463f141ec37ea5c8a1a1e986e0d3","price_changes":[{"asset_id":"110222991870854778724082971333105906777328061970448875974576460135015541883929","price":"0.97","size":"878","side":"BUY","hash":"ff83d79c0ec89c6829849c116f94eadeb78bea0e","best_bid":"0.991","best_ask":"1"},{"asset_id":"103575991306220918671611575108050794364462782362354955892418399227289531345027","price":"0.03","size":"878","side":"SELL","hash":"72d77de9cdd33786ec8de4237f98b4c7462cc3e8","best_bid":"0","best_ask":"0.009"}],"timestamp":"1768359582375","event_type":"price_change"}
{"market":"0x5977c69bca02e6cc150855b0faec463b38be463f141ec37ea5c8a1a1e986e0d3","price_changes":[{"asset_id":"110222991870854778724082971333105906777328061970448875974576460135015541883929","price":"0.83","size":"418.78","side":"BUY","hash":"187581372b16839bc3cebeca1c21f3214355b60f","best_bid":"0.991","best_ask":"1"},{"asset_id":"103575991306220918671611575108050794364462782362354955892418399227289531345027","price":"0.17","size":"418.78","side":"SELL","hash":"30ddb7c14445a625c5746bc75d927c0b23c2b612","best_bid":"0","best_ask":"0.009"}],"timestamp":"1768359582641","event_type":"price_change"}
{"market":"0x5977c69bca02e6cc150855b0faec463b38be463f141ec37ea5c8a1a1e986e0d3","price_changes":[{"asset_id":"110222991870854778724082971333105906777328061970448875974576460135015541883929","price":"0.83","size":"428.78","side":"BUY","hash":"95ae238f24ae6cbad1bb329d902d208fa701b4ad","best_bid":"0.991","best_ask":"1"},{"asset_id":"103575991306220918671611575108050794364462782362354955892418399227289531345027","price":"0.17","size":"428.78","side":"SELL","hash":"d8f63416e45e32236740f1f5e07ca927620b7be9","best_bid":"0","best_ask":"0.009"}],"timestamp":"1768359582699","event_type":"price_change"}
{"market":"0x5977c69bca02e6cc150855b0faec463b38be463f141ec37ea5c8a1a1e986e0d3","price_changes":[{"asset_id":"110222991870854778724082971333105906777328061970448875974576460135015541883929","price":"0.991","size":"687.88","side":"BUY","hash":"4b0ee60352a845173e78b754dcfc2faf80d5f982","best_bid":"0.991","best_ask":"1"},{"asset_id":"103575991306220918671611575108050794364462782362354955892418399227289531345027","price":"0.009","size":"687.88","side":"SELL","hash":"3f17c0c404c07020b30473b1411f39a72d0acc4d","best_bid":"0","best_ask":"0.009"}],"timestamp":"1768359583231","event_type":"price_change"}
{"market":"0x5977c69bca02e6cc150855b0faec463b38be463f141ec37ea5c8a1a1e986e0d3","asset_id":"103575991306220918671611575108050794364462782362354955892418399227289531345027","bids":[],"asks":[{"price":"0.999","size":"270"},{"price":"0.998","size":"60"},{"price":"0.99","size":"8146.4"},{"price":"0.98","size":"4061.8"},{"price":"0.97","size":"2960.5"},{"price":"0.96","size":"2724.52"},{"price":"0.95","size":"2640"},{"price":"0.94","size":"2505"},{"price":"0.93","size":"2505"},{"price":"0.92","size":"2505"},{"price":"0.91","size":"2505"},{"price":"0.9","size":"2515"},{"price":"0.89","size":"5"},{"price":"0.88","size":"10"},{"price":"0.87","size":"5"},{"price":"0.86","size":"5"},{"price":"0.85","size":"10"},{"price":"0.84","size":"5"},{"price":"0.83","size":"5"},{"price":"0.82","size":"5"},{"price":"0.81","size":"380"},{"price":"0.8","size":"420"},{"price":"0.79","size":"380"},{"price":"0.78","size":"380"},{"price":"0.77","size":"380"},{"price":"0.76","size":"380"},{"price":"0.75","size":"413.5"},{"price":"0.74","size":"380"},{"price":"0.73","size":"380"},{"price":"0.72","size":"403.14"},{"price":"0.71","size":"380"},{"price":"0.7","size":"606.69"},{"price":"0.69","size":"380"},{"price":"0.68","size":"385"},{"price":"0.67","size":"380"},{"price":"0.66","size":"385"},{"price":"0.65","size":"398.93"},{"price":"0.64","size":"394.18"},{"price":"0.63","size":"403.13"},{"price":"0.62","size":"380"},{"price":"0.61","size":"374.09"},{"price":"0.6","size":"39"},{"price":"0.59","size":"5"},{"price":"0.58","size":"28.41"},{"price":"0.57","size":"10"},{"price":"0.56","size":"16"},{"price":"0.55","size":"319.33"},{"price":"0.54","size":"10"},{"price":"0.53","size":"15"},{"price":"0.52","size":"88.05"},{"price":"0.51","size":"5"},{"price":"0.5","size":"25"},{"price":"0.49","size":"107.65"},{"price":"0.48","size":"43"},{"price":"0.47","size":"380"},{"price":"0.46","size":"380"},{"price":"0.45","size":"380"},{"price":"0.44","size":"395"},{"price":"0.43","size":"385"},{"price":"0.42","size":"385"},{"price":"0.41","size":"390"},{"price":"0.4","size":"396"},{"price":"0.39","size":"385"},{"price":"0.38","size":"380"},{"price":"0.37","size":"400.24"},{"price":"0.36","size":"516.18"},{"price":"0.35","size":"530.75"},{"price":"0.34","size":"510.37"},{"price":"0.33","size":"298.95"},{"price":"0.32","size":"490.24"},{"price":"0.31","size":"474.01"},{"price":"0.3","size":"677.5"},{"price":"0.29","size":"682.74"},{"price":"0.28","size":"582.84"},{"price":"0.27","size":"414.37"},{"price":"0.26","size":"490.67"},{"price":"0.259","size":"5"},{"price":"0.25","size":"820.01"},{"price":"0.24","size":"659.24"},{"price":"0.23","size":"470"},{"price":"0.22","size":"389.97"},{"price":"0.21","size":"385"},{"price":"0.2","size":"385"},{"price":"0.19","size":"497.75"},{"price":"0.18","size":"380"},{"price":"0.17","size":"428.78"},{"price":"0.16","size":"396.56"},{"price":"0.15","size":"406.25"},{"price":"0.14","size":"905.94"},{"price":"0.13","size":"380"},{"price":"0.12","size":"1391.36"},{"price":"0.11","size":"1390"},{"price":"0.1","size":"424.19"},{"price":"0.09","size":"380"},{"price":"0.08","size":"594.2"},{"price":"0.07","size":"453"},{"price":"0.06","size":"802.08"},{"price":"0.05","size":"436.43"},{"price":"0.04","size":"594.7"},{"price":"0.03","size":"878"},{"price":"0.02","size":"1828.45"},{"price":"0.01","size":"1551.24"},{"price":"0.009","size":"687.88"}],"hash":"3f17c0c404c07020b30473b1411f39a72d0acc4d","timestamp":"1768359583231","event_type":"book"}
{"market":"0x5977c69bca02e6cc150855b0faec463b38be463f141ec37ea5c8a1a1e986e0d3","asset_id":"110222991870854778724082971333105906777328061970448875974576460135015541883929","bids":[{"price":"0.001","size":"270"},{"price":"0.002","size":"60"},{"price":"0.01","size":"8146.4"},{"price":"0.02","size":"4061.8"},{"price":"0.03","size":"2960.5"},{"price":"0.04","size":"2724.52"},{"price":"0.05","size":"2640"},{"price":"0.06","size":"2505"},{"price":"0.07","size":"2505"},{"price":"0.08","size":"2505"},{"price":"0.09","size":"2505"},{"price":"0.1","size":"2515"},{"price":"0.11","size":"5"},{"price":"0.12","size":"10"},{"price":"0.13","size":"5"},{"price":"0.14","size":"5"},{"price":"0.15","size":"10"},{"price":"0.16","size":"5"},{"price":"0.17","size":"5"},{"price":"0.18","size":"5"},{"price":"0.19","size":"380"},{"price":"0.2","size":"420"},{"price":"0.21","size":"380"},{"price":"0.22","size":"380"},{"price":"0.23","size":"380"},{"price":"0.24","size":"380"},{"price":"0.25","size":"413.5"},{"price":"0.26","size":"380"},{"price":"0.27","size":"380"},{"price":"0.28","size":"403.14"},{"price":"0.29","size":"380"},{"price":"0.3","size":"606.69"},{"price":"0.31","size":"380"},{"price":"0.32","size":"385"},{"price":"0.33","size":"380"},{"price":"0.34","size":"385"},{"price":"0.35","size":"398.93"},{"price":"0.36","size":"394.18"},{"price":"0.37","size":"403.13"},{"price":"0.38","size":"380"},{"price":"0.39","size":"374.09"},{"price":"0.4","size":"39"},{"price":"0.41","size":"5"},{"price":"0.42","size":"28.41"},{"price":"0.43","size":"10"},{"price":"0.44","size":"16"},{"price":"0.45","size":"319.33"},{"price":"0.46","size":"10"},{"price":"0.47","size":"15"},{"price":"0.48","size":"88.05"},{"price":"0.49","size":"5"},{"price":"0.5","size":"25"},{"price":"0.51","size":"107.65"},{"price":"0.52","size":"43"},{"price":"0.53","size":"380"},{"price":"0.54","size":"380"},{"price":"0.55","size":"380"},{"price":"0.56","size":"395"},{"price":"0.57","size":"385"},{"price":"0.58","size":"385"},{"price":"0.59","size":"390"},{"price":"0.6","size":"396"},{"price":"0.61","size":"385"},{"price":"0.62","size":"380"},{"price":"0.63","size":"400.24"},{"price":"0.64","size":"516.18"},{"price":"0.65","size":"530.75"},{"price":"0.66","size":"510.37"},{"price":"0.67","size":"298.95"},{"price":"0.68","size":"490.24"},{"price":"0.69","size":"474.01"},{"price":"0.7","size":"677.5"},{"price":"0.71","size":"682.74"},{"price":"0.72","size":"582.84"},{"price":"0.73","size":"414.37"},{"price":"0.74","size":"490.67"},{"price":"0.741","size":"5"},{"price":"0.75","size":"820.01"},{"price":"0.76","size":"659.24"},{"price":"0.77","size":"470"},{"price":"0.78","size":"389.97"},{"price":"0.79","size":"385"},{"price":"0.8","size":"385"},{"price":"0.81","size":"497.75"},{"price":"0.82","size":"380"},{"price":"0.83","size":"428.78"},{"price":"0.84","size":"396.56"},{"price":"0.85","size":"406.25"},{"price":"0.86","size":"905.94"},{"price":"0.87","size":"380"},{"price":"0.88","size":"1391.36"},{"price":"0.89","size":"1390"},{"price":"0.9","size":"424.19"},{"price":"0.91","size":"380"},{"price":"0.92","size":"594.2"},{"price":"0.93","size":"453"},{"price":"0.94","size":"802.08"},{"price":"0.95","size":"436.43"},{"price":"0.96","size":"594.7"},{"price":"0.97","size":"878"},{"price":"0.98","size":"1828.45"},{"price":"0.99","size":"1551.24"},{"price":"0.991","size":"687.88"}],"asks":[],"hash":"4b0ee60352a845173e78b754dcfc2faf80d5f982","timestamp":"1768359583231","event_type":"book"}
{"market":"0x5977c69bca02e6cc150855b0faec463b38be463f141ec37ea5c8a1a1e986e0d3","asset_id":"103575991306220918671611575108050794364462782362354955892418399227289531345027","price":"0.009","size":"5","fee_rate_bps":"1000","side":"BUY","timestamp":"1768359583261","event_type":"last_trade_price","transaction_hash":"0x89cef93ee5493b18fc068927a70521b92cd73f3ecbc6190e269c7b75cb8cc352"}
{"market":"0x5977c69bca02e6cc150855b0faec463b38be463f141ec37ea5c8a1a1e986e0d3","price_changes":[{"asset_id":"110222991870854778724082971333105906777328061970448875974576460135015541883929","price":"0.05","size":"2540","side":"BUY","hash":"e883b59865c169204021b0797d4a719b917533cd","best_bid":"0.991","best_ask":"1"},{"asset_id":"103575991306220918671611575108050794364462782362354955892418399227289531345027","price":"0.95","size":"2540","side":"SELL","hash":"f5a420d4419a81a32c7f222c2a1dcdf54bf6d8a9","best_bid":"0","best_ask":"0.009"}],"timestamp":"1768359583293","event_type":"price_change"}
{"market":"0x5977c69bca02e6cc150855b0faec463b38be463f141ec37ea5c8a1a1e986e0d3","price_changes":[{"asset_id":"110222991870854778724082971333105906777328061970448875974576460135015541883929","price":"0.991","size":"672.88","side":"BUY","hash":"3ff5a267e93af85559b88ce04d0d60f7bfced1b7","best_bid":"0.991","best_ask":"1"},{"asset_id":"103575991306220918671611575108050794364462782362354955892418399227289531345027","price":"0.009","size":"672.88","side":"SELL","hash":"a22e0c0c24ed41ebf0cd0a74e9b2267418d00ae0","best_bid":"0","best_ask":"0.009"}],"timestamp":"1768359583309","event_type":"price_change"}
{"market":"0x5977c69bca02e6cc150855b0faec463b38be463f141ec37ea5c8a1a1e986e0d3","asset_id":"103575991306220918671611575108050794364462782362354955892418399227289531345027","bids":[],"asks":[{"price":"0.999","size":"270"},{"price":"0.998","size":"60"},{"price":"0.99","size":"8146.4"},{"price":"0.98","size":"4061.8"},{"price":"0.97","size":"2960.5"},{"price":"0.96","size":"2724.52"},{"price":"0.95","size":"2540"},{"price":"0.94","size":"2505"},{"price":"0.93","size":"2505"},{"price":"0.92","size":"2505"},{"price":"0.91","size":"2505"},{"price":"0.9","size":"2515"},{"price":"0.89","size":"5"},{"price":"0.88","size":"10"},{"price":"0.87","size":"5"},{"price":"0.86","size":"5"},{"price":"0.85","size":"10"},{"price":"0.84","size":"5"},{"price":"0.83","size":"5"},{"price":"0.82","size":"5"},{"price":"0.81","size":"380"},{"price":"0.8","size":"420"},{"price":"0.79","size":"380"},{"price":"0.78","size":"380"},{"price":"0.77","size":"380"},{"price":"0.76","size":"380"},{"price":"0.75","size":"413.5"},{"price":"0.74","size":"380"},{"price":"0.73","size":"380"},{"price":"0.72","size":"403.14"},{"price":"0.71","size":"380"},{"price":"0.7","size":"606.69"},{"price":"0.69","size":"380"},{"price":"0.68","size":"385"},{"price":"0.67","size":"380"},{"price":"0.66","size":"385"},{"price":"0.65","size":"398.93"},{"price":"0.64","size":"394.18"},{"price":"0.63","size":"403.13"},{"price":"0.62","size":"380"},{"price":"0.61","size":"374.09"},{"price":"0.6","size":"39"},{"price":"0.59","size":"5"},{"price":"0.58","size":"28.41"},{"price":"0.57","size":"10"},{"price":"0.56","size":"16"},{"price":"0.55","size":"319.33"},{"price":"0.54","size":"10"},{"price":"0.53","size":"15"},{"price":"0.52","size":"88.05"},{"price":"0.51","size":"5"},{"price":"0.5","size":"25"},{"price":"0.49","size":"107.65"},{"price":"0.48","size":"43"},{"price":"0.47","size":"380"},{"price":"0.46","size":"380"},{"price":"0.45","size":"380"},{"price":"0.44","size":"395"},{"price":"0.43","size":"385"},{"price":"0.42","size":"385"},{"price":"0.41","size":"390"},{"price":"0.4","size":"396"},{"price":"0.39","size":"385"},{"price":"0.38","size":"380"},{"price":"0.37","size":"400.24"},{"price":"0.36","size":"516.18"},{"price":"0.35","size":"530.75"},{"price":"0.34","size":"510.37"},{"price":"0.33","size":"298.95"},{"price":"0.32","size":"490.24"},{"price":"0.31","size":"474.01"},{"price":"0.3","size":"677.5"},{"price":"0.29","size":"682.74"},{"price":"0.28","size":"582.84"},{"price":"0.27","size":"414.37"},{"price":"0.26","size":"490.67"},{"price":"0.259","size":"5"},{"price":"0.25","size":"820.01"},{"price":"0.24","size":"659.24"},{"price":"0.23","size":"470"},{"price":"0.22","size":"389.97"},{"price":"0.21","size":"385"},{"price":"0.2","size":"385"},{"price":"0.19","size":"497.75"},{"price":"0.18","size":"380"},{"price":"0.17","size":"428.78"},{"price":"0.16","size":"396.56"},{"price":"0.15","size":"406.25"},{"price":"0.14","size":"905.94"},{"price":"0.13","size":"380"},{"price":"0.12","size":"1391.36"},{"price":"0.11","size":"1390"},{"price":"0.1","size":"424.19"},{"price":"0.09","size":"380"},{"price":"0.08","size":"594.2"},{"price":"0.07","size":"453"},{"price":"0.06","size":"802.08"},{"price":"0.05","size":"436.43"},{"price":"0.04","size":"594.7"},{"price":"0.03","size":"878"},{"price":"0.02","size":"1828.45"},{"price":"0.01","size":"1551.24"},{"price":"0.009","size":"672.88"}],"hash":"a22e0c0c24ed41ebf0cd0a74e9b2267418d00ae0","timestamp":"1768359583309","event_type":"book"}
{"market":"0x5977c69bca02e6cc150855b0faec463b38be463f141ec37ea5c8a1a1e986e0d3","asset_id":"110222991870854778724082971333105906777328061970448875974576460135015541883929","bids":[{"price":"0.001","size":"270"},{"price":"0.002","size":"60"},{"price":"0.01","size":"8146.4"},{"price":"0.02","size":"4061.8"},{"price":"0.03","size":"2960.5"},{"price":"0.04","size":"2724.52"},{"price":"0.05","size":"2540"},{"price":"0.06","size":"2505"},{"price":"0.07","size":"2505"},{"price":"0.08","size":"2505"},{"price":"0.09","size":"2505"},{"price":"0.1","size":"2515"},{"price":"0.11","size":"5"},{"price":"0.12","size":"10"},{"price":"0.13","size":"5"},{"price":"0.14","size":"5"},{"price":"0.15","size":"10"},{"price":"0.16","size":"5"},{"price":"0.17","size":"5"},{"price":"0.18","size":"5"},{"price":"0.19","size":"380"},{"price":"0.2","size":"420"},{"price":"0.21","size":"380"},{"price":"0.22","size":"380"},{"price":"0.23","size":"380"},{"price":"0.24","size":"380"},{"price":"0.25","size":"413.5"},{"price":"0.26","size":"380"},{"price":"0.27","size":"380"},{"price":"0.28","size":"403.14"},{"price":"0.29","size":"380"},{"price":"0.3","size":"606.69"},{"price":"0.31","size":"380"},{"price":"0.32","size":"385"},{"price":"0.33","size":"380"},{"price":"0.34","size":"385"},{"price":"0.35","size":"398.93"},{"price":"0.36","size":"394.18"},{"price":"0.37","size":"403.13"},{"price":"0.38","size":"380"},{"price":"0.39","size":"374.09"},{"price":"0.4","size":"39"},{"price":"0.41","size":"5"},{"price":"0.42","size":"28.41"},{"price":"0.43","size":"10"},{"price":"0.44","size":"16"},{"price":"0.45","size":"319.33"},{"price":"0.46","size":"10"},{"price":"0.47","size":"15"},{"price":"0.48","size":"88.05"},{"price":"0.49","size":"5"},{"price":"0.5","size":"25"},{"price":"0.51","size":"107.65"},{"price":"0.52","size":"43"},{"price":"0.53","size":"380"},{"price":"0.54","size":"380"},{"price":"0.55","size":"380"},{"price":"0.56","size":"395"},{"price":"0.57","size":"385"},{"price":"0.58","size":"385"},{"price":"0.59","size":"390"},{"price":"0.6","size":"396"},{"price":"0.61","size":"385"},{"price":"0.62","size":"380"},{"price":"0.63","size":"400.24"},{"price":"0.64","size":"516.18"},{"price":"0.65","size":"530.75"},{"price":"0.66","size":"510.37"},{"price":"0.67","size":"298.95"},{"price":"0.68","size":"490.24"},{"price":"0.69","size":"474.01"},{"price":"0.7","size":"677.5"},{"price":"0.71","size":"682.74"},{"price":"0.72","size":"582.84"},{"price":"0.73","size":"414.37"},{"price":"0.74","size":"490.67"},{"price":"0.741","size":"5"},{"price":"0.75","size":"820.01"},{"price":"0.76","size":"659.24"},{"price":"0.77","size":"470"},{"price":"0.78","size":"389.97"},{"price":"0.79","size":"385"},{"price":"0.8","size":"385"},{"price":"0.81","size":"497.75"},{"price":"0.82","size":"380"},{"price":"0.83","size":"428.78"},{"price":"0.84","size":"396.56"},{"price":"0.85","size":"406.25"},{"price":"0.86","size":"905.94"},{"price":"0.87","size":"380"},{"price":"0.88","size":"1391.36"},{"price":"0.89","size":"1390"},{"price":"0.9","size":"424.19"},{"price":"0.91","size":"380"},{"price":"0.92","size":"594.2"},{"price":"0.93","size":"453"},{"price":"0.94","size":"802.08"},{"price":"0.95","size":"436.43"},{"price":"0.96","size":"594.7"},{"price":"0.97","size":"878"},{"price":"0.98","size":"1828.45"},{"price":"0.99","size":"1551.24"},{"price":"0.991","size":"672.88"}],"asks":[],"hash":"3ff5a267e93af85559b88ce04d0d60f7bfced1b7","timestamp":"1768359583309","event_type":"book"}
{"market":"0x5977c69bca02e6cc150855b0faec463b38be463f141ec37ea5c8a1a1e986e0d3","asset_id":"110222991870854778724082971333105906777328061970448875974576460135015541883929","price":"0.991","size":"15","fee_rate_bps":"1000","side":"SELL","timestamp":"1768359583338","event_type":"last_trade_price","transaction_hash":"0x8bd34ee0f2381904e4fc7c02dbd88663b27d071b8bd709d33cd51714bb3bd90d"}
{"market":"0x5977c69bca02e6cc150855b0faec463b38be463f141ec37ea5c8a1a1e986e0d3","price_changes":[{"asset_id":"110222991870854778724082971333105906777328061970448875974576460135015541883929","price":"0.83","size":"418.78","side":"BUY","hash":"ba731cc647a23b0140d86467b615c2f1ee7876ae","best_bid":"0.991","best_ask":"1"},{"asset_id":"103575991306220918671611575108050794364462782362354955892418399227289531345027","price":"0.17","size":"418.78","side":"SELL","hash":"b8fa46d0eb666975f5c10e52a90c911debb142d8","best_bid":"0","best_ask":"0.009"}],"timestamp":"1768359583741","event_type":"price_change"}
{"market":"0x5977c69bca02e6cc150855b0faec463b38be463f141ec37ea5c8a1a1e986e0d3","price_changes":[{"asset_id":"110222991870854778724082971333105906777328061970448875974576460135015541883929","price":"0.83","size":"428.78","side":"BUY","hash":"ffd1b8af6cac76d15f65838d2a7dfd56464163e0","best_bid":"0.991","best_ask":"1"},{"asset_id":"103575991306220918671611575108050794364462782362354955892418399227289531345027","price":"0.17","size":"428.78","side":"SELL","hash":"b88e7a205a35ac5475802483a11641557bc01c40","best_bid":"0","best_ask":"0.009"}],"timestamp":"1768359583764","event_type":"price_change"}
{"market":"0x5977c69bca02e6cc150855b0faec463b38be463f141ec37ea5c8a1a1e986e0d3","price_changes":[{"asset_id":"110222991870854778724082971333105906777328061970448875974576460135015541883929","price":"0.01","size":"8141.4","side":"BUY","hash":"c089270f9dafccf7016fd716b83a8e1b5f874b08","best_bid":"0.991","best_ask":"1"},{"asset_id":"103575991306220918671611575108050794364462782362354955892418399227289531345027","price":"0.99","size":"8141.4","side":"SELL","hash":"5b84f8078a93bd219fcbfe2751bd752bb74396b8","best_bid":"0","best_ask":"0.009"}],"timestamp":"1768359584082","event_type":"price_change"}
{"market":"0x5977c69bca02e6cc150855b0faec463b38be463f141ec37ea5c8a1a1e986e0d3","price_changes":[{"asset_id":"110222991870854778724082971333105906777328061970448875974576460135015541883929","price":"0.83","size":"418.78","side":"BUY","hash":"54785246ea7e449e1ac2d7672504bf8d65cfad77","best_bid":"0.991","best_ask":"1"},{"asset_id":"103575991306220918671611575108050794364462782362354955892418399227289531345027","price":"0.17","size":"418.78","side":"SELL","hash":"68e66eead82f4b22dd4ad22f7b18dd727cb67afd","best_bid":"0","best_ask":"0.009"}],"timestamp":"1768359584863","event_type":"price_change"}
{"market":"0x5977c69bca02e6cc150855b0faec463b38be463f141ec37ea5c8a1a1e986e0d3","price_changes":[{"asset_id":"110222991870854778724082971333105906777328061970448875974576460135015541883929","price":"0.83","size":"428.78","side":"BUY","hash":"a978126cebfaf37ccb4053958d684dcb7350730a","best_bid":"0.991","best_ask":"1"},{"asset_id":"103575991306220918671611575108050794364462782362354955892418399227289531345027","price":"0.17","size":"428.78","side":"SELL","hash":"a9edba14e3fbecc5b2693b4c0b442cc96976933b","best_bid":"0","best_ask":"0.009"}],"timestamp":"1768359584925","event_type":"price_change"}
{"market":"0x5977c69bca02e6cc150855b0faec463b38be463f141ec37ea5c8a1a1e986e0d3","price_changes":[{"asset_id":"110222991870854778724082971333105906777328061970448875974576460135015541883929","price":"0.01","size":"8136.4","side":"BUY","hash":"144b78bce30520486880e2addf3788e6465c9155","best_bid":"0.991","best_ask":"1"},{"asset_id":"103575991306220918671611575108050794364462782362354955892418399227289531345027","price":"0.99","size":"8136.4","side":"SELL","hash":"164e3b343412d48e25a279da2581200880f3f35f","best_bid":"0","best_ask":"0.009"}],"timestamp":"1768359585044","event_type":"price_change"}
PONG
{"market":"0x5977c69bca02e6cc150855b0faec463b38be463f141ec37ea5c8a1a1e986e0d3","price_changes":[{"asset_id":"103575991306220918671611575108050794364462782362354955892418399227289531345027","price":"0.03","size":"848","side":"SELL","hash":"e703b9f202af6ce09bcb51724f78b94abb32c5c6","best_bid":"0","best_ask":"0.009"},{"asset_id":"110222991870854778724082971333105906777328061970448875974576460135015541883929","price":"0.97","size":"848","side":"BUY","hash":"e85974c25b14f4d827f20da6ba202ad7010acbc6","best_bid":"0.991","best_ask":"1"}],"timestamp":"1768359585238","event_type":"price_change"}
{"market":"0x5977c69bca02e6cc150855b0faec463b38be463f141ec37ea5c8a1a1e986e0d3","price_changes":[{"asset_id":"110222991870854778724082971333105906777328061970448875974576460135015541883929","price":"0.96","size":"487.78","side":"BUY","hash":"0c88851209d1ee16979b6b5d4ee4b142ea5d431f","best_bid":"0.991","best_ask":"1"},{"asset_id":"103575991306220918671611575108050794364462782362354955892418399227289531345027","price":"0.04","size":"487.78","side":"SELL","hash":"ab615c9143c70c63765e72ed5c5bdae1eca2fa9e","best_bid":"0","best_ask":"0.009"}],"timestamp":"1768359585239","event_type":"price_change"}
{"market":"0x5977c69bca02e6cc150855b0faec463b38be463f141ec37ea5c8a1a1e986e0d3","price_changes":[{"asset_id":"110222991870854778724082971333105906777328061970448875974576460135015541883929","price":"0.98","size":"1721.53","side":"BUY","hash":"0c88851209d1ee16979b6b5d4ee4b142ea5d431f","best_bid":"0.991","best_ask":"1"},{"asset_id":"103575991306220918671611575108050794364462782362354955892418399227289531345027","price":"0.02","size":"1721.53","side":"SELL","hash":"ab615c9143c70c63765e72ed5c5bdae1eca2fa9e","best_bid":"0","best_ask":"0.009"}],"timestamp":"1768359585239","event_type":"price_change"}
{"market":"0x5977c69bca02e6cc150855b0faec463b38be463f141ec37ea5c8a1a1e986e0d3","price_changes":[{"asset_id":"110222991870854778724082971333105906777328061970448875974576460135015541883929","price":"0.95","size":"329.51","side":"BUY","hash":"0c88851209d1ee16979b6b5d4ee4b142ea5d431f","best_bid":"0.991","best_ask":"1"},{"asset_id":"103575991306220918671611575108050794364462782362354955892418399227289531345027","price":"0.05","size":"329.51","side":"SELL","hash":"ab615c9143c70c63765e72ed5c5bdae1eca2fa9e","best_bid":"0","best_ask":"0.009"}],"timestamp":"1768359585239","event_type":"price_change"}
{"market":"0x5977c69bca02e6cc150855b0faec463b38be463f141ec37ea5c8a1a1e986e0d3","price_changes":[{"asset_id":"110222991870854778724082971333105906777328061970448875974576460135015541883929","price":"0.94","size":"695.16","side":"BUY","hash":"0c88851209d1ee16979b6b5d4ee4b142ea5d431f","best_bid":"0.991","best_ask":"1"},{"asset_id":"103575991306220918671611575108050794364462782362354955892418399227289531345027","price":"0.06","size":"695.16","side":"SELL","hash":"ab615c9143c70c63765e72ed5c5bdae1eca2fa9e","best_bid":"0","best_ask":"0.009"}],"timestamp":"1768359585239","event_type":"price_change"}
{"market":"0x5977c69bca02e6cc150855b0faec463b38be463f141ec37ea5c8a1a1e986e0d3","price_changes":[{"asset_id":"110222991870854778724082971333105906777328061970448875974576460135015541883929","price":"0.01","size":"8131.4","side":"BUY","hash":"f0f6d039ebb53866a3a144407b08a120619a1f30","best_bid":"0.991","best_ask":"1"},{"asset_id":"103575991306220918671611575108050794364462782362354955892418399227289531345027","price":"0.99","size":"8131.4","side":"SELL","hash":"2ac910f1983f7f5b8765100992d0526f1fc1ecd4","best_bid":"0","best_ask":"0.009"}],"timestamp":"1768359585593","event_type":"price_change"}
{"market":"0x5977c69bca02e6cc150855b0faec463b38be463f141ec37ea5c8a1a1e986e0d3","price_changes":[{"asset_id":"110222991870854778724082971333105906777328061970448875974576460135015541883929","price":"0.81","size":"484.75","side":"BUY","hash":"2769fb3bfda7f05d88d0ed12c62ddf3a5ffb100c","best_bid":"0.991","best_ask":"1"},{"asset_id":"103575991306220918671611575108050794364462782362354955892418399227289531345027","price":"0.19","size":"484.75","side":"SELL","hash":"e5de9ba2f531b0aecfc62f4bff26ca8dd71e10aa","best_bid":"0","best_ask":"0.009"}],"timestamp":"1768359585656","event_type":"price_change"}
{"market":"0x5977c69bca02e6cc150855b0faec463b38be463f141ec37ea5c8a1a1e986e0d3","price_changes":[{"asset_id":"110222991870854778724082971333105906777328061970448875974576460135015541883929","price":"0.01","size":"8126.4","side":"BUY","hash":"cf5f8f26ad7798f8a4d425e0eb1983d9fbf92a22","best_bid":"0.991","best_ask":"1"},{"asset_id":"103575991306220918671611575108050794364462782362354955892418399227289531345027","price":"0.99","size":"8126.4","side":"SELL","hash":"668dee8070c1d0fe0b462b97ffa5058c169c915c","best_bid":"0","best_ask":"0.009"}],"timestamp":"1768359585762","event_type":"price_change"}
{"market":"0x5977c69bca02e6cc150855b0faec463b38be463f141ec37ea5c8a1a1e986e0d3","price_changes":[{"asset_id":"110222991870854778724082971333105906777328061970448875974576460135015541883929","price":"0.98","size":"1021.53","side":"BUY","hash":"10891e1b642ff671bcc9913e721647a1ba7f9ede","best_bid":"0.991","best_ask":"1"},{"asset_id":"103575991306220918671611575108050794364462782362354955892418399227289531345027","price":"0.02","size":"1021.53","side":"SELL","hash":"ab369273d0af2961971de7aae056395b5aa80187","best_bid":"0","best_ask":"0.009"}],"timestamp":"1768359585785","event_type":"price_change"}
{"market":"0x5977c69bca02e6cc150855b0faec463b38be463f141ec37ea5c8a1a1e986e0d3","price_changes":[{"asset_id":"110222991870854778724082971333105906777328061970448875974576460135015541883929","price":"0.01","size":"8121.4","side":"BUY","hash":"6865918962c0af78dc308d7af1158a3853358aec","best_bid":"0.991","best_ask":"1"},{"asset_id":"103575991306220918671611575108050794364462782362354955892418399227289531345027","price":"0.99","size":"8121.4","side":"SELL","hash":"1c28cf065bc9b4b79dfd80c01ab5cd68e7919700","best_bid":"0","best_ask":"0.009"}],"timestamp":"1768359585798","event_type":"price_change"}
{"market":"0x5977c69bca02e6cc150855b0faec463b38be463f141ec37ea5c8a1a1e986e0d3","price_changes":[{"asset_id":"110222991870854778724082971333105906777328061970448875974576460135015541883929","price":"0.8","size":"397","side":"BUY","hash":"30e99e6f5e99f73cff1c5ab99c03daaad5f0e264","best_bid":"0.991","best_ask":"1"},{"asset_id":"103575991306220918671611575108050794364462782362354955892418399227289531345027","price":"0.2","size":"397","side":"SELL","hash":"978a9119e1b2efaea26a7642491dfb03d099d820","best_bid":"0","best_ask":"0.009"}],"timestamp":"1768359585818","event_type":"price_change"}
{"market":"0x5977c69bca02e6cc150855b0faec463b38be463f141ec37ea5c8a1a1e986e0d3","price_changes":[{"asset_id":"110222991870854778724082971333105906777328061970448875974576460135015541883929","price":"0.83","size":"418.78","side":"BUY","hash":"62d3f460231e9702bb2d6255c1c924f28351522a","best_bid":"0.991","best_ask":"1"},{"asset_id":"103575991306220918671611575108050794364462782362354955892418399227289531345027","price":"0.17","size":"418.78","side":"SELL","hash":"a306c7859fda43ee66cb54e650f15bc0f0fd2165","best_bid":"0","best_ask":"0.009"}],"timestamp":"1768359585943","event_type":"price_change"}
{"market":"0x5977c69bca02e6cc150855b0faec463b38be463f141ec37ea5c8a1a1e986e0d3","price_changes":[{"asset_id":"110222991870854778724082971333105906777328061970448875974576460135015541883929","price":"0.83","size":"428.78","side":"BUY","hash":"2e7fd154b17a0b61e331df337c09afa9f06caae1","best_bid":"0.991","best_ask":"1"},{"asset_id":"103575991306220918671611575108050794364462782362354955892418399227289531345027","price":"0.17","size":"428.78","side":"SELL","hash":"ba272066be0a6fcd7b665b6ce7f0f52b7f1574bb","best_bid":"0","best_ask":"0.009"}],"timestamp":"1768359585968","event_type":"price_change"}
{"market":"0x5977c69bca02e6cc150855b0faec463b38be463f141ec37ea5c8a1a1e986e0d3","price_changes":[{"asset_id":"110222991870854778724082971333105906777328061970448875974576460135015541883929","price":"0.01","size":"8116.4","side":"BUY","hash":"223670493cb2348fc2a945fe1c85d651e6dc2122","best_bid":"0.991","best_ask":"1"},{"asset_id":"103575991306220918671611575108050794364462782362354955892418399227289531345027","price":"0.99","size":"8116.4","side":"SELL","hash":"5dbe3886cfbf5e05eb63a4dcb73ee9e738bfeacc","best_bid":"0","best_ask":"0.009"}],"timestamp":"1768359585998","event_type":"price_change"}
{"market":"0x5977c69bca02e6cc150855b0faec463b38be463f141ec37ea5c8a1a1e986e0d3","price_changes":[{"asset_id":"110222991870854778724082971333105906777328061970448875974576460135015541883929","price":"0.01","size":"8111.4","side":"BUY","hash":"c96382927dbe9ee03e974fa66c9be0d397c668a3","best_bid":"0.991","best_ask":"1"},{"asset_id":"103575991306220918671611575108050794364462782362354955892418399227289531345027","price":"0.99","size":"8111.4","side":"SELL","hash":"83983f61c18cc067d910cac19b4ac361a5e614c7","best_bid":"0","best_ask":"0.009"}],"timestamp":"1768359586004","event_type":"price_change"}
{"market":"0x5977c69bca02e6cc150855b0faec463b38be463f141ec37ea5c8a1a1e986e0d3","price_changes":[{"asset_id":"110222991870854778724082971333105906777328061970448875974576460135015541883929","price":"0.01","size":"8106.4","side":"BUY","hash":"219d7f84024c625c100fc087de33b18428bae06f","best_bid":"0.991","best_ask":"1"},{"asset_id":"103575991306220918671611575108050794364462782362354955892418399227289531345027","price":"0.99","size":"8106.4","side":"SELL","hash":"4f7f7f572d90846972f5470a1c9934f58a606bfb","best_bid":"0","best_ask":"0.009"}],"timestamp":"1768359586056","event_type":"price_change"}
{"market":"0x5977c69bca02e6cc150855b0faec463b38be463f141ec37ea5c8a1a1e986e0d3","price_changes":[{"asset_id":"110222991870854778724082971333105906777328061970448875974576460135015541883929","price":"0.01","size":"8101.4","side":"BUY","hash":"86bb311dc6e2453a85d3248b2f2d707031e7a28a","best_bid":"0.991","best_ask":"1"},{"asset_id":"103575991306220918671611575108050794364462782362354955892418399227289531345027","price":"0.99","size":"8101.4","side":"SELL","hash":"b1a04146f9024fa56d7b464d60ed044748d41899","best_bid":"0","best_ask":"0.009"}],"timestamp":"1768359586067","event_type":"price_change"}
{"market":"0x5977c69bca02e6cc150855b0faec463b38be463f141ec37ea5c8a1a1e986e0d3","price_changes":[{"asset_id":"110222991870854778724082971333105906777328061970448875974576460135015541883929","price":"0.985","size":"5","side":"BUY","hash":"9fc49b00deb83c3cc1ddf97a3e72248aaa66d704","best_bid":"0.991","best_ask":"1"},{"asset_id":"103575991306220918671611575108050794364462782362354955892418399227289531345027","price":"0.015","size":"5","side":"SELL","hash":"96137d84ff620aa25d6d31d9eeef480c15d93547","best_bid":"0","best_ask":"0.009"}],"timestamp":"1768359586379","event_type":"price_change"}
{"market":"0x5977c69bca02e6cc150855b0faec463b38be463f141ec37ea5c8a1a1e986e0d3","price_changes":[{"asset_id":"110222991870854778724082971333105906777328061970448875974576460135015541883929","price":"0.99","size":"406.83","side":"BUY","hash":"fe7e20096ff8c68327712042c40abe48362f4db6","best_bid":"0.99","best_ask":"1"},{"asset_id":"103575991306220918671611575108050794364462782362354955892418399227289531345027","price":"0.01","size":"406.83","side":"SELL","hash":"804826a61e5ad621fe641b566ad37a831b10e1ed","best_bid":"0","best_ask":"0.01"}],"timestamp":"1768359586608","event_type":"price_change"}
{"market":"0x5977c69bca02e6cc150855b0faec463b38be463f141ec37ea5c8a1a1e986e0d3","price_changes":[{"asset_id":"110222991870854778724082971333105906777328061970448875974576460135015541883929","price":"0.991","size":"0","side":"BUY","hash":"fe7e20096ff8c68327712042c40abe48362f4db6","best_bid":"0.99","best_ask":"1"},{"asset_id":"103575991306220918671611575108050794364462782362354955892418399227289531345027","price":"0.009","size":"0","side":"SELL","hash":"804826a61e5ad621fe641b566ad37a831b10e1ed","best_bid":"0","best_ask":"0.01"}],"timestamp":"1768359586608","event_type":"price_change"}
{"market":"0x5977c69bca02e6cc150855b0faec463b38be463f141ec37ea5c8a1a1e986e0d3","price_changes":[{"asset_id":"103575991306220918671611575108050794364462782362354955892418399227289531345027","price":"0.01","size":"406.83","side":"SELL","hash":"804826a61e5ad621fe641b566ad37a831b10e1ed","best_bid":"0","best_ask":"0.01"},{"asset_id":"110222991870854778724082971333105906777328061970448875974576460135015541883929","price":"0.99","size":"406.83","side":"BUY","hash":"fe7e20096ff8c68327712042c40abe48362f4db6","best_bid":"0.99","best_ask":"1"}],"timestamp":"1768359586608","event_type":"price_change"}
{"market":"0x5977c69bca02e6cc150855b0faec463b38be463f141ec37ea5c8a1a1e986e0d3","asset_id":"103575991306220918671611575108050794364462782362354955892418399227289531345027","bids":[],"asks":[{"price":"0.999","size":"270"},{"price":"0.998","size":"60"},{"price":"0.99","size":"8101.4"},{"price":"0.98","size":"4061.8"},{"price":"0.97","size":"2960.5"},{"price":"0.96","size":"2724.52"},{"price":"0.95","size":"2540"},{"price":"0.94","size":"2505"},{"price":"0.93","size":"2505"},{"price":"0.92","size":"2505"},{"price":"0.91","size":"2505"},{"price":"0.9","size":"2515"},{"price":"0.89","size":"5"},{"price":"0.88","size":"10"},{"price":"0.87","size":"5"},{"price":"0.86","size":"5"},{"price":"0.85","size":"10"},{"price":"0.84","size":"5"},{"price":"0.83","size":"5"},{"price":"0.82","size":"5"},{"price":"0.81","size":"380"},{"price":"0.8","size":"420"},{"price":"0.79","size":"380"},{"price":"0.78","size":"380"},{"price":"0.77","size":"380"},{"price":"0.76","size":"380"},{"price":"0.75","size":"413.5"},{"price":"0.74","size":"380"},{"price":"0.73","size":"380"},{"price":"0.72","size":"403.14"},{"price":"0.71","size":"380"},{"price":"0.7","size":"606.69"},{"price":"0.69","size":"380"},{"price":"0.68","size":"385"},{"price":"0.67","size":"380"},{"price":"0.66","size":"385"},{"price":"0.65","size":"398.93"},{"price":"0.64","size":"394.18"},{"price":"0.63","size":"403.13"},{"price":"0.62","size":"380"},{"price":"0.61","size":"374.09"},{"price":"0.6","size":"39"},{"price":"0.59","size":"5"},{"price":"0.58","size":"28.41"},{"price":"0.57","size":"10"},{"price":"0.56","size":"16"},{"price":"0.55","size":"319.33"},{"price":"0.54","size":"10"},{"price":"0.53","size":"15"},{"price":"0.52","size":"88.05"},{"price":"0.51","size":"5"},{"price":"0.5","size":"25"},{"price":"0.49","size":"107.65"},{"price":"0.48","size":"43"},{"price":"0.47","size":"380"},{"price":"0.46","size":"380"},{"price":"0.45","size":"380"},{"price":"0.44","size":"395"},{"price":"0.43","size":"385"},{"price":"0.42","size":"385"},{"price":"0.41","size":"390"},{"price":"0.4","size":"396"},{"price":"0.39","size":"385"},{"price":"0.38","size":"380"},{"price":"0.37","size":"400.24"},{"price":"0.36","size":"516.18"},{"price":"0.35","size":"530.75"},{"price":"0.34","size":"510.37"},{"price":"0.33","size":"298.95"},{"price":"0.32","size":"490.24"},{"price":"0.31","size":"474.01"},{"price":"0.3","size":"677.5"},{"price":"0.29","size":"682.74"},{"price":"0.28","size":"582.84"},{"price":"0.27","size":"414.37"},{"price":"0.26","size":"490.67"},{"price":"0.259","size":"5"},{"price":"0.25","size":"820.01"},{"price":"0.24","size":"659.24"},{"price":"0.23","size":"470"},{"price":"0.22","size":"389.97"},{"price":"0.21","size":"385"},{"price":"0.2","size":"397"},{"price":"0.19","size":"484.75"},{"price":"0.18","size":"380"},{"price":"0.17","size":"428.78"},{"price":"0.16","size":"396.56"},{"price":"0.15","size":"406.25"},{"price":"0.14","size":"905.94"},{"price":"0.13","size":"380"},{"price":"0.12","size":"1391.36"},{"price":"0.11","size":"1390"},{"price":"0.1","size":"424.19"},{"price":"0.09","size":"380"},{"price":"0.08","size":"594.2"},{"price":"0.07","size":"453"},{"price":"0.06","size":"695.16"},{"price":"0.05","size":"329.51"},{"price":"0.04","size":"487.78"},{"price":"0.03","size":"848"},{"price":"0.02","size":"1021.53"},{"price":"0.015","size":"5"},{"price":"0.01","size":"406.83"}],"hash":"804826a61e5ad621fe641b566ad37a831b10e1ed","timestamp":"1768359586608","event_type":"book"}
{"market":"0x5977c69bca02e6cc150855b0faec463b38be463f141ec37ea5c8a1a1e986e0d3","asset_id":"110222991870854778724082971333105906777328061970448875974576460135015541883929","bids":[{"price":"0.001","size":"270"},{"price":"0.002","size":"60"},{"price":"0.01","size":"8101.4"},{"price":"0.02","size":"4061.8"},{"price":"0.03","size":"2960.5"},{"price":"0.04","size":"2724.52"},{"price":"0.05","size":"2540"},{"price":"0.06","size":"2505"},{"price":"0.07","size":"2505"},{"price":"0.08","size":"2505"},{"price":"0.09","size":"2505"},{"price":"0.1","size":"2515"},{"price":"0.11","size":"5"},{"price":"0.12","size":"10"},{"price":"0.13","size":"5"},{"price":"0.14","size":"5"},{"price":"0.15","size":"10"},{"price":"0.16","size":"5"},{"price":"0.17","size":"5"},{"price":"0.18","size":"5"},{"price":"0.19","size":"380"},{"price":"0.2","size":"420"},{"price":"0.21","size":"380"},{"price":"0.22","size":"380"},{"price":"0.23","size":"380"},{"price":"0.24","size":"380"},{"price":"0.25","size":"413.5"},{"price":"0.26","size":"380"},{"price":"0.27","size":"380"},{"price":"0.28","size":"403.14"},{"price":"0.29","size":"380"},{"price":"0.3","size":"606.69"},{"price":"0.31","size":"380"},{"price":"0.32","size":"385"},{"price":"0.33","size":"380"},{"price":"0.34","size":"385"},{"price":"0.35","size":"398.93"},{"price":"0.36","size":"394.18"},{"price":"0.37","size":"403.13"},{"price":"0.38","size":"380"},{"price":"0.39","size":"374.09"},{"price":"0.4","size":"39"},{"price":"0.41","size":"5"},{"price":"0.42","size":"28.41"},{"price":"0.43","size":"10"},{"price":"0.44","size":"16"},{"price":"0.45","size":"319.33"},{"price":"0.46","size":"10"},{"price":"0.47","size":"15"},{"price":"0.48","size":"88.05"},{"price":"0.49","size":"5"},{"price":"0.5","size":"25"},{"price":"0.51","size":"107.65"},{"price":"0.52","size":"43"},{"price":"0.53","size":"380"},{"price":"0.54","size":"380"},{"price":"0.55","size":"380"},{"price":"0.56","size":"395"},{"price":"0.57","size":"385"},{"price":"0.58","size":"385"},{"price":"0.59","size":"390"},{"price":"0.6","size":"396"},{"price":"0.61","size":"385"},{"price":"0.62","size":"380"},{"price":"0.63","size":"400.24"},{"price":"0.64","size":"516.18"},{"price":"0.65","size":"530.75"},{"price":"0.66","size":"510.37"},{"price":"0.67","size":"298.95"},{"price":"0.68","size":"490.24"},{"price":"0.69","size":"474.01"},{"price":"0.7","size":"677.5"},{"price":"0.71","size":"682.74"},{"price":"0.72","size":"582.84"},{"price":"0.73","size":"414.37"},{"price":"0.74","size":"490.67"},{"price":"0.741","size":"5"},{"price":"0.75","size":"820.01"},{"price":"0.76","size":"659.24"},{"price":"0.77","size":"470"},{"price":"0.78","size":"389.97"},{"price":"0.79","size":"385"},{"price":"0.8","size":"397"},{"price":"0.81","size":"484.75"},{"price":"0.82","size":"380"},{"price":"0.83","size":"428.78"},{"price":"0.84","size":"396.56"},{"price":"0.85","size":"406.25"},{"price":"0.86","size":"905.94"},{"price":"0.87","size":"380"},{"price":"0.88","size":"1391.36"},{"price":"0.89","size":"1390"},{"price":"0.9","size":"424.19"},{"price":"0.91","size":"380"},{"price":"0.92","size":"594.2"},{"price":"0.93","size":"453"},{"price":"0.94","size":"695.16"},{"price":"0.95","size":"329.51"},{"price":"0.96","size":"487.78"},{"price":"0.97","size":"848"},{"price":"0.98","size":"1021.53"},{"price":"0.985","size":"5"},{"price":"0.99","size":"406.83"}],"asks":[],"hash":"fe7e20096ff8c68327712042c40abe48362f4db6","timestamp":"1768359586608","event_type":"book"}
{"market":"0x5977c69bca02e6cc150855b0faec463b38be463f141ec37ea5c8a1a1e986e0d3","price_changes":[{"asset_id":"110222991870854778724082971333105906777328061970448875974576460135015541883929","price":"0.741","size":"0","side":"BUY","hash":"cecdbe269cc630548dcceb80ade5c2596ebd5fdd","best_bid":"0.99","best_ask":"1"},{"asset_id":"103575991306220918671611575108050794364462782362354955892418399227289531345027","price":"0.259","size":"0","side":"SELL","hash":"e9a34b6e93ffd49d31fb178234568114af02ef51","best_bid":"0","best_ask":"0.01"}],"timestamp":"1768359586616","event_type":"price_change"}
{"market":"0x5977c69bca02e6cc150855b0faec463b38be463f141ec37ea5c8a1a1e986e0d3","asset_id":"103575991306220918671611575108050794364462782362354955892418399227289531345027","price":"0.01","size":"1817.288","fee_rate_bps":"1000","side":"BUY","timestamp":"1768359586658","event_type":"last_trade_price","transaction_hash":"0xc7ee073a6424ef331f9a501663444884243b2ba242434f2a2791e6c2d4a3bad4"}
{"market":"0x5977c69bca02e6cc150855b0faec463b38be463f141ec37ea5c8a1a1e986e0d3","price_changes":[{"asset_id":"110222991870854778724082971333105906777328061970448875974576460135015541883929","price":"0.981","size":"700","side":"BUY","hash":"2f015ca118ae81d1a5526cc0c09681cc3660c0f8","best_bid":"0.99","best_ask":"1"},{"asset_id":"103575991306220918671611575108050794364462782362354955892418399227289531345027","price":"0.019","size":"700","side":"SELL","hash":"caa0fe82719e72e012b4b3e6b4e9d4309561bd40","best_bid":"0","best_ask":"0.01"}],"timestamp":"1768359586697","event_type":"price_change"}
{"market":"0x5977c69bca02e6cc150855b0faec463b38be463f141ec37ea5c8a1a1e986e0d3","price_changes":[{"asset_id":"110222991870854778724082971333105906777328061970448875974576460135015541883929","price":"0.99","size":"411.83","side":"BUY","hash":"a5ad8454a0205562398b2408ad04a5577dc6cea9","best_bid":"0.99","best_ask":"1"},{"asset_id":"103575991306220918671611575108050794364462782362354955892418399227289531345027","price":"0.01","size":"411.83","side":"SELL","hash":"de0805e3bf7dd70becad02416ec6e6ee4045f5e0","best_bid":"0","best_ask":"0.01"}],"timestamp":"1768359586913","event_type":"price_change"}
{"market":"0x5977c69bca02e6cc150855b0faec463b38be463f141ec37ea5c8a1a1e986e0d3","price_changes":[{"asset_id":"110222991870854778724082971333105906777328061970448875974576460135015541883929","price":"0.83","size":"418.78","side":"BUY","hash":"a85f8d2aebaf51574e59c4a37a0bc456cbee9d80","best_bid":"0.99","best_ask":"1"},{"asset_id":"103575991306220918671611575108050794364462782362354955892418399227289531345027","price":"0.17","size":"418.78","side":"SELL","hash":"9beb126521d96ce16685cb9b105ba622c0beb06a","best_bid":"0","best_ask":"0.01"}],"timestamp":"1768359587042","event_type":"price_change"}
{"market":"0x5977c69bca02e6cc150855b0faec463b38be463f141ec37ea5c8a1a1e986e0d3","price_changes":[{"asset_id":"110222991870854778724082971333105906777328061970448875974576460135015541883929","price":"0.82","size":"390","side":"BUY","hash":"1bf6f508534306279de8a089cdb45ca67e24b2b4","best_bid":"0.99","best_ask":"1"},{"asset_id":"103575991306220918671611575108050794364462782362354955892418399227289531345027","price":"0.18","size":"390","side":"SELL","hash":"5534f0f3a9f38548b48d05bb2e351e2c58717fe9","best_bid":"0","best_ask":"0.01"}],"timestamp":"1768359587066","event_type":"price_change"}
{"market":"0x5977c69bca02e6cc150855b0faec463b38be463f141ec37ea5c8a1a1e986e0d3","price_changes":[{"asset_id":"110222991870854778724082971333105906777328061970448875974576460135015541883929","price":"0.99","size":"311.83","side":"BUY","hash":"82f2dedaee0ab5c3cea633955c594ff8c760e6f8","best_bid":"0.99","best_ask":"1"},{"asset_id":"103575991306220918671611575108050794364462782362354955892418399227289531345027","price":"0.01","size":"311.83","side":"SELL","hash":"68d44e7a61c581b5c0c7fb99bd3296b64050904a","best_bid":"0","best_ask":"0.01"}],"timestamp":"1768359587469","event_type":"price_change"}
{"market":"0x5977c69bca02e6cc150855b0faec463b38be463f141ec37ea5c8a1a1e986e0d3","asset_id":"103575991306220918671611575108050794364462782362354955892418399227289531345027","bids":[],"asks":[{"price":"0.999","size":"270"},{"price":"0.998","size":"60"},{"price":"0.99","size":"8101.4"},{"price":"0.98","size":"4061.8"},{"price":"0.97","size":"2960.5"},{"price":"0.96","size":"2724.52"},{"price":"0.95","size":"2540"},{"price":"0.94","size":"2505"},{"price":"0.93","size":"2505"},{"price":"0.92","size":"2505"},{"price":"0.91","size":"2505"},{"price":"0.9","size":"2515"},{"price":"0.89","size":"5"},{"price":"0.88","size":"10"},{"price":"0.87","size":"5"},{"price":"0.86","size":"5"},{"price":"0.85","size":"10"},{"price":"0.84","size":"5"},{"price":"0.83","size":"5"},{"price":"0.82","size":"5"},{"price":"0.81","size":"380"},{"price":"0.8","size":"420"},{"price":"0.79","size":"380"},{"price":"0.78","size":"380"},{"price":"0.77","size":"380"},{"price":"0.76","size":"380"},{"price":"0.75","size":"413.5"},{"price":"0.74","size":"380"},{"price":"0.73","size":"380"},{"price":"0.72","size":"403.14"},{"price":"0.71","size":"380"},{"price":"0.7","size":"606.69"},{"price":"0.69","size":"380"},{"price":"0.68","size":"385"},{"price":"0.67","size":"380"},{"price":"0.66","size":"385"},{"price":"0.65","size":"398.93"},{"price":"0.64","size":"394.18"},{"price":"0.63","size":"403.13"},{"price":"0.62","size":"380"},{"price":"0.61","size":"374.09"},{"price":"0.6","size":"39"},{"price":"0.59","size":"5"},{"price":"0.58","size":"28.41"},{"price":"0.57","size":"10"},{"price":"0.56","size":"16"},{"price":"0.55","size":"319.33"},{"price":"0.54","size":"10"},{"price":"0.53","size":"15"},{"price":"0.52","size":"88.05"},{"price":"0.51","size":"5"},{"price":"0.5","size":"25"},{"price":"0.49","size":"107.65"},{"price":"0.48","size":"43"},{"price":"0.47","size":"380"},{"price":"0.46","size":"380"},{"price":"0.45","size":"380"},{"price":"0.44","size":"395"},{"price":"0.43","size":"385"},{"price":"0.42","size":"385"},{"price":"0.41","size":"390"},{"price":"0.4","size":"396"},{"price":"0.39","size":"385"},{"price":"0.38","size":"380"},{"price":"0.37","size":"400.24"},{"price":"0.36","size":"516.18"},{"price":"0.35","size":"530.75"},{"price":"0.34","size":"510.37"},{"price":"0.33","size":"298.95"},{"price":"0.32","size":"490.24"},{"price":"0.31","size":"474.01"},{"price":"0.3","size":"677.5"},{"price":"0.29","size":"682.74"},{"price":"0.28","size":"582.84"},{"price":"0.27","size":"414.37"},{"price":"0.26","size":"490.67"},{"price":"0.25","size":"820.01"},{"price":"0.24","size":"659.24"},{"price":"0.23","size":"470"},{"price":"0.22","size":"389.97"},{"price":"0.21","size":"385"},{"price":"0.2","size":"397"},{"price":"0.19","size":"484.75"},{"price":"0.18","size":"390"},{"price":"0.17","size":"418.78"},{"price":"0.16","size":"396.56"},{"price":"0.15","size":"406.25"},{"price":"0.14","size":"905.94"},{"price":"0.13","size":"380"},{"price":"0.12","size":"1391.36"},{"price":"0.11","size":"1390"},{"price":"0.1","size":"424.19"},{"price":"0.09","size":"380"},{"price":"0.08","size":"594.2"},{"price":"0.07","size":"453"},{"price":"0.06","size":"695.16"},{"price":"0.05","size":"329.51"},{"price":"0.04","size":"487.78"},{"price":"0.03","size":"848"},{"price":"0.02","size":"1021.53"},{"price":"0.019","size":"700"},{"price":"0.015","size":"5"},{"price":"0.01","size":"311.83"}],"hash":"68d44e7a61c581b5c0c7fb99bd3296b64050904a","timestamp":"1768359587469","event_type":"book"}
{"market":"0x5977c69bca02e6cc150855b0faec463b38be463f141ec37ea5c8a1a1e986e0d3","asset_id":"110222991870854778724082971333105906777328061970448875974576460135015541883929","bids":[{"price":"0.001","size":"270"},{"price":"0.002","size":"60"},{"price":"0.01","size":"8101.4"},{"price":"0.02","size":"4061.8"},{"price":"0.03","size":"2960.5"},{"price":"0.04","size":"2724.52"},{"price":"0.05","size":"2540"},{"price":"0.06","size":"2505"},{"price":"0.07","size":"2505"},{"price":"0.08","size":"2505"},{"price":"0.09","size":"2505"},{"price":"0.1","size":"2515"},{"price":"0.11","size":"5"},{"price":"0.12","size":"10"},{"price":"0.13","size":"5"},{"price":"0.14","size":"5"},{"price":"0.15","size":"10"},{"price":"0.16","size":"5"},{"price":"0.17","size":"5"},{"price":"0.18","size":"5"},{"price":"0.19","size":"380"},{"price":"0.2","size":"420"},{"price":"0.21","size":"380"},{"price":"0.22","size":"380"},{"price":"0.23","size":"380"},{"price":"0.24","size":"380"},{"price":"0.25","size":"413.5"},{"price":"0.26","size":"380"},{"price":"0.27","size":"380"},{"price":"0.28","size":"403.14"},{"price":"0.29","size":"380"},{"price":"0.3","size":"606.69"},{"price":"0.31","size":"380"},{"price":"0.32","size":"385"},{"price":"0.33","size":"380"},{"price":"0.34","size":"385"},{"price":"0.35","size":"398.93"},{"price":"0.36","size":"394.18"},{"price":"0.37","size":"403.13"},{"price":"0.38","size":"380"},{"price":"0.39","size":"374.09"},{"price":"0.4","size":"39"},{"price":"0.41","size":"5"},{"price":"0.42","size":"28.41"},{"price":"0.43","size":"10"},{"price":"0.44","size":"16"},{"price":"0.45","size":"319.33"},{"price":"0.46","size":"10"},{"price":"0.47","size":"15"},{"price":"0.48","size":"88.05"},{"price":"0.49","size":"5"},{"price":"0.5","size":"25"},{"price":"0.51","size":"107.65"},{"price":"0.52","size":"43"},{"price":"0.53","size":"380"},{"price":"0.54","size":"380"},{"price":"0.55","size":"380"},{"price":"0.56","size":"395"},{"price":"0.57","size":"385"},{"price":"0.58","size":"385"},{"price":"0.59","size":"390"},{"price":"0.6","size":"396"},{"price":"0.61","size":"385"},{"price":"0.62","size":"380"},{"price":"0.63","size":"400.24"},{"price":"0.64","size":"516.18"},{"price":"0.65","size":"530.75"},{"price":"0.66","size":"510.37"},{"price":"0.67","size":"298.95"},{"price":"0.68","size":"490.24"},{"price":"0.69","size":"474.01"},{"price":"0.7","size":"677.5"},{"price":"0.71","size":"682.74"},{"price":"0.72","size":"582.84"},{"price":"0.73","size":"414.37"},{"price":"0.74","size":"490.67"},{"price":"0.75","size":"820.01"},{"price":"0.76","size":"659.24"},{"price":"0.77","size":"470"},{"price":"0.78","size":"389.97"},{"price":"0.79","size":"385"},{"price":"0.8","size":"397"},{"price":"0.81","size":"484.75"},{"price":"0.82","size":"390"},{"price":"0.83","size":"418.78"},{"price":"0.84","size":"396.56"},{"price":"0.85","size":"406.25"},{"price":"0.86","size":"905.94"},{"price":"0.87","size":"380"},{"price":"0.88","size":"1391.36"},{"price":"0.89","size":"1390"},{"price":"0.9","size":"424.19"},{"price":"0.91","size":"380"},{"price":"0.92","size":"594.2"},{"price":"0.93","size":"453"},{"price":"0.94","size":"695.16"},{"price":"0.95","size":"329.51"},{"price":"0.96","size":"487.78"},{"price":"0.97","size":"848"},{"price":"0.98","size":"1021.53"},{"price":"0.981","size":"700"},{"price":"0.985","size":"5"},{"price":"0.99","size":"311.83"}],"asks":[],"hash":"82f2dedaee0ab5c3cea633955c594ff8c760e6f8","timestamp":"1768359587469","event_type":"book"}
{"market":"0x5977c69bca02e6cc150855b0faec463b38be463f141ec37ea5c8a1a1e986e0d3","asset_id":"103575991306220918671611575108050794364462782362354955892418399227289531345027","price":"0.01","size":"100","fee_rate_bps":"1000","side":"BUY","timestamp":"1768359587501","event_type":"last_trade_price","transaction_hash":"0x632c563d0c4f660b0befd8889ac6dc2960165ef83948c26ac12886f1871173b7"}
{"market":"0x5977c69bca02e6cc150855b0faec463b38be463f141ec37ea5c8a1a1e986e0d3","price_changes":[{"asset_id":"110222991870854778724082971333105906777328061970448875974576460135015541883929","price":"0.741","size":"5","side":"BUY","hash":"273802fc106a2d1facdb10bd7803ccca218eeffa","best_bid":"0.99","best_ask":"1"},{"asset_id":"103575991306220918671611575108050794364462782362354955892418399227289531345027","price":"0.259","size":"5","side":"SELL","hash":"15b7fbac276aed6b987909e93d63f6fbdcd5032c","best_bid":"0","best_ask":"0.01"}],"timestamp":"1768359587577","event_type":"price_change"}
{"market":"0x5977c69bca02e6cc150855b0faec463b38be463f141ec37ea5c8a1a1e986e0d3","price_changes":[{"asset_id":"110222991870854778724082971333105906777328061970448875974576460135015541883929","price":"0.82","size":"380","side":"BUY","hash":"ea62a592ce156ba0630a0f1c6c791ff2c991cada","best_bid":"0.99","best_ask":"1"},{"asset_id":"103575991306220918671611575108050794364462782362354955892418399227289531345027","price":"0.18","size":"380","side":"SELL","hash":"6dd83c6d51e4ff0bf7e262ba1215018decb294bc","best_bid":"0","best_ask":"0.01"}],"timestamp":"1768359588144","event_type":"price_change"}
{"market":"0x5977c69bca02e6cc150855b0faec463b38be463f141ec37ea5c8a1a1e986e0d3","price_changes":[{"asset_id":"110222991870854778724082971333105906777328061970448875974576460135015541883929","price":"0.81","size":"494.75","side":"BUY","hash":"d0a9b2992e2f7b62bb8f298c588e9e12f3b4d4f7","best_bid":"0.99","best_ask":"1"},{"asset_id":"103575991306220918671611575108050794364462782362354955892418399227289531345027","price":"0.19","size":"494.75","side":"SELL","hash":"9296ac365d9afdc169c87c8be1978e93a7923146","best_bid":"0","best_ask":"0.01"}],"timestamp":"1768359588173","event_type":"price_change"}
{"market":"0x5977c69bca02e6cc150855b0faec463b38be463f141ec37ea5c8a1a1e986e0d3","price_changes":[{"asset_id":"110222991870854778724082971333105906777328061970448875974576460135015541883929","price":"0.81","size":"484.75","side":"BUY","hash":"2aa93475928690282166933408b47378afe1dda2","best_bid":"0.99","best_ask":"1"},{"asset_id":"103575991306220918671611575108050794364462782362354955892418399227289531345027","price":"0.19","size":"484.75","side":"SELL","hash":"e12c65fa137e47ded1a85529fc8afb26e9be9f2a","best_bid":"0","best_ask":"0.01"}],"timestamp":"1768359589242","event_type":"price_change"}
{"market":"0x5977c69bca02e6cc150855b0faec463b38be463f141ec37ea5c8a1a1e986e0d3","price_changes":[{"asset_id":"110222991870854778724082971333105906777328061970448875974576460135015541883929","price":"0.8","size":"407","side":"BUY","hash":"28ced131a13380286be78b01369d74ceaae7e8fb","best_bid":"0.99","best_ask":"1"},{"asset_id":"103575991306220918671611575108050794364462782362354955892418399227289531345027","price":"0.2","size":"407","side":"SELL","hash":"305e745e85f37a74a8cb2eb586bc1a8a427950ef","best_bid":"0","best_ask":"0.01"}],"timestamp":"1768359589264","event_type":"price_change"}
{"market":"0x5977c69bca02e6cc150855b0faec463b38be463f141ec37ea5c8a1a1e986e0d3","price_changes":[{"asset_id":"110222991870854778724082971333105906777328061970448875974576460135015541883929","price":"0.15","size":"5","side":"BUY","hash":"a567f53b0a964dca1aba9fd8cea46b44ce5d8732","best_bid":"0.99","best_ask":"1"},{"asset_id":"103575991306220918671611575108050794364462782362354955892418399227289531345027","price":"0.85","size":"5","side":"SELL","hash":"7be31ad39545dc4edbb7e4ad475ff89af71be47d","best_bid":"0","best_ask":"0.01"}],"timestamp":"1768359590044","event_type":"price_change"}
{"market":"0x5977c69bca02e6cc150855b0faec463b38be463f141ec37ea5c8a1a1e986e0d3","price_changes":[{"asset_id":"110222991870854778724082971333105906777328061970448875974576460135015541883929","price":"0.08","size":"2500","side":"BUY","hash":"a567f53b0a964dca1aba9fd8cea46b44ce5d8732","best_bid":"0.99","best_ask":"1"},{"asset_id":"103575991306220918671611575108050794364462782362354955892418399227289531345027","price":"0.92","size":"2500","side":"SELL","hash":"7be31ad39545dc4edbb7e4ad475ff89af71be47d","best_bid":"0","best_ask":"0.01"}],"timestamp":"1768359590044","event_type":"price_change"}
{"market":"0x5977c69bca02e6cc150855b0faec463b38be463f141ec37ea5c8a1a1e986e0d3","price_changes":[{"asset_id":"110222991870854778724082971333105906777328061970448875974576460135015541883929","price":"0.1","size":"2510","side":"BUY","hash":"a567f53b0a964dca1aba9fd8cea46b44ce5d8732","best_bid":"0.99","best_ask":"1"},{"asset_id":"103575991306220918671611575108050794364462782362354955892418399227289531345027","price":"0.9","size":"2510","side":"SELL","hash":"7be31ad39545dc4edbb7e4ad475ff89af71be47d","best_bid":"0","best_ask":"0.01"}],"timestamp":"1768359590044","event_type":"price_change"}
{"market":"0x5977c69bca02e6cc150855b0faec463b38be463f141ec37ea5c8a1a1e986e0d3","price_changes":[{"asset_id":"110222991870854778724082971333105906777328061970448875974576460135015541883929","price":"0.92","size":"589.2","side":"BUY","hash":"a567f53b0a964dca1aba9fd8cea46b44ce5d8732","best_bid":"0.99","best_ask":"1"},{"asset_id":"103575991306220918671611575108050794364462782362354955892418399227289531345027","price":"0.08","size":"589.2","side":"SELL","hash":"7be31ad39545dc4edbb7e4ad475ff89af71be47d","best_bid":"0","best_ask":"0.01"}],"timestamp":"1768359590044","event_type":"price_change"}
{"market":"0x5977c69bca02e6cc150855b0faec463b38be463f141ec37ea5c8a1a1e986e0d3","price_changes":[{"asset_id":"110222991870854778724082971333105906777328061970448875974576460135015541883929","price":"0.99","size":"306.83","side":"BUY","hash":"a567f53b0a964dca1aba9fd8cea46b44ce5d8732","best_bid":"0.99","best_ask":"1"},{"asset_id":"103575991306220918671611575108050794364462782362354955892418399227289531345027","price":"0.01","size":"306.83","side":"SELL","hash":"7be31ad39545dc4edbb7e4ad475ff89af71be47d","best_bid":"0","best_ask":"0.01"}],"timestamp":"1768359590044","event_type":"price_change"}
{"market":"0x5977c69bca02e6cc150855b0faec463b38be463f141ec37ea5c8a1a1e986e0d3","price_changes":[{"asset_id":"110222991870854778724082971333105906777328061970448875974576460135015541883929","price":"0.16","size":"0","side":"BUY","hash":"a567f53b0a964dca1aba9fd8cea46b44ce5d8732","best_bid":"0.99","best_ask":"1"},{"asset_id":"103575991306220918671611575108050794364462782362354955892418399227289531345027","price":"0.84","size":"0","side":"SELL","hash":"7be31ad39545dc4edbb7e4ad475ff89af71be47d","best_bid":"0","best_ask":"0.01"}],"timestamp":"1768359590044","event_type":"price_change"}
{"market":"0x5977c69bca02e6cc150855b0faec463b38be463f141ec37ea5c8a1a1e986e0d3","price_changes":[{"asset_id":"110222991870854778724082971333105906777328061970448875974576460135015541883929","price":"0.6","size":"391","side":"BUY","hash":"a567f53b0a964dca1aba9fd8cea46b44ce5d8732","best_bid":"0.99","best_ask":"1"},{"asset_id":"103575991306220918671611575108050794364462782362354955892418399227289531345027","price":"0.4","size":"391","side":"SELL","hash":"7be31ad39545dc4edbb7e4ad475ff89af71be47d","best_bid":"0","best_ask":"0.01"}],"timestamp":"1768359590044","event_type":"price_change"}
{"market":"0x5977c69bca02e6cc150855b0faec463b38be463f141ec37ea5c8a1a1e986e0d3","price_changes":[{"asset_id":"110222991870854778724082971333105906777328061970448875974576460135015541883929","price":"0.75","size":"815.01","side":"BUY","hash":"a567f53b0a964dca1aba9fd8cea46b44ce5d8732","best_bid":"0.99","best_ask":"1"},{"asset_id":"103575991306220918671611575108050794364462782362354955892418399227289531345027","price":"0.25","size":"815.01","side":"SELL","hash":"7be31ad39545dc4edbb7e4ad475ff89af71be47d","best_bid":"0","best_ask":"0.01"}],"timestamp":"1768359590044","event_type":"price_change"}
{"market":"0x5977c69bca02e6cc150855b0faec463b38be463f141ec37ea5c8a1a1e986e0d3","price_changes":[{"asset_id":"110222991870854778724082971333105906777328061970448875974576460135015541883929","price":"0.01","size":"8096.4","side":"BUY","hash":"a567f53b0a964dca1aba9fd8cea46b44ce5d8732","best_bid":"0.99","best_ask":"1"},{"asset_id":"103575991306220918671611575108050794364462782362354955892418399227289531345027","price":"0.99","size":"8096.4","side":"SELL","hash":"7be31ad39545dc4edbb7e4ad475ff89af71be47d","best_bid":"0","best_ask":"0.01"}],"timestamp":"1768359590044","event_type":"price_change"}
{"market":"0x5977c69bca02e6cc150855b0faec463b38be463f141ec37ea5c8a1a1e986e0d3","price_changes":[{"asset_id":"110222991870854778724082971333105906777328061970448875974576460135015541883929","price":"0.96","size":"482.78","side":"BUY","hash":"a567f53b0a964dca1aba9fd8cea46b44ce5d8732","best_bid":"0.99","best_ask":"1"},{"asset_id":"103575991306220918671611575108050794364462782362354955892418399227289531345027","price":"0.04","size":"482.78","side":"SELL","hash":"7be31ad39545dc4edbb7e4ad475ff89af71be47d","best_bid":"0","best_ask":"0.01"}],"timestamp":"1768359590044","event_type":"price_change"}
{"market":"0x5977c69bca02e6cc150855b0faec463b38be463f141ec37ea5c8a1a1e986e0d3","price_changes":[{"asset_id":"110222991870854778724082971333105906777328061970448875974576460135015541883929","price":"0.19","size":"375","side":"BUY","hash":"a567f53b0a964dca1aba9fd8cea46b44ce5d8732","best_bid":"0.99","best_ask":"1"},{"asset_id":"103575991306220918671611575108050794364462782362354955892418399227289531345027","price":"0.81","size":"375","side":"SELL","hash":"7be31ad39545dc4edbb7e4ad475ff89af71be47d","best_bid":"0","best_ask":"0.01"}],"timestamp":"1768359590044","event_type":"price_change"}
{"market":"0x5977c69bca02e6cc150855b0faec463b38be463f141ec37ea5c8a1a1e986e0d3","price_changes":[{"asset_id":"110222991870854778724082971333105906777328061970448875974576460135015541883929","price":"0.55","size":"375","side":"BUY","hash":"a567f53b0a964dca1aba9fd8cea46b44ce5d8732","best_bid":"0.99","best_ask":"1"},{"asset_id":"103575991306220918671611575108050794364462782362354955892418399227289531345027","price":"0.45","size":"375","side":"SELL","hash":"7be31ad39545dc4edbb7e4ad475ff89af71be47d","best_bid":"0","best_ask":"0.01"}],"timestamp":"1768359590044","event_type":"price_change"}
{"market":"0x5977c69bca02e6cc150855b0faec463b38be463f141ec37ea5c8a1a1e986e0d3","price_changes":[{"asset_id":"110222991870854778724082971333105906777328061970448875974576460135015541883929","price":"0.58","size":"380","side":"BUY","hash":"a567f53b0a964dca1aba9fd8cea46b44ce5d8732","best_bid":"0.99","best_ask":"1"},{"asset_id":"103575991306220918671611575108050794364462782362354955892418399227289531345027","price":"0.42","size":"380","side":"SELL","hash":"7be31ad39545dc4edbb7e4ad475ff89af71be47d","best_bid":"0","best_ask":"0.01"}],"timestamp":"1768359590044","event_type":"price_change"}
{"market":"0x5977c69bca02e6cc150855b0faec463b38be463f141ec37ea5c8a1a1e986e0d3","price_changes":[{"asset_id":"110222991870854778724082971333105906777328061970448875974576460135015541883929","price":"0.34","size":"380","side":"BUY","hash":"a567f53b0a964dca1aba9fd8cea46b44ce5d8732","best_bid":"0.99","best_ask":"1"},{"asset_id":"103575991306220918671611575108050794364462782362354955892418399227289531345027","price":"0.66","size":"380","side":"SELL","hash":"7be31ad39545dc4edbb7e4ad475ff89af71be47d","best_bid":"0","best_ask":"0.01"}],"timestamp":"1768359590044","event_type":"price_change"}
{"market":"0x5977c69bca02e6cc150855b0faec463b38be463f141ec37ea5c8a1a1e986e0d3","price_changes":[{"asset_id":"110222991870854778724082971333105906777328061970448875974576460135015541883929","price":"0.05","size":"2535","side":"BUY","hash":"a567f53b0a964dca1aba9fd8cea46b44ce5d8732","best_bid":"0.99","best_ask":"1"},{"asset_id":"103575991306220918671611575108050794364462782362354955892418399227289531345027","price":"0.95","size":"2535","side":"SELL","hash":"7be31ad39545dc4edbb7e4ad475ff89af71be47d","best_bid":"0","best_ask":"0.01"}],"timestamp":"1768359590044","event_type":"price_change"}
{"market":"0x5977c69bca02e6cc150855b0faec463b38be463f141ec37ea5c8a1a1e986e0d3","price_changes":[{"asset_id":"110222991870854778724082971333105906777328061970448875974576460135015541883929","price":"0.91","size":"375","side":"BUY","hash":"a567f53b0a964dca1aba9fd8cea46b44ce5d8732","best_bid":"0.99","best_ask":"1"},{"asset_id":"103575991306220918671611575108050794364462782362354955892418399227289531345027","price":"0.09","size":"375","side":"SELL","hash":"7be31ad39545dc4edbb7e4ad475ff89af71be47d","best_bid":"0","best_ask":"0.01"}],"timestamp":"1768359590044","event_type":"price_change"}
{"market":"0x5977c69bca02e6cc150855b0faec463b38be463f141ec37ea5c8a1a1e986e0d3","price_changes":[{"asset_id":"110222991870854778724082971333105906777328061970448875974576460135015541883929","price":"0.29","size":"375","side":"BUY","hash":"a567f53b0a964dca1aba9fd8cea46b44ce5d8732","best_bid":"0.99","best_ask":"1"},{"asset_id":"103575991306220918671611575108050794364462782362354955892418399227289531345027","price":"0.71","size":"375","side":"SELL","hash":"7be31ad39545dc4edbb7e4ad475ff89af71be47d","best_bid":"0","best_ask":"0.01"}],"timestamp":"1768359590044","event_type":"price_change"}
{"market":"0x5977c69bca02e6cc150855b0faec463b38be463f141ec37ea5c8a1a1e986e0d3","price_changes":[{"asset_id":"110222991870854778724082971333105906777328061970448875974576460135015541883929","price":"0.61","size":"380","side":"BUY","hash":"a567f53b0a964dca1aba9fd8cea46b44ce5d8732","best_bid":"0.99","best_ask":"1"},{"asset_id":"103575991306220918671611575108050794364462782362354955892418399227289531345027","price":"0.39","size":"380","side":"SELL","hash":"7be31ad39545dc4edbb7e4ad475ff89af71be47d","best_bid":"0","best_ask":"0.01"}],"timestamp":"1768359590044","event_type":"price_change"}
{"market":"0x5977c69bca02e6cc150855b0faec463b38be463f141ec37ea5c8a1a1e986e0d3","price_changes":[{"asset_id":"110222991870854778724082971333105906777328061970448875974576460135015541883929","price":"0.98","size":"1016.53","side":"BUY","hash":"a567f53b0a964dca1aba9fd8cea46b44ce5d8732","best_bid":"0.99","best_ask":"1"},{"asset_id":"103575991306220918671611575108050794364462782362354955892418399227289531345027","price":"0.02","size":"1016.53","side":"SELL","hash":"7be31ad39545dc4edbb7e4ad475ff89af71be47d","best_bid":"0","best_ask":"0.01"}],"timestamp":"1768359590044","event_type":"price_change"}
{"market":"0x5977c69bca02e6cc150855b0faec463b38be463f141ec37ea5c8a1a1e986e0d3","price_changes":[{"asset_id":"110222991870854778724082971333105906777328061970448875974576460135015541883929","price":"0.37","size":"398.13","side":"BUY","hash":"a567f53b0a964dca1aba9fd8cea46b44ce5d8732","best_bid":"0.99","best_ask":"1"},{"asset_id":"103575991306220918671611575108050794364462782362354955892418399227289531345027","price":"0.63","size":"398.13","side":"SELL","hash":"7be31ad39545dc4edbb7e4ad475ff89af71be47d","best_bid":"0","best_ask":"0.01"}],"timestamp":"1768359590044","event_type":"price_change"}
{"market":"0x5977c69bca02e6cc150855b0faec463b38be463f141ec37ea5c8a1a1e986e0d3","price_changes":[{"asset_id":"110222991870854778724082971333105906777328061970448875974576460135015541883929","price":"0.02","size":"4056.8","side":"BUY","hash":"a567f53b0a964dca1aba9fd8cea46b44ce5d8732","best_bid":"0.99","best_ask":"1"},{"asset_id":"103575991306220918671611575108050794364462782362354955892418399227289531345027","price":"0.98","size":"4056.8","side":"SELL","hash":"7be31ad39545dc4edbb7e4ad475ff89af71be47d","best_bid":"0","best_ask":"0.01"}],"timestamp":"1768359590044","event_type":"price_change"}
{"market":"0x5977c69bca02e6cc150855b0faec463b38be463f141ec37ea5c8a1a1e986e0d3","price_changes":[{"asset_id":"110222991870854778724082971333105906777328061970448875974576460135015541883929","price":"0.73","size":"409.37","side":"BUY","hash":"a567f53b0a964dca1aba9fd8cea46b44ce5d8732","best_bid":"0.99","best_ask":"1"},{"asset_id":"103575991306220918671611575108050794364462782362354955892418399227289531345027","price":"0.27","size":"409.37","side":"SELL","hash":"7be31ad39545dc4edbb7e4ad475ff89af71be47d","best_bid":"0","best_ask":"0.01"}],"timestamp":"1768359590044","event_type":"price_change"}
{"market":"0x5977c69bca02e6cc150855b0faec463b38be463f141ec37ea5c8a1a1e986e0d3","price_changes":[{"asset_id":"110222991870854778724082971333105906777328061970448875974576460135015541883929","price":"0.03","size":"2955.5","side":"BUY","hash":"a567f53b0a964dca1aba9fd8cea46b44ce5d8732","best_bid":"0.99","best_ask":"1"},{"asset_id":"103575991306220918671611575108050794364462782362354955892418399227289531345027","price":"0.97","size":"2955.5","side":"SELL","hash":"7be31ad39545dc4edbb7e4ad475ff89af71be47d","best_bid":"0","best_ask":"0.01"}],"timestamp":"1768359590044","event_type":"price_change"}
{"market":"0x5977c69bca02e6cc150855b0faec463b38be463f141ec37ea5c8a1a1e986e0d3","price_changes":[{"asset_id":"110222991870854778724082971333105906777328061970448875974576460135015541883929","price":"0.81","size":"479.75","side":"BUY","hash":"a567f53b0a964dca1aba9fd8cea46b44ce5d8732","best_bid":"0.99","best_ask":"1"},{"asset_id":"103575991306220918671611575108050794364462782362354955892418399227289531345027","price":"0.19","size":"479.75","side":"SELL","hash":"7be31ad39545dc4edbb7e4ad475ff89af71be47d","best_bid":"0","best_ask":"0.01"}],"timestamp":"1768359590044","event_type":"price_change"}
{"market":"0x5977c69bca02e6cc150855b0faec463b38be463f141ec37ea5c8a1a1e986e0d3","price_changes":[{"asset_id":"110222991870854778724082971333105906777328061970448875974576460135015541883929","price":"0.22","size":"375","side":"BUY","hash":"a567f53b0a964dca1aba9fd8cea46b44ce5d8732","best_bid":"0.99","best_ask":"1"},{"asset_id":"103575991306220918671611575108050794364462782362354955892418399227289531345027","price":"0.78","size":"375","side":"SELL","hash":"7be31ad39545dc4edbb7e4ad475ff89af71be47d","best_bid":"0","best_ask":"0.01"}],"timestamp":"1768359590044","event_type":"price_change"}
{"market":"0x5977c69bca02e6cc150855b0faec463b38be463f141ec37ea5c8a1a1e986e0d3","price_changes":[{"asset_id":"110222991870854778724082971333105906777328061970448875974576460135015541883929","price":"0.24","size":"375","side":"BUY","hash":"a567f53b0a964dca1aba9fd8cea46b44ce5d8732","best_bid":"0.99","best_ask":"1"},{"asset_id":"103575991306220918671611575108050794364462782362354955892418399227289531345027","price":"0.76","size":"375","side":"SELL","hash":"7be31ad39545dc4edbb7e4ad475ff89af71be47d","best_bid":"0","best_ask":"0.01"}],"timestamp":"1768359590044","event_type":"price_change"}
{"market":"0x5977c69bca02e6cc150855b0faec463b38be463f141ec37ea5c8a1a1e986e0d3","price_changes":[{"asset_id":"110222991870854778724082971333105906777328061970448875974576460135015541883929","price":"0.31","size":"375","side":"BUY","hash":"a567f53b0a964dca1aba9fd8cea46b44ce5d8732","best_bid":"0.99","best_ask":"1"},{"asset_id":"103575991306220918671611575108050794364462782362354955892418399227289531345027","price":"0.69","size":"375","side":"SELL","hash":"7be31ad39545dc4edbb7e4ad475ff89af71be47d","best_bid":"0","best_ask":"0.01"}],"timestamp":"1768359590044","event_type":"price_change"}
{"market":"0x5977c69bca02e6cc150855b0faec463b38be463f141ec37ea5c8a1a1e986e0d3","price_changes":[{"asset_id":"110222991870854778724082971333105906777328061970448875974576460135015541883929","price":"0.52","size":"38","side":"BUY","hash":"a567f53b0a964dca1aba9fd8cea46b44ce5d8732","best_bid":"0.99","best_ask":"1"},{"asset_id":"103575991306220918671611575108050794364462782362354955892418399227289531345027","price":"0.48","size":"38","side":"SELL","hash":"7be31ad39545dc4edbb7e4ad475ff89af71be47d","best_bid":"0","best_ask":"0.01"}],"timestamp":"1768359590044","event_type":"price_change"}
{"market":"0x5977c69bca02e6cc150855b0faec463b38be463f141ec37ea5c8a1a1e986e0d3","price_changes":[{"asset_id":"110222991870854778724082971333105906777328061970448875974576460135015541883929","price":"0.32","size":"380","side":"BUY","hash":"a567f53b0a964dca1aba9fd8cea46b44ce5d8732","best_bid":"0.99","best_ask":"1"},{"asset_id":"103575991306220918671611575108050794364462782362354955892418399227289531345027","price":"0.68","size":"380","side":"SELL","hash":"7be31ad39545dc4edbb7e4ad475ff89af71be47d","best_bid":"0","best_ask":"0.01"}],"timestamp":"1768359590044","event_type":"price_change"}
{"market":"0x5977c69bca02e6cc150855b0faec463b38be463f141ec37ea5c8a1a1e986e0d3","price_changes":[{"asset_id":"110222991870854778724082971333105906777328061970448875974576460135015541883929","price":"0.95","size":"324.51","side":"BUY","hash":"a567f53b0a964dca1aba9fd8cea46b44ce5d8732","best_bid":"0.99","best_ask":"1"},{"asset_id":"103575991306220918671611575108050794364462782362354955892418399227289531345027","price":"0.05","size":"324.51","side":"SELL","hash":"7be31ad39545dc4edbb7e4ad475ff89af71be47d","best_bid":"0","best_ask":"0.01"}],"timestamp":"1768359590044","event_type":"price_change"}
{"market":"0x5977c69bca02e6cc150855b0faec463b38be463f141ec37ea5c8a1a1e986e0d3","price_changes":[{"asset_id":"110222991870854778724082971333105906777328061970448875974576460135015541883929","price":"0.43","size":"5","side":"BUY","hash":"a567f53b0a964dca1aba9fd8cea46b44ce5d8732","best_bid":"0.99","best_ask":"1"},{"asset_id":"103575991306220918671611575108050794364462782362354955892418399227289531345027","price":"0.57","size":"5","side":"SELL","hash":"7be31ad39545dc4edbb7e4ad475ff89af71be47d","best_bid":"0","best_ask":"0.01"}],"timestamp":"1768359590044","event_type":"price_change"}
{"market":"0x5977c69bca02e6cc150855b0faec463b38be463f141ec37ea5c8a1a1e986e0d3","price_changes":[{"asset_id":"110222991870854778724082971333105906777328061970448875974576460135015541883929","price":"0.23","size":"375","side":"BUY","hash":"a567f53b0a964dca1aba9fd8cea46b44ce5d8732","best_bid":"0.99","best_ask":"1"},{"asset_id":"103575991306220918671611575108050794364462782362354955892418399227289531345027","price":"0.77","size":"375","side":"SELL","hash":"7be31ad39545dc4edbb7e4ad475ff89af71be47d","best_bid":"0","best_ask":"0.01"}],"timestamp":"1768359590044","event_type":"price_change"}
{"market":"0x5977c69bca02e6cc150855b0faec463b38be463f141ec37ea5c8a1a1e986e0d3","price_changes":[{"asset_id":"110222991870854778724082971333105906777328061970448875974576460135015541883929","price":"0.46","size":"5","side":"BUY","hash":"a567f53b0a964dca1aba9fd8cea46b44ce5d8732","best_bid":"0.99","best_ask":"1"},{"asset_id":"103575991306220918671611575108050794364462782362354955892418399227289531345027","price":"0.54","size":"5","side":"SELL","hash":"7be31ad39545dc4edbb7e4ad475ff89af71be47d","best_bid":"0","best_ask":"0.01"}],"timestamp":"1768359590044","event_type":"price_change"}
{"market":"0x5977c69bca02e6cc150855b0faec463b38be463f141ec37ea5c8a1a1e986e0d3","price_changes":[{"asset_id":"110222991870854778724082971333105906777328061970448875974576460135015541883929","price":"0.63","size":"395.24","side":"BUY","hash":"a567f53b0a964dca1aba9fd8cea46b44ce5d8732","best_bid":"0.99","best_ask":"1"},{"asset_id":"103575991306220918671611575108050794364462782362354955892418399227289531345027","price":"0.37","size":"395.24","side":"SELL","hash":"7be31ad39545dc4edbb7e4ad475ff89af71be47d","best_bid":"0","best_ask":"0.01"}],"timestamp":"1768359590044","event_type":"price_change"}
{"market":"0x5977c69bca02e6cc150855b0faec463b38be463f141ec37ea5c8a1a1e986e0d3","price_changes":[{"asset_id":"110222991870854778724082971333105906777328061970448875974576460135015541883929","price":"0.64","size":"511.18","side":"BUY","hash":"a567f53b0a964dca1aba9fd8cea46b44ce5d8732","best_bid":"0.99","best_ask":"1"},{"asset_id":"103575991306220918671611575108050794364462782362354955892418399227289531345027","price":"0.36","size":"511.18","side":"SELL","hash":"7be31ad39545dc4edbb7e4ad475ff89af71be47d","best_bid":"0","best_ask":"0.01"}],"timestamp":"1768359590044","event_type":"price_change"}
{"market":"0x5977c69bca02e6cc150855b0faec463b38be463f141ec37ea5c8a1a1e986e0d3","price_changes":[{"asset_id":"110222991870854778724082971333105906777328061970448875974576460135015541883929","price":"0.18","size":"0","side":"BUY","hash":"a567f53b0a964dca1aba9fd8cea46b44ce5d8732","best_bid":"0.99","best_ask":"1"},{"asset_id":"103575991306220918671611575108050794364462782362354955892418399227289531345027","price":"0.82","size":"0","side":"SELL","hash":"7be31ad39545dc4edbb7e4ad475ff89af71be47d","best_bid":"0","best_ask":"0.01"}],"timestamp":"1768359590044","event_type":"price_change"}
{"market":"0x5977c69bca02e6cc150855b0faec463b38be463f141ec37ea5c8a1a1e986e0d3","price_changes":[{"asset_id":"110222991870854778724082971333105906777328061970448875974576460135015541883929","price":"0.56","size":"390","side":"BUY","hash":"a567f53b0a964dca1aba9fd8cea46b44ce5d8732","best_bid":"0.99","best_ask":"1"},{"asset_id":"103575991306220918671611575108050794364462782362354955892418399227289531345027","price":"0.44","size":"390","side":"SELL","hash":"7be31ad39545dc4edbb7e4ad475ff89af71be47d","best_bid":"0","best_ask":"0.01"}],"timestamp":"1768359590044","event_type":"price_change"}
{"market":"0x5977c69bca02e6cc150855b0faec463b38be463f141ec37ea5c8a1a1e986e0d3","price_changes":[{"asset_id":"110222991870854778724082971333105906777328061970448875974576460135015541883929","price":"0.57","size":"380","side":"BUY","hash":"a567f53b0a964dca1aba9fd8cea46b44ce5d8732","best_bid":"0.99","best_ask":"1"},{"asset_id":"103575991306220918671611575108050794364462782362354955892418399227289531345027","price":"0.43","size":"380","side":"SELL","hash":"7be31ad39545dc4edbb7e4ad475ff89af71be47d","best_bid":"0","best_ask":"0.01"}],"timestamp":"1768359590044","event_type":"price_change"}
{"market":"0x5977c69bca02e6cc150855b0faec463b38be463f141ec37ea5c8a1a1e986e0d3","price_changes":[{"asset_id":"110222991870854778724082971333105906777328061970448875974576460135015541883929","price":"0.7","size":"672.5","side":"BUY","hash":"a567f53b0a964dca1aba9fd8cea46b44ce5d8732","best_bid":"0.99","best_ask":"1"},{"asset_id":"103575991306220918671611575108050794364462782362354955892418399227289531345027","price":"0.3","size":"672.5","side":"SELL","hash":"7be31ad39545dc4edbb7e4ad475ff89af71be47d","best_bid":"0","best_ask":"0.01"}],"timestamp":"1768359590044","event_type":"price_change"}
{"market":"0x5977c69bca02e6cc150855b0faec463b38be463f141ec37ea5c8a1a1e986e0d3","price_changes":[{"asset_id":"110222991870854778724082971333105906777328061970448875974576460135015541883929","price":"0.72","size":"577.84","side":"BUY","hash":"a567f53b0a964dca1aba9fd8cea46b44ce5d8732","best_bid":"0.99","best_ask":"1"},{"asset_id":"103575991306220918671611575108050794364462782362354955892418399227289531345027","price":"0.28","size":"577.84","side":"SELL","hash":"7be31ad39545dc4edbb7e4ad475ff89af71be47d","best_bid":"0","best_ask":"0.01"}],"timestamp":"1768359590044","event_type":"price_change"}
{"market":"0x5977c69bca02e6cc150855b0faec463b38be463f141ec37ea5c8a1a1e986e0d3","price_changes":[{"asset_id":"110222991870854778724082971333105906777328061970448875974576460135015541883929","price":"0.9","size":"419.19","side":"BUY","hash":"a567f53b0a964dca1aba9fd8cea46b44ce5d8732","best_bid":"0.99","best_ask":"1"},{"asset_id":"103575991306220918671611575108050794364462782362354955892418399227289531345027","price":"0.1","size":"419.19","side":"SELL","hash":"7be31ad39545dc4edbb7e4ad475ff89af71be47d","best_bid":"0","best_ask":"0.01"}],"timestamp":"1768359590044","event_type":"price_change"}
{"market":"0x5977c69bca02e6cc150855b0faec463b38be463f141ec37ea5c8a1a1e986e0d3","price_changes":[{"asset_id":"110222991870854778724082971333105906777328061970448875974576460135015541883929","price":"0.09","size":"2500","side":"BUY","hash":"a567f53b0a964dca1aba9fd8cea46b44ce5d8732","best_bid":"0.99","best_ask":"1"},{"asset_id":"103575991306220918671611575108050794364462782362354955892418399227289531345027","price":"0.91","size":"2500","side":"SELL","hash":"7be31ad39545dc4edbb7e4ad475ff89af71be47d","best_bid":"0","best_ask":"0.01"}],"timestamp":"1768359590044","event_type":"price_change"}
{"market":"0x5977c69bca02e6cc150855b0faec463b38be463f141ec37ea5c8a1a1e986e0d3","price_changes":[{"asset_id":"110222991870854778724082971333105906777328061970448875974576460135015541883929","price":"0.35","size":"393.93","side":"BUY","hash":"a567f53b0a964dca1aba9fd8cea46b44ce5d8732","best_bid":"0.99","best_ask":"1"},{"asset_id":"103575991306220918671611575108050794364462782362354955892418399227289531345027","price":"0.65","size":"393.93","side":"SELL","hash":"7be31ad39545dc4edbb7e4ad475ff89af71be47d","best_bid":"0","best_ask":"0.01"}],"timestamp":"1768359590044","event_type":"price_change"}
{"market":"0x5977c69bca02e6cc150855b0faec463b38be463f141ec37ea5c8a1a1e986e0d3","price_changes":[{"asset_id":"110222991870854778724082971333105906777328061970448875974576460135015541883929","price":"0.36","size":"390","side":"BUY","hash":"a567f53b0a964dca1aba9fd8cea46b44ce5d8732","best_bid":"0.99","best_ask":"1"},{"asset_id":"103575991306220918671611575108050794364462782362354955892418399227289531345027","price":"0.64","size":"390","side":"SELL","hash":"7be31ad39545dc4edbb7e4ad475ff89af71be47d","best_bid":"0","best_ask":"0.01"}],"timestamp":"1768359590044","event_type":"price_change"}
{"market":"0x5977c69bca02e6cc150855b0faec463b38be463f141ec37ea5c8a1a1e986e0d3","price_changes":[{"asset_id":"110222991870854778724082971333105906777328061970448875974576460135015541883929","price":"0.48","size":"83.05","side":"BUY","hash":"a567f53b0a964dca1aba9fd8cea46b44ce5d8732","best_bid":"0.99","best_ask":"1"},{"asset_id":"103575991306220918671611575108050794364462782362354955892418399227289531345027","price":"0.52","size":"83.05","side":"SELL","hash":"7be31ad39545dc4edbb7e4ad475ff89af71be47d","best_bid":"0","best_ask":"0.01"}],"timestamp":"1768359590044","event_type":"price_change"}
{"market":"0x5977c69bca02e6cc150855b0faec463b38be463f141ec37ea5c8a1a1e986e0d3","price_changes":[{"asset_id":"110222991870854778724082971333105906777328061970448875974576460135015541883929","price":"0.39","size":"369.09","side":"BUY","hash":"a567f53b0a964dca1aba9fd8cea46b44ce5d8732","best_bid":"0.99","best_ask":"1"},{"asset_id":"103575991306220918671611575108050794364462782362354955892418399227289531345027","price":"0.61","size":"369.09","side":"SELL","hash":"7be31ad39545dc4edbb7e4ad475ff89af71be47d","best_bid":"0","best_ask":"0.01"}],"timestamp":"1768359590044","event_type":"price_change"}
{"market":"0x5977c69bca02e6cc150855b0faec463b38be463f141ec37ea5c8a1a1e986e0d3","price_changes":[{"asset_id":"110222991870854778724082971333105906777328061970448875974576460135015541883929","price":"0.5","size":"20","side":"BUY","hash":"a567f53b0a964dca1aba9fd8cea46b44ce5d8732","best_bid":"0.99","best_ask":"1"},{"asset_id":"103575991306220918671611575108050794364462782362354955892418399227289531345027","price":"0.5","size":"20","side":"SELL","hash":"7be31ad39545dc4edbb7e4ad475ff89af71be47d","best_bid":"0","best_ask":"0.01"}],"timestamp":"1768359590044","event_type":"price_change"}
{"market":"0x5977c69bca02e6cc150855b0faec463b38be463f141ec37ea5c8a1a1e986e0d3","price_changes":[{"asset_id":"110222991870854778724082971333105906777328061970448875974576460135015541883929","price":"0.87","size":"375","side":"BUY","hash":"a567f53b0a964dca1aba9fd8cea46b44ce5d8732","best_bid":"0.99","best_ask":"1"},{"asset_id":"103575991306220918671611575108050794364462782362354955892418399227289531345027","price":"0.13","size":"375","side":"SELL","hash":"7be31ad39545dc4edbb7e4ad475ff89af71be47d","best_bid":"0","best_ask":"0.01"}],"timestamp":"1768359590044","event_type":"price_change"}
{"market":"0x5977c69bca02e6cc150855b0faec463b38be463f141ec37ea5c8a1a1e986e0d3","price_changes":[{"asset_id":"110222991870854778724082971333105906777328061970448875974576460135015541883929","price":"0.82","size":"375","side":"BUY","hash":"a567f53b0a964dca1aba9fd8cea46b44ce5d8732","best_bid":"0.99","best_ask":"1"},{"asset_id":"103575991306220918671611575108050794364462782362354955892418399227289531345027","price":"0.18","size":"375","side":"SELL","hash":"7be31ad39545dc4edbb7e4ad475ff89af71be47d","best_bid":"0","best_ask":"0.01"}],"timestamp":"1768359590044","event_type":"price_change"}
{"market":"0x5977c69bca02e6cc150855b0faec463b38be463f141ec37ea5c8a1a1e986e0d3","price_changes":[{"asset_id":"110222991870854778724082971333105906777328061970448875974576460135015541883929","price":"0.14","size":"0","side":"BUY","hash":"a567f53b0a964dca1aba9fd8cea46b44ce5d8732","best_bid":"0.99","best_ask":"1"},{"asset_id":"103575991306220918671611575108050794364462782362354955892418399227289531345027","price":"0.86","size":"0","side":"SELL","hash":"7be31ad39545dc4edbb7e4ad475ff89af71be47d","best_bid":"0","best_ask":"0.01"}],"timestamp":"1768359590044","event_type":"price_change"}
{"market":"0x5977c69bca02e6cc150855b0faec463b38be463f141ec37ea5c8a1a1e986e0d3","price_changes":[{"asset_id":"110222991870854778724082971333105906777328061970448875974576460135015541883929","price":"0.06","size":"2500","side":"BUY","hash":"a567f53b0a964dca1aba9fd8cea46b44ce5d8732","best_bid":"0.99","best_ask":"1"},{"asset_id":"103575991306220918671611575108050794364462782362354955892418399227289531345027","price":"0.94","size":"2500","side":"SELL","hash":"7be31ad39545dc4edbb7e4ad475ff89af71be47d","best_bid":"0","best_ask":"0.01"}],"timestamp":"1768359590044","event_type":"price_change"}
{"market":"0x5977c69bca02e6cc150855b0faec463b38be463f141ec37ea5c8a1a1e986e0d3","price_changes":[{"asset_id":"110222991870854778724082971333105906777328061970448875974576460135015541883929","price":"0.84","size":"391.56","side":"BUY","hash":"a567f53b0a964dca1aba9fd8cea46b44ce5d8732","best_bid":"0.99","best_ask":"1"},{"asset_id":"103575991306220918671611575108050794364462782362354955892418399227289531345027","price":"0.16","size":"391.56","side":"SELL","hash":"7be31ad39545dc4edbb7e4ad475ff89af71be47d","best_bid":"0","best_ask":"0.01"}],"timestamp":"1768359590044","event_type":"price_change"}
{"market":"0x5977c69bca02e6cc150855b0faec463b38be463f141ec37ea5c8a1a1e986e0d3","price_changes":[{"asset_id":"110222991870854778724082971333105906777328061970448875974576460135015541883929","price":"0.85","size":"401.25","side":"BUY","hash":"a567f53b0a964dca1aba9fd8cea46b44ce5d8732","best_bid":"0.99","best_ask":"1"},{"asset_id":"103575991306220918671611575108050794364462782362354955892418399227289531345027","price":"0.15","size":"401.25","side":"SELL","hash":"7be31ad39545dc4edbb7e4ad475ff89af71be47d","best_bid":"0","best_ask":"0.01"}],"timestamp":"1768359590044","event_type":"price_change"}
{"market":"0x5977c69bca02e6cc150855b0faec463b38be463f141ec37ea5c8a1a1e986e0d3","price_changes":[{"asset_id":"110222991870854778724082971333105906777328061970448875974576460135015541883929","price":"0.2","size":"415","side":"BUY","hash":"a567f53b0a964dca1aba9fd8cea46b44ce5d8732","best_bid":"0.99","best_ask":"1"},{"asset_id":"103575991306220918671611575108050794364462782362354955892418399227289531345027","price":"0.8","size":"415","side":"SELL","hash":"7be31ad39545dc4edbb7e4ad475ff89af71be47d","best_bid":"0","best_ask":"0.01"}],"timestamp":"1768359590044","event_type":"price_change"}
{"market":"0x5977c69bca02e6cc150855b0faec463b38be463f141ec37ea5c8a1a1e986e0d3","price_changes":[{"asset_id":"110222991870854778724082971333105906777328061970448875974576460135015541883929","price":"0.44","size":"11","side":"BUY","hash":"a567f53b0a964dca1aba9fd8cea46b44ce5d8732","best_bid":"0.99","best_ask":"1"},{"asset_id":"103575991306220918671611575108050794364462782362354955892418399227289531345027","price":"0.56","size":"11","side":"SELL","hash":"7be31ad39545dc4edbb7e4ad475ff89af71be47d","best_bid":"0","best_ask":"0.01"}],"timestamp":"1768359590044","event_type":"price_change"}
{"market":"0x5977c69bca02e6cc150855b0faec463b38be463f141ec37ea5c8a1a1e986e0d3","price_changes":[{"asset_id":"110222991870854778724082971333105906777328061970448875974576460135015541883929","price":"0.04","size":"2719.52","side":"BUY","hash":"a567f53b0a964dca1aba9fd8cea46b44ce5d8732","best_bid":"0.99","best_ask":"1"},{"asset_id":"103575991306220918671611575108050794364462782362354955892418399227289531345027","price":"0.96","size":"2719.52","side":"SELL","hash":"7be31ad39545dc4edbb7e4ad475ff89af71be47d","best_bid":"0","best_ask":"0.01"}],"timestamp":"1768359590044","event_type":"price_change"}
{"market":"0x5977c69bca02e6cc150855b0faec463b38be463f141ec37ea5c8a1a1e986e0d3","price_changes":[{"asset_id":"110222991870854778724082971333105906777328061970448875974576460135015541883929","price":"0.12","size":"5","side":"BUY","hash":"a567f53b0a964dca1aba9fd8cea46b44ce5d8732","best_bid":"0.99","best_ask":"1"},{"asset_id":"103575991306220918671611575108050794364462782362354955892418399227289531345027","price":"0.88","size":"5","side":"SELL","hash":"7be31ad39545dc4edbb7e4ad475ff89af71be47d","best_bid":"0","best_ask":"0.01"}],"timestamp":"1768359590044","event_type":"price_change"}
{"market":"0x5977c69bca02e6cc150855b0faec463b38be463f141ec37ea5c8a1a1e986e0d3","price_changes":[{"asset_id":"110222991870854778724082971333105906777328061970448875974576460135015541883929","price":"0.69","size":"469.01","side":"BUY","hash":"a567f53b0a964dca1aba9fd8cea46b44ce5d8732","best_bid":"0.99","best_ask":"1"},{"asset_id":"103575991306220918671611575108050794364462782362354955892418399227289531345027","price":"0.31","size":"469.01","side":"SELL","hash":"7be31ad39545dc4edbb7e4ad475ff89af71be47d","best_bid":"0","best_ask":"0.01"}],"timestamp":"1768359590044","event_type":"price_change"}
{"market":"0x5977c69bca02e6cc150855b0faec463b38be463f141ec37ea5c8a1a1e986e0d3","price_changes":[{"asset_id":"110222991870854778724082971333105906777328061970448875974576460135015541883929","price":"0.49","size":"0","side":"BUY","hash":"a567f53b0a964dca1aba9fd8cea46b44ce5d8732","best_bid":"0.99","best_ask":"1"},{"asset_id":"103575991306220918671611575108050794364462782362354955892418399227289531345027","price":"0.51","size":"0","side":"SELL","hash":"7be31ad39545dc4edbb7e4ad475ff89af71be47d","best_bid":"0","best_ask":"0.01"}],"timestamp":"1768359590044","event_type":"price_change"}
{"market":"0x5977c69bca02e6cc150855b0faec463b38be463f141ec37ea5c8a1a1e986e0d3","price_changes":[{"asset_id":"110222991870854778724082971333105906777328061970448875974576460135015541883929","price":"0.4","size":"34","side":"BUY","hash":"a567f53b0a964dca1aba9fd8cea46b44ce5d8732","best_bid":"0.99","best_ask":"1"},{"asset_id":"103575991306220918671611575108050794364462782362354955892418399227289531345027","price":"0.6","size":"34","side":"SELL","hash":"7be31ad39545dc4edbb7e4ad475ff89af71be47d","best_bid":"0","best_ask":"0.01"}],"timestamp":"1768359590044","event_type":"price_change"}
{"market":"0x5977c69bca02e6cc150855b0faec463b38be463f141ec37ea5c8a1a1e986e0d3","price_changes":[{"asset_id":"110222991870854778724082971333105906777328061970448875974576460135015541883929","price":"0.27","size":"375","side":"BUY","hash":"a567f53b0a964dca1aba9fd8cea46b44ce5d8732","best_bid":"0.99","best_ask":"1"},{"asset_id":"103575991306220918671611575108050794364462782362354955892418399227289531345027","price":"0.73","size":"375","side":"SELL","hash":"7be31ad39545dc4edbb7e4ad475ff89af71be47d","best_bid":"0","best_ask":"0.01"}],"timestamp":"1768359590044","event_type":"price_change"}
{"market":"0x5977c69bca02e6cc150855b0faec463b38be463f141ec37ea5c8a1a1e986e0d3","price_changes":[{"asset_id":"110222991870854778724082971333105906777328061970448875974576460135015541883929","price":"0.86","size":"900.94","side":"BUY","hash":"a567f53b0a964dca1aba9fd8cea46b44ce5d8732","best_bid":"0.99","best_ask":"1"},{"asset_id":"103575991306220918671611575108050794364462782362354955892418399227289531345027","price":"0.14","size":"900.94","side":"SELL","hash":"7be31ad39545dc4edbb7e4ad475ff89af71be47d","best_bid":"0","best_ask":"0.01"}],"timestamp":"1768359590044","event_type":"price_change"}
{"market":"0x5977c69bca02e6cc150855b0faec463b38be463f141ec37ea5c8a1a1e986e0d3","price_changes":[{"asset_id":"110222991870854778724082971333105906777328061970448875974576460135015541883929","price":"0.28","size":"398.14","side":"BUY","hash":"a567f53b0a964dca1aba9fd8cea46b44ce5d8732","best_bid":"0.99","best_ask":"1"},{"asset_id":"103575991306220918671611575108050794364462782362354955892418399227289531345027","price":"0.72","size":"398.14","side":"SELL","hash":"7be31ad39545dc4edbb7e4ad475ff89af71be47d","best_bid":"0","best_ask":"0.01"}],"timestamp":"1768359590044","event_type":"price_change"}
{"market":"0x5977c69bca02e6cc150855b0faec463b38be463f141ec37ea5c8a1a1e986e0d3","price_changes":[{"asset_id":"110222991870854778724082971333105906777328061970448875974576460135015541883929","price":"0.38","size":"375","side":"BUY","hash":"a567f53b0a964dca1aba9fd8cea46b44ce5d8732","best_bid":"0.99","best_ask":"1"},{"asset_id":"103575991306220918671611575108050794364462782362354955892418399227289531345027","price":"0.62","size":"375","side":"SELL","hash":"7be31ad39545dc4edbb7e4ad475ff89af71be47d","best_bid":"0","best_ask":"0.01"}],"timestamp":"1768359590044","event_type":"price_change"}
{"market":"0x5977c69bca02e6cc150855b0faec463b38be463f141ec37ea5c8a1a1e986e0d3","price_changes":[{"asset_id":"110222991870854778724082971333105906777328061970448875974576460135015541883929","price":"0.42","size":"23.41","side":"BUY","hash":"a567f53b0a964dca1aba9fd8cea46b44ce5d8732","best_bid":"0.99","best_ask":"1"},{"asset_id":"103575991306220918671611575108050794364462782362354955892418399227289531345027","price":"0.58","size":"23.41","side":"SELL","hash":"7be31ad39545dc4edbb7e4ad475ff89af71be47d","best_bid":"0","best_ask":"0.01"}],"timestamp":"1768359590044","event_type":"price_change"}
{"market":"0x5977c69bca02e6cc150855b0faec463b38be463f141ec37ea5c8a1a1e986e0d3","price_changes":[{"asset_id":"110222991870854778724082971333105906777328061970448875974576460135015541883929","price":"0.51","size":"102.65","side":"BUY","hash":"a567f53b0a964dca1aba9fd8cea46b44ce5d8732","best_bid":"0.99","best_ask":"1"},{"asset_id":"103575991306220918671611575108050794364462782362354955892418399227289531345027","price":"0.49","size":"102.65","side":"SELL","hash":"7be31ad39545dc4edbb7e4ad475ff89af71be47d","best_bid":"0","best_ask":"0.01"}],"timestamp":"1768359590044","event_type":"price_change"}
{"market":"0x5977c69bca02e6cc150855b0faec463b38be463f141ec37ea5c8a1a1e986e0d3","price_changes":[{"asset_id":"110222991870854778724082971333105906777328061970448875974576460135015541883929","price":"0.54","size":"375","side":"BUY","hash":"a567f53b0a964dca1aba9fd8cea46b44ce5d8732","best_bid":"0.99","best_ask":"1"},{"asset_id":"103575991306220918671611575108050794364462782362354955892418399227289531345027","price":"0.46","size":"375","side":"SELL","hash":"7be31ad39545dc4edbb7e4ad475ff89af71be47d","best_bid":"0","best_ask":"0.01"}],"timestamp":"1768359590044","event_type":"price_change"}
{"market":"0x5977c69bca02e6cc150855b0faec463b38be463f141ec37ea5c8a1a1e986e0d3","price_changes":[{"asset_id":"110222991870854778724082971333105906777328061970448875974576460135015541883929","price":"0.26","size":"375","side":"BUY","hash":"a567f53b0a964dca1aba9fd8cea46b44ce5d8732","best_bid":"0.99","best_ask":"1"},{"asset_id":"103575991306220918671611575108050794364462782362354955892418399227289531345027","price":"0.74","size":"375","side":"SELL","hash":"7be31ad39545dc4edbb7e4ad475ff89af71be47d","best_bid":"0","best_ask":"0.01"}],"timestamp":"1768359590044","event_type":"price_change"}
{"market":"0x5977c69bca02e6cc150855b0faec463b38be463f141ec37ea5c8a1a1e986e0d3","price_changes":[{"asset_id":"110222991870854778724082971333105906777328061970448875974576460135015541883929","price":"0.11","size":"0","side":"BUY","hash":"a567f53b0a964dca1aba9fd8cea46b44ce5d8732","best_bid":"0.99","best_ask":"1"},{"asset_id":"103575991306220918671611575108050794364462782362354955892418399227289531345027","price":"0.89","size":"0","side":"SELL","hash":"7be31ad39545dc4edbb7e4ad475ff89af71be47d","best_bid":"0","best_ask":"0.01"}],"timestamp":"1768359590044","event_type":"price_change"}
{"market":"0x5977c69bca02e6cc150855b0faec463b38be463f141ec37ea5c8a1a1e986e0d3","price_changes":[{"asset_id":"110222991870854778724082971333105906777328061970448875974576460135015541883929","price":"0.74","size":"485.67","side":"BUY","hash":"a567f53b0a964dca1aba9fd8cea46b44ce5d8732","best_bid":"0.99","best_ask":"1"},{"asset_id":"103575991306220918671611575108050794364462782362354955892418399227289531345027","price":"0.26","size":"485.67","side":"SELL","hash":"7be31ad39545dc4edbb7e4ad475ff89af71be47d","best_bid":"0","best_ask":"0.01"}],"timestamp":"1768359590044","event_type":"price_change"}
{"market":"0x5977c69bca02e6cc150855b0faec463b38be463f141ec37ea5c8a1a1e986e0d3","price_changes":[{"asset_id":"110222991870854778724082971333105906777328061970448875974576460135015541883929","price":"0.76","size":"654.24","side":"BUY","hash":"a567f53b0a964dca1aba9fd8cea46b44ce5d8732","best_bid":"0.99","best_ask":"1"},{"asset_id":"103575991306220918671611575108050794364462782362354955892418399227289531345027","price":"0.24","size":"654.24","side":"SELL","hash":"7be31ad39545dc4edbb7e4ad475ff89af71be47d","best_bid":"0","best_ask":"0.01"}],"timestamp":"1768359590044","event_type":"price_change"}
{"market":"0x5977c69bca02e6cc150855b0faec463b38be463f141ec37ea5c8a1a1e986e0d3","price_changes":[{"asset_id":"110222991870854778724082971333105906777328061970448875974576460135015541883929","price":"0.3","size":"601.69","side":"BUY","hash":"a567f53b0a964dca1aba9fd8cea46b44ce5d8732","best_bid":"0.99","best_ask":"1"},{"asset_id":"103575991306220918671611575108050794364462782362354955892418399227289531345027","price":"0.7","size":"601.69","side":"SELL","hash":"7be31ad39545dc4edbb7e4ad475ff89af71be47d","best_bid":"0","best_ask":"0.01"}],"timestamp":"1768359590044","event_type":"price_change"}
{"market":"0x5977c69bca02e6cc150855b0faec463b38be463f141ec37ea5c8a1a1e986e0d3","price_changes":[{"asset_id":"110222991870854778724082971333105906777328061970448875974576460135015541883929","price":"0.59","size":"385","side":"BUY","hash":"a567f53b0a964dca1aba9fd8cea46b44ce5d8732","best_bid":"0.99","best_ask":"1"},{"asset_id":"103575991306220918671611575108050794364462782362354955892418399227289531345027","price":"0.41","size":"385","side":"SELL","hash":"7be31ad39545dc4edbb7e4ad475ff89af71be47d","best_bid":"0","best_ask":"0.01"}],"timestamp":"1768359590044","event_type":"price_change"}
{"market":"0x5977c69bca02e6cc150855b0faec463b38be463f141ec37ea5c8a1a1e986e0d3","price_changes":[{"asset_id":"110222991870854778724082971333105906777328061970448875974576460135015541883929","price":"0.67","size":"293.95","side":"BUY","hash":"a567f53b0a964dca1aba9fd8cea46b44ce5d8732","best_bid":"0.99","best_ask":"1"},{"asset_id":"103575991306220918671611575108050794364462782362354955892418399227289531345027","price":"0.33","size":"293.95","side":"SELL","hash":"7be31ad39545dc4edbb7e4ad475ff89af71be47d","best_bid":"0","best_ask":"0.01"}],"timestamp":"1768359590044","event_type":"price_change"}
{"market":"0x5977c69bca02e6cc150855b0faec463b38be463f141ec37ea5c8a1a1e986e0d3","price_changes":[{"asset_id":"110222991870854778724082971333105906777328061970448875974576460135015541883929","price":"0.78","size":"384.97","side":"BUY","hash":"a567f53b0a964dca1aba9fd8cea46b44ce5d8732","best_bid":"0.99","best_ask":"1"},{"asset_id":"103575991306220918671611575108050794364462782362354955892418399227289531345027","price":"0.22","size":"384.97","side":"SELL","hash":"7be31ad39545dc4edbb7e4ad475ff89af71be47d","best_bid":"0","best_ask":"0.01"}],"timestamp":"1768359590044","event_type":"price_change"}
{"market":"0x5977c69bca02e6cc150855b0faec463b38be463f141ec37ea5c8a1a1e986e0d3","price_changes":[{"asset_id":"110222991870854778724082971333105906777328061970448875974576460135015541883929","price":"0.25","size":"408.5","side":"BUY","hash":"a567f53b0a964dca1aba9fd8cea46b44ce5d8732","best_bid":"0.99","best_ask":"1"},{"asset_id":"103575991306220918671611575108050794364462782362354955892418399227289531345027","price":"0.75","size":"408.5","side":"SELL","hash":"7be31ad39545dc4edbb7e4ad475ff89af71be47d","best_bid":"0","best_ask":"0.01"}],"timestamp":"1768359590044","event_type":"price_change"}
{"market":"0x5977c69bca02e6cc150855b0faec463b38be463f141ec37ea5c8a1a1e986e0d3","price_changes":[{"asset_id":"110222991870854778724082971333105906777328061970448875974576460135015541883929","price":"0.93","size":"448","side":"BUY","hash":"a567f53b0a964dca1aba9fd8cea46b44ce5d8732","best_bid":"0.99","best_ask":"1"},{"asset_id":"103575991306220918671611575108050794364462782362354955892418399227289531345027","price":"0.07","size":"448","side":"SELL","hash":"7be31ad39545dc4edbb7e4ad475ff89af71be47d","best_bid":"0","best_ask":"0.01"}],"timestamp":"1768359590044","event_type":"price_change"}
{"market":"0x5977c69bca02e6cc150855b0faec463b38be463f141ec37ea5c8a1a1e986e0d3","price_changes":[{"asset_id":"110222991870854778724082971333105906777328061970448875974576460135015541883929","price":"0.77","size":"465","side":"BUY","hash":"a567f53b0a964dca1aba9fd8cea46b44ce5d8732","best_bid":"0.99","best_ask":"1"},{"asset_id":"103575991306220918671611575108050794364462782362354955892418399227289531345027","price":"0.23","size":"465","side":"SELL","hash":"7be31ad39545dc4edbb7e4ad475ff89af71be47d","best_bid":"0","best_ask":"0.01"}],"timestamp":"1768359590044","event_type":"price_change"}
{"market":"0x5977c69bca02e6cc150855b0faec463b38be463f141ec37ea5c8a1a1e986e0d3","price_changes":[{"asset_id":"110222991870854778724082971333105906777328061970448875974576460135015541883929","price":"0.47","size":"10","side":"BUY","hash":"a567f53b0a964dca1aba9fd8cea46b44ce5d8732","best_bid":"0.99","best_ask":"1"},{"asset_id":"103575991306220918671611575108050794364462782362354955892418399227289531345027","price":"0.53","size":"10","side":"SELL","hash":"7be31ad39545dc4edbb7e4ad475ff89af71be47d","best_bid":"0","best_ask":"0.01"}],"timestamp":"1768359590044","event_type":"price_change"}
{"market":"0x5977c69bca02e6cc150855b0faec463b38be463f141ec37ea5c8a1a1e986e0d3","price_changes":[{"asset_id":"110222991870854778724082971333105906777328061970448875974576460135015541883929","price":"0.71","size":"677.74","side":"BUY","hash":"a567f53b0a964dca1aba9fd8cea46b44ce5d8732","best_bid":"0.99","best_ask":"1"},{"asset_id":"103575991306220918671611575108050794364462782362354955892418399227289531345027","price":"0.29","size":"677.74","side":"SELL","hash":"7be31ad39545dc4edbb7e4ad475ff89af71be47d","best_bid":"0","best_ask":"0.01"}],"timestamp":"1768359590044","event_type":"price_change"}
{"market":"0x5977c69bca02e6cc150855b0faec463b38be463f141ec37ea5c8a1a1e986e0d3","price_changes":[{"asset_id":"110222991870854778724082971333105906777328061970448875974576460135015541883929","price":"0.8","size":"402","side":"BUY","hash":"a567f53b0a964dca1aba9fd8cea46b44ce5d8732","best_bid":"0.99","best_ask":"1"},{"asset_id":"103575991306220918671611575108050794364462782362354955892418399227289531345027","price":"0.2","size":"402","side":"SELL","hash":"7be31ad39545dc4edbb7e4ad475ff89af71be47d","best_bid":"0","best_ask":"0.01"}],"timestamp":"1768359590044","event_type":"price_change"}
{"market":"0x5977c69bca02e6cc150855b0faec463b38be463f141ec37ea5c8a1a1e986e0d3","price_changes":[{"asset_id":"110222991870854778724082971333105906777328061970448875974576460135015541883929","price":"0.83","size":"413.78","side":"BUY","hash":"a567f53b0a964dca1aba9fd8cea46b44ce5d8732","best_bid":"0.99","best_ask":"1"},{"asset_id":"103575991306220918671611575108050794364462782362354955892418399227289531345027","price":"0.17","size":"413.78","side":"SELL","hash":"7be31ad39545dc4edbb7e4ad475ff89af71be47d","best_bid":"0","best_ask":"0.01"}],"timestamp":"1768359590044","event_type":"price_change"}
{"market":"0x5977c69bca02e6cc150855b0faec463b38be463f141ec37ea5c8a1a1e986e0d3","price_changes":[{"asset_id":"110222991870854778724082971333105906777328061970448875974576460135015541883929","price":"0.97","size":"843","side":"BUY","hash":"a567f53b0a964dca1aba9fd8cea46b44ce5d8732","best_bid":"0.99","best_ask":"1"},{"asset_id":"103575991306220918671611575108050794364462782362354955892418399227289531345027","price":"0.03","size":"843","side":"SELL","hash":"7be31ad39545dc4edbb7e4ad475ff89af71be47d","best_bid":"0","best_ask":"0.01"}],"timestamp":"1768359590044","event_type":"price_change"}
{"market":"0x5977c69bca02e6cc150855b0faec463b38be463f141ec37ea5c8a1a1e986e0d3","price_changes":[{"asset_id":"110222991870854778724082971333105906777328061970448875974576460135015541883929","price":"0.33","size":"375","side":"BUY","hash":"a567f53b0a964dca1aba9fd8cea46b44ce5d8732","best_bid":"0.99","best_ask":"1"},{"asset_id":"103575991306220918671611575108050794364462782362354955892418399227289531345027","price":"0.67","size":"375","side":"SELL","hash":"7be31ad39545dc4edbb7e4ad475ff89af71be47d","best_bid":"0","best_ask":"0.01"}],"timestamp":"1768359590044","event_type":"price_change"}
{"market":"0x5977c69bca02e6cc150855b0faec463b38be463f141ec37ea5c8a1a1e986e0d3","price_changes":[{"asset_id":"110222991870854778724082971333105906777328061970448875974576460135015541883929","price":"0.45","size":"314.33","side":"BUY","hash":"a567f53b0a964dca1aba9fd8cea46b44ce5d8732","best_bid":"0.99","best_ask":"1"},{"asset_id":"103575991306220918671611575108050794364462782362354955892418399227289531345027","price":"0.55","size":"314.33","side":"SELL","hash":"7be31ad39545dc4edbb7e4ad475ff89af71be47d","best_bid":"0","best_ask":"0.01"}],"timestamp":"1768359590044","event_type":"price_change"}
{"market":"0x5977c69bca02e6cc150855b0faec463b38be463f141ec37ea5c8a1a1e986e0d3","price_changes":[{"asset_id":"110222991870854778724082971333105906777328061970448875974576460135015541883929","price":"0.62","size":"375","side":"BUY","hash":"a567f53b0a964dca1aba9fd8cea46b44ce5d8732","best_bid":"0.99","best_ask":"1"},{"asset_id":"103575991306220918671611575108050794364462782362354955892418399227289531345027","price":"0.38","size":"375","side":"SELL","hash":"7be31ad39545dc4edbb7e4ad475ff89af71be47d","best_bid":"0","best_ask":"0.01"}],"timestamp":"1768359590044","event_type":"price_change"}
{"market":"0x5977c69bca02e6cc150855b0faec463b38be463f141ec37ea5c8a1a1e986e0d3","price_changes":[{"asset_id":"110222991870854778724082971333105906777328061970448875974576460135015541883929","price":"0.68","size":"485.24","side":"BUY","hash":"a567f53b0a964dca1aba9fd8cea46b44ce5d8732","best_bid":"0.99","best_ask":"1"},{"asset_id":"103575991306220918671611575108050794364462782362354955892418399227289531345027","price":"0.32","size":"485.24","side":"SELL","hash":"7be31ad39545dc4edbb7e4ad475ff89af71be47d","best_bid":"0","best_ask":"0.01"}],"timestamp":"1768359590044","event_type":"price_change"}
{"market":"0x5977c69bca02e6cc150855b0faec463b38be463f141ec37ea5c8a1a1e986e0d3","price_changes":[{"asset_id":"110222991870854778724082971333105906777328061970448875974576460135015541883929","price":"0.89","size":"1385","side":"BUY","hash":"a567f53b0a964dca1aba9fd8cea46b44ce5d8732","best_bid":"0.99","best_ask":"1"},{"asset_id":"103575991306220918671611575108050794364462782362354955892418399227289531345027","price":"0.11","size":"1385","side":"SELL","hash":"7be31ad39545dc4edbb7e4ad475ff89af71be47d","best_bid":"0","best_ask":"0.01"}],"timestamp":"1768359590044","event_type":"price_change"}
{"market":"0x5977c69bca02e6cc150855b0faec463b38be463f141ec37ea5c8a1a1e986e0d3","price_changes":[{"asset_id":"110222991870854778724082971333105906777328061970448875974576460135015541883929","price":"0.07","size":"2500","side":"BUY","hash":"a567f53b0a964dca1aba9fd8cea46b44ce5d8732","best_bid":"0.99","best_ask":"1"},{"asset_id":"103575991306220918671611575108050794364462782362354955892418399227289531345027","price":"0.93","size":"2500","side":"SELL","hash":"7be31ad39545dc4edbb7e4ad475ff89af71be47d","best_bid":"0","best_ask":"0.01"}],"timestamp":"1768359590044","event_type":"price_change"}
{"market":"0x5977c69bca02e6cc150855b0faec463b38be463f141ec37ea5c8a1a1e986e0d3","price_changes":[{"asset_id":"110222991870854778724082971333105906777328061970448875974576460135015541883929","price":"0.21","size":"375","side":"BUY","hash":"a567f53b0a964dca1aba9fd8cea46b44ce5d8732","best_bid":"0.99","best_ask":"1"},{"asset_id":"103575991306220918671611575108050794364462782362354955892418399227289531345027","price":"0.79","size":"375","side":"SELL","hash":"7be31ad39545dc4edbb7e4ad475ff89af71be47d","best_bid":"0","best_ask":"0.01"}],"timestamp":"1768359590044","event_type":"price_change"}
{"market":"0x5977c69bca02e6cc150855b0faec463b38be463f141ec37ea5c8a1a1e986e0d3","price_changes":[{"asset_id":"110222991870854778724082971333105906777328061970448875974576460135015541883929","price":"0.41","size":"0","side":"BUY","hash":"a567f53b0a964dca1aba9fd8cea46b44ce5d8732","best_bid":"0.99","best_ask":"1"},{"asset_id":"103575991306220918671611575108050794364462782362354955892418399227289531345027","price":"0.59","size":"0","side":"SELL","hash":"7be31ad39545dc4edbb7e4ad475ff89af71be47d","best_bid":"0","best_ask":"0.01"}],"timestamp":"1768359590044","event_type":"price_change"}
{"market":"0x5977c69bca02e6cc150855b0faec463b38be463f141ec37ea5c8a1a1e986e0d3","price_changes":[{"asset_id":"110222991870854778724082971333105906777328061970448875974576460135015541883929","price":"0.66","size":"505.37","side":"BUY","hash":"a567f53b0a964dca1aba9fd8cea46b44ce5d8732","best_bid":"0.99","best_ask":"1"},{"asset_id":"103575991306220918671611575108050794364462782362354955892418399227289531345027","price":"0.34","size":"505.37","side":"SELL","hash":"7be31ad39545dc4edbb7e4ad475ff89af71be47d","best_bid":"0","best_ask":"0.01"}],"timestamp":"1768359590044","event_type":"price_change"}
{"market":"0x5977c69bca02e6cc150855b0faec463b38be463f141ec37ea5c8a1a1e986e0d3","price_changes":[{"asset_id":"110222991870854778724082971333105906777328061970448875974576460135015541883929","price":"0.65","size":"525.75","side":"BUY","hash":"a567f53b0a964dca1aba9fd8cea46b44ce5d8732","best_bid":"0.99","best_ask":"1"},{"asset_id":"103575991306220918671611575108050794364462782362354955892418399227289531345027","price":"0.35","size":"525.75","side":"SELL","hash":"7be31ad39545dc4edbb7e4ad475ff89af71be47d","best_bid":"0","best_ask":"0.01"}],"timestamp":"1768359590044","event_type":"price_change"}
{"market":"0x5977c69bca02e6cc150855b0faec463b38be463f141ec37ea5c8a1a1e986e0d3","price_changes":[{"asset_id":"110222991870854778724082971333105906777328061970448875974576460135015541883929","price":"0.13","size":"0","side":"BUY","hash":"a567f53b0a964dca1aba9fd8cea46b44ce5d8732","best_bid":"0.99","best_ask":"1"},{"asset_id":"103575991306220918671611575108050794364462782362354955892418399227289531345027","price":"0.87","size":"0","side":"SELL","hash":"7be31ad39545dc4edbb7e4ad475ff89af71be47d","best_bid":"0","best_ask":"0.01"}],"timestamp":"1768359590044","event_type":"price_change"}
{"market":"0x5977c69bca02e6cc150855b0faec463b38be463f141ec37ea5c8a1a1e986e0d3","price_changes":[{"asset_id":"110222991870854778724082971333105906777328061970448875974576460135015541883929","price":"0.17","size":"0","side":"BUY","hash":"a567f53b0a964dca1aba9fd8cea46b44ce5d8732","best_bid":"0.99","best_ask":"1"},{"asset_id":"103575991306220918671611575108050794364462782362354955892418399227289531345027","price":"0.83","size":"0","side":"SELL","hash":"7be31ad39545dc4edbb7e4ad475ff89af71be47d","best_bid":"0","best_ask":"0.01"}],"timestamp":"1768359590044","event_type":"price_change"}
{"market":"0x5977c69bca02e6cc150855b0faec463b38be463f141ec37ea5c8a1a1e986e0d3","price_changes":[{"asset_id":"110222991870854778724082971333105906777328061970448875974576460135015541883929","price":"0.53","size":"375","side":"BUY","hash":"a567f53b0a964dca1aba9fd8cea46b44ce5d8732","best_bid":"0.99","best_ask":"1"},{"asset_id":"103575991306220918671611575108050794364462782362354955892418399227289531345027","price":"0.47","size":"375","side":"SELL","hash":"7be31ad39545dc4edbb7e4ad475ff89af71be47d","best_bid":"0","best_ask":"0.01"}],"timestamp":"1768359590044","event_type":"price_change"}
{"market":"0x5977c69bca02e6cc150855b0faec463b38be463f141ec37ea5c8a1a1e986e0d3","price_changes":[{"asset_id":"110222991870854778724082971333105906777328061970448875974576460135015541883929","price":"0.79","size":"380","side":"BUY","hash":"a567f53b0a964dca1aba9fd8cea46b44ce5d8732","best_bid":"0.99","best_ask":"1"},{"asset_id":"103575991306220918671611575108050794364462782362354955892418399227289531345027","price":"0.21","size":"380","side":"SELL","hash":"7be31ad39545dc4edbb7e4ad475ff89af71be47d","best_bid":"0","best_ask":"0.01"}],"timestamp":"1768359590044","event_type":"price_change"}
{"market":"0x5977c69bca02e6cc150855b0faec463b38be463f141ec37ea5c8a1a1e986e0d3","price_changes":[{"asset_id":"110222991870854778724082971333105906777328061970448875974576460135015541883929","price":"0.88","size":"1386.36","side":"BUY","hash":"a567f53b0a964dca1aba9fd8cea46b44ce5d8732","best_bid":"0.99","best_ask":"1"},{"asset_id":"103575991306220918671611575108050794364462782362354955892418399227289531345027","price":"0.12","size":"1386.36","side":"SELL","hash":"7be31ad39545dc4edbb7e4ad475ff89af71be47d","best_bid":"0","best_ask":"0.01"}],"timestamp":"1768359590044","event_type":"price_change"}
PONG
{"market":"0x5977c69bca02e6cc150855b0faec463b38be463f141ec37ea5c8a1a1e986e0d3","price_changes":[{"asset_id":"110222991870854778724082971333105906777328061970448875974576460135015541883929","price":"0.8","size":"392","side":"BUY","hash":"6e441b34a56475b391f437a0f71bd8743dba2b88","best_bid":"0.99","best_ask":"1"},{"asset_id":"103575991306220918671611575108050794364462782362354955892418399227289531345027","price":"0.2","size":"392","side":"SELL","hash":"8702a00e1e8d0a302a35f70528d6bdfe3151c39a","best_bid":"0","best_ask":"0.01"}],"timestamp":"1768359590342","event_type":"price_change"}
{"market":"0x5977c69bca02e6cc150855b0faec463b38be463f141ec37ea5c8a1a1e986e0d3","price_changes":[{"asset_id":"110222991870854778724082971333105906777328061970448875974576460135015541883929","price":"0.8","size":"402","side":"BUY","hash":"eb45abff0445efbef6b9081b0b47c029f9be4c48","best_bid":"0.99","best_ask":"1"},{"asset_id":"103575991306220918671611575108050794364462782362354955892418399227289531345027","price":"0.2","size":"402","side":"SELL","hash":"7d9abcf7e1ab1cb7e77c6caf3f908fcac3486c69","best_bid":"0","best_ask":"0.01"}],"timestamp":"1768359590364","event_type":"price_change"}
{"market":"0x5977c69bca02e6cc150855b0faec463b38be463f141ec37ea5c8a1a1e986e0d3","price_changes":[{"asset_id":"110222991870854778724082971333105906777328061970448875974576460135015541883929","price":"0.99","size":"336.83","side":"BUY","hash":"c995ff62f2829413f3dbb4c428ae5a9f581b3662","best_bid":"0.99","best_ask":"1"},{"asset_id":"103575991306220918671611575108050794364462782362354955892418399227289531345027","price":"0.01","size":"336.83","side":"SELL","hash":"466bb0ed37dc55f3a5c4a86f606eba406d1f5df2","best_bid":"0","best_ask":"0.01"}],"timestamp":"1768359590412","event_type":"price_change"}
{"market":"0x5977c69bca02e6cc150855b0faec463b38be463f141ec37ea5c8a1a1e986e0d3","price_changes":[{"asset_id":"110222991870854778724082971333105906777328061970448875974576460135015541883929","price":"0.3","size":"226.69","side":"BUY","hash":"cd72457b042000c72ff659f7c7505f6b8b2add64","best_bid":"0.99","best_ask":"1"},{"asset_id":"103575991306220918671611575108050794364462782362354955892418399227289531345027","price":"0.7","size":"226.69","side":"SELL","hash":"4f2174a5b6f3d88796a33202c65c43560ed6c807","best_bid":"0","best_ask":"0.01"}],"timestamp":"1768359590627","event_type":"price_change"}
{"market":"0x5977c69bca02e6cc150855b0faec463b38be463f141ec37ea5c8a1a1e986e0d3","price_changes":[{"asset_id":"110222991870854778724082971333105906777328061970448875974576460135015541883929","price":"0.01","size":"5596.4","side":"BUY","hash":"cd72457b042000c72ff659f7c7505f6b8b2add64","best_bid":"0.99","best_ask":"1"},{"asset_id":"103575991306220918671611575108050794364462782362354955892418399227289531345027","price":"0.99","size":"5596.4","side":"SELL","hash":"4f2174a5b6f3d88796a33202c65c43560ed6c807","best_bid":"0","best_ask":"0.01"}],"timestamp":"1768359590627","event_type":"price_change"}
{"market":"0x5977c69bca02e6cc150855b0faec463b38be463f141ec37ea5c8a1a1e986e0d3","price_changes":[{"asset_id":"110222991870854778724082971333105906777328061970448875974576460135015541883929","price":"0.96","size":"107.78","side":"BUY","hash":"cd72457b042000c72ff659f7c7505f6b8b2add64","best_bid":"0.99","best_ask":"1"},{"asset_id":"103575991306220918671611575108050794364462782362354955892418399227289531345027","price":"0.04","size":"107.78","side":"SELL","hash":"4f2174a5b6f3d88796a33202c65c43560ed6c807","best_bid":"0","best_ask":"0.01"}],"timestamp":"1768359590627","event_type":"price_change"}
{"market":"0x5977c69bca02e6cc150855b0faec463b38be463f141ec37ea5c8a1a1e986e0d3","price_changes":[{"asset_id":"110222991870854778724082971333105906777328061970448875974576460135015541883929","price":"0.04","size":"219.52","side":"BUY","hash":"cd72457b042000c72ff659f7c7505f6b8b2add64","best_bid":"0.99","best_ask":"1"},{"asset_id":"103575991306220918671611575108050794364462782362354955892418399227289531345027","price":"0.96","size":"219.52","side":"SELL","hash":"4f2174a5b6f3d88796a33202c65c43560ed6c807","best_bid":"0","best_ask":"0.01"}],"timestamp":"1768359590627","event_type":"price_change"}
{"market":"0x5977c69bca02e6cc150855b0faec463b38be463f141ec37ea5c8a1a1e986e0d3","price_changes":[{"asset_id":"110222991870854778724082971333105906777328061970448875974576460135015541883929","price":"0.95","size":"270.38","side":"BUY","hash":"cd72457b042000c72ff659f7c7505f6b8b2add64","best_bid":"0.99","best_ask":"1"},{"asset_id":"103575991306220918671611575108050794364462782362354955892418399227289531345027","price":"0.05","size":"270.38","side":"SELL","hash":"4f2174a5b6f3d88796a33202c65c43560ed6c807","best_bid":"0","best_ask":"0.01"}],"timestamp":"1768359590627","event_type":"price_change"}
{"market":"0x5977c69bca02e6cc150855b0faec463b38be463f141ec37ea5c8a1a1e986e0d3","price_changes":[{"asset_id":"110222991870854778724082971333105906777328061970448875974576460135015541883929","price":"0.26","size":"0","side":"BUY","hash":"cd72457b042000c72ff659f7c7505f6b8b2add64","best_bid":"0.99","best_ask":"1"},{"asset_id":"103575991306220918671611575108050794364462782362354955892418399227289531345027","price":"0.74","size":"0","side":"SELL","hash":"4f2174a5b6f3d88796a33202c65c43560ed6c807","best_bid":"0","best_ask":"0.01"}],"timestamp":"1768359590627","event_type":"price_change"}
{"market":"0x5977c69bca02e6cc150855b0faec463b38be463f141ec37ea5c8a1a1e986e0d3","price_changes":[{"asset_id":"110222991870854778724082971333105906777328061970448875974576460135015541883929","price":"0.76","size":"279.24","side":"BUY","hash":"cd72457b042000c72ff659f7c7505f6b8b2add64","best_bid":"0.99","best_ask":"1"},{"asset_id":"103575991306220918671611575108050794364462782362354955892418399227289531345027","price":"0.24","size":"279.24","side":"SELL","hash":"4f2174a5b6f3d88796a33202c65c43560ed6c807","best_bid":"0","best_ask":"0.01"}],"timestamp":"1768359590627","event_type":"price_change"}
{"market":"0x5977c69bca02e6cc150855b0faec463b38be463f141ec37ea5c8a1a1e986e0d3","price_changes":[{"asset_id":"110222991870854778724082971333105906777328061970448875974576460135015541883929","price":"0.37","size":"23.13","side":"BUY","hash":"cd72457b042000c72ff659f7c7505f6b8b2add64","best_bid":"0.99","best_ask":"1"},{"asset_id":"103575991306220918671611575108050794364462782362354955892418399227289531345027","price":"0.63","size":"23.13","side":"SELL","hash":"4f2174a5b6f3d88796a33202c65c43560ed6c807","best_bid":"0","best_ask":"0.01"}],"timestamp":"1768359590627","event_type":"price_change"}
{"market":"0x5977c69bca02e6cc150855b0faec463b38be463f141ec37ea5c8a1a1e986e0d3","price_changes":[{"asset_id":"110222991870854778724082971333105906777328061970448875974576460135015541883929","price":"0.28","size":"23.14","side":"BUY","hash":"cd72457b042000c72ff659f7c7505f6b8b2add64","best_bid":"0.99","best_ask":"1"},{"asset_id":"103575991306220918671611575108050794364462782362354955892418399227289531345027","price":"0.72","size":"23.14","side":"SELL","hash":"4f2174a5b6f3d88796a33202c65c43560ed6c807","best_bid":"0","best_ask":"0.01"}],"timestamp":"1768359590627","event_type":"price_change"}
{"market":"0x5977c69bca02e6cc150855b0faec463b38be463f141ec37ea5c8a1a1e986e0d3","price_changes":[{"asset_id":"110222991870854778724082971333105906777328061970448875974576460135015541883929","price":"0.77","size":"90","side":"BUY","hash":"cd72457b042000c72ff659f7c7505f6b8b2add64","best_bid":"0.99","best_ask":"1"},{"asset_id":"103575991306220918671611575108050794364462782362354955892418399227289531345027","price":"0.23","size":"90","side":"SELL","hash":"4f2174a5b6f3d88796a33202c65c43560ed6c807","best_bid":"0","best_ask":"0.01"}],"timestamp":"1768359590627","event_type":"price_change"}
{"market":"0x5977c69bca02e6cc150855b0faec463b38be463f141ec37ea5c8a1a1e986e0d3","price_changes":[{"asset_id":"110222991870854778724082971333105906777328061970448875974576460135015541883929","price":"0.62","size":"0","side":"BUY","hash":"cd72457b042000c72ff659f7c7505f6b8b2add64","best_bid":"0.99","best_ask":"1"},{"asset_id":"103575991306220918671611575108050794364462782362354955892418399227289531345027","price":"0.38","size":"0","side":"SELL","hash":"4f2174a5b6f3d88796a33202c65c43560ed6c807","best_bid":"0","best_ask":"0.01"}],"timestamp":"1768359590627","event_type":"price_change"}
{"market":"0x5977c69bca02e6cc150855b0faec463b38be463f141ec37ea5c8a1a1e986e0d3","price_changes":[{"asset_id":"110222991870854778724082971333105906777328061970448875974576460135015541883929","price":"0.23","size":"0","side":"BUY","hash":"cd72457b042000c72ff659f7c7505f6b8b2add64","best_bid":"0.99","best_ask":"1"},{"asset_id":"103575991306220918671611575108050794364462782362354955892418399227289531345027","price":"0.77","size":"0","side":"SELL","hash":"4f2174a5b6f3d88796a33202c65c43560ed6c807","best_bid":"0","best_ask":"0.01"}],"timestamp":"1768359590627","event_type":"price_change"}
{"market":"0x5977c69bca02e6cc150855b0faec463b38be463f141ec37ea5c8a1a1e986e0d3","price_changes":[{"asset_id":"110222991870854778724082971333105906777328061970448875974576460135015541883929","price":"0.9","size":"44.19","side":"BUY","hash":"cd72457b042000c72ff659f7c7505f6b8b2add64","best_bid":"0.99","best_ask":"1"},{"asset_id":"103575991306220918671611575108050794364462782362354955892418399227289531345027","price":"0.1","size":"44.19","side":"SELL","hash":"4f2174a5b6f3d88796a33202c65c43560ed6c807","best_bid":"0","best_ask":"0.01"}],"timestamp":"1768359590627","event_type":"price_change"}
{"market":"0x5977c69bca02e6cc150855b0faec463b38be463f141ec37ea5c8a1a1e986e0d3","price_changes":[{"asset_id":"110222991870854778724082971333105906777328061970448875974576460135015541883929","price":"0.1","size":"10","side":"BUY","hash":"cd72457b042000c72ff659f7c7505f6b8b2add64","best_bid":"0.99","best_ask":"1"},{"asset_id":"103575991306220918671611575108050794364462782362354955892418399227289531345027","price":"0.9","size":"10","side":"SELL","hash":"4f2174a5b6f3d88796a33202c65c43560ed6c807","best_bid":"0","best_ask":"0.01"}],"timestamp":"1768359590627","event_type":"price_change"}
{"market":"0x5977c69bca02e6cc150855b0faec463b38be463f141ec37ea5c8a1a1e986e0d3","price_changes":[{"asset_id":"110222991870854778724082971333105906777328061970448875974576460135015541883929","price":"0.34","size":"5","side":"BUY","hash":"cd72457b042000c72ff659f7c7505f6b8b2add64","best_bid":"0.99","best_ask":"1"},{"asset_id":"103575991306220918671611575108050794364462782362354955892418399227289531345027","price":"0.66","size":"5","side":"SELL","hash":"4f2174a5b6f3d88796a33202c65c43560ed6c807","best_bid":"0","best_ask":"0.01"}],"timestamp":"1768359590627","event_type":"price_change"}
{"market":"0x5977c69bca02e6cc150855b0faec463b38be463f141ec37ea5c8a1a1e986e0d3","price_changes":[{"asset_id":"110222991870854778724082971333105906777328061970448875974576460135015541883929","price":"0.73","size":"34.37","side":"BUY","hash":"cd72457b042000c72ff659f7c7505f6b8b2add64","best_bid":"0.99","best_ask":"1"},{"asset_id":"103575991306220918671611575108050794364462782362354955892418399227289531345027","price":"0.27","size":"34.37","side":"SELL","hash":"4f2174a5b6f3d88796a33202c65c43560ed6c807","best_bid":"0","best_ask":"0.01"}],"timestamp":"1768359590627","event_type":"price_change"}
{"market":"0x5977c69bca02e6cc150855b0faec463b38be463f141ec37ea5c8a1a1e986e0d3","price_changes":[{"asset_id":"110222991870854778724082971333105906777328061970448875974576460135015541883929","price":"0.8","size":"27","side":"BUY","hash":"cd72457b042000c72ff659f7c7505f6b8b2add64","best_bid":"0.99","best_ask":"1"},{"asset_id":"103575991306220918671611575108050794364462782362354955892418399227289531345027","price":"0.2","size":"27","side":"SELL","hash":"4f2174a5b6f3d88796a33202c65c43560ed6c807","best_bid":"0","best_ask":"0.01"}],"timestamp":"1768359590627","event_type":"price_change"}
{"market":"0x5977c69bca02e6cc150855b0faec463b38be463f141ec37ea5c8a1a1e986e0d3","price_changes":[{"asset_id":"110222991870854778724082971333105906777328061970448875974576460135015541883929","price":"0.68","size":"110.24","side":"BUY","hash":"cd72457b042000c72ff659f7c7505f6b8b2add64","best_bid":"0.99","best_ask":"1"},{"asset_id":"103575991306220918671611575108050794364462782362354955892418399227289531345027","price":"0.32","size":"110.24","side":"SELL","hash":"4f2174a5b6f3d88796a33202c65c43560ed6c807","best_bid":"0","best_ask":"0.01"}],"timestamp":"1768359590627","event_type":"price_change"}
{"market":"0x5977c69bca02e6cc150855b0faec463b38be463f141ec37ea5c8a1a1e986e0d3","price_changes":[{"asset_id":"110222991870854778724082971333105906777328061970448875974576460135015541883929","price":"0.82","size":"0","side":"BUY","hash":"cd72457b042000c72ff659f7c7505f6b8b2add64","best_bid":"0.99","best_ask":"1"},{"asset_id":"103575991306220918671611575108050794364462782362354955892418399227289531345027","price":"0.18","size":"0","side":"SELL","hash":"4f2174a5b6f3d88796a33202c65c43560ed6c807","best_bid":"0","best_ask":"0.01"}],"timestamp":"1768359590627","event_type":"price_change"}
{"market":"0x5977c69bca02e6cc150855b0faec463b38be463f141ec37ea5c8a1a1e986e0d3","price_changes":[{"asset_id":"110222991870854778724082971333105906777328061970448875974576460135015541883929","price":"0.27","size":"0","side":"BUY","hash":"cd72457b042000c72ff659f7c7505f6b8b2add64","best_bid":"0.99","best_ask":"1"},{"asset_id":"103575991306220918671611575108050794364462782362354955892418399227289531345027","price":"0.73","size":"0","side":"SELL","hash":"4f2174a5b6f3d88796a33202c65c43560ed6c807","best_bid":"0","best_ask":"0.01"}],"timestamp":"1768359590627","event_type":"price_change"}
{"market":"0x5977c69bca02e6cc150855b0faec463b38be463f141ec37ea5c8a1a1e986e0d3","price_changes":[{"asset_id":"110222991870854778724082971333105906777328061970448875974576460135015541883929","price":"0.89","size":"1010","side":"BUY","hash":"cd72457b042000c72ff659f7c7505f6b8b2add64","best_bid":"0.99","best_ask":"1"},{"asset_id":"103575991306220918671611575108050794364462782362354955892418399227289531345027","price":"0.11","size":"1010","side":"SELL","hash":"4f2174a5b6f3d88796a33202c65c43560ed6c807","best_bid":"0","best_ask":"0.01"}],"timestamp":"1768359590627","event_type":"price_change"}
{"market":"0x5977c69bca02e6cc150855b0faec463b38be463f141ec37ea5c8a1a1e986e0d3","price_changes":[{"asset_id":"110222991870854778724082971333105906777328061970448875974576460135015541883929","price":"0.36","size":"15","side":"BUY","hash":"cd72457b042000c72ff659f7c7505f6b8b2add64","best_bid":"0.99","best_ask":"1"},{"asset_id":"103575991306220918671611575108050794364462782362354955892418399227289531345027","price":"0.64","size":"15","side":"SELL","hash":"4f2174a5b6f3d88796a33202c65c43560ed6c807","best_bid":"0","best_ask":"0.01"}],"timestamp":"1768359590627","event_type":"price_change"}
{"market":"0x5977c69bca02e6cc150855b0faec463b38be463f141ec37ea5c8a1a1e986e0d3","price_changes":[{"asset_id":"110222991870854778724082971333105906777328061970448875974576460135015541883929","price":"0.32","size":"5","side":"BUY","hash":"cd72457b042000c72ff659f7c7505f6b8b2add64","best_bid":"0.99","best_ask":"1"},{"asset_id":"103575991306220918671611575108050794364462782362354955892418399227289531345027","price":"0.68","size":"5","side":"SELL","hash":"4f2174a5b6f3d88796a33202c65c43560ed6c807","best_bid":"0","best_ask":"0.01"}],"timestamp":"1768359590627","event_type":"price_change"}
{"market":"0x5977c69bca02e6cc150855b0faec463b38be463f141ec37ea5c8a1a1e986e0d3","price_changes":[{"asset_id":"110222991870854778724082971333105906777328061970448875974576460135015541883929","price":"0.25","size":"33.5","side":"BUY","hash":"cd72457b042000c72ff659f7c7505f6b8b2add64","best_bid":"0.99","best_ask":"1"},{"asset_id":"103575991306220918671611575108050794364462782362354955892418399227289531345027","price":"0.75","size":"33.5","side":"SELL","hash":"4f2174a5b6f3d88796a33202c65c43560ed6c807","best_bid":"0","best_ask":"0.01"}],"timestamp":"1768359590627","event_type":"price_change"}
{"market":"0x5977c69bca02e6cc150855b0faec463b38be463f141ec37ea5c8a1a1e986e0d3","price_changes":[{"asset_id":"110222991870854778724082971333105906777328061970448875974576460135015541883929","price":"0.79","size":"5","side":"BUY","hash":"cd72457b042000c72ff659f7c7505f6b8b2add64","best_bid":"0.99","best_ask":"1"},{"asset_id":"103575991306220918671611575108050794364462782362354955892418399227289531345027","price":"0.21","size":"5","side":"SELL","hash":"4f2174a5b6f3d88796a33202c65c43560ed6c807","best_bid":"0","best_ask":"0.01"}],"timestamp":"1768359590627","event_type":"price_change"}
{"market":"0x5977c69bca02e6cc150855b0faec463b38be463f141ec37ea5c8a1a1e986e0d3","price_changes":[{"asset_id":"110222991870854778724082971333105906777328061970448875974576460135015541883929","price":"0.58","size":"5","side":"BUY","hash":"cd72457b042000c72ff659f7c7505f6b8b2add64","best_bid":"0.99","best_ask":"1"},{"asset_id":"103575991306220918671611575108050794364462782362354955892418399227289531345027","price":"0.42","size":"5","side":"SELL","hash":"4f2174a5b6f3d88796a33202c65c43560ed6c807","best_bid":"0","best_ask":"0.01"}],"timestamp":"1768359590627","event_type":"price_change"}
{"market":"0x5977c69bca02e6cc150855b0faec463b38be463f141ec37ea5c8a1a1e986e0d3","price_changes":[{"asset_id":"110222991870854778724082971333105906777328061970448875974576460135015541883929","price":"0.6","size":"16","side":"BUY","hash":"cd72457b042000c72ff659f7c7505f6b8b2add64","best_bid":"0.99","best_ask":"1"},{"asset_id":"103575991306220918671611575108050794364462782362354955892418399227289531345027","price":"0.4","size":"16","side":"SELL","hash":"4f2174a5b6f3d88796a33202c65c43560ed6c807","best_bid":"0","best_ask":"0.01"}],"timestamp":"1768359590627","event_type":"price_change"}
{"market":"0x5977c69bca02e6cc150855b0faec463b38be463f141ec37ea5c8a1a1e986e0d3","price_changes":[{"asset_id":"110222991870854778724082971333105906777328061970448875974576460135015541883929","price":"0.65","size":"150.75","side":"BUY","hash":"cd72457b042000c72ff659f7c7505f6b8b2add64","best_bid":"0.99","best_ask":"1"},{"asset_id":"103575991306220918671611575108050794364462782362354955892418399227289531345027","price":"0.35","size":"150.75","side":"SELL","hash":"4f2174a5b6f3d88796a33202c65c43560ed6c807","best_bid":"0","best_ask":"0.01"}],"timestamp":"1768359590627","event_type":"price_change"}
{"market":"0x5977c69bca02e6cc150855b0faec463b38be463f141ec37ea5c8a1a1e986e0d3","price_changes":[{"asset_id":"110222991870854778724082971333105906777328061970448875974576460135015541883929","price":"0.56","size":"15","side":"BUY","hash":"cd72457b042000c72ff659f7c7505f6b8b2add64","best_bid":"0.99","best_ask":"1"},{"asset_id":"103575991306220918671611575108050794364462782362354955892418399227289531345027","price":"0.44","size":"15","side":"SELL","hash":"4f2174a5b6f3d88796a33202c65c43560ed6c807","best_bid":"0","best_ask":"0.01"}],"timestamp":"1768359590627","event_type":"price_change"}
{"market":"0x5977c69bca02e6cc150855b0faec463b38be463f141ec37ea5c8a1a1e986e0d3","price_changes":[{"asset_id":"110222991870854778724082971333105906777328061970448875974576460135015541883929","price":"0.78","size":"9.97","side":"BUY","hash":"cd72457b042000c72ff659f7c7505f6b8b2add64","best_bid":"0.99","best_ask":"1"},{"asset_id":"103575991306220918671611575108050794364462782362354955892418399227289531345027","price":"0.22","size":"9.97","side":"SELL","hash":"4f2174a5b6f3d88796a33202c65c43560ed6c807","best_bid":"0","best_ask":"0.01"}],"timestamp":"1768359590627","event_type":"price_change"}
{"market":"0x5977c69bca02e6cc150855b0faec463b38be463f141ec37ea5c8a1a1e986e0d3","price_changes":[{"asset_id":"110222991870854778724082971333105906777328061970448875974576460135015541883929","price":"0.87","size":"0","side":"BUY","hash":"cd72457b042000c72ff659f7c7505f6b8b2add64","best_bid":"0.99","best_ask":"1"},{"asset_id":"103575991306220918671611575108050794364462782362354955892418399227289531345027","price":"0.13","size":"0","side":"SELL","hash":"4f2174a5b6f3d88796a33202c65c43560ed6c807","best_bid":"0","best_ask":"0.01"}],"timestamp":"1768359590627","event_type":"price_change"}
{"market":"0x5977c69bca02e6cc150855b0faec463b38be463f141ec37ea5c8a1a1e986e0d3","price_changes":[{"asset_id":"110222991870854778724082971333105906777328061970448875974576460135015541883929","price":"0.91","size":"0","side":"BUY","hash":"cd72457b042000c72ff659f7c7505f6b8b2add64","best_bid":"0.99","best_ask":"1"},{"asset_id":"103575991306220918671611575108050794364462782362354955892418399227289531345027","price":"0.09","size":"0","side":"SELL","hash":"4f2174a5b6f3d88796a33202c65c43560ed6c807","best_bid":"0","best_ask":"0.01"}],"timestamp":"1768359590627","event_type":"price_change"}
{"market":"0x5977c69bca02e6cc150855b0faec463b38be463f141ec37ea5c8a1a1e986e0d3","price_changes":[{"asset_id":"110222991870854778724082971333105906777328061970448875974576460135015541883929","price":"0.55","size":"0","side":"BUY","hash":"cd72457b042000c72ff659f7c7505f6b8b2add64","best_bid":"0.99","best_ask":"1"},{"asset_id":"103575991306220918671611575108050794364462782362354955892418399227289531345027","price":"0.45","size":"0","side":"SELL","hash":"4f2174a5b6f3d88796a33202c65c43560ed6c807","best_bid":"0","best_ask":"0.01"}],"timestamp":"1768359590627","event_type":"price_change"}
{"market":"0x5977c69bca02e6cc150855b0faec463b38be463f141ec37ea5c8a1a1e986e0d3","price_changes":[{"asset_id":"110222991870854778724082971333105906777328061970448875974576460135015541883929","price":"0.38","size":"0","side":"BUY","hash":"cd72457b042000c72ff659f7c7505f6b8b2add64","best_bid":"0.99","best_ask":"1"},{"asset_id":"103575991306220918671611575108050794364462782362354955892418399227289531345027","price":"0.62","size":"0","side":"SELL","hash":"4f2174a5b6f3d88796a33202c65c43560ed6c807","best_bid":"0","best_ask":"0.01"}],"timestamp":"1768359590627","event_type":"price_change"}
{"market":"0x5977c69bca02e6cc150855b0faec463b38be463f141ec37ea5c8a1a1e986e0d3","price_changes":[{"asset_id":"110222991870854778724082971333105906777328061970448875974576460135015541883929","price":"0.53","size":"0","side":"BUY","hash":"cd72457b042000c72ff659f7c7505f6b8b2add64","best_bid":"0.99","best_ask":"1"},{"asset_id":"103575991306220918671611575108050794364462782362354955892418399227289531345027","price":"0.47","size":"0","side":"SELL","hash":"4f2174a5b6f3d88796a33202c65c43560ed6c807","best_bid":"0","best_ask":"0.01"}],"timestamp":"1768359590627","event_type":"price_change"}
{"market":"0x5977c69bca02e6cc150855b0faec463b38be463f141ec37ea5c8a1a1e986e0d3","price_changes":[{"asset_id":"110222991870854778724082971333105906777328061970448875974576460135015541883929","price":"0.39","size":"0","side":"BUY","hash":"cd72457b042000c72ff659f7c7505f6b8b2add64","best_bid":"0.99","best_ask":"1"},{"asset_id":"103575991306220918671611575108050794364462782362354955892418399227289531345027","price":"0.61","size":"0","side":"SELL","hash":"4f2174a5b6f3d88796a33202c65c43560ed6c807","best_bid":"0","best_ask":"0.01"}],"timestamp":"1768359590627","event_type":"price_change"}
{"market":"0x5977c69bca02e6cc150855b0faec463b38be463f141ec37ea5c8a1a1e986e0d3","price_changes":[{"asset_id":"110222991870854778724082971333105906777328061970448875974576460135015541883929","price":"0.24","size":"0","side":"BUY","hash":"cd72457b042000c72ff659f7c7505f6b8b2add64","best_bid":"0.99","best_ask":"1"},{"asset_id":"103575991306220918671611575108050794364462782362354955892418399227289531345027","price":"0.76","size":"0","side":"SELL","hash":"4f2174a5b6f3d88796a33202c65c43560ed6c807","best_bid":"0","best_ask":"0.01"}],"timestamp":"1768359590627","event_type":"price_change"}
{"market":"0x5977c69bca02e6cc150855b0faec463b38be463f141ec37ea5c8a1a1e986e0d3","price_changes":[{"asset_id":"110222991870854778724082971333105906777328061970448875974576460135015541883929","price":"0.19","size":"0","side":"BUY","hash":"cd72457b042000c72ff659f7c7505f6b8b2add64","best_bid":"0.99","best_ask":"1"},{"asset_id":"103575991306220918671611575108050794364462782362354955892418399227289531345027","price":"0.81","size":"0","side":"SELL","hash":"4f2174a5b6f3d88796a33202c65c43560ed6c807","best_bid":"0","best_ask":"0.01"}],"timestamp":"1768359590627","event_type":"price_change"}
{"market":"0x5977c69bca02e6cc150855b0faec463b38be463f141ec37ea5c8a1a1e986e0d3","price_changes":[{"asset_id":"110222991870854778724082971333105906777328061970448875974576460135015541883929","price":"0.75","size":"440.01","side":"BUY","hash":"cd72457b042000c72ff659f7c7505f6b8b2add64","best_bid":"0.99","best_ask":"1"},{"asset_id":"103575991306220918671611575108050794364462782362354955892418399227289531345027","price":"0.25","size":"440.01","side":"SELL","hash":"4f2174a5b6f3d88796a33202c65c43560ed6c807","best_bid":"0","best_ask":"0.01"}],"timestamp":"1768359590627","event_type":"price_change"}
{"market":"0x5977c69bca02e6cc150855b0faec463b38be463f141ec37ea5c8a1a1e986e0d3","price_changes":[{"asset_id":"110222991870854778724082971333105906777328061970448875974576460135015541883929","price":"0.57","size":"5","side":"BUY","hash":"cd72457b042000c72ff659f7c7505f6b8b2add64","best_bid":"0.99","best_ask":"1"},{"asset_id":"103575991306220918671611575108050794364462782362354955892418399227289531345027","price":"0.43","size":"5","side":"SELL","hash":"4f2174a5b6f3d88796a33202c65c43560ed6c807","best_bid":"0","best_ask":"0.01"}],"timestamp":"1768359590627","event_type":"price_change"}
{"market":"0x5977c69bca02e6cc150855b0faec463b38be463f141ec37ea5c8a1a1e986e0d3","price_changes":[{"asset_id":"110222991870854778724082971333105906777328061970448875974576460135015541883929","price":"0.22","size":"0","side":"BUY","hash":"cd72457b042000c72ff659f7c7505f6b8b2add64","best_bid":"0.99","best_ask":"1"},{"asset_id":"103575991306220918671611575108050794364462782362354955892418399227289531345027","price":"0.78","size":"0","side":"SELL","hash":"4f2174a5b6f3d88796a33202c65c43560ed6c807","best_bid":"0","best_ask":"0.01"}],"timestamp":"1768359590627","event_type":"price_change"}
{"market":"0x5977c69bca02e6cc150855b0faec463b38be463f141ec37ea5c8a1a1e986e0d3","price_changes":[{"asset_id":"110222991870854778724082971333105906777328061970448875974576460135015541883929","price":"0.05","size":"35","side":"BUY","hash":"cd72457b042000c72ff659f7c7505f6b8b2add64","best_bid":"0.99","best_ask":"1"},{"asset_id":"103575991306220918671611575108050794364462782362354955892418399227289531345027","price":"0.95","size":"35","side":"SELL","hash":"4f2174a5b6f3d88796a33202c65c43560ed6c807","best_bid":"0","best_ask":"0.01"}],"timestamp":"1768359590627","event_type":"price_change"}
{"market":"0x5977c69bca02e6cc150855b0faec463b38be463f141ec37ea5c8a1a1e986e0d3","price_changes":[{"asset_id":"110222991870854778724082971333105906777328061970448875974576460135015541883929","price":"0.08","size":"0","side":"BUY","hash":"cd72457b042000c72ff659f7c7505f6b8b2add64","best_bid":"0.99","best_ask":"1"},{"asset_id":"103575991306220918671611575108050794364462782362354955892418399227289531345027","price":"0.92","size":"0","side":"SELL","hash":"4f2174a5b6f3d88796a33202c65c43560ed6c807","best_bid":"0","best_ask":"0.01"}],"timestamp":"1768359590627","event_type":"price_change"}
{"market":"0x5977c69bca02e6cc150855b0faec463b38be463f141ec37ea5c8a1a1e986e0d3","price_changes":[{"asset_id":"110222991870854778724082971333105906777328061970448875974576460135015541883929","price":"0.69","size":"94.01","side":"BUY","hash":"cd72457b042000c72ff659f7c7505f6b8b2add64","best_bid":"0.99","best_ask":"1"},{"asset_id":"103575991306220918671611575108050794364462782362354955892418399227289531345027","price":"0.31","size":"94.01","side":"SELL","hash":"4f2174a5b6f3d88796a33202c65c43560ed6c807","best_bid":"0","best_ask":"0.01"}],"timestamp":"1768359590627","event_type":"price_change"}
{"market":"0x5977c69bca02e6cc150855b0faec463b38be463f141ec37ea5c8a1a1e986e0d3","price_changes":[{"asset_id":"110222991870854778724082971333105906777328061970448875974576460135015541883929","price":"0.72","size":"202.84","side":"BUY","hash":"cd72457b042000c72ff659f7c7505f6b8b2add64","best_bid":"0.99","best_ask":"1"},{"asset_id":"103575991306220918671611575108050794364462782362354955892418399227289531345027","price":"0.28","size":"202.84","side":"SELL","hash":"4f2174a5b6f3d88796a33202c65c43560ed6c807","best_bid":"0","best_ask":"0.01"}],"timestamp":"1768359590627","event_type":"price_change"}
{"market":"0x5977c69bca02e6cc150855b0faec463b38be463f141ec37ea5c8a1a1e986e0d3","price_changes":[{"asset_id":"110222991870854778724082971333105906777328061970448875974576460135015541883929","price":"0.85","size":"26.25","side":"BUY","hash":"cd72457b042000c72ff659f7c7505f6b8b2add64","best_bid":"0.99","best_ask":"1"},{"asset_id":"103575991306220918671611575108050794364462782362354955892418399227289531345027","price":"0.15","size":"26.25","side":"SELL","hash":"4f2174a5b6f3d88796a33202c65c43560ed6c807","best_bid":"0","best_ask":"0.01"}],"timestamp":"1768359590627","event_type":"price_change"}
{"market":"0x5977c69bca02e6cc150855b0faec463b38be463f141ec37ea5c8a1a1e986e0d3","price_changes":[{"asset_id":"110222991870854778724082971333105906777328061970448875974576460135015541883929","price":"0.63","size":"20.24","side":"BUY","hash":"cd72457b042000c72ff659f7c7505f6b8b2add64","best_bid":"0.99","best_ask":"1"},{"asset_id":"103575991306220918671611575108050794364462782362354955892418399227289531345027","price":"0.37","size":"20.24","side":"SELL","hash":"4f2174a5b6f3d88796a33202c65c43560ed6c807","best_bid":"0","best_ask":"0.01"}],"timestamp":"1768359590627","event_type":"price_change"}
{"market":"0x5977c69bca02e6cc150855b0faec463b38be463f141ec37ea5c8a1a1e986e0d3","price_changes":[{"asset_id":"110222991870854778724082971333105906777328061970448875974576460135015541883929","price":"0.7","size":"297.5","side":"BUY","hash":"cd72457b042000c72ff659f7c7505f6b8b2add64","best_bid":"0.99","best_ask":"1"},{"asset_id":"103575991306220918671611575108050794364462782362354955892418399227289531345027","price":"0.3","size":"297.5","side":"SELL","hash":"4f2174a5b6f3d88796a33202c65c43560ed6c807","best_bid":"0","best_ask":"0.01"}],"timestamp":"1768359590627","event_type":"price_change"}
{"market":"0x5977c69bca02e6cc150855b0faec463b38be463f141ec37ea5c8a1a1e986e0d3","price_changes":[{"asset_id":"110222991870854778724082971333105906777328061970448875974576460135015541883929","price":"0.83","size":"38.78","side":"BUY","hash":"cd72457b042000c72ff659f7c7505f6b8b2add64","best_bid":"0.99","best_ask":"1"},{"asset_id":"103575991306220918671611575108050794364462782362354955892418399227289531345027","price":"0.17","size":"38.78","side":"SELL","hash":"4f2174a5b6f3d88796a33202c65c43560ed6c807","best_bid":"0","best_ask":"0.01"}],"timestamp":"1768359590627","event_type":"price_change"}
{"market":"0x5977c69bca02e6cc150855b0faec463b38be463f141ec37ea5c8a1a1e986e0d3","price_changes":[{"asset_id":"110222991870854778724082971333105906777328061970448875974576460135015541883929","price":"0.92","size":"214.2","side":"BUY","hash":"cd72457b042000c72ff659f7c7505f6b8b2add64","best_bid":"0.99","best_ask":"1"},{"asset_id":"103575991306220918671611575108050794364462782362354955892418399227289531345027","price":"0.08","size":"214.2","side":"SELL","hash":"4f2174a5b6f3d88796a33202c65c43560ed6c807","best_bid":"0","best_ask":"0.01"}],"timestamp":"1768359590627","event_type":"price_change"}
{"market":"0x5977c69bca02e6cc150855b0faec463b38be463f141ec37ea5c8a1a1e986e0d3","price_changes":[{"asset_id":"110222991870854778724082971333105906777328061970448875974576460135015541883929","price":"0.74","size":"110.67","side":"BUY","hash":"cd72457b042000c72ff659f7c7505f6b8b2add64","best_bid":"0.99","best_ask":"1"},{"asset_id":"103575991306220918671611575108050794364462782362354955892418399227289531345027","price":"0.26","size":"110.67","side":"SELL","hash":"4f2174a5b6f3d88796a33202c65c43560ed6c807","best_bid":"0","best_ask":"0.01"}],"timestamp":"1768359590627","event_type":"price_change"}
{"market":"0x5977c69bca02e6cc150855b0faec463b38be463f141ec37ea5c8a1a1e986e0d3","price_changes":[{"asset_id":"110222991870854778724082971333105906777328061970448875974576460135015541883929","price":"0.93","size":"73","side":"BUY","hash":"cd72457b042000c72ff659f7c7505f6b8b2add64","best_bid":"0.99","best_ask":"1"},{"asset_id":"103575991306220918671611575108050794364462782362354955892418399227289531345027","price":"0.07","size":"73","side":"SELL","hash":"4f2174a5b6f3d88796a33202c65c43560ed6c807","best_bid":"0","best_ask":"0.01"}],"timestamp":"1768359590627","event_type":"price_change"}
{"market":"0x5977c69bca02e6cc150855b0faec463b38be463f141ec37ea5c8a1a1e986e0d3","price_changes":[{"asset_id":"110222991870854778724082971333105906777328061970448875974576460135015541883929","price":"0.31","size":"0","side":"BUY","hash":"cd72457b042000c72ff659f7c7505f6b8b2add64","best_bid":"0.99","best_ask":"1"},{"asset_id":"103575991306220918671611575108050794364462782362354955892418399227289531345027","price":"0.69","size":"0","side":"SELL","hash":"4f2174a5b6f3d88796a33202c65c43560ed6c807","best_bid":"0","best_ask":"0.01"}],"timestamp":"1768359590627","event_type":"price_change"}
{"market":"0x5977c69bca02e6cc150855b0faec463b38be463f141ec37ea5c8a1a1e986e0d3","price_changes":[{"asset_id":"110222991870854778724082971333105906777328061970448875974576460135015541883929","price":"0.88","size":"1011.36","side":"BUY","hash":"cd72457b042000c72ff659f7c7505f6b8b2add64","best_bid":"0.99","best_ask":"1"},{"asset_id":"103575991306220918671611575108050794364462782362354955892418399227289531345027","price":"0.12","size":"1011.36","side":"SELL","hash":"4f2174a5b6f3d88796a33202c65c43560ed6c807","best_bid":"0","best_ask":"0.01"}],"timestamp":"1768359590627","event_type":"price_change"}
{"market":"0x5977c69bca02e6cc150855b0faec463b38be463f141ec37ea5c8a1a1e986e0d3","price_changes":[{"asset_id":"110222991870854778724082971333105906777328061970448875974576460135015541883929","price":"0.06","size":"0","side":"BUY","hash":"cd72457b042000c72ff659f7c7505f6b8b2add64","best_bid":"0.99","best_ask":"1"},{"asset_id":"103575991306220918671611575108050794364462782362354955892418399227289531345027","price":"0.94","size":"0","side":"SELL","hash":"4f2174a5b6f3d88796a33202c65c43560ed6c807","best_bid":"0","best_ask":"0.01"}],"timestamp":"1768359590627","event_type":"price_change"}
{"market":"0x5977c69bca02e6cc150855b0faec463b38be463f141ec37ea5c8a1a1e986e0d3","price_changes":[{"asset_id":"110222991870854778724082971333105906777328061970448875974576460135015541883929","price":"0.29","size":"0","side":"BUY","hash":"cd72457b042000c72ff659f7c7505f6b8b2add64","best_bid":"0.99","best_ask":"1"},{"asset_id":"103575991306220918671611575108050794364462782362354955892418399227289531345027","price":"0.71","size":"0","side":"SELL","hash":"4f2174a5b6f3d88796a33202c65c43560ed6c807","best_bid":"0","best_ask":"0.01"}],"timestamp":"1768359590627","event_type":"price_change"}
{"market":"0x5977c69bca02e6cc150855b0faec463b38be463f141ec37ea5c8a1a1e986e0d3","price_changes":[{"asset_id":"110222991870854778724082971333105906777328061970448875974576460135015541883929","price":"0.94","size":"320.16","side":"BUY","hash":"cd72457b042000c72ff659f7c7505f6b8b2add64","best_bid":"0.99","best_ask":"1"},{"asset_id":"103575991306220918671611575108050794364462782362354955892418399227289531345027","price":"0.06","size":"320.16","side":"SELL","hash":"4f2174a5b6f3d88796a33202c65c43560ed6c807","best_bid":"0","best_ask":"0.01"}],"timestamp":"1768359590627","event_type":"price_change"}
{"market":"0x5977c69bca02e6cc150855b0faec463b38be463f141ec37ea5c8a1a1e986e0d3","price_changes":[{"asset_id":"110222991870854778724082971333105906777328061970448875974576460135015541883929","price":"0.03","size":"455.5","side":"BUY","hash":"cd72457b042000c72ff659f7c7505f6b8b2add64","best_bid":"0.99","best_ask":"1"},{"asset_id":"103575991306220918671611575108050794364462782362354955892418399227289531345027","price":"0.97","size":"455.5","side":"SELL","hash":"4f2174a5b6f3d88796a33202c65c43560ed6c807","best_bid":"0","best_ask":"0.01"}],"timestamp":"1768359590627","event_type":"price_change"}
{"market":"0x5977c69bca02e6cc150855b0faec463b38be463f141ec37ea5c8a1a1e986e0d3","price_changes":[{"asset_id":"110222991870854778724082971333105906777328061970448875974576460135015541883929","price":"0.07","size":"0","side":"BUY","hash":"cd72457b042000c72ff659f7c7505f6b8b2add64","best_bid":"0.99","best_ask":"1"},{"asset_id":"103575991306220918671611575108050794364462782362354955892418399227289531345027","price":"0.93","size":"0","side":"SELL","hash":"4f2174a5b6f3d88796a33202c65c43560ed6c807","best_bid":"0","best_ask":"0.01"}],"timestamp":"1768359590627","event_type":"price_change"}
{"market":"0x5977c69bca02e6cc150855b0faec463b38be463f141ec37ea5c8a1a1e986e0d3","price_changes":[{"asset_id":"110222991870854778724082971333105906777328061970448875974576460135015541883929","price":"0.09","size":"0","side":"BUY","hash":"cd72457b042000c72ff659f7c7505f6b8b2add64","best_bid":"0.99","best_ask":"1"},{"asset_id":"103575991306220918671611575108050794364462782362354955892418399227289531345027","price":"0.91","size":"0","side":"SELL","hash":"4f2174a5b6f3d88796a33202c65c43560ed6c807","best_bid":"0","best_ask":"0.01"}],"timestamp":"1768359590627","event_type":"price_change"}
{"market":"0x5977c69bca02e6cc150855b0faec463b38be463f141ec37ea5c8a1a1e986e0d3","price_changes":[{"asset_id":"110222991870854778724082971333105906777328061970448875974576460135015541883929","price":"0.97","size":"509.14","side":"BUY","hash":"cd72457b042000c72ff659f7c7505f6b8b2add64","best_bid":"0.99","best_ask":"1"},{"asset_id":"103575991306220918671611575108050794364462782362354955892418399227289531345027","price":"0.03","size":"509.14","side":"SELL","hash":"4f2174a5b6f3d88796a33202c65c43560ed6c807","best_bid":"0","best_ask":"0.01"}],"timestamp":"1768359590627","event_type":"price_change"}
{"market":"0x5977c69bca02e6cc150855b0faec463b38be463f141ec37ea5c8a1a1e986e0d3","price_changes":[{"asset_id":"110222991870854778724082971333105906777328061970448875974576460135015541883929","price":"0.35","size":"18.93","side":"BUY","hash":"cd72457b042000c72ff659f7c7505f6b8b2add64","best_bid":"0.99","best_ask":"1"},{"asset_id":"103575991306220918671611575108050794364462782362354955892418399227289531345027","price":"0.65","size":"18.93","side":"SELL","hash":"4f2174a5b6f3d88796a33202c65c43560ed6c807","best_bid":"0","best_ask":"0.01"}],"timestamp":"1768359590627","event_type":"price_change"}
{"market":"0x5977c69bca02e6cc150855b0faec463b38be463f141ec37ea5c8a1a1e986e0d3","price_changes":[{"asset_id":"110222991870854778724082971333105906777328061970448875974576460135015541883929","price":"0.84","size":"16.56","side":"BUY","hash":"cd72457b042000c72ff659f7c7505f6b8b2add64","best_bid":"0.99","best_ask":"1"},{"asset_id":"103575991306220918671611575108050794364462782362354955892418399227289531345027","price":"0.16","size":"16.56","side":"SELL","hash":"4f2174a5b6f3d88796a33202c65c43560ed6c807","best_bid":"0","best_ask":"0.01"}],"timestamp":"1768359590627","event_type":"price_change"}
{"market":"0x5977c69bca02e6cc150855b0faec463b38be463f141ec37ea5c8a1a1e986e0d3","price_changes":[{"asset_id":"110222991870854778724082971333105906777328061970448875974576460135015541883929","price":"0.59","size":"10","side":"BUY","hash":"cd72457b042000c72ff659f7c7505f6b8b2add64","best_bid":"0.99","best_ask":"1"},{"asset_id":"103575991306220918671611575108050794364462782362354955892418399227289531345027","price":"0.41","size":"10","side":"SELL","hash":"4f2174a5b6f3d88796a33202c65c43560ed6c807","best_bid":"0","best_ask":"0.01"}],"timestamp":"1768359590627","event_type":"price_change"}
{"market":"0x5977c69bca02e6cc150855b0faec463b38be463f141ec37ea5c8a1a1e986e0d3","price_changes":[{"asset_id":"110222991870854778724082971333105906777328061970448875974576460135015541883929","price":"0.81","size":"104.75","side":"BUY","hash":"cd72457b042000c72ff659f7c7505f6b8b2add64","best_bid":"0.99","best_ask":"1"},{"asset_id":"103575991306220918671611575108050794364462782362354955892418399227289531345027","price":"0.19","size":"104.75","side":"SELL","hash":"4f2174a5b6f3d88796a33202c65c43560ed6c807","best_bid":"0","best_ask":"0.01"}],"timestamp":"1768359590627","event_type":"price_change"}
{"market":"0x5977c69bca02e6cc150855b0faec463b38be463f141ec37ea5c8a1a1e986e0d3","price_changes":[{"asset_id":"110222991870854778724082971333105906777328061970448875974576460135015541883929","price":"0.21","size":"0","side":"BUY","hash":"cd72457b042000c72ff659f7c7505f6b8b2add64","best_bid":"0.99","best_ask":"1"},{"asset_id":"103575991306220918671611575108050794364462782362354955892418399227289531345027","price":"0.79","size":"0","side":"SELL","hash":"4f2174a5b6f3d88796a33202c65c43560ed6c807","best_bid":"0","best_ask":"0.01"}],"timestamp":"1768359590627","event_type":"price_change"}
{"market":"0x5977c69bca02e6cc150855b0faec463b38be463f141ec37ea5c8a1a1e986e0d3","price_changes":[{"asset_id":"110222991870854778724082971333105906777328061970448875974576460135015541883929","price":"0.67","size":"15.12","side":"BUY","hash":"cd72457b042000c72ff659f7c7505f6b8b2add64","best_bid":"0.99","best_ask":"1"},{"asset_id":"103575991306220918671611575108050794364462782362354955892418399227289531345027","price":"0.33","size":"15.12","side":"SELL","hash":"4f2174a5b6f3d88796a33202c65c43560ed6c807","best_bid":"0","best_ask":"0.01"}],"timestamp":"1768359590627","event_type":"price_change"}
{"market":"0x5977c69bca02e6cc150855b0faec463b38be463f141ec37ea5c8a1a1e986e0d3","price_changes":[{"asset_id":"110222991870854778724082971333105906777328061970448875974576460135015541883929","price":"0.02","size":"1556.8","side":"BUY","hash":"cd72457b042000c72ff659f7c7505f6b8b2add64","best_bid":"0.99","best_ask":"1"},{"asset_id":"103575991306220918671611575108050794364462782362354955892418399227289531345027","price":"0.98","size":"1556.8","side":"SELL","hash":"4f2174a5b6f3d88796a33202c65c43560ed6c807","best_bid":"0","best_ask":"0.01"}],"timestamp":"1768359590627","event_type":"price_change"}
{"market":"0x5977c69bca02e6cc150855b0faec463b38be463f141ec37ea5c8a1a1e986e0d3","price_changes":[{"asset_id":"110222991870854778724082971333105906777328061970448875974576460135015541883929","price":"0.2","size":"40","side":"BUY","hash":"cd72457b042000c72ff659f7c7505f6b8b2add64","best_bid":"0.99","best_ask":"1"},{"asset_id":"103575991306220918671611575108050794364462782362354955892418399227289531345027","price":"0.8","size":"40","side":"SELL","hash":"4f2174a5b6f3d88796a33202c65c43560ed6c807","best_bid":"0","best_ask":"0.01"}],"timestamp":"1768359590627","event_type":"price_change"}
{"market":"0x5977c69bca02e6cc150855b0faec463b38be463f141ec37ea5c8a1a1e986e0d3","price_changes":[{"asset_id":"110222991870854778724082971333105906777328061970448875974576460135015541883929","price":"0.71","size":"302.74","side":"BUY","hash":"cd72457b042000c72ff659f7c7505f6b8b2add64","best_bid":"0.99","best_ask":"1"},{"asset_id":"103575991306220918671611575108050794364462782362354955892418399227289531345027","price":"0.29","size":"302.74","side":"SELL","hash":"4f2174a5b6f3d88796a33202c65c43560ed6c807","best_bid":"0","best_ask":"0.01"}],"timestamp":"1768359590627","event_type":"price_change"}
{"market":"0x5977c69bca02e6cc150855b0faec463b38be463f141ec37ea5c8a1a1e986e0d3","price_changes":[{"asset_id":"110222991870854778724082971333105906777328061970448875974576460135015541883929","price":"0.86","size":"525.94","side":"BUY","hash":"cd72457b042000c72ff659f7c7505f6b8b2add64","best_bid":"0.99","best_ask":"1"},{"asset_id":"103575991306220918671611575108050794364462782362354955892418399227289531345027","price":"0.14","size":"525.94","side":"SELL","hash":"4f2174a5b6f3d88796a33202c65c43560ed6c807","best_bid":"0","best_ask":"0.01"}],"timestamp":"1768359590627","event_type":"price_change"}
{"market":"0x5977c69bca02e6cc150855b0faec463b38be463f141ec37ea5c8a1a1e986e0d3","price_changes":[{"asset_id":"110222991870854778724082971333105906777328061970448875974576460135015541883929","price":"0.54","size":"0","side":"BUY","hash":"cd72457b042000c72ff659f7c7505f6b8b2add64","best_bid":"0.99","best_ask":"1"},{"asset_id":"103575991306220918671611575108050794364462782362354955892418399227289531345027","price":"0.46","size":"0","side":"SELL","hash":"4f2174a5b6f3d88796a33202c65c43560ed6c807","best_bid":"0","best_ask":"0.01"}],"timestamp":"1768359590627","event_type":"price_change"}
{"market":"0x5977c69bca02e6cc150855b0faec463b38be463f141ec37ea5c8a1a1e986e0d3","price_changes":[{"asset_id":"110222991870854778724082971333105906777328061970448875974576460135015541883929","price":"0.33","size":"0","side":"BUY","hash":"cd72457b042000c72ff659f7c7505f6b8b2add64","best_bid":"0.99","best_ask":"1"},{"asset_id":"103575991306220918671611575108050794364462782362354955892418399227289531345027","price":"0.67","size":"0","side":"SELL","hash":"4f2174a5b6f3d88796a33202c65c43560ed6c807","best_bid":"0","best_ask":"0.01"}],"timestamp":"1768359590627","event_type":"price_change"}
{"market":"0x5977c69bca02e6cc150855b0faec463b38be463f141ec37ea5c8a1a1e986e0d3","price_changes":[{"asset_id":"110222991870854778724082971333105906777328061970448875974576460135015541883929","price":"0.66","size":"130.37","side":"BUY","hash":"cd72457b042000c72ff659f7c7505f6b8b2add64","best_bid":"0.99","best_ask":"1"},{"asset_id":"103575991306220918671611575108050794364462782362354955892418399227289531345027","price":"0.34","size":"130.37","side":"SELL","hash":"4f2174a5b6f3d88796a33202c65c43560ed6c807","best_bid":"0","best_ask":"0.01"}],"timestamp":"1768359590627","event_type":"price_change"}
{"market":"0x5977c69bca02e6cc150855b0faec463b38be463f141ec37ea5c8a1a1e986e0d3","price_changes":[{"asset_id":"110222991870854778724082971333105906777328061970448875974576460135015541883929","price":"0.64","size":"136.18","side":"BUY","hash":"cd72457b042000c72ff659f7c7505f6b8b2add64","best_bid":"0.99","best_ask":"1"},{"asset_id":"103575991306220918671611575108050794364462782362354955892418399227289531345027","price":"0.36","size":"136.18","side":"SELL","hash":"4f2174a5b6f3d88796a33202c65c43560ed6c807","best_bid":"0","best_ask":"0.01"}],"timestamp":"1768359590627","event_type":"price_change"}
{"market":"0x5977c69bca02e6cc150855b0faec463b38be463f141ec37ea5c8a1a1e986e0d3","price_changes":[{"asset_id":"110222991870854778724082971333105906777328061970448875974576460135015541883929","price":"0.61","size":"5","side":"BUY","hash":"cd72457b042000c72ff659f7c7505f6b8b2add64","best_bid":"0.99","best_ask":"1"},{"asset_id":"103575991306220918671611575108050794364462782362354955892418399227289531345027","price":"0.39","size":"5","side":"SELL","hash":"4f2174a5b6f3d88796a33202c65c43560ed6c807","best_bid":"0","best_ask":"0.01"}],"timestamp":"1768359590627","event_type":"price_change"}
{"market":"0x5977c69bca02e6cc150855b0faec463b38be463f141ec37ea5c8a1a1e986e0d3","price_changes":[{"asset_id":"110222991870854778724082971333105906777328061970448875974576460135015541883929","price":"0.97","size":"504.14","side":"BUY","hash":"0d1cb2008f18431b76a9b9d55b92e1aafb61f194","best_bid":"0.99","best_ask":"1"},{"asset_id":"103575991306220918671611575108050794364462782362354955892418399227289531345027","price":"0.03","size":"504.14","side":"SELL","hash":"7184abad562945a9d0d2d132910b14059c698371","best_bid":"0","best_ask":"0.01"}],"timestamp":"1768359591023","event_type":"price_change"}
{"market":"0x5977c69bca02e6cc150855b0faec463b38be463f141ec37ea5c8a1a1e986e0d3","price_changes":[{"asset_id":"110222991870854778724082971333105906777328061970448875974576460135015541883929","price":"0.8","size":"17","side":"BUY","hash":"47b4ce73665e0fe07f63bbe17e0cf00a7670ec40","best_bid":"0.99","best_ask":"1"},{"asset_id":"103575991306220918671611575108050794364462782362354955892418399227289531345027","price":"0.2","size":"17","side":"SELL","hash":"845d6593ce1ccbdf93672af83d7409be1b5fa1ba","best_bid":"0","best_ask":"0.01"}],"timestamp":"1768359591441","event_type":"price_change"}
{"market":"0x5977c69bca02e6cc150855b0faec463b38be463f141ec37ea5c8a1a1e986e0d3","price_changes":[{"asset_id":"110222991870854778724082971333105906777328061970448875974576460135015541883929","price":"0.8","size":"27","side":"BUY","hash":"738aa56ef18eb6bd37b125fbc8a55b097f888be4","best_bid":"0.99","best_ask":"1"},{"asset_id":"103575991306220918671611575108050794364462782362354955892418399227289531345027","price":"0.2","size":"27","side":"SELL","hash":"ba1a6bb2a740004cccac804cadad6b7d5c6c9a69","best_bid":"0","best_ask":"0.01"}],"timestamp":"1768359591463","event_type":"price_change"}
{"market":"0x5977c69bca02e6cc150855b0faec463b38be463f141ec37ea5c8a1a1e986e0d3","price_changes":[{"asset_id":"110222991870854778724082971333105906777328061970448875974576460135015541883929","price":"0.99","size":"376.83","side":"BUY","hash":"79d69cae07726653a6ed1a6482234c93cf138434","best_bid":"0.99","best_ask":"1"},{"asset_id":"103575991306220918671611575108050794364462782362354955892418399227289531345027","price":"0.01","size":"376.83","side":"SELL","hash":"5f2cdb1b378ff5d7fe84c1808dc0c5a78b6f9766","best_bid":"0","best_ask":"0.01"}],"timestamp":"1768359591838","event_type":"price_change"}
{"market":"0x5977c69bca02e6cc150855b0faec463b38be463f141ec37ea5c8a1a1e986e0d3","price_changes":[{"asset_id":"110222991870854778724082971333105906777328061970448875974576460135015541883929","price":"0.99","size":"381.83","side":"BUY","hash":"676202736cca6bc429727038d830400bb51648ec","best_bid":"0.99","best_ask":"1"},{"asset_id":"103575991306220918671611575108050794364462782362354955892418399227289531345027","price":"0.01","size":"381.83","side":"SELL","hash":"44b986890e3aa3f581088b891ad2b5b26b15566e","best_bid":"0","best_ask":"0.01"}],"timestamp":"1768359592017","event_type":"price_change"}
{"market":"0x5977c69bca02e6cc150855b0faec463b38be463f141ec37ea5c8a1a1e986e0d3","price_changes":[{"asset_id":"110222991870854778724082971333105906777328061970448875974576460135015541883929","price":"0.99","size":"461.83","side":"BUY","hash":"23f76070bec427ce1b334d857ada146f12a841f3","best_bid":"0.99","best_ask":"1"},{"asset_id":"103575991306220918671611575108050794364462782362354955892418399227289531345027","price":"0.01","size":"461.83","side":"SELL","hash":"05acb7de1178ea5a26a5fda54039f82567878e8a","best_bid":"0","best_ask":"0.01"}],"timestamp":"1768359592023","event_type":"price_change"}
{"market":"0x5977c69bca02e6cc150855b0faec463b38be463f141ec37ea5c8a1a1e986e0d3","price_changes":[{"asset_id":"110222991870854778724082971333105906777328061970448875974576460135015541883929","price":"0.99","size":"466.83","side":"BUY","hash":"a42219e0f3f2c30457e8a3bb8c7a961a3a5bcd27","best_bid":"0.99","best_ask":"1"},{"asset_id":"103575991306220918671611575108050794364462782362354955892418399227289531345027","price":"0.01","size":"466.83","side":"SELL","hash":"29f0e1a47caefe427735f78f9976a9132316deaa","best_bid":"0","best_ask":"0.01"}],"timestamp":"1768359592027","event_type":"price_change"}
{"market":"0x5977c69bca02e6cc150855b0faec463b38be463f141ec37ea5c8a1a1e986e0d3","price_changes":[{"asset_id":"110222991870854778724082971333105906777328061970448875974576460135015541883929","price":"0.981","size":"0","side":"BUY","hash":"5cf0ce8a2ac86c7b79111fc488f0d351f2188802","best_bid":"0.99","best_ask":"1"},{"asset_id":"103575991306220918671611575108050794364462782362354955892418399227289531345027","price":"0.019","size":"0","side":"SELL","hash":"7e41cd20dad423c492d3280cd6594a0f20dd95f8","best_bid":"0","best_ask":"0.01"}],"timestamp":"1768359592107","event_type":"price_change"}
{"market":"0x5977c69bca02e6cc150855b0faec463b38be463f141ec37ea5c8a1a1e986e0d3","price_changes":[{"asset_id":"110222991870854778724082971333105906777328061970448875974576460135015541883929","price":"0.99","size":"416.83","side":"BUY","hash":"ed1616a85da9a9de48e9d1173efb5f315f948dee","best_bid":"0.99","best_ask":"1"},{"asset_id":"103575991306220918671611575108050794364462782362354955892418399227289531345027","price":"0.01","size":"416.83","side":"SELL","hash":"124c9c816a2bce65812bc6cc49349645d4aacd73","best_bid":"0","best_ask":"0.01"}],"timestamp":"1768359592518","event_type":"price_change"}
