{"market":"0x5977c69bca02e6cc150855b0faec463b38be463f141ec37ea5c8a1a1e986e0d3","asset_id":"103575991306220918671611575108050794364462782362354955892418399227289531345027","bids":[{"price":"0.001","size":"140"},{"price":"0.002","size":"4.94"}],"asks":[{"price":"0.999","size":"270"},{"price":"0.998","size":"60"},{"price":"0.99","size":"8277.7"},{"price":"0.98","size":"4128.1"},{"price":"0.97","size":"3005.2"},{"price":"0.96","size":"2758.42"},{"price":"0.95","size":"2667.4"},{"price":"0.94","size":"2528"},{"price":"0.93","size":"2525"},{"price":"0.92","size":"2522.7"},{"price":"0.91","size":"2520.9"},{"price":"0.9","size":"2529.4"},{"price":"0.89","size":"18.3"},{"price":"0.88","size":"22.3"},{"price":"0.87","size":"16.5"},{"price":"0.86","size":"15.8"},{"price":"0.85","size":"20.19"},{"price":"0.84","size":"14.69"},{"price":"0.83","size":"14.19"},{"price":"0.82","size":"13.8"},{"price":"0.81","size":"388.4"},{"price":"0.8","size":"428.1"},{"price":"0.79","size":"387.8"},{"price":"0.78","size":"387.6"},{"price":"0.77","size":"387.3"},{"price":"0.76","size":"387.1"},{"price":"0.75","size":"420.4"},{"price":"0.74","size":"386.8"},{"price":"0.73","size":"386.6"},{"price":"0.72","size":"409.54"},{"price":"0.71","size":"386.3"},{"price":"0.7","size":"612.89"},{"price":"0.69","size":"386.1"},{"price":"0.68","size":"391"},{"price":"0.67","size":"385.9"},{"price":"0.66","size":"390.8"},{"price":"0.65","size":"404.63"},{"price":"0.64","size":"399.78"},{"price":"0.63","size":"408.73"},{"price":"0.62","size":"385.5"},{"price":"0.61","size":"379.59"},{"price":"0.6","size":"44.4"},{"price":"0.59","size":"10.4"},{"price":"0.58","size":"33.71"},{"price":"0.57","size":"15.3"},{"price":"0.56","size":"21.3"},{"price":"0.55","size":"324.63"},{"price":"0.54","size":"15.2"},{"price":"0.53","size":"20.2"},{"price":"0.52","size":"93.25"},{"price":"0.51","size":"10.2"},{"price":"0.5","size":"30.2"},{"price":"0.49","size":"112.85"},{"price":"0.48","size":"48.2"},{"price":"0.47","size":"385.2"},{"price":"0.46","size":"385.2"},{"price":"0.45","size":"385.3"},{"price":"0.44","size":"400.3"},{"price":"0.43","size":"390.3"},{"price":"0.42","size":"390.3"},{"price":"0.41","size":"395.4"},{"price":"0.4","size":"401.4"},{"price":"0.39","size":"390.5"},{"price":"0.38","size":"385.5"},{"price":"0.37","size":"405.84"},{"price":"0.36","size":"521.78"},{"price":"0.35","size":"536.45"},{"price":"0.34","size":"516.17"},{"price":"0.33","size":"304.85"},{"price":"0.32","size":"496.24"},{"price":"0.31","size":"480.11"},{"price":"0.3","size":"683.7"},{"price":"0.29","size":"689.04"},{"price":"0.28","size":"589.24"},{"price":"0.27","size":"420.97"},{"price":"0.26","size":"497.47"},{"price":"0.259","size":"5"},{"price":"0.25","size":"826.91"},{"price":"0.24","size":"666.34"},{"price":"0.23","size":"477.3"},{"price":"0.22","size":"397.57"},{"price":"0.21","size":"392.8"},{"price":"0.2","size":"393.1"},{"price":"0.19","size":"501.55"},{"price":"0.18","size":"410.6"},{"price":"0.17","size":"437.17"},{"price":"0.16","size":"425.95"},{"price":"0.15","size":"426.64"},{"price":"0.14","size":"927.54"},{"price":"0.13","size":"403"},{"price":"0.12","size":"1415.96"},{"price":"0.11","size":"1416.6"},{"price":"0.1","size":"451.49"},{"price":"0.09","size":"380"},{"price":"0.08","size":"594.2"},{"price":"0.07","size":"491"},{"price":"0.06","size":"755.16"},{"price":"0.05","size":"329.51"},{"price":"0.04","size":"509.17"},{"price":"0.03","size":"908"},{"price":"0.02","size":"6033.23"},{"price":"0.01","size":"1156.24"},{"price":"0.009","size":"997.36"}],"hash":"0af06c0951232e9f598c496ec6ac97ae1cb9ff84","timestamp":"1768359569494","event_type":"book"}
{"market":"0x5977c69bca02e6cc150855b0faec463b38be463f141ec37ea5c8a1a1e986e0d3","asset_id":"110222991870854778724082971333105906777328061970448875974576460135015541883929","bids":[{"price":"0.001","size":"270"},{"price":"0.002","size":"60"},{"price":"0.01","size":"8277.7"},{"price":"0.02","size":"4128.1"},{"price":"0.03","size":"3005.2"},{"price":"0.04","size":"2758.42"},{"price":"0.05","size":"2667.4"},{"price":"0.06","size":"2528"},{"price":"0.07","size":"2525"},{"price":"0.08","size":"2522.7"},{"price":"0.09","size":"2520.9"},{"price":"0.1","size":"2529.4"},{"price":"0.11","size":"18.3"},{"price":"0.12","size":"22.3"},{"price":"0.13","size":"16.5"},{"price":"0.14","size":"15.8"},{"price":"0.15","size":"20.19"},{"price":"0.16","size":"14.69"},{"price":"0.17","size":"14.19"},{"price":"0.18","size":"13.8"},{"price":"0.19","size":"388.4"},{"price":"0.2","size":"428.1"},{"price":"0.21","size":"387.8"},{"price":"0.22","size":"387.6"},{"price":"0.23","size":"387.3"},{"price":"0.24","size":"387.1"},{"price":"0.25","size":"420.4"},{"price":"0.26","size":"386.8"},{"price":"0.27","size":"386.6"},{"price":"0.28","size":"409.54"},{"price":"0.29","size":"386.3"},{"price":"0.3","size":"612.89"},{"price":"0.31","size":"386.1"},{"price":"0.32","size":"391"},{"price":"0.33","size":"385.9"},{"price":"0.34","size":"390.8"},{"price":"0.35","size":"404.63"},{"price":"0.36","size":"399.78"},{"price":"0.37","size":"408.73"},{"price":"0.38","size":"385.5"},{"price":"0.39","size":"379.59"},{"price":"0.4","size":"44.4"},{"price":"0.41","size":"10.4"},{"price":"0.42","size":"33.71"},{"price":"0.43","size":"15.3"},{"price":"0.44","size":"21.3"},{"price":"0.45","size":"324.63"},{"price":"0.46","size":"15.2"},{"price":"0.47","size":"20.2"},{"price":"0.48","size":"93.25"},{"price":"0.49","size":"10.2"},{"price":"0.5","size":"30.2"},{"price":"0.51","size":"112.85"},{"price":"0.52","size":"48.2"},{"price":"0.53","size":"385.2"},{"price":"0.54","size":"385.2"},{"price":"0.55","size":"385.3"},{"price":"0.56","size":"400.3"},{"price":"0.57","size":"390.3"},{"price":"0.58","size":"390.3"},{"price":"0.59","size":"395.4"},{"price":"0.6","size":"401.4"},{"price":"0.61","size":"390.5"},{"price":"0.62","size":"385.5"},{"price":"0.63","size":"405.84"},{"price":"0.64","size":"521.78"},{"price":"0.65","size":"536.45"},{"price":"0.66","size":"516.17"},{"price":"0.67","size":"304.85"},{"price":"0.68","size":"496.24"},{"price":"0.69","size":"480.11"},{"price":"0.7","size":"683.7"},{"price":"0.71","size":"689.04"},{"price":"0.72","size":"589.24"},{"price":"0.73","size":"420.97"},{"price":"0.74","size":"497.47"},{"price":"0.741","size":"5"},{"price":"0.75","size":"826.91"},{"price":"0.76","size":"666.34"},{"price":"0.77","size":"477.3"},{"price":"0.78","size":"397.57"},{"price":"0.79","size":"392.8"},{"price":"0.8","size":"393.1"},{"price":"0.81","size":"501.55"},{"price":"0.82","size":"410.6"},{"price":"0.83","size":"437.17"},{"price":"0.84","size":"425.95"},{"price":"0.85","size":"426.64"},{"price":"0.86","size":"927.54"},{"price":"0.87","size":"403"},{"price":"0.88","size":"1415.96"},{"price":"0.89","size":"1416.6"},{"price":"0.9","size":"451.49"},{"price":"0.91","size":"380"},{"price":"0.92","size":"594.2"},{"price":"0.93","size":"491"},{"price":"0.94","size":"755.16"},{"price":"0.95","size":"329.51"},{"price":"0.96","size":"509.17"},{"price":"0.97","size":"908"},{"price":"0.98","size":"6033.23"},{"price":"0.99","size":"1156.24"},{"price":"0.991","size":"997.36"}],"asks":[{"price":"0.999","size":"140"},{"price":"0.998","size":"4.94"}],"hash":"509560798ab3ea2065949bd1c7630f6862285767","timestamp":"1768359569494","event_type":"book"}
{"market":"0x5977c69bca02e6cc150855b0faec463b38be463f141ec37ea5c8a1a1e986e0d3","price_changes":[{"asset_id":"110222991870854778724082971333105906777328061970448875974576460135015541883929","price":"0.98","size":"1045.53","side":"BUY","hash":"7c866ad1f9f846479ac816630fe5b31dd41d45b9","best_bid":"0.991","best_ask":"0.998"},{"asset_id":"103575991306220918671611575108050794364462782362354955892418399227289531345027","price":"0.02","size":"1045.53","side":"SELL","hash":"83bb805aabb18050dadb10fd085ab01d59e5ac25","best_bid":"0.002","best_ask":"0.009"}],"timestamp":"1768359569796","event_type":"price_change"}
{"market":"0x5977c69bca02e6cc150855b0faec463b38be463f141ec37ea5c8a1a1e986e0d3","asset_id":"110222991870854778724082971333105906777328061970448875974576460135015541883929","price":"0.991","size":"13.13","fee_rate_bps":"1000","side":"SELL","timestamp":"1768359570044","event_type":"last_trade_price","transaction_hash":"0x2bad0456f4401d6c57ca3180a47fbbee6d1a2028ec8cf7af4955aaec946fe884"}
PONG
{"market":"0x5977c69bca02e6cc150855b0faec463b38be463f141ec37ea5c8a1a1e986e0d3","asset_id":"110222991870854778724082971333105906777328061970448875974576460135015541883929","price":"0.991","size":"12.12","fee_rate_bps":"1000","side":"SELL","timestamp":"1768359570127","event_type":"last_trade_price","transaction_hash":"0x9627d963d5529c1cc9f1c157762ab046429fdd1eabd22a2ae8598aa0237e2999"}
{"market":"0x5977c69bca02e6cc150855b0faec463b38be463f141ec37ea5c8a1a1e986e0d3","price_changes":[{"asset_id":"110222991870854778724082971333105906777328061970448875974576460135015541883929","price":"0.991","size":"984.23","side":"BUY","hash":"626119eb3d8bc03296bf619071bbe5cc33e4371c","best_bid":"0.991","best_ask":"0.998"},{"asset_id":"103575991306220918671611575108050794364462782362354955892418399227289531345027","price":"0.009","size":"984.23","side":"SELL","hash":"f066581ca7a7f87e6f99fd9ec2640291791ea71e","best_bid":"0.002","best_ask":"0.009"}],"timestamp":"1768359570017","event_type":"price_change"}
{"market":"0x5977c69bca02e6cc150855b0faec463b38be463f141ec37ea5c8a1a1e986e0d3","asset_id":"103575991306220918671611575108050794364462782362354955892418399227289531345027","bids":[{"price":"0.001","size":"140"},{"price":"0.002","size":"4.94"}],"asks":[{"price":"0.999","size":"270"},{"price":"0.998","size":"60"},{"price":"0.99","size":"8277.7"},{"price":"0.98","size":"4128.1"},{"price":"0.97","size":"3005.2"},{"price":"0.96","size":"2758.42"},{"price":"0.95","size":"2667.4"},{"price":"0.94","size":"2528"},{"price":"0.93","size":"2525"},{"price":"0.92","size":"2522.7"},{"price":"0.91","size":"2520.9"},{"price":"0.9","size":"2529.4"},{"price":"0.89","size":"18.3"},{"price":"0.88","size":"22.3"},{"price":"0.87","size":"16.5"},{"price":"0.86","size":"15.8"},{"price":"0.85","size":"20.19"},{"price":"0.84","size":"14.69"},{"price":"0.83","size":"14.19"},{"price":"0.82","size":"13.8"},{"price":"0.81","size":"388.4"},{"price":"0.8","size":"428.1"},{"price":"0.79","size":"387.8"},{"price":"0.78","size":"387.6"},{"price":"0.77","size":"387.3"},{"price":"0.76","size":"387.1"},{"price":"0.75","size":"420.4"},{"price":"0.74","size":"386.8"},{"price":"0.73","size":"386.6"},{"price":"0.72","size":"409.54"},{"price":"0.71","size":"386.3"},{"price":"0.7","size":"612.89"},{"price":"0.69","size":"386.1"},{"price":"0.68","size":"391"},{"price":"0.67","size":"385.9"},{"price":"0.66","size":"390.8"},{"price":"0.65","size":"404.63"},{"price":"0.64","size":"399.78"},{"price":"0.63","size":"408.73"},{"price":"0.62","size":"385.5"},{"price":"0.61","size":"379.59"},{"price":"0.6","size":"44.4"},{"price":"0.59","size":"10.4"},{"price":"0.58","size":"33.71"},{"price":"0.57","size":"15.3"},{"price":"0.56","size":"21.3"},{"price":"0.55","size":"324.63"},{"price":"0.54","size":"15.2"},{"price":"0.53","size":"20.2"},{"price":"0.52","size":"93.25"},{"price":"0.51","size":"10.2"},{"price":"0.5","size":"30.2"},{"price":"0.49","size":"112.85"},{"price":"0.48","size":"48.2"},{"price":"0.47","size":"385.2"},{"price":"0.46","size":"385.2"},{"price":"0.45","size":"385.3"},{"price":"0.44","size":"400.3"},{"price":"0.43","size":"390.3"},{"price":"0.42","size":"390.3"},{"price":"0.41","size":"395.4"},{"price":"0.4","size":"401.4"},{"price":"0.39","size":"390.5"},{"price":"0.38","size":"385.5"},{"price":"0.37","size":"405.84"},{"price":"0.36","size":"521.78"},{"price":"0.35","size":"536.45"},{"price":"0.34","size":"516.17"},{"price":"0.33","size":"304.85"},{"price":"0.32","size":"496.24"},{"price":"0.31","size":"480.11"},{"price":"0.3","size":"683.7"},{"price":"0.29","size":"689.04"},{"price":"0.28","size":"589.24"},{"price":"0.27","size":"420.97"},{"price":"0.26","size":"497.47"},{"price":"0.259","size":"5"},{"price":"0.25","size":"826.91"},{"price":"0.24","size":"666.34"},{"price":"0.23","size":"477.3"},{"price":"0.22","size":"397.57"},{"price":"0.21","size":"392.8"},{"price":"0.2","size":"393.1"},{"price":"0.19","size":"501.55"},{"price":"0.18","size":"410.6"},{"price":"0.17","size":"437.17"},{"price":"0.16","size":"425.95"},{"price":"0.15","size":"426.64"},{"price":"0.14","size":"927.54"},{"price":"0.13","size":"403"},{"price":"0.12","size":"1415.96"},{"price":"0.11","size":"1416.6"},{"price":"0.1","size":"451.49"},{"price":"0.09","size":"380"},{"price":"0.08","size":"594.2"},{"price":"0.07","size":"491"},{"price":"0.06","size":"755.16"},{"price":"0.05","size":"329.51"},{"price":"0.04","size":"509.17"},{"price":"0.03","size":"908"},{"price":"0.02","size":"1045.53"},{"price":"0.01","size":"1156.24"},{"price":"0.009","size":"984.23"}],"hash":"f066581ca7a7f87e6f99fd9ec2640291791ea71e","timestamp":"1768359570017","event_type":"book"}
{"market":"0x5977c69bca02e6cc150855b0faec463b38be463f141ec37ea5c8a1a1e986e0d3","asset_id":"110222991870854778724082971333105906777328061970448875974576460135015541883929","bids":[{"price":"0.001","size":"270"},{"price":"0.002","size":"60"},{"price":"0.01","size":"8277.7"},{"price":"0.02","size":"4128.1"},{"price":"0.03","size":"3005.2"},{"price":"0.04","size":"2758.42"},{"price":"0.05","size":"2667.4"},{"price":"0.06","size":"2528"},{"price":"0.07","size":"2525"},{"price":"0.08","size":"2522.7"},{"price":"0.09","size":"2520.9"},{"price":"0.1","size":"2529.4"},{"price":"0.11","size":"18.3"},{"price":"0.12","size":"22.3"},{"price":"0.13","size":"16.5"},{"price":"0.14","size":"15.8"},{"price":"0.15","size":"20.19"},{"price":"0.16","size":"14.69"},{"price":"0.17","size":"14.19"},{"price":"0.18","size":"13.8"},{"price":"0.19","size":"388.4"},{"price":"0.2","size":"428.1"},{"price":"0.21","size":"387.8"},{"price":"0.22","size":"387.6"},{"price":"0.23","size":"387.3"},{"price":"0.24","size":"387.1"},{"price":"0.25","size":"420.4"},{"price":"0.26","size":"386.8"},{"price":"0.27","size":"386.6"},{"price":"0.28","size":"409.54"},{"price":"0.29","size":"386.3"},{"price":"0.3","size":"612.89"},{"price":"0.31","size":"386.1"},{"price":"0.32","size":"391"},{"price":"0.33","size":"385.9"},{"price":"0.34","size":"390.8"},{"price":"0.35","size":"404.63"},{"price":"0.36","size":"399.78"},{"price":"0.37","size":"408.73"},{"price":"0.38","size":"385.5"},{"price":"0.39","size":"379.59"},{"price":"0.4","size":"44.4"},{"price":"0.41","size":"10.4"},{"price":"0.42","size":"33.71"},{"price":"0.43","size":"15.3"},{"price":"0.44","size":"21.3"},{"price":"0.45","size":"324.63"},{"price":"0.46","size":"15.2"},{"price":"0.47","size":"20.2"},{"price":"0.48","size":"93.25"},{"price":"0.49","size":"10.2"},{"price":"0.5","size":"30.2"},{"price":"0.51","size":"112.85"},{"price":"0.52","size":"48.2"},{"price":"0.53","size":"385.2"},{"price":"0.54","size":"385.2"},{"price":"0.55","size":"385.3"},{"price":"0.56","size":"400.3"},{"price":"0.57","size":"390.3"},{"price":"0.58","size":"390.3"},{"price":"0.59","size":"395.4"},{"price":"0.6","size":"401.4"},{"price":"0.61","size":"390.5"},{"price":"0.62","size":"385.5"},{"price":"0.63","size":"405.84"},{"price":"0.64","size":"521.78"},{"price":"0.65","size":"536.45"},{"price":"0.66","size":"516.17"},{"price":"0.67","size":"304.85"},{"price":"0.68","size":"496.24"},{"price":"0.69","size":"480.11"},{"price":"0.7","size":"683.7"},{"price":"0.71","size":"689.04"},{"price":"0.72","size":"589.24"},{"price":"0.73","size":"420.97"},{"price":"0.74","size":"497.47"},{"price":"0.741","size":"5"},{"price":"0.75","size":"826.91"},{"price":"0.76","size":"666.34"},{"price":"0.77","size":"477.3"},{"price":"0.78","size":"397.57"},{"price":"0.79","size":"392.8"},{"price":"0.8","size":"393.1"},{"price":"0.81","size":"501.55"},{"price":"0.82","size":"410.6"},{"price":"0.83","size":"437.17"},{"price":"0.84","size":"425.95"},{"price":"0.85","size":"426.64"},{"price":"0.86","size":"927.54"},{"price":"0.87","size":"403"},{"price":"0.88","size":"1415.96"},{"price":"0.89","size":"1416.6"},{"price":"0.9","size":"451.49"},{"price":"0.91","size":"380"},{"price":"0.92","size":"594.2"},{"price":"0.93","size":"491"},{"price":"0.94","size":"755.16"},{"price":"0.95","size":"329.51"},{"price":"0.96","size":"509.17"},{"price":"0.97","size":"908"},{"price":"0.98","size":"1045.53"},{"price":"0.99","size":"1156.24"},{"price":"0.991","size":"984.23"}],"asks":[{"price":"0.999","size":"140"},{"price":"0.998","size":"4.94"}],"hash":"626119eb3d8bc03296bf619071bbe5cc33e4371c","timestamp":"1768359570017","event_type":"book"}
{"market":"0x5977c69bca02e6cc150855b0faec463b38be463f141ec37ea5c8a1a1e986e0d3","price_changes":[{"asset_id":"110222991870854778724082971333105906777328061970448875974576460135015541883929","price":"0.991","size":"972.11","side":"BUY","hash":"9f5a5ddfdd7c2573d9022c5e757be54c54c34563","best_bid":"0.991","best_ask":"0.998"},{"asset_id":"103575991306220918671611575108050794364462782362354955892418399227289531345027","price":"0.009","size":"972.11","side":"SELL","hash":"76a77c9db920e86f6fd78a5116bd51df6abc0afd","best_bid":"0.002","best_ask":"0.009"}],"timestamp":"1768359570098","event_type":"price_change"}
{"market":"0x5977c69bca02e6cc150855b0faec463b38be463f141ec37ea5c8a1a1e986e0d3","asset_id":"103575991306220918671611575108050794364462782362354955892418399227289531345027","bids":[{"price":"0.001","size":"140"},{"price":"0.002","size":"4.94"}],"asks":[{"price":"0.999","size":"270"},{"price":"0.998","size":"60"},{"price":"0.99","size":"8277.7"},{"price":"0.98","size":"4128.1"},{"price":"0.97","size":"3005.2"},{"price":"0.96","size":"2758.42"},{"price":"0.95","size":"2667.4"},{"price":"0.94","size":"2528"},{"price":"0.93","size":"2525"},{"price":"0.92","size":"2522.7"},{"price":"0.91","size":"2520.9"},{"price":"0.9","size":"2529.4"},{"price":"0.89","size":"18.3"},{"price":"0.88","size":"22.3"},{"price":"0.87","size":"16.5"},{"price":"0.86","size":"15.8"},{"price":"0.85","size":"20.19"},{"price":"0.84","size":"14.69"},{"price":"0.83","size":"14.19"},{"price":"0.82","size":"13.8"},{"price":"0.81","size":"388.4"},{"price":"0.8","size":"428.1"},{"price":"0.79","size":"387.8"},{"price":"0.78","size":"387.6"},{"price":"0.77","size":"387.3"},{"price":"0.76","size":"387.1"},{"price":"0.75","size":"420.4"},{"price":"0.74","size":"386.8"},{"price":"0.73","size":"386.6"},{"price":"0.72","size":"409.54"},{"price":"0.71","size":"386.3"},{"price":"0.7","size":"612.89"},{"price":"0.69","size":"386.1"},{"price":"0.68","size":"391"},{"price":"0.67","size":"385.9"},{"price":"0.66","size":"390.8"},{"price":"0.65","size":"404.63"},{"price":"0.64","size":"399.78"},{"price":"0.63","size":"408.73"},{"price":"0.62","size":"385.5"},{"price":"0.61","size":"379.59"},{"price":"0.6","size":"44.4"},{"price":"0.59","size":"10.4"},{"price":"0.58","size":"33.71"},{"price":"0.57","size":"15.3"},{"price":"0.56","size":"21.3"},{"price":"0.55","size":"324.63"},{"price":"0.54","size":"15.2"},{"price":"0.53","size":"20.2"},{"price":"0.52","size":"93.25"},{"price":"0.51","size":"10.2"},{"price":"0.5","size":"30.2"},{"price":"0.49","size":"112.85"},{"price":"0.48","size":"48.2"},{"price":"0.47","size":"385.2"},{"price":"0.46","size":"385.2"},{"price":"0.45","size":"385.3"},{"price":"0.44","size":"400.3"},{"price":"0.43","size":"390.3"},{"price":"0.42","size":"390.3"},{"price":"0.41","size":"395.4"},{"price":"0.4","size":"401.4"},{"price":"0.39","size":"390.5"},{"price":"0.38","size":"385.5"},{"price":"0.37","size":"405.84"},{"price":"0.36","size":"521.78"},{"price":"0.35","size":"536.45"},{"price":"0.34","size":"516.17"},{"price":"0.33","size":"304.85"},{"price":"0.32","size":"496.24"},{"price":"0.31","size":"480.11"},{"price":"0.3","size":"683.7"},{"price":"0.29","size":"689.04"},{"price":"0.28","size":"589.24"},{"price":"0.27","size":"420.97"},{"price":"0.26","size":"497.47"},{"price":"0.259","size":"5"},{"price":"0.25","size":"826.91"},{"price":"0.24","size":"666.34"},{"price":"0.23","size":"477.3"},{"price":"0.22","size":"397.57"},{"price":"0.21","size":"392.8"},{"price":"0.2","size":"393.1"},{"price":"0.19","size":"501.55"},{"price":"0.18","size":"410.6"},{"price":"0.17","size":"437.17"},{"price":"0.16","size":"425.95"},{"price":"0.15","size":"426.64"},{"price":"0.14","size":"927.54"},{"price":"0.13","size":"403"},{"price":"0.12","size":"1415.96"},{"price":"0.11","size":"1416.6"},{"price":"0.1","size":"451.49"},{"price":"0.09","size":"380"},{"price":"0.08","size":"594.2"},{"price":"0.07","size":"491"},{"price":"0.06","size":"755.16"},{"price":"0.05","size":"329.51"},{"price":"0.04","size":"509.17"},{"price":"0.03","size":"908"},{"price":"0.02","size":"1045.53"},{"price":"0.01","size":"1156.24"},{"price":"0.009","size":"972.11"}],"hash":"76a77c9db920e86f6fd78a5116bd51df6abc0afd","timestamp":"1768359570098","event_type":"book"}
{"market":"0x5977c69bca02e6cc150855b0faec463b38be463f141ec37ea5c8a1a1e986e0d3","asset_id":"110222991870854778724082971333105906777328061970448875974576460135015541883929","bids":[{"price":"0.001","size":"270"},{"price":"0.002","size":"60"},{"price":"0.01","size":"8277.7"},{"price":"0.02","size":"4128.1"},{"price":"0.03","size":"3005.2"},{"price":"0.04","size":"2758.42"},{"price":"0.05","size":"2667.4"},{"price":"0.06","size":"2528"},{"price":"0.07","size":"2525"},{"price":"0.08","size":"2522.7"},{"price":"0.09","size":"2520.9"},{"price":"0.1","size":"2529.4"},{"price":"0.11","size":"18.3"},{"price":"0.12","size":"22.3"},{"price":"0.13","size":"16.5"},{"price":"0.14","size":"15.8"},{"price":"0.15","size":"20.19"},{"price":"0.16","size":"14.69"},{"price":"0.17","size":"14.19"},{"price":"0.18","size":"13.8"},{"price":"0.19","size":"388.4"},{"price":"0.2","size":"428.1"},{"price":"0.21","size":"387.8"},{"price":"0.22","size":"387.6"},{"price":"0.23","size":"387.3"},{"price":"0.24","size":"387.1"},{"price":"0.25","size":"420.4"},{"price":"0.26","size":"386.8"},{"price":"0.27","size":"386.6"},{"price":"0.28","size":"409.54"},{"price":"0.29","size":"386.3"},{"price":"0.3","size":"612.89"},{"price":"0.31","size":"386.1"},{"price":"0.32","size":"391"},{"price":"0.33","size":"385.9"},{"price":"0.34","size":"390.8"},{"price":"0.35","size":"404.63"},{"price":"0.36","size":"399.78"},{"price":"0.37","size":"408.73"},{"price":"0.38","size":"385.5"},{"price":"0.39","size":"379.59"},{"price":"0.4","size":"44.4"},{"price":"0.41","size":"10.4"},{"price":"0.42","size":"33.71"},{"price":"0.43","size":"15.3"},{"price":"0.44","size":"21.3"},{"price":"0.45","size":"324.63"},{"price":"0.46","size":"15.2"},{"price":"0.47","size":"20.2"},{"price":"0.48","size":"93.25"},{"price":"0.49","size":"10.2"},{"price":"0.5","size":"30.2"},{"price":"0.51","size":"112.85"},{"price":"0.52","size":"48.2"},{"price":"0.53","size":"385.2"},{"price":"0.54","size":"385.2"},{"price":"0.55","size":"385.3"},{"price":"0.56","size":"400.3"},{"price":"0.57","size":"390.3"},{"price":"0.58","size":"390.3"},{"price":"0.59","size":"395.4"},{"price":"0.6","size":"401.4"},{"price":"0.61","size":"390.5"},{"price":"0.62","size":"385.5"},{"price":"0.63","size":"405.84"},{"price":"0.64","size":"521.78"},{"price":"0.65","size":"536.45"},{"price":"0.66","size":"516.17"},{"price":"0.67","size":"304.85"},{"price":"0.68","size":"496.24"},{"price":"0.69","size":"480.11"},{"price":"0.7","size":"683.7"},{"price":"0.71","size":"689.04"},{"price":"0.72","size":"589.24"},{"price":"0.73","size":"420.97"},{"price":"0.74","size":"497.47"},{"price":"0.741","size":"5"},{"price":"0.75","size":"826.91"},{"price":"0.76","size":"666.34"},{"price":"0.77","size":"477.3"},{"price":"0.78","size":"397.57"},{"price":"0.79","size":"392.8"},{"price":"0.8","size":"393.1"},{"price":"0.81","size":"501.55"},{"price":"0.82","size":"410.6"},{"price":"0.83","size":"437.17"},{"price":"0.84","size":"425.95"},{"price":"0.85","size":"426.64"},{"price":"0.86","size":"927.54"},{"price":"0.87","size":"403"},{"price":"0.88","size":"1415.96"},{"price":"0.89","size":"1416.6"},{"price":"0.9","size":"451.49"},{"price":"0.91","size":"380"},{"price":"0.92","size":"594.2"},{"price":"0.93","size":"491"},{"price":"0.94","size":"755.16"},{"price":"0.95","size":"329.51"},{"price":"0.96","size":"509.17"},{"price":"0.97","size":"908"},{"price":"0.98","size":"1045.53"},{"price":"0.99","size":"1156.24"},{"price":"0.991","size":"972.11"}],"asks":[{"price":"0.999","size":"140"},{"price":"0.998","size":"4.94"}],"hash":"9f5a5ddfdd7c2573d9022c5e757be54c54c34563","timestamp":"1768359570098","event_type":"book"}
{"market":"0x5977c69bca02e6cc150855b0faec463b38be463f141ec37ea5c8a1a1e986e0d3","price_changes":[{"asset_id":"110222991870854778724082971333105906777328061970448875974576460135015541883929","price":"0.94","size":"709.16","side":"BUY","hash":"a5a0815b61ebe50cb8b9249c11377c695730683b","best_bid":"0.991","best_ask":"0.998"},{"asset_id":"103575991306220918671611575108050794364462782362354955892418399227289531345027","price":"0.06","size":"709.16","side":"SELL","hash":"f34bc7dc23d43b2afeeec97d9fff7523ac652eb0","best_bid":"0.002","best_ask":"0.009"}],"timestamp":"1768359570108","event_type":"price_change"}
{"market":"0x5977c69bca02e6cc150855b0faec463b38be463f141ec37ea5c8a1a1e986e0d3","price_changes":[{"asset_id":"110222991870854778724082971333105906777328061970448875974576460135015541883929","price":"0.16","size":"5","side":"BUY","hash":"a5a0815b61ebe50cb8b9249c11377c695730683b","best_bid":"0.991","best_ask":"0.998"},{"asset_id":"103575991306220918671611575108050794364462782362354955892418399227289531345027","price":"0.84","size":"5","side":"SELL","hash":"f34bc7dc23d43b2afeeec97d9fff7523ac652eb0","best_bid":"0.002","best_ask":"0.009"}],"timestamp":"1768359570108","event_type":"price_change"}
{"market":"0x5977c69bca02e6cc150855b0faec463b38be463f141ec37ea5c8a1a1e986e0d3","price_changes":[{"asset_id":"110222991870854778724082971333105906777328061970448875974576460135015541883929","price":"0.45","size":"319.33","side":"BUY","hash":"a5a0815b61ebe50cb8b9249c11377c695730683b","best_bid":"0.991","best_ask":"0.998"},{"asset_id":"103575991306220918671611575108050794364462782362354955892418399227289531345027","price":"0.55","size":"319.33","side":"SELL","hash":"f34bc7dc23d43b2afeeec97d9fff7523ac652eb0","best_bid":"0.002","best_ask":"0.009"}],"timestamp":"1768359570108","event_type":"price_change"}
{"market":"0x5977c69bca02e6cc150855b0faec463b38be463f141ec37ea5c8a1a1e986e0d3","price_changes":[{"asset_id":"110222991870854778724082971333105906777328061970448875974576460135015541883929","price":"0.57","size":"385","side":"BUY","hash":"a5a0815b61ebe50cb8b9249c11377c695730683b","best_bid":"0.991","best_ask":"0.998"},{"asset_id":"103575991306220918671611575108050794364462782362354955892418399227289531345027","price":"0.43","size":"385","side":"SELL","hash":"f34bc7dc23d43b2afeeec97d9fff7523ac652eb0","best_bid":"0.002","best_ask":"0.009"}],"timestamp":"1768359570108","event_type":"price_change"}
{"market":"0x5977c69bca02e6cc150855b0faec463b38be463f141ec37ea5c8a1a1e986e0d3","price_changes":[{"asset_id":"110222991870854778724082971333105906777328061970448875974576460135015541883929","price":"0.69","size":"474.01","side":"BUY","hash":"a5a0815b61ebe50cb8b9249c11377c695730683b","best_bid":"0.991","best_ask":"0.998"},{"asset_id":"103575991306220918671611575108050794364462782362354955892418399227289531345027","price":"0.31","size":"474.01","side":"SELL","hash":"f34bc7dc23d43b2afeeec97d9fff7523ac652eb0","best_bid":"0.002","best_ask":"0.009"}],"timestamp":"1768359570108","event_type":"price_change"}
{"market":"0x5977c69bca02e6cc150855b0faec463b38be463f141ec37ea5c8a1a1e986e0d3","price_changes":[{"asset_id":"110222991870854778724082971333105906777328061970448875974576460135015541883929","price":"0.78","size":"389.97","side":"BUY","hash":"a5a0815b61ebe50cb8b9249c11377c695730683b","best_bid":"0.991","best_ask":"0.998"},{"asset_id":"103575991306220918671611575108050794364462782362354955892418399227289531345027","price":"0.22","size":"389.97","side":"SELL","hash":"f34bc7dc23d43b2afeeec97d9fff7523ac652eb0","best_bid":"0.002","best_ask":"0.009"}],"timestamp":"1768359570108","event_type":"price_change"}
{"market":"0x5977c69bca02e6cc150855b0faec463b38be463f141ec37ea5c8a1a1e986e0d3","price_changes":[{"asset_id":"110222991870854778724082971333105906777328061970448875974576460135015541883929","price":"0.88","size":"1391.36","side":"BUY","hash":"a5a0815b61ebe50cb8b9249c11377c695730683b","best_bid":"0.991","best_ask":"0.998"},{"asset_id":"103575991306220918671611575108050794364462782362354955892418399227289531345027","price":"0.12","size":"1391.36","side":"SELL","hash":"f34bc7dc23d43b2afeeec97d9fff7523ac652eb0","best_bid":"0.002","best_ask":"0.009"}],"timestamp":"1768359570108","event_type":"price_change"}
{"market":"0x5977c69bca02e6cc150855b0faec463b38be463f141ec37ea5c8a1a1e986e0d3","price_changes":[{"asset_id":"110222991870854778724082971333105906777328061970448875974576460135015541883929","price":"0.03","size":"2960.5","side":"BUY","hash":"a5a0815b61ebe50cb8b9249c11377c695730683b","best_bid":"0.991","best_ask":"0.998"},{"asset_id":"103575991306220918671611575108050794364462782362354955892418399227289531345027","price":"0.97","size":"2960.5","side":"SELL","hash":"f34bc7dc23d43b2afeeec97d9fff7523ac652eb0","best_bid":"0.002","best_ask":"0.009"}],"timestamp":"1768359570108","event_type":"price_change"}
{"market":"0x5977c69bca02e6cc150855b0faec463b38be463f141ec37ea5c8a1a1e986e0d3","price_changes":[{"asset_id":"110222991870854778724082971333105906777328061970448875974576460135015541883929","price":"0.2","size":"420","side":"BUY","hash":"a5a0815b61ebe50cb8b9249c11377c695730683b","best_bid":"0.991","best_ask":"0.998"},{"asset_id":"103575991306220918671611575108050794364462782362354955892418399227289531345027","price":"0.8","size":"420","side":"SELL","hash":"f34bc7dc23d43b2afeeec97d9fff7523ac652eb0","best_bid":"0.002","best_ask":"0.009"}],"timestamp":"1768359570108","event_type":"price_change"}
{"market":"0x5977c69bca02e6cc150855b0faec463b38be463f141ec37ea5c8a1a1e986e0d3","price_changes":[{"asset_id":"110222991870854778724082971333105906777328061970448875974576460135015541883929","price":"0.53","size":"380","side":"BUY","hash":"a5a0815b61ebe50cb8b9249c11377c695730683b","best_bid":"0.991","best_ask":"0.998"},{"asset_id":"103575991306220918671611575108050794364462782362354955892418399227289531345027","price":"0.47","size":"380","side":"SELL","hash":"f34bc7dc23d43b2afeeec97d9fff7523ac652eb0","best_bid":"0.002","best_ask":"0.009"}],"timestamp":"1768359570108","event_type":"price_change"}
{"market":"0x5977c69bca02e6cc150855b0faec463b38be463f141ec37ea5c8a1a1e986e0d3","price_changes":[{"asset_id":"110222991870854778724082971333105906777328061970448875974576460135015541883929","price":"0.42","size":"28.41","side":"BUY","hash":"a5a0815b61ebe50cb8b9249c11377c695730683b","best_bid":"0.991","best_ask":"0.998"},{"asset_id":"103575991306220918671611575108050794364462782362354955892418399227289531345027","price":"0.58","size":"28.41","side":"SELL","hash":"f34bc7dc23d43b2afeeec97d9fff7523ac652eb0","best_bid":"0.002","best_ask":"0.009"}],"timestamp":"1768359570108","event_type":"price_change"}
{"market":"0x5977c69bca02e6cc150855b0faec463b38be463f141ec37ea5c8a1a1e986e0d3","price_changes":[{"asset_id":"110222991870854778724082971333105906777328061970448875974576460135015541883929","price":"0.08","size":"2505","side":"BUY","hash":"a5a0815b61ebe50cb8b9249c11377c695730683b","best_bid":"0.991","best_ask":"0.998"},{"asset_id":"103575991306220918671611575108050794364462782362354955892418399227289531345027","price":"0.92","size":"2505","side":"SELL","hash":"f34bc7dc23d43b2afeeec97d9fff7523ac652eb0","best_bid":"0.002","best_ask":"0.009"}],"timestamp":"1768359570108","event_type":"price_change"}
{"market":"0x5977c69bca02e6cc150855b0faec463b38be463f141ec37ea5c8a1a1e986e0d3","price_changes":[{"asset_id":"110222991870854778724082971333105906777328061970448875974576460135015541883929","price":"0.1","size":"2515","side":"BUY","hash":"a5a0815b61ebe50cb8b9249c11377c695730683b","best_bid":"0.991","best_ask":"0.998"},{"asset_id":"103575991306220918671611575108050794364462782362354955892418399227289531345027","price":"0.9","size":"2515","side":"SELL","hash":"f34bc7dc23d43b2afeeec97d9fff7523ac652eb0","best_bid":"0.002","best_ask":"0.009"}],"timestamp":"1768359570108","event_type":"price_change"}
{"market":"0x5977c69bca02e6cc150855b0faec463b38be463f141ec37ea5c8a1a1e986e0d3","price_changes":[{"asset_id":"110222991870854778724082971333105906777328061970448875974576460135015541883929","price":"0.19","size":"380","side":"BUY","hash":"a5a0815b61ebe50cb8b9249c11377c695730683b","best_bid":"0.991","best_ask":"0.998"},{"asset_id":"103575991306220918671611575108050794364462782362354955892418399227289531345027","price":"0.81","size":"380","side":"SELL","hash":"f34bc7dc23d43b2afeeec97d9fff7523ac652eb0","best_bid":"0.002","best_ask":"0.009"}],"timestamp":"1768359570108","event_type":"price_change"}
{"market":"0x5977c69bca02e6cc150855b0faec463b38be463f141ec37ea5c8a1a1e986e0d3","price_changes":[{"asset_id":"110222991870854778724082971333105906777328061970448875974576460135015541883929","price":"0.62","size":"380","side":"BUY","hash":"a5a0815b61ebe50cb8b9249c11377c695730683b","best_bid":"0.991","best_ask":"0.998"},{"asset_id":"103575991306220918671611575108050794364462782362354955892418399227289531345027","price":"0.38","size":"380","side":"SELL","hash":"f34bc7dc23d43b2afeeec97d9fff7523ac652eb0","best_bid":"0.002","best_ask":"0.009"}],"timestamp":"1768359570108","event_type":"price_change"}
{"market":"0x5977c69bca02e6cc150855b0faec463b38be463f141ec37ea5c8a1a1e986e0d3","price_changes":[{"asset_id":"110222991870854778724082971333105906777328061970448875974576460135015541883929","price":"0.46","size":"10","side":"BUY","hash":"a5a0815b61ebe50cb8b9249c11377c695730683b","best_bid":"0.991","best_ask":"0.998"},{"asset_id":"103575991306220918671611575108050794364462782362354955892418399227289531345027","price":"0.54","size":"10","side":"SELL","hash":"f34bc7dc23d43b2afeeec97d9fff7523ac652eb0","best_bid":"0.002","best_ask":"0.009"}],"timestamp":"1768359570108","event_type":"price_change"}
{"market":"0x5977c69bca02e6cc150855b0faec463b38be463f141ec37ea5c8a1a1e986e0d3","price_changes":[{"asset_id":"110222991870854778724082971333105906777328061970448875974576460135015541883929","price":"0.25","size":"413.5","side":"BUY","hash":"a5a0815b61ebe50cb8b9249c11377c695730683b","best_bid":"0.991","best_ask":"0.998"},{"asset_id":"103575991306220918671611575108050794364462782362354955892418399227289531345027","price":"0.75","size":"413.5","side":"SELL","hash":"f34bc7dc23d43b2afeeec97d9fff7523ac652eb0","best_bid":"0.002","best_ask":"0.009"}],"timestamp":"1768359570108","event_type":"price_change"}
{"market":"0x5977c69bca02e6cc150855b0faec463b38be463f141ec37ea5c8a1a1e986e0d3","price_changes":[{"asset_id":"110222991870854778724082971333105906777328061970448875974576460135015541883929","price":"0.26","size":"380","side":"BUY","hash":"a5a0815b61ebe50cb8b9249c11377c695730683b","best_bid":"0.991","best_ask":"0.998"},{"asset_id":"103575991306220918671611575108050794364462782362354955892418399227289531345027","price":"0.74","size":"380","side":"SELL","hash":"f34bc7dc23d43b2afeeec97d9fff7523ac652eb0","best_bid":"0.002","best_ask":"0.009"}],"timestamp":"1768359570108","event_type":"price_change"}
{"market":"0x5977c69bca02e6cc150855b0faec463b38be463f141ec37ea5c8a1a1e986e0d3","price_changes":[{"asset_id":"110222991870854778724082971333105906777328061970448875974576460135015541883929","price":"0.71","size":"682.74","side":"BUY","hash":"a5a0815b61ebe50cb8b9249c11377c695730683b","best_bid":"0.991","best_ask":"0.998"},{"asset_id":"103575991306220918671611575108050794364462782362354955892418399227289531345027","price":"0.29","size":"682.74","side":"SELL","hash":"f34bc7dc23d43b2afeeec97d9fff7523ac652eb0","best_bid":"0.002","best_ask":"0.009"}],"timestamp":"1768359570108","event_type":"price_change"}
{"market":"0x5977c69bca02e6cc150855b0faec463b38be463f141ec37ea5c8a1a1e986e0d3","price_changes":[{"asset_id":"110222991870854778724082971333105906777328061970448875974576460135015541883929","price":"0.31","size":"380","side":"BUY","hash":"a5a0815b61ebe50cb8b9249c11377c695730683b","best_bid":"0.991","best_ask":"0.998"},{"asset_id":"103575991306220918671611575108050794364462782362354955892418399227289531345027","price":"0.69","size":"380","side":"SELL","hash":"f34bc7dc23d43b2afeeec97d9fff7523ac652eb0","best_bid":"0.002","best_ask":"0.009"}],"timestamp":"1768359570108","event_type":"price_change"}
{"market":"0x5977c69bca02e6cc150855b0faec463b38be463f141ec37ea5c8a1a1e986e0d3","price_changes":[{"asset_id":"110222991870854778724082971333105906777328061970448875974576460135015541883929","price":"0.34","size":"385","side":"BUY","hash":"a5a0815b61ebe50cb8b9249c11377c695730683b","best_bid":"0.991","best_ask":"0.998"},{"asset_id":"103575991306220918671611575108050794364462782362354955892418399227289531345027","price":"0.66","size":"385","side":"SELL","hash":"f34bc7dc23d43b2afeeec97d9fff7523ac652eb0","best_bid":"0.002","best_ask":"0.009"}],"timestamp":"1768359570108","event_type":"price_change"}
{"market":"0x5977c69bca02e6cc150855b0faec463b38be463f141ec37ea5c8a1a1e986e0d3","price_changes":[{"asset_id":"110222991870854778724082971333105906777328061970448875974576460135015541883929","price":"0.35","size":"398.93","side":"BUY","hash":"a5a0815b61ebe50cb8b9249c11377c695730683b","best_bid":"0.991","best_ask":"0.998"},{"asset_id":"103575991306220918671611575108050794364462782362354955892418399227289531345027","price":"0.65","size":"398.93","side":"SELL","hash":"f34bc7dc23d43b2afeeec97d9fff7523ac652eb0","best_bid":"0.002","best_ask":"0.009"}],"timestamp":"1768359570108","event_type":"price_change"}
{"market":"0x5977c69bca02e6cc150855b0faec463b38be463f141ec37ea5c8a1a1e986e0d3","price_changes":[{"asset_id":"110222991870854778724082971333105906777328061970448875974576460135015541883929","price":"0.82","size":"393","side":"BUY","hash":"a5a0815b61ebe50cb8b9249c11377c695730683b","best_bid":"0.991","best_ask":"0.998"},{"asset_id":"103575991306220918671611575108050794364462782362354955892418399227289531345027","price":"0.18","size":"393","side":"SELL","hash":"f34bc7dc23d43b2afeeec97d9fff7523ac652eb0","best_bid":"0.002","best_ask":"0.009"}],"timestamp":"1768359570108","event_type":"price_change"}
{"market":"0x5977c69bca02e6cc150855b0faec463b38be463f141ec37ea5c8a1a1e986e0d3","price_changes":[{"asset_id":"110222991870854778724082971333105906777328061970448875974576460135015541883929","price":"0.61","size":"385","side":"BUY","hash":"a5a0815b61ebe50cb8b9249c11377c695730683b","best_bid":"0.991","best_ask":"0.998"},{"asset_id":"103575991306220918671611575108050794364462782362354955892418399227289531345027","price":"0.39","size":"385","side":"SELL","hash":"f34bc7dc23d43b2afeeec97d9fff7523ac652eb0","best_bid":"0.002","best_ask":"0.009"}],"timestamp":"1768359570108","event_type":"price_change"}
{"market":"0x5977c69bca02e6cc150855b0faec463b38be463f141ec37ea5c8a1a1e986e0d3","price_changes":[{"asset_id":"110222991870854778724082971333105906777328061970448875974576460135015541883929","price":"0.96","size":"487.78","side":"BUY","hash":"a5a0815b61ebe50cb8b9249c11377c695730683b","best_bid":"0.991","best_ask":"0.998"},{"asset_id":"103575991306220918671611575108050794364462782362354955892418399227289531345027","price":"0.04","size":"487.78","side":"SELL","hash":"f34bc7dc23d43b2afeeec97d9fff7523ac652eb0","best_bid":"0.002","best_ask":"0.009"}],"timestamp":"1768359570108","event_type":"price_change"}
{"market":"0x5977c69bca02e6cc150855b0faec463b38be463f141ec37ea5c8a1a1e986e0d3","price_changes":[{"asset_id":"110222991870854778724082971333105906777328061970448875974576460135015541883929","price":"0.79","size":"385","side":"BUY","hash":"a5a0815b61ebe50cb8b9249c11377c695730683b","best_bid":"0.991","best_ask":"0.998"},{"asset_id":"103575991306220918671611575108050794364462782362354955892418399227289531345027","price":"0.21","size":"385","side":"SELL","hash":"f34bc7dc23d43b2afeeec97d9fff7523ac652eb0","best_bid":"0.002","best_ask":"0.009"}],"timestamp":"1768359570108","event_type":"price_change"}
{"market":"0x5977c69bca02e6cc150855b0faec463b38be463f141ec37ea5c8a1a1e986e0d3","price_changes":[{"asset_id":"110222991870854778724082971333105906777328061970448875974576460135015541883929","price":"0.73","size":"414.37","side":"BUY","hash":"a5a0815b61ebe50cb8b9249c11377c695730683b","best_bid":"0.991","best_ask":"0.998"},{"asset_id":"103575991306220918671611575108050794364462782362354955892418399227289531345027","price":"0.27","size":"414.37","side":"SELL","hash":"f34bc7dc23d43b2afeeec97d9fff7523ac652eb0","best_bid":"0.002","best_ask":"0.009"}],"timestamp":"1768359570108","event_type":"price_change"}
{"market":"0x5977c69bca02e6cc150855b0faec463b38be463f141ec37ea5c8a1a1e986e0d3","price_changes":[{"asset_id":"110222991870854778724082971333105906777328061970448875974576460135015541883929","price":"0.01","size":"8146.4","side":"BUY","hash":"a5a0815b61ebe50cb8b9249c11377c695730683b","best_bid":"0.991","best_ask":"0.998"},{"asset_id":"103575991306220918671611575108050794364462782362354955892418399227289531345027","price":"0.99","size":"8146.4","side":"SELL","hash":"f34bc7dc23d43b2afeeec97d9fff7523ac652eb0","best_bid":"0.002","best_ask":"0.009"}],"timestamp":"1768359570108","event_type":"price_change"}
{"market":"0x5977c69bca02e6cc150855b0faec463b38be463f141ec37ea5c8a1a1e986e0d3","price_changes":[{"asset_id":"110222991870854778724082971333105906777328061970448875974576460135015541883929","price":"0.06","size":"2505","side":"BUY","hash":"a5a0815b61ebe50cb8b9249c11377c695730683b","best_bid":"0.991","best_ask":"0.998"},{"asset_id":"103575991306220918671611575108050794364462782362354955892418399227289531345027","price":"0.94","size":"2505","side":"SELL","hash":"f34bc7dc23d43b2afeeec97d9fff7523ac652eb0","best_bid":"0.002","best_ask":"0.009"}],"timestamp":"1768359570108","event_type":"price_change"}
{"market":"0x5977c69bca02e6cc150855b0faec463b38be463f141ec37ea5c8a1a1e986e0d3","price_changes":[{"asset_id":"110222991870854778724082971333105906777328061970448875974576460135015541883929","price":"0.76","size":"659.24","side":"BUY","hash":"a5a0815b61ebe50cb8b9249c11377c695730683b","best_bid":"0.991","best_ask":"0.998"},{"asset_id":"103575991306220918671611575108050794364462782362354955892418399227289531345027","price":"0.24","size":"659.24","side":"SELL","hash":"f34bc7dc23d43b2afeeec97d9fff7523ac652eb0","best_bid":"0.002","best_ask":"0.009"}],"timestamp":"1768359570108","event_type":"price_change"}
{"market":"0x5977c69bca02e6cc150855b0faec463b38be463f141ec37ea5c8a1a1e986e0d3","price_changes":[{"asset_id":"110222991870854778724082971333105906777328061970448875974576460135015541883929","price":"0.41","size":"5","side":"BUY","hash":"a5a0815b61ebe50cb8b9249c11377c695730683b","best_bid":"0.991","best_ask":"0.998"},{"asset_id":"103575991306220918671611575108050794364462782362354955892418399227289531345027","price":"0.59","size":"5","side":"SELL","hash":"f34bc7dc23d43b2afeeec97d9fff7523ac652eb0","best_bid":"0.002","best_ask":"0.009"}],"timestamp":"1768359570108","event_type":"price_change"}
{"market":"0x5977c69bca02e6cc150855b0faec463b38be463f141ec37ea5c8a1a1e986e0d3","price_changes":[{"asset_id":"110222991870854778724082971333105906777328061970448875974576460135015541883929","price":"0.43","size":"10","side":"BUY","hash":"a5a0815b61ebe50cb8b9249c11377c695730683b","best_bid":"0.991","best_ask":"0.998"},{"asset_id":"103575991306220918671611575108050794364462782362354955892418399227289531345027","price":"0.57","size":"10","side":"SELL","hash":"f34bc7dc23d43b2afeeec97d9fff7523ac652eb0","best_bid":"0.002","best_ask":"0.009"}],"timestamp":"1768359570108","event_type":"price_change"}
{"market":"0x5977c69bca02e6cc150855b0faec463b38be463f141ec37ea5c8a1a1e986e0d3","price_changes":[{"asset_id":"110222991870854778724082971333105906777328061970448875974576460135015541883929","price":"0.87","size":"380","side":"BUY","hash":"a5a0815b61ebe50cb8b9249c11377c695730683b","best_bid":"0.991","best_ask":"0.998"},{"asset_id":"103575991306220918671611575108050794364462782362354955892418399227289531345027","price":"0.13","size":"380","side":"SELL","hash":"f34bc7dc23d43b2afeeec97d9fff7523ac652eb0","best_bid":"0.002","best_ask":"0.009"}],"timestamp":"1768359570108","event_type":"price_change"}
{"market":"0x5977c69bca02e6cc150855b0faec463b38be463f141ec37ea5c8a1a1e986e0d3","price_changes":[{"asset_id":"110222991870854778724082971333105906777328061970448875974576460135015541883929","price":"0.93","size":"451","side":"BUY","hash":"a5a0815b61ebe50cb8b9249c11377c695730683b","best_bid":"0.991","best_ask":"0.998"},{"asset_id":"103575991306220918671611575108050794364462782362354955892418399227289531345027","price":"0.07","size":"451","side":"SELL","hash":"f34bc7dc23d43b2afeeec97d9fff7523ac652eb0","best_bid":"0.002","best_ask":"0.009"}],"timestamp":"1768359570108","event_type":"price_change"}
{"market":"0x5977c69bca02e6cc150855b0faec463b38be463f141ec37ea5c8a1a1e986e0d3","price_changes":[{"asset_id":"110222991870854778724082971333105906777328061970448875974576460135015541883929","price":"0.05","size":"2640","side":"BUY","hash":"a5a0815b61ebe50cb8b9249c11377c695730683b","best_bid":"0.991","best_ask":"0.998"},{"asset_id":"103575991306220918671611575108050794364462782362354955892418399227289531345027","price":"0.95","size":"2640","side":"SELL","hash":"f34bc7dc23d43b2afeeec97d9fff7523ac652eb0","best_bid":"0.002","best_ask":"0.009"}],"timestamp":"1768359570108","event_type":"price_change"}
{"market":"0x5977c69bca02e6cc150855b0faec463b38be463f141ec37ea5c8a1a1e986e0d3","price_changes":[{"asset_id":"110222991870854778724082971333105906777328061970448875974576460135015541883929","price":"0.07","size":"2505","side":"BUY","hash":"a5a0815b61ebe50cb8b9249c11377c695730683b","best_bid":"0.991","best_ask":"0.998"},{"asset_id":"103575991306220918671611575108050794364462782362354955892418399227289531345027","price":"0.93","size":"2505","side":"SELL","hash":"f34bc7dc23d43b2afeeec97d9fff7523ac652eb0","best_bid":"0.002","best_ask":"0.009"}],"timestamp":"1768359570108","event_type":"price_change"}
{"market":"0x5977c69bca02e6cc150855b0faec463b38be463f141ec37ea5c8a1a1e986e0d3","price_changes":[{"asset_id":"110222991870854778724082971333105906777328061970448875974576460135015541883929","price":"0.28","size":"403.14","side":"BUY","hash":"a5a0815b61ebe50cb8b9249c11377c695730683b","best_bid":"0.991","best_ask":"0.998"},{"asset_id":"103575991306220918671611575108050794364462782362354955892418399227289531345027","price":"0.72","size":"403.14","side":"SELL","hash":"f34bc7dc23d43b2afeeec97d9fff7523ac652eb0","best_bid":"0.002","best_ask":"0.009"}],"timestamp":"1768359570108","event_type":"price_change"}
{"market":"0x5977c69bca02e6cc150855b0faec463b38be463f141ec37ea5c8a1a1e986e0d3","price_changes":[{"asset_id":"110222991870854778724082971333105906777328061970448875974576460135015541883929","price":"0.29","size":"380","side":"BUY","hash":"a5a0815b61ebe50cb8b9249c11377c695730683b","best_bid":"0.991","best_ask":"0.998"},{"asset_id":"103575991306220918671611575108050794364462782362354955892418399227289531345027","price":"0.71","size":"380","side":"SELL","hash":"f34bc7dc23d43b2afeeec97d9fff7523ac652eb0","best_bid":"0.002","best_ask":"0.009"}],"timestamp":"1768359570108","event_type":"price_change"}
{"market":"0x5977c69bca02e6cc150855b0faec463b38be463f141ec37ea5c8a1a1e986e0d3","price_changes":[{"asset_id":"110222991870854778724082971333105906777328061970448875974576460135015541883929","price":"0.3","size":"606.69","side":"BUY","hash":"a5a0815b61ebe50cb8b9249c11377c695730683b","best_bid":"0.991","best_ask":"0.998"},{"asset_id":"103575991306220918671611575108050794364462782362354955892418399227289531345027","price":"0.7","size":"606.69","side":"SELL","hash":"f34bc7dc23d43b2afeeec97d9fff7523ac652eb0","best_bid":"0.002","best_ask":"0.009"}],"timestamp":"1768359570108","event_type":"price_change"}
{"market":"0x5977c69bca02e6cc150855b0faec463b38be463f141ec37ea5c8a1a1e986e0d3","price_changes":[{"asset_id":"110222991870854778724082971333105906777328061970448875974576460135015541883929","price":"0.54","size":"380","side":"BUY","hash":"a5a0815b61ebe50cb8b9249c11377c695730683b","best_bid":"0.991","best_ask":"0.998"},{"asset_id":"103575991306220918671611575108050794364462782362354955892418399227289531345027","price":"0.46","size":"380","side":"SELL","hash":"f34bc7dc23d43b2afeeec97d9fff7523ac652eb0","best_bid":"0.002","best_ask":"0.009"}],"timestamp":"1768359570108","event_type":"price_change"}
{"market":"0x5977c69bca02e6cc150855b0faec463b38be463f141ec37ea5c8a1a1e986e0d3","price_changes":[{"asset_id":"110222991870854778724082971333105906777328061970448875974576460135015541883929","price":"0.67","size":"298.95","side":"BUY","hash":"a5a0815b61ebe50cb8b9249c11377c695730683b","best_bid":"0.991","best_ask":"0.998"},{"asset_id":"103575991306220918671611575108050794364462782362354955892418399227289531345027","price":"0.33","size":"298.95","side":"SELL","hash":"f34bc7dc23d43b2afeeec97d9fff7523ac652eb0","best_bid":"0.002","best_ask":"0.009"}],"timestamp":"1768359570108","event_type":"price_change"}
{"market":"0x5977c69bca02e6cc150855b0faec463b38be463f141ec37ea5c8a1a1e986e0d3","price_changes":[{"asset_id":"110222991870854778724082971333105906777328061970448875974576460135015541883929","price":"0.09","size":"2505","side":"BUY","hash":"a5a0815b61ebe50cb8b9249c11377c695730683b","best_bid":"0.991","best_ask":"0.998"},{"asset_id":"103575991306220918671611575108050794364462782362354955892418399227289531345027","price":"0.91","size":"2505","side":"SELL","hash":"f34bc7dc23d43b2afeeec97d9fff7523ac652eb0","best_bid":"0.002","best_ask":"0.009"}],"timestamp":"1768359570108","event_type":"price_change"}
{"market":"0x5977c69bca02e6cc150855b0faec463b38be463f141ec37ea5c8a1a1e986e0d3","price_changes":[{"asset_id":"110222991870854778724082971333105906777328061970448875974576460135015541883929","price":"0.75","size":"820.01","side":"BUY","hash":"a5a0815b61ebe50cb8b9249c11377c695730683b","best_bid":"0.991","best_ask":"0.998"},{"asset_id":"103575991306220918671611575108050794364462782362354955892418399227289531345027","price":"0.25","size":"820.01","side":"SELL","hash":"f34bc7dc23d43b2afeeec97d9fff7523ac652eb0","best_bid":"0.002","best_ask":"0.009"}],"timestamp":"1768359570108","event_type":"price_change"}
{"market":"0x5977c69bca02e6cc150855b0faec463b38be463f141ec37ea5c8a1a1e986e0d3","price_changes":[{"asset_id":"110222991870854778724082971333105906777328061970448875974576460135015541883929","price":"0.86","size":"905.94","side":"BUY","hash":"a5a0815b61ebe50cb8b9249c11377c695730683b","best_bid":"0.991","best_ask":"0.998"},{"asset_id":"103575991306220918671611575108050794364462782362354955892418399227289531345027","price":"0.14","size":"905.94","side":"SELL","hash":"f34bc7dc23d43b2afeeec97d9fff7523ac652eb0","best_bid":"0.002","best_ask":"0.009"}],"timestamp":"1768359570108","event_type":"price_change"}
{"market":"0x5977c69bca02e6cc150855b0faec463b38be463f141ec37ea5c8a1a1e986e0d3","price_changes":[{"asset_id":"110222991870854778724082971333105906777328061970448875974576460135015541883929","price":"0.32","size":"385","side":"BUY","hash":"a5a0815b61ebe50cb8b9249c11377c695730683b","best_bid":"0.991","best_ask":"0.998"},{"asset_id":"103575991306220918671611575108050794364462782362354955892418399227289531345027","price":"0.68","size":"385","side":"SELL","hash":"f34bc7dc23d43b2afeeec97d9fff7523ac652eb0","best_bid":"0.002","best_ask":"0.009"}],"timestamp":"1768359570108","event_type":"price_change"}
{"market":"0x5977c69bca02e6cc150855b0faec463b38be463f141ec37ea5c8a1a1e986e0d3","price_changes":[{"asset_id":"110222991870854778724082971333105906777328061970448875974576460135015541883929","price":"0.7","size":"677.5","side":"BUY","hash":"a5a0815b61ebe50cb8b9249c11377c695730683b","best_bid":"0.991","best_ask":"0.998"},{"asset_id":"103575991306220918671611575108050794364462782362354955892418399227289531345027","price":"0.3","size":"677.5","side":"SELL","hash":"f34bc7dc23d43b2afeeec97d9fff7523ac652eb0","best_bid":"0.002","best_ask":"0.009"}],"timestamp":"1768359570108","event_type":"price_change"}
{"market":"0x5977c69bca02e6cc150855b0faec463b38be463f141ec37ea5c8a1a1e986e0d3","price_changes":[{"asset_id":"110222991870854778724082971333105906777328061970448875974576460135015541883929","price":"0.47","size":"15","side":"BUY","hash":"a5a0815b61ebe50cb8b9249c11377c695730683b","best_bid":"0.991","best_ask":"0.998"},{"asset_id":"103575991306220918671611575108050794364462782362354955892418399227289531345027","price":"0.53","size":"15","side":"SELL","hash":"f34bc7dc23d43b2afeeec97d9fff7523ac652eb0","best_bid":"0.002","best_ask":"0.009"}],"timestamp":"1768359570108","event_type":"price_change"}
{"market":"0x5977c69bca02e6cc150855b0faec463b38be463f141ec37ea5c8a1a1e986e0d3","price_changes":[{"asset_id":"110222991870854778724082971333105906777328061970448875974576460135015541883929","price":"0.55","size":"380","side":"BUY","hash":"a5a0815b61ebe50cb8b9249c11377c695730683b","best_bid":"0.991","best_ask":"0.998"},{"asset_id":"103575991306220918671611575108050794364462782362354955892418399227289531345027","price":"0.45","size":"380","side":"SELL","hash":"f34bc7dc23d43b2afeeec97d9fff7523ac652eb0","best_bid":"0.002","best_ask":"0.009"}],"timestamp":"1768359570108","event_type":"price_change"}
{"market":"0x5977c69bca02e6cc150855b0faec463b38be463f141ec37ea5c8a1a1e986e0d3","price_changes":[{"asset_id":"110222991870854778724082971333105906777328061970448875974576460135015541883929","price":"0.59","size":"390","side":"BUY","hash":"a5a0815b61ebe50cb8b9249c11377c695730683b","best_bid":"0.991","best_ask":"0.998"},{"asset_id":"103575991306220918671611575108050794364462782362354955892418399227289531345027","price":"0.41","size":"390","side":"SELL","hash":"f34bc7dc23d43b2afeeec97d9fff7523ac652eb0","best_bid":"0.002","best_ask":"0.009"}],"timestamp":"1768359570108","event_type":"price_change"}
{"market":"0x5977c69bca02e6cc150855b0faec463b38be463f141ec37ea5c8a1a1e986e0d3","price_changes":[{"asset_id":"110222991870854778724082971333105906777328061970448875974576460135015541883929","price":"0.14","size":"5","side":"BUY","hash":"a5a0815b61ebe50cb8b9249c11377c695730683b","best_bid":"0.991","best_ask":"0.998"},{"asset_id":"103575991306220918671611575108050794364462782362354955892418399227289531345027","price":"0.86","size":"5","side":"SELL","hash":"f34bc7dc23d43b2afeeec97d9fff7523ac652eb0","best_bid":"0.002","best_ask":"0.009"}],"timestamp":"1768359570108","event_type":"price_change"}
{"market":"0x5977c69bca02e6cc150855b0faec463b38be463f141ec37ea5c8a1a1e986e0d3","price_changes":[{"asset_id":"110222991870854778724082971333105906777328061970448875974576460135015541883929","price":"0.22","size":"380","side":"BUY","hash":"a5a0815b61ebe50cb8b9249c11377c695730683b","best_bid":"0.991","best_ask":"0.998"},{"asset_id":"103575991306220918671611575108050794364462782362354955892418399227289531345027","price":"0.78","size":"380","side":"SELL","hash":"f34bc7dc23d43b2afeeec97d9fff7523ac652eb0","best_bid":"0.002","best_ask":"0.009"}],"timestamp":"1768359570108","event_type":"price_change"}
{"market":"0x5977c69bca02e6cc150855b0faec463b38be463f141ec37ea5c8a1a1e986e0d3","price_changes":[{"asset_id":"110222991870854778724082971333105906777328061970448875974576460135015541883929","price":"0.27","size":"380","side":"BUY","hash":"a5a0815b61ebe50cb8b9249c11377c695730683b","best_bid":"0.991","best_ask":"0.998"},{"asset_id":"103575991306220918671611575108050794364462782362354955892418399227289531345027","price":"0.73","size":"380","side":"SELL","hash":"f34bc7dc23d43b2afeeec97d9fff7523ac652eb0","best_bid":"0.002","best_ask":"0.009"}],"timestamp":"1768359570108","event_type":"price_change"}
{"market":"0x5977c69bca02e6cc150855b0faec463b38be463f141ec37ea5c8a1a1e986e0d3","price_changes":[{"asset_id":"110222991870854778724082971333105906777328061970448875974576460135015541883929","price":"0.64","size":"516.18","side":"BUY","hash":"a5a0815b61ebe50cb8b9249c11377c695730683b","best_bid":"0.991","best_ask":"0.998"},{"asset_id":"103575991306220918671611575108050794364462782362354955892418399227289531345027","price":"0.36","size":"516.18","side":"SELL","hash":"f34bc7dc23d43b2afeeec97d9fff7523ac652eb0","best_bid":"0.002","best_ask":"0.009"}],"timestamp":"1768359570108","event_type":"price_change"}
{"market":"0x5977c69bca02e6cc150855b0faec463b38be463f141ec37ea5c8a1a1e986e0d3","price_changes":[{"asset_id":"110222991870854778724082971333105906777328061970448875974576460135015541883929","price":"0.89","size":"1390","side":"BUY","hash":"a5a0815b61ebe50cb8b9249c11377c695730683b","best_bid":"0.991","best_ask":"0.998"},{"asset_id":"103575991306220918671611575108050794364462782362354955892418399227289531345027","price":"0.11","size":"1390","side":"SELL","hash":"f34bc7dc23d43b2afeeec97d9fff7523ac652eb0","best_bid":"0.002","best_ask":"0.009"}],"timestamp":"1768359570108","event_type":"price_change"}
{"market":"0x5977c69bca02e6cc150855b0faec463b38be463f141ec37ea5c8a1a1e986e0d3","price_changes":[{"asset_id":"110222991870854778724082971333105906777328061970448875974576460135015541883929","price":"0.68","size":"490.24","side":"BUY","hash":"a5a0815b61ebe50cb8b9249c11377c695730683b","best_bid":"0.991","best_ask":"0.998"},{"asset_id":"103575991306220918671611575108050794364462782362354955892418399227289531345027","price":"0.32","size":"490.24","side":"SELL","hash":"f34bc7dc23d43b2afeeec97d9fff7523ac652eb0","best_bid":"0.002","best_ask":"0.009"}],"timestamp":"1768359570108","event_type":"price_change"}
{"market":"0x5977c69bca02e6cc150855b0faec463b38be463f141ec37ea5c8a1a1e986e0d3","price_changes":[{"asset_id":"110222991870854778724082971333105906777328061970448875974576460135015541883929","price":"0.12","size":"10","side":"BUY","hash":"a5a0815b61ebe50cb8b9249c11377c695730683b","best_bid":"0.991","best_ask":"0.998"},{"asset_id":"103575991306220918671611575108050794364462782362354955892418399227289531345027","price":"0.88","size":"10","side":"SELL","hash":"f34bc7dc23d43b2afeeec97d9fff7523ac652eb0","best_bid":"0.002","best_ask":"0.009"}],"timestamp":"1768359570108","event_type":"price_change"}
{"market":"0x5977c69bca02e6cc150855b0faec463b38be463f141ec37ea5c8a1a1e986e0d3","price_changes":[{"asset_id":"110222991870854778724082971333105906777328061970448875974576460135015541883929","price":"0.15","size":"10","side":"BUY","hash":"a5a0815b61ebe50cb8b9249c11377c695730683b","best_bid":"0.991","best_ask":"0.998"},{"asset_id":"103575991306220918671611575108050794364462782362354955892418399227289531345027","price":"0.85","size":"10","side":"SELL","hash":"f34bc7dc23d43b2afeeec97d9fff7523ac652eb0","best_bid":"0.002","best_ask":"0.009"}],"timestamp":"1768359570108","event_type":"price_change"}
{"market":"0x5977c69bca02e6cc150855b0faec463b38be463f141ec37ea5c8a1a1e986e0d3","price_changes":[{"asset_id":"110222991870854778724082971333105906777328061970448875974576460135015541883929","price":"0.72","size":"582.84","side":"BUY","hash":"a5a0815b61ebe50cb8b9249c11377c695730683b","best_bid":"0.991","best_ask":"0.998"},{"asset_id":"103575991306220918671611575108050794364462782362354955892418399227289531345027","price":"0.28","size":"582.84","side":"SELL","hash":"f34bc7dc23d43b2afeeec97d9fff7523ac652eb0","best_bid":"0.002","best_ask":"0.009"}],"timestamp":"1768359570108","event_type":"price_change"}
{"market":"0x5977c69bca02e6cc150855b0faec463b38be463f141ec37ea5c8a1a1e986e0d3","price_changes":[{"asset_id":"110222991870854778724082971333105906777328061970448875974576460135015541883929","price":"0.36","size":"394.18","side":"BUY","hash":"a5a0815b61ebe50cb8b9249c11377c695730683b","best_bid":"0.991","best_ask":"0.998"},{"asset_id":"103575991306220918671611575108050794364462782362354955892418399227289531345027","price":"0.64","size":"394.18","side":"SELL","hash":"f34bc7dc23d43b2afeeec97d9fff7523ac652eb0","best_bid":"0.002","best_ask":"0.009"}],"timestamp":"1768359570108","event_type":"price_change"}
{"market":"0x5977c69bca02e6cc150855b0faec463b38be463f141ec37ea5c8a1a1e986e0d3","price_changes":[{"asset_id":"110222991870854778724082971333105906777328061970448875974576460135015541883929","price":"0.74","size":"490.67","side":"BUY","hash":"a5a0815b61ebe50cb8b9249c11377c695730683b","best_bid":"0.991","best_ask":"0.998"},{"asset_id":"103575991306220918671611575108050794364462782362354955892418399227289531345027","price":"0.26","size":"490.67","side":"SELL","hash":"f34bc7dc23d43b2afeeec97d9fff7523ac652eb0","best_bid":"0.002","best_ask":"0.009"}],"timestamp":"1768359570108","event_type":"price_change"}
{"market":"0x5977c69bca02e6cc150855b0faec463b38be463f141ec37ea5c8a1a1e986e0d3","price_changes":[{"asset_id":"110222991870854778724082971333105906777328061970448875974576460135015541883929","price":"0.02","size":"4061.8","side":"BUY","hash":"a5a0815b61ebe50cb8b9249c11377c695730683b","best_bid":"0.991","best_ask":"0.998"},{"asset_id":"103575991306220918671611575108050794364462782362354955892418399227289531345027","price":"0.98","size":"4061.8","side":"SELL","hash":"f34bc7dc23d43b2afeeec97d9fff7523ac652eb0","best_bid":"0.002","best_ask":"0.009"}],"timestamp":"1768359570108","event_type":"price_change"}
{"market":"0x5977c69bca02e6cc150855b0faec463b38be463f141ec37ea5c8a1a1e986e0d3","price_changes":[{"asset_id":"110222991870854778724082971333105906777328061970448875974576460135015541883929","price":"0.17","size":"5","side":"BUY","hash":"a5a0815b61ebe50cb8b9249c11377c695730683b","best_bid":"0.991","best_ask":"0.998"},{"asset_id":"103575991306220918671611575108050794364462782362354955892418399227289531345027","price":"0.83","size":"5","side":"SELL","hash":"f34bc7dc23d43b2afeeec97d9fff7523ac652eb0","best_bid":"0.002","best_ask":"0.009"}],"timestamp":"1768359570108","event_type":"price_change"}
{"market":"0x5977c69bca02e6cc150855b0faec463b38be463f141ec37ea5c8a1a1e986e0d3","price_changes":[{"asset_id":"110222991870854778724082971333105906777328061970448875974576460135015541883929","price":"0.21","size":"380","side":"BUY","hash":"a5a0815b61ebe50cb8b9249c11377c695730683b","best_bid":"0.991","best_ask":"0.998"},{"asset_id":"103575991306220918671611575108050794364462782362354955892418399227289531345027","price":"0.79","size":"380","side":"SELL","hash":"f34bc7dc23d43b2afeeec97d9fff7523ac652eb0","best_bid":"0.002","best_ask":"0.009"}],"timestamp":"1768359570108","event_type":"price_change"}
{"market":"0x5977c69bca02e6cc150855b0faec463b38be463f141ec37ea5c8a1a1e986e0d3","price_changes":[{"asset_id":"110222991870854778724082971333105906777328061970448875974576460135015541883929","price":"0.23","size":"380","side":"BUY","hash":"a5a0815b61ebe50cb8b9249c11377c695730683b","best_bid":"0.991","best_ask":"0.998"},{"asset_id":"103575991306220918671611575108050794364462782362354955892418399227289531345027","price":"0.77","size":"380","side":"SELL","hash":"f34bc7dc23d43b2afeeec97d9fff7523ac652eb0","best_bid":"0.002","best_ask":"0.009"}],"timestamp":"1768359570108","event_type":"price_change"}
{"market":"0x5977c69bca02e6cc150855b0faec463b38be463f141ec37ea5c8a1a1e986e0d3","price_changes":[{"asset_id":"110222991870854778724082971333105906777328061970448875974576460135015541883929","price":"0.4","size":"39","side":"BUY","hash":"a5a0815b61ebe50cb8b9249c11377c695730683b","best_bid":"0.991","best_ask":"0.998"},{"asset_id":"103575991306220918671611575108050794364462782362354955892418399227289531345027","price":"0.6","size":"39","side":"SELL","hash":"f34bc7dc23d43b2afeeec97d9fff7523ac652eb0","best_bid":"0.002","best_ask":"0.009"}],"timestamp":"1768359570108","event_type":"price_change"}
{"market":"0x5977c69bca02e6cc150855b0faec463b38be463f141ec37ea5c8a1a1e986e0d3","price_changes":[{"asset_id":"110222991870854778724082971333105906777328061970448875974576460135015541883929","price":"0.56","size":"395","side":"BUY","hash":"a5a0815b61ebe50cb8b9249c11377c695730683b","best_bid":"0.991","best_ask":"0.998"},{"asset_id":"103575991306220918671611575108050794364462782362354955892418399227289531345027","price":"0.44","size":"395","side":"SELL","hash":"f34bc7dc23d43b2afeeec97d9fff7523ac652eb0","best_bid":"0.002","best_ask":"0.009"}],"timestamp":"1768359570108","event_type":"price_change"}
{"market":"0x5977c69bca02e6cc150855b0faec463b38be463f141ec37ea5c8a1a1e986e0d3","price_changes":[{"asset_id":"110222991870854778724082971333105906777328061970448875974576460135015541883929","price":"0.85","size":"406.25","side":"BUY","hash":"a5a0815b61ebe50cb8b9249c11377c695730683b","best_bid":"0.991","best_ask":"0.998"},{"asset_id":"103575991306220918671611575108050794364462782362354955892418399227289531345027","price":"0.15","size":"406.25","side":"SELL","hash":"f34bc7dc23d43b2afeeec97d9fff7523ac652eb0","best_bid":"0.002","best_ask":"0.009"}],"timestamp":"1768359570108","event_type":"price_change"}
{"market":"0x5977c69bca02e6cc150855b0faec463b38be463f141ec37ea5c8a1a1e986e0d3","price_changes":[{"asset_id":"110222991870854778724082971333105906777328061970448875974576460135015541883929","price":"0.6","size":"396","side":"BUY","hash":"a5a0815b61ebe50cb8b9249c11377c695730683b","best_bid":"0.991","best_ask":"0.998"},{"asset_id":"103575991306220918671611575108050794364462782362354955892418399227289531345027","price":"0.4","size":"396","side":"SELL","hash":"f34bc7dc23d43b2afeeec97d9fff7523ac652eb0","best_bid":"0.002","best_ask":"0.009"}],"timestamp":"1768359570108","event_type":"price_change"}
{"market":"0x5977c69bca02e6cc150855b0faec463b38be463f141ec37ea5c8a1a1e986e0d3","price_changes":[{"asset_id":"110222991870854778724082971333105906777328061970448875974576460135015541883929","price":"0.37","size":"403.13","side":"BUY","hash":"a5a0815b61ebe50cb8b9249c11377c695730683b","best_bid":"0.991","best_ask":"0.998"},{"asset_id":"103575991306220918671611575108050794364462782362354955892418399227289531345027","price":"0.63","size":"403.13","side":"SELL","hash":"f34bc7dc23d43b2afeeec97d9fff7523ac652eb0","best_bid":"0.002","best_ask":"0.009"}],"timestamp":"1768359570108","event_type":"price_change"}
{"market":"0x5977c69bca02e6cc150855b0faec463b38be463f141ec37ea5c8a1a1e986e0d3","price_changes":[{"asset_id":"110222991870854778724082971333105906777328061970448875974576460135015541883929","price":"0.49","size":"5","side":"BUY","hash":"a5a0815b61ebe50cb8b9249c11377c695730683b","best_bid":"0.991","best_ask":"0.998"},{"asset_id":"103575991306220918671611575108050794364462782362354955892418399227289531345027","price":"0.51","size":"5","side":"SELL","hash":"f34bc7dc23d43b2afeeec97d9fff7523ac652eb0","best_bid":"0.002","best_ask":"0.009"}],"timestamp":"1768359570108","event_type":"price_change"}
{"market":"0x5977c69bca02e6cc150855b0faec463b38be463f141ec37ea5c8a1a1e986e0d3","price_changes":[{"asset_id":"110222991870854778724082971333105906777328061970448875974576460135015541883929","price":"0.24","size":"380","side":"BUY","hash":"a5a0815b61ebe50cb8b9249c11377c695730683b","best_bid":"0.991","best_ask":"0.998"},{"asset_id":"103575991306220918671611575108050794364462782362354955892418399227289531345027","price":"0.76","size":"380","side":"SELL","hash":"f34bc7dc23d43b2afeeec97d9fff7523ac652eb0","best_bid":"0.002","best_ask":"0.009"}],"timestamp":"1768359570108","event_type":"price_change"}
{"market":"0x5977c69bca02e6cc150855b0faec463b38be463f141ec37ea5c8a1a1e986e0d3","price_changes":[{"asset_id":"110222991870854778724082971333105906777328061970448875974576460135015541883929","price":"0.33","size":"380","side":"BUY","hash":"a5a0815b61ebe50cb8b9249c11377c695730683b","best_bid":"0.991","best_ask":"0.998"},{"asset_id":"103575991306220918671611575108050794364462782362354955892418399227289531345027","price":"0.67","size":"380","side":"SELL","hash":"f34bc7dc23d43b2afeeec97d9fff7523ac652eb0","best_bid":"0.002","best_ask":"0.009"}],"timestamp":"1768359570108","event_type":"price_change"}
{"market":"0x5977c69bca02e6cc150855b0faec463b38be463f141ec37ea5c8a1a1e986e0d3","price_changes":[{"asset_id":"110222991870854778724082971333105906777328061970448875974576460135015541883929","price":"0.65","size":"530.75","side":"BUY","hash":"a5a0815b61ebe50cb8b9249c11377c695730683b","best_bid":"0.991","best_ask":"0.998"},{"asset_id":"103575991306220918671611575108050794364462782362354955892418399227289531345027","price":"0.35","size":"530.75","side":"SELL","hash":"f34bc7dc23d43b2afeeec97d9fff7523ac652eb0","best_bid":"0.002","best_ask":"0.009"}],"timestamp":"1768359570108","event_type":"price_change"}
{"market":"0x5977c69bca02e6cc150855b0faec463b38be463f141ec37ea5c8a1a1e986e0d3","price_changes":[{"asset_id":"110222991870854778724082971333105906777328061970448875974576460135015541883929","price":"0.44","size":"16","side":"BUY","hash":"a5a0815b61ebe50cb8b9249c11377c695730683b","best_bid":"0.991","best_ask":"0.998"},{"asset_id":"103575991306220918671611575108050794364462782362354955892418399227289531345027","price":"0.56","size":"16","side":"SELL","hash":"f34bc7dc23d43b2afeeec97d9fff7523ac652eb0","best_bid":"0.002","best_ask":"0.009"}],"timestamp":"1768359570108","event_type":"price_change"}
{"market":"0x5977c69bca02e6cc150855b0faec463b38be463f141ec37ea5c8a1a1e986e0d3","price_changes":[{"asset_id":"110222991870854778724082971333105906777328061970448875974576460135015541883929","price":"0.11","size":"5","side":"BUY","hash":"a5a0815b61ebe50cb8b9249c11377c695730683b","best_bid":"0.991","best_ask":"0.998"},{"asset_id":"103575991306220918671611575108050794364462782362354955892418399227289531345027","price":"0.89","size":"5","side":"SELL","hash":"f34bc7dc23d43b2afeeec97d9fff7523ac652eb0","best_bid":"0.002","best_ask":"0.009"}],"timestamp":"1768359570108","event_type":"price_change"}
{"market":"0x5977c69bca02e6cc150855b0faec463b38be463f141ec37ea5c8a1a1e986e0d3","price_changes":[{"asset_id":"110222991870854778724082971333105906777328061970448875974576460135015541883929","price":"0.66","size":"510.37","side":"BUY","hash":"a5a0815b61ebe50cb8b9249c11377c695730683b","best_bid":"0.991","best_ask":"0.998"},{"asset_id":"103575991306220918671611575108050794364462782362354955892418399227289531345027","price":"0.34","size":"510.37","side":"SELL","hash":"f34bc7dc23d43b2afeeec97d9fff7523ac652eb0","best_bid":"0.002","best_ask":"0.009"}],"timestamp":"1768359570108","event_type":"price_change"}
{"market":"0x5977c69bca02e6cc150855b0faec463b38be463f141ec37ea5c8a1a1e986e0d3","price_changes":[{"asset_id":"110222991870854778724082971333105906777328061970448875974576460135015541883929","price":"0.8","size":"385","side":"BUY","hash":"a5a0815b61ebe50cb8b9249c11377c695730683b","best_bid":"0.991","best_ask":"0.998"},{"asset_id":"103575991306220918671611575108050794364462782362354955892418399227289531345027","price":"0.2","size":"385","side":"SELL","hash":"f34bc7dc23d43b2afeeec97d9fff7523ac652eb0","best_bid":"0.002","best_ask":"0.009"}],"timestamp":"1768359570108","event_type":"price_change"}
{"market":"0x5977c69bca02e6cc150855b0faec463b38be463f141ec37ea5c8a1a1e986e0d3","price_changes":[{"asset_id":"110222991870854778724082971333105906777328061970448875974576460135015541883929","price":"0.63","size":"400.24","side":"BUY","hash":"a5a0815b61ebe50cb8b9249c11377c695730683b","best_bid":"0.991","best_ask":"0.998"},{"asset_id":"103575991306220918671611575108050794364462782362354955892418399227289531345027","price":"0.37","size":"400.24","side":"SELL","hash":"f34bc7dc23d43b2afeeec97d9fff7523ac652eb0","best_bid":"0.002","best_ask":"0.009"}],"timestamp":"1768359570108","event_type":"price_change"}
{"market":"0x5977c69bca02e6cc150855b0faec463b38be463f141ec37ea5c8a1a1e986e0d3","price_changes":[{"asset_id":"110222991870854778724082971333105906777328061970448875974576460135015541883929","price":"0.04","size":"2724.52","side":"BUY","hash":"a5a0815b61ebe50cb8b9249c11377c695730683b","best_bid":"0.991","best_ask":"0.998"},{"asset_id":"103575991306220918671611575108050794364462782362354955892418399227289531345027","price":"0.96","size":"2724.52","side":"SELL","hash":"f34bc7dc23d43b2afeeec97d9fff7523ac652eb0","best_bid":"0.002","best_ask":"0.009"}],"timestamp":"1768359570108","event_type":"price_change"}
{"market":"0x5977c69bca02e6cc150855b0faec463b38be463f141ec37ea5c8a1a1e986e0d3","price_changes":[{"asset_id":"110222991870854778724082971333105906777328061970448875974576460135015541883929","price":"0.13","size":"5","side":"BUY","hash":"a5a0815b61ebe50cb8b9249c11377c695730683b","best_bid":"0.991","best_ask":"0.998"},{"asset_id":"103575991306220918671611575108050794364462782362354955892418399227289531345027","price":"0.87","size":"5","side":"SELL","hash":"f34bc7dc23d43b2afeeec97d9fff7523ac652eb0","best_bid":"0.002","best_ask":"0.009"}],"timestamp":"1768359570108","event_type":"price_change"}
{"market":"0x5977c69bca02e6cc150855b0faec463b38be463f141ec37ea5c8a1a1e986e0d3","price_changes":[{"asset_id":"110222991870854778724082971333105906777328061970448875974576460135015541883929","price":"0.48","size":"88.05","side":"BUY","hash":"a5a0815b61ebe50cb8b9249c11377c695730683b","best_bid":"0.991","best_ask":"0.998"},{"asset_id":"103575991306220918671611575108050794364462782362354955892418399227289531345027","price":"0.52","size":"88.05","side":"SELL","hash":"f34bc7dc23d43b2afeeec97d9fff7523ac652eb0","best_bid":"0.002","best_ask":"0.009"}],"timestamp":"1768359570108","event_type":"price_change"}
{"market":"0x5977c69bca02e6cc150855b0faec463b38be463f141ec37ea5c8a1a1e986e0d3","price_changes":[{"asset_id":"110222991870854778724082971333105906777328061970448875974576460135015541883929","price":"0.51","size":"107.65","side":"BUY","hash":"a5a0815b61ebe50cb8b9249c11377c695730683b","best_bid":"0.991","best_ask":"0.998"},{"asset_id":"103575991306220918671611575108050794364462782362354955892418399227289531345027","price":"0.49","size":"107.65","side":"SELL","hash":"f34bc7dc23d43b2afeeec97d9fff7523ac652eb0","best_bid":"0.002","best_ask":"0.009"}],"timestamp":"1768359570108","event_type":"price_change"}
{"market":"0x5977c69bca02e6cc150855b0faec463b38be463f141ec37ea5c8a1a1e986e0d3","price_changes":[{"asset_id":"110222991870854778724082971333105906777328061970448875974576460135015541883929","price":"0.77","size":"470","side":"BUY","hash":"a5a0815b61ebe50cb8b9249c11377c695730683b","best_bid":"0.991","best_ask":"0.998"},{"asset_id":"103575991306220918671611575108050794364462782362354955892418399227289531345027","price":"0.23","size":"470","side":"SELL","hash":"f34bc7dc23d43b2afeeec97d9fff7523ac652eb0","best_bid":"0.002","best_ask":"0.009"}],"timestamp":"1768359570108","event_type":"price_change"}
{"market":"0x5977c69bca02e6cc150855b0faec463b38be463f141ec37ea5c8a1a1e986e0d3","price_changes":[{"asset_id":"110222991870854778724082971333105906777328061970448875974576460135015541883929","price":"0.81","size":"484.75","side":"BUY","hash":"a5a0815b61ebe50cb8b9249c11377c695730683b","best_bid":"0.991","best_ask":"0.998"},{"asset_id":"103575991306220918671611575108050794364462782362354955892418399227289531345027","price":"0.19","size":"484.75","side":"SELL","hash":"f34bc7dc23d43b2afeeec97d9fff7523ac652eb0","best_bid":"0.002","best_ask":"0.009"}],"timestamp":"1768359570108","event_type":"price_change"}
{"market":"0x5977c69bca02e6cc150855b0faec463b38be463f141ec37ea5c8a1a1e986e0d3","price_changes":[{"asset_id":"110222991870854778724082971333105906777328061970448875974576460135015541883929","price":"0.84","size":"406.56","side":"BUY","hash":"a5a0815b61ebe50cb8b9249c11377c695730683b","best_bid":"0.991","best_ask":"0.998"},{"asset_id":"103575991306220918671611575108050794364462782362354955892418399227289531345027","price":"0.16","size":"406.56","side":"SELL","hash":"f34bc7dc23d43b2afeeec97d9fff7523ac652eb0","best_bid":"0.002","best_ask":"0.009"}],"timestamp":"1768359570108","event_type":"price_change"}
{"market":"0x5977c69bca02e6cc150855b0faec463b38be463f141ec37ea5c8a1a1e986e0d3","price_changes":[{"asset_id":"110222991870854778724082971333105906777328061970448875974576460135015541883929","price":"0.18","size":"5","side":"BUY","hash":"a5a0815b61ebe50cb8b9249c11377c695730683b","best_bid":"0.991","best_ask":"0.998"},{"asset_id":"103575991306220918671611575108050794364462782362354955892418399227289531345027","price":"0.82","size":"5","side":"SELL","hash":"f34bc7dc23d43b2afeeec97d9fff7523ac652eb0","best_bid":"0.002","best_ask":"0.009"}],"timestamp":"1768359570108","event_type":"price_change"}
{"market":"0x5977c69bca02e6cc150855b0faec463b38be463f141ec37ea5c8a1a1e986e0d3","price_changes":[{"asset_id":"110222991870854778724082971333105906777328061970448875974576460135015541883929","price":"0.39","size":"374.09","side":"BUY","hash":"a5a0815b61ebe50cb8b9249c11377c695730683b","best_bid":"0.991","best_ask":"0.998"},{"asset_id":"103575991306220918671611575108050794364462782362354955892418399227289531345027","price":"0.61","size":"374.09","side":"SELL","hash":"f34bc7dc23d43b2afeeec97d9fff7523ac652eb0","best_bid":"0.002","best_ask":"0.009"}],"timestamp":"1768359570108","event_type":"price_change"}
{"market":"0x5977c69bca02e6cc150855b0faec463b38be463f141ec37ea5c8a1a1e986e0d3","price_changes":[{"asset_id":"110222991870854778724082971333105906777328061970448875974576460135015541883929","price":"0.5","size":"25","side":"BUY","hash":"a5a0815b61ebe50cb8b9249c11377c695730683b","best_bid":"0.991","best_ask":"0.998"},{"asset_id":"103575991306220918671611575108050794364462782362354955892418399227289531345027","price":"0.5","size":"25","side":"SELL","hash":"f34bc7dc23d43b2afeeec97d9fff7523ac652eb0","best_bid":"0.002","best_ask":"0.009"}],"timestamp":"1768359570108","event_type":"price_change"}
{"market":"0x5977c69bca02e6cc150855b0faec463b38be463f141ec37ea5c8a1a1e986e0d3","price_changes":[{"asset_id":"110222991870854778724082971333105906777328061970448875974576460135015541883929","price":"0.52","size":"43","side":"BUY","hash":"a5a0815b61ebe50cb8b9249c11377c695730683b","best_bid":"0.991","best_ask":"0.998"},{"asset_id":"103575991306220918671611575108050794364462782362354955892418399227289531345027","price":"0.48","size":"43","side":"SELL","hash":"f34bc7dc23d43b2afeeec97d9fff7523ac652eb0","best_bid":"0.002","best_ask":"0.009"}],"timestamp":"1768359570108","event_type":"price_change"}
{"market":"0x5977c69bca02e6cc150855b0faec463b38be463f141ec37ea5c8a1a1e986e0d3","price_changes":[{"asset_id":"110222991870854778724082971333105906777328061970448875974576460135015541883929","price":"0.38","size":"380","side":"BUY","hash":"a5a0815b61ebe50cb8b9249c11377c695730683b","best_bid":"0.991","best_ask":"0.998"},{"asset_id":"103575991306220918671611575108050794364462782362354955892418399227289531345027","price":"0.62","size":"380","side":"SELL","hash":"f34bc7dc23d43b2afeeec97d9fff7523ac652eb0","best_bid":"0.002","best_ask":"0.009"}],"timestamp":"1768359570108","event_type":"price_change"}
{"market":"0x5977c69bca02e6cc150855b0faec463b38be463f141ec37ea5c8a1a1e986e0d3","price_changes":[{"asset_id":"110222991870854778724082971333105906777328061970448875974576460135015541883929","price":"0.58","size":"385","side":"BUY","hash":"a5a0815b61ebe50cb8b9249c11377c695730683b","best_bid":"0.991","best_ask":"0.998"},{"asset_id":"103575991306220918671611575108050794364462782362354955892418399227289531345027","price":"0.42","size":"385","side":"SELL","hash":"f34bc7dc23d43b2afeeec97d9fff7523ac652eb0","best_bid":"0.002","best_ask":"0.009"}],"timestamp":"1768359570108","event_type":"price_change"}
{"market":"0x5977c69bca02e6cc150855b0faec463b38be463f141ec37ea5c8a1a1e986e0d3","price_changes":[{"asset_id":"110222991870854778724082971333105906777328061970448875974576460135015541883929","price":"0.83","size":"418.78","side":"BUY","hash":"a5a0815b61ebe50cb8b9249c11377c695730683b","best_bid":"0.991","best_ask":"0.998"},{"asset_id":"103575991306220918671611575108050794364462782362354955892418399227289531345027","price":"0.17","size":"418.78","side":"SELL","hash":"f34bc7dc23d43b2afeeec97d9fff7523ac652eb0","best_bid":"0.002","best_ask":"0.009"}],"timestamp":"1768359570108","event_type":"price_change"}
{"market":"0x5977c69bca02e6cc150855b0faec463b38be463f141ec37ea5c8a1a1e986e0d3","price_changes":[{"asset_id":"110222991870854778724082971333105906777328061970448875974576460135015541883929","price":"0.9","size":"424.19","side":"BUY","hash":"a5a0815b61ebe50cb8b9249c11377c695730683b","best_bid":"0.991","best_ask":"0.998"},{"asset_id":"103575991306220918671611575108050794364462782362354955892418399227289531345027","price":"0.1","size":"424.19","side":"SELL","hash":"f34bc7dc23d43b2afeeec97d9fff7523ac652eb0","best_bid":"0.002","best_ask":"0.009"}],"timestamp":"1768359570108","event_type":"price_change"}
{"market":"0x5977c69bca02e6cc150855b0faec463b38be463f141ec37ea5c8a1a1e986e0d3","price_changes":[{"asset_id":"110222991870854778724082971333105906777328061970448875974576460135015541883929","price":"0.991","size":"959.86","side":"BUY","hash":"7bfeec3a235e55c1adc364b70b09c8974ad9d471","best_bid":"0.991","best_ask":"0.998"},{"asset_id":"103575991306220918671611575108050794364462782362354955892418399227289531345027","price":"0.009","size":"959.86","side":"SELL","hash":"7e51803ee0b9221b6b0d365694b4c4d65e5c0806","best_bid":"0.002","best_ask":"0.009"}],"timestamp":"1768359570271","event_type":"price_change"}
{"market":"0x5977c69bca02e6cc150855b0faec463b38be463f141ec37ea5c8a1a1e986e0d3","asset_id":"103575991306220918671611575108050794364462782362354955892418399227289531345027","bids":[{"price":"0.001","size":"140"},{"price":"0.002","size":"4.94"}],"asks":[{"price":"0.999","size":"270"},{"price":"0.998","size":"60"},{"price":"0.99","size":"8146.4"},{"price":"0.98","size":"4061.8"},{"price":"0.97","size":"2960.5"},{"price":"0.96","size":"2724.52"},{"price":"0.95","size":"2640"},{"price":"0.94","size":"2505"},{"price":"0.93","size":"2505"},{"price":"0.92","size":"2505"},{"price":"0.91","size":"2505"},{"price":"0.9","size":"2515"},{"price":"0.89","size":"5"},{"price":"0.88","size":"10"},{"price":"0.87","size":"5"},{"price":"0.86","size":"5"},{"price":"0.85","size":"10"},{"price":"0.84","size":"5"},{"price":"0.83","size":"5"},{"price":"0.82","size":"5"},{"price":"0.81","size":"380"},{"price":"0.8","size":"420"},{"price":"0.79","size":"380"},{"price":"0.78","size":"380"},{"price":"0.77","size":"380"},{"price":"0.76","size":"380"},{"price":"0.75","size":"413.5"},{"price":"0.74","size":"380"},{"price":"0.73","size":"380"},{"price":"0.72","size":"403.14"},{"price":"0.71","size":"380"},{"price":"0.7","size":"606.69"},{"price":"0.69","size":"380"},{"price":"0.68","size":"385"},{"price":"0.67","size":"380"},{"price":"0.66","size":"385"},{"price":"0.65","size":"398.93"},{"price":"0.64","size":"394.18"},{"price":"0.63","size":"403.13"},{"price":"0.62","size":"380"},{"price":"0.61","size":"374.09"},{"price":"0.6","size":"39"},{"price":"0.59","size":"5"},{"price":"0.58","size":"28.41"},{"price":"0.57","size":"10"},{"price":"0.56","size":"16"},{"price":"0.55","size":"319.33"},{"price":"0.54","size":"10"},{"price":"0.53","size":"15"},{"price":"0.52","size":"88.05"},{"price":"0.51","size":"5"},{"price":"0.5","size":"25"},{"price":"0.49","size":"107.65"},{"price":"0.48","size":"43"},{"price":"0.47","size":"380"},{"price":"0.46","size":"380"},{"price":"0.45","size":"380"},{"price":"0.44","size":"395"},{"price":"0.43","size":"385"},{"price":"0.42","size":"385"},{"price":"0.41","size":"390"},{"price":"0.4","size":"396"},{"price":"0.39","size":"385"},{"price":"0.38","size":"380"},{"price":"0.37","size":"400.24"},{"price":"0.36","size":"516.18"},{"price":"0.35","size":"530.75"},{"price":"0.34","size":"510.37"},{"price":"0.33","size":"298.95"},{"price":"0.32","size":"490.24"},{"price":"0.31","size":"474.01"},{"price":"0.3","size":"677.5"},{"price":"0.29","size":"682.74"},{"price":"0.28","size":"582.84"},{"price":"0.27","size":"414.37"},{"price":"0.26","size":"490.67"},{"price":"0.259","size":"5"},{"price":"0.25","size":"820.01"},{"price":"0.24","size":"659.24"},{"price":"0.23","size":"470"},{"price":"0.22","size":"389.97"},{"price":"0.21","size":"385"},{"price":"0.2","size":"385"},{"price":"0.19","size":"484.75"},{"price":"0.18","size":"393"},{"price":"0.17","size":"418.78"},{"price":"0.16","size":"406.56"},{"price":"0.15","size":"406.25"},{"price":"0.14","size":"905.94"},{"price":"0.13","size":"380"},{"price":"0.12","size":"1391.36"},{"price":"0.11","size":"1390"},{"price":"0.1","size":"424.19"},{"price":"0.09","size":"380"},{"price":"0.08","size":"594.2"},{"price":"0.07","size":"451"},{"price":"0.06","size":"709.16"},{"price":"0.05","size":"329.51"},{"price":"0.04","size":"487.78"},{"price":"0.03","size":"908"},{"price":"0.02","size":"1045.53"},{"price":"0.01","size":"1156.24"},{"price":"0.009","size":"959.86"}],"hash":"7e51803ee0b9221b6b0d365694b4c4d65e5c0806","timestamp":"1768359570271","event_type":"book"}
{"market":"0x5977c69bca02e6cc150855b0faec463b38be463f141ec37ea5c8a1a1e986e0d3","asset_id":"110222991870854778724082971333105906777328061970448875974576460135015541883929","bids":[{"price":"0.001","size":"270"},{"price":"0.002","size":"60"},{"price":"0.01","size":"8146.4"},{"price":"0.02","size":"4061.8"},{"price":"0.03","size":"2960.5"},{"price":"0.04","size":"2724.52"},{"price":"0.05","size":"2640"},{"price":"0.06","size":"2505"},{"price":"0.07","size":"2505"},{"price":"0.08","size":"2505"},{"price":"0.09","size":"2505"},{"price":"0.1","size":"2515"},{"price":"0.11","size":"5"},{"price":"0.12","size":"10"},{"price":"0.13","size":"5"},{"price":"0.14","size":"5"},{"price":"0.15","size":"10"},{"price":"0.16","size":"5"},{"price":"0.17","size":"5"},{"price":"0.18","size":"5"},{"price":"0.19","size":"380"},{"price":"0.2","size":"420"},{"price":"0.21","size":"380"},{"price":"0.22","size":"380"},{"price":"0.23","size":"380"},{"price":"0.24","size":"380"},{"price":"0.25","size":"413.5"},{"price":"0.26","size":"380"},{"price":"0.27","size":"380"},{"price":"0.28","size":"403.14"},{"price":"0.29","size":"380"},{"price":"0.3","size":"606.69"},{"price":"0.31","size":"380"},{"price":"0.32","size":"385"},{"price":"0.33","size":"380"},{"price":"0.34","size":"385"},{"price":"0.35","size":"398.93"},{"price":"0.36","size":"394.18"},{"price":"0.37","size":"403.13"},{"price":"0.38","size":"380"},{"price":"0.39","size":"374.09"},{"price":"0.4","size":"39"},{"price":"0.41","size":"5"},{"price":"0.42","size":"28.41"},{"price":"0.43","size":"10"},{"price":"0.44","size":"16"},{"price":"0.45","size":"319.33"},{"price":"0.46","size":"10"},{"price":"0.47","size":"15"},{"price":"0.48","size":"88.05"},{"price":"0.49","size":"5"},{"price":"0.5","size":"25"},{"price":"0.51","size":"107.65"},{"price":"0.52","size":"43"},{"price":"0.53","size":"380"},{"price":"0.54","size":"380"},{"price":"0.55","size":"380"},{"price":"0.56","size":"395"},{"price":"0.57","size":"385"},{"price":"0.58","size":"385"},{"price":"0.59","size":"390"},{"price":"0.6","size":"396"},{"price":"0.61","size":"385"},{"price":"0.62","size":"380"},{"price":"0.63","size":"400.24"},{"price":"0.64","size":"516.18"},{"price":"0.65","size":"530.75"},{"price":"0.66","size":"510.37"},{"price":"0.67","size":"298.95"},{"price":"0.68","size":"490.24"},{"price":"0.69","size":"474.01"},{"price":"0.7","size":"677.5"},{"price":"0.71","size":"682.74"},{"price":"0.72","size":"582.84"},{"price":"0.73","size":"414.37"},{"price":"0.74","size":"490.67"},{"price":"0.741","size":"5"},{"price":"0.75","size":"820.01"},{"price":"0.76","size":"659.24"},{"price":"0.77","size":"470"},{"price":"0.78","size":"389.97"},{"price":"0.79","size":"385"},{"price":"0.8","size":"385"},{"price":"0.81","size":"484.75"},{"price":"0.82","size":"393"},{"price":"0.83","size":"418.78"},{"price":"0.84","size":"406.56"},{"price":"0.85","size":"406.25"},{"price":"0.86","size":"905.94"},{"price":"0.87","size":"380"},{"price":"0.88","size":"1391.36"},{"price":"0.89","size":"1390"},{"price":"0.9","size":"424.19"},{"price":"0.91","size":"380"},{"price":"0.92","size":"594.2"},{"price":"0.93","size":"451"},{"price":"0.94","size":"709.16"},{"price":"0.95","size":"329.51"},{"price":"0.96","size":"487.78"},{"price":"0.97","size":"908"},{"price":"0.98","size":"1045.53"},{"price":"0.99","size":"1156.24"},{"price":"0.991","size":"959.86"}],"asks":[{"price":"0.999","size":"140"},{"price":"0.998","size":"4.94"}],"hash":"7bfeec3a235e55c1adc364b70b09c8974ad9d471","timestamp":"1768359570271","event_type":"book"}
{"market":"0x5977c69bca02e6cc150855b0faec463b38be463f141ec37ea5c8a1a1e986e0d3","asset_id":"110222991870854778724082971333105906777328061970448875974576460135015541883929","price":"0.991","size":"12.25","fee_rate_bps":"1000","side":"SELL","timestamp":"1768359570306","event_type":"last_trade_price","transaction_hash":"0x7ac6f31ed09380aef59d49ec9d480dcffaec3a123c48c23001029120e7025bda"}
{"market":"0x5977c69bca02e6cc150855b0faec463b38be463f141ec37ea5c8a1a1e986e0d3","price_changes":[{"asset_id":"110222991870854778724082971333105906777328061970448875974576460135015541883929","price":"0.99","size":"1164.24","side":"BUY","hash":"ce4b411e9ac3a5a49cbc5b14405b2c2b015da6b8","best_bid":"0.991","best_ask":"0.998"},{"asset_id":"103575991306220918671611575108050794364462782362354955892418399227289531345027","price":"0.01","size":"1164.24","side":"SELL","hash":"299a26a1639921c2d7f54008074de5651c8e9cac","best_bid":"0.002","best_ask":"0.009"}],"timestamp":"1768359570311","event_type":"price_change"}
{"market":"0x5977c69bca02e6cc150855b0faec463b38be463f141ec37ea5c8a1a1e986e0d3","price_changes":[{"asset_id":"110222991870854778724082971333105906777328061970448875974576460135015541883929","price":"0.94","size":"695.16","side":"BUY","hash":"6010f8685cc50959e24393f90c7eb2e03d7a0b15","best_bid":"0.991","best_ask":"0.998"},{"asset_id":"103575991306220918671611575108050794364462782362354955892418399227289531345027","price":"0.06","size":"695.16","side":"SELL","hash":"2aaac9a98d63255d11c28f7247ceccc99fad6e58","best_bid":"0.002","best_ask":"0.009"}],"timestamp":"1768359570491","event_type":"price_change"}
{"market":"0x5977c69bca02e6cc150855b0faec463b38be463f141ec37ea5c8a1a1e986e0d3","price_changes":[{"asset_id":"110222991870854778724082971333105906777328061970448875974576460135015541883929","price":"0.93","size":"464","side":"BUY","hash":"5d1734076d7dda792d5394058bb67f96fd05584f","best_bid":"0.991","best_ask":"0.998"},{"asset_id":"103575991306220918671611575108050794364462782362354955892418399227289531345027","price":"0.07","size":"464","side":"SELL","hash":"5aa60ed8a158fb0ed93b83cb1179eebe6430a633","best_bid":"0.002","best_ask":"0.009"}],"timestamp":"1768359570532","event_type":"price_change"}
{"market":"0x5977c69bca02e6cc150855b0faec463b38be463f141ec37ea5c8a1a1e986e0d3","price_changes":[{"asset_id":"110222991870854778724082971333105906777328061970448875974576460135015541883929","price":"0.84","size":"396.56","side":"BUY","hash":"5326dc57bd6fff4d0e730cb73dc065918abcff18","best_bid":"0.991","best_ask":"0.998"},{"asset_id":"103575991306220918671611575108050794364462782362354955892418399227289531345027","price":"0.16","size":"396.56","side":"SELL","hash":"b61a835902da21d3a474e45a4314701d4520bf9b","best_bid":"0.002","best_ask":"0.009"}],"timestamp":"1768359570540","event_type":"price_change"}
{"market":"0x5977c69bca02e6cc150855b0faec463b38be463f141ec37ea5c8a1a1e986e0d3","price_changes":[{"asset_id":"110222991870854778724082971333105906777328061970448875974576460135015541883929","price":"0.84","size":"406.56","side":"BUY","hash":"31446f79abf82834cabb9e9c09c76db00f6042ae","best_bid":"0.991","best_ask":"0.998"},{"asset_id":"103575991306220918671611575108050794364462782362354955892418399227289531345027","price":"0.16","size":"406.56","side":"SELL","hash":"866a4a76d515d9ddfbc8a7a1a5873cff92f2e658","best_bid":"0.002","best_ask":"0.009"}],"timestamp":"1768359570568","event_type":"price_change"}
{"market":"0x5977c69bca02e6cc150855b0faec463b38be463f141ec37ea5c8a1a1e986e0d3","price_changes":[{"asset_id":"110222991870854778724082971333105906777328061970448875974576460135015541883929","price":"0.991","size":"948.75","side":"BUY","hash":"1f9a58da1c206ca2e29affb31ac0f32d407c877f","best_bid":"0.991","best_ask":"0.998"},{"asset_id":"103575991306220918671611575108050794364462782362354955892418399227289531345027","price":"0.009","size":"948.75","side":"SELL","hash":"d34b41f7f23aa1b7f89dffcba92b3abb0121bd57","best_bid":"0.002","best_ask":"0.009"}],"timestamp":"1768359570661","event_type":"price_change"}
{"market":"0x5977c69bca02e6cc150855b0faec463b38be463f141ec37ea5c8a1a1e986e0d3","asset_id":"103575991306220918671611575108050794364462782362354955892418399227289531345027","bids":[{"price":"0.001","size":"140"},{"price":"0.002","size":"4.94"}],"asks":[{"price":"0.999","size":"270"},{"price":"0.998","size":"60"},{"price":"0.99","size":"8146.4"},{"price":"0.98","size":"4061.8"},{"price":"0.97","size":"2960.5"},{"price":"0.96","size":"2724.52"},{"price":"0.95","size":"2640"},{"price":"0.94","size":"2505"},{"price":"0.93","size":"2505"},{"price":"0.92","size":"2505"},{"price":"0.91","size":"2505"},{"price":"0.9","size":"2515"},{"price":"0.89","size":"5"},{"price":"0.88","size":"10"},{"price":"0.87","size":"5"},{"price":"0.86","size":"5"},{"price":"0.85","size":"10"},{"price":"0.84","size":"5"},{"price":"0.83","size":"5"},{"price":"0.82","size":"5"},{"price":"0.81","size":"380"},{"price":"0.8","size":"420"},{"price":"0.79","size":"380"},{"price":"0.78","size":"380"},{"price":"0.77","size":"380"},{"price":"0.76","size":"380"},{"price":"0.75","size":"413.5"},{"price":"0.74","size":"380"},{"price":"0.73","size":"380"},{"price":"0.72","size":"403.14"},{"price":"0.71","size":"380"},{"price":"0.7","size":"606.69"},{"price":"0.69","size":"380"},{"price":"0.68","size":"385"},{"price":"0.67","size":"380"},{"price":"0.66","size":"385"},{"price":"0.65","size":"398.93"},{"price":"0.64","size":"394.18"},{"price":"0.63","size":"403.13"},{"price":"0.62","size":"380"},{"price":"0.61","size":"374.09"},{"price":"0.6","size":"39"},{"price":"0.59","size":"5"},{"price":"0.58","size":"28.41"},{"price":"0.57","size":"10"},{"price":"0.56","size":"16"},{"price":"0.55","size":"319.33"},{"price":"0.54","size":"10"},{"price":"0.53","size":"15"},{"price":"0.52","size":"88.05"},{"price":"0.51","size":"5"},{"price":"0.5","size":"25"},{"price":"0.49","size":"107.65"},{"price":"0.48","size":"43"},{"price":"0.47","size":"380"},{"price":"0.46","size":"380"},{"price":"0.45","size":"380"},{"price":"0.44","size":"395"},{"price":"0.43","size":"385"},{"price":"0.42","size":"385"},{"price":"0.41","size":"390"},{"price":"0.4","size":"396"},{"price":"0.39","size":"385"},{"price":"0.38","size":"380"},{"price":"0.37","size":"400.24"},{"price":"0.36","size":"516.18"},{"price":"0.35","size":"530.75"},{"price":"0.34","size":"510.37"},{"price":"0.33","size":"298.95"},{"price":"0.32","size":"490.24"},{"price":"0.31","size":"474.01"},{"price":"0.3","size":"677.5"},{"price":"0.29","size":"682.74"},{"price":"0.28","size":"582.84"},{"price":"0.27","size":"414.37"},{"price":"0.26","size":"490.67"},{"price":"0.259","size":"5"},{"price":"0.25","size":"820.01"},{"price":"0.24","size":"659.24"},{"price":"0.23","size":"470"},{"price":"0.22","size":"389.97"},{"price":"0.21","size":"385"},{"price":"0.2","size":"385"},{"price":"0.19","size":"484.75"},{"price":"0.18","size":"393"},{"price":"0.17","size":"418.78"},{"price":"0.16","size":"406.56"},{"price":"0.15","size":"406.25"},{"price":"0.14","size":"905.94"},{"price":"0.13","size":"380"},{"price":"0.12","size":"1391.36"},{"price":"0.11","size":"1390"},{"price":"0.1","size":"424.19"},{"price":"0.09","size":"380"},{"price":"0.08","size":"594.2"},{"price":"0.07","size":"464"},{"price":"0.06","size":"695.16"},{"price":"0.05","size":"329.51"},{"price":"0.04","size":"487.78"},{"price":"0.03","size":"908"},{"price":"0.02","size":"1045.53"},{"price":"0.01","size":"1164.24"},{"price":"0.009","size":"948.75"}],"hash":"d34b41f7f23aa1b7f89dffcba92b3abb0121bd57","timestamp":"1768359570661","event_type":"book"}
{"market":"0x5977c69bca02e6cc150855b0faec463b38be463f141ec37ea5c8a1a1e986e0d3","asset_id":"110222991870854778724082971333105906777328061970448875974576460135015541883929","bids":[{"price":"0.001","size":"270"},{"price":"0.002","size":"60"},{"price":"0.01","size":"8146.4"},{"price":"0.02","size":"4061.8"},{"price":"0.03","size":"2960.5"},{"price":"0.04","size":"2724.52"},{"price":"0.05","size":"2640"},{"price":"0.06","size":"2505"},{"price":"0.07","size":"2505"},{"price":"0.08","size":"2505"},{"price":"0.09","size":"2505"},{"price":"0.1","size":"2515"},{"price":"0.11","size":"5"},{"price":"0.12","size":"10"},{"price":"0.13","size":"5"},{"price":"0.14","size":"5"},{"price":"0.15","size":"10"},{"price":"0.16","size":"5"},{"price":"0.17","size":"5"},{"price":"0.18","size":"5"},{"price":"0.19","size":"380"},{"price":"0.2","size":"420"},{"price":"0.21","size":"380"},{"price":"0.22","size":"380"},{"price":"0.23","size":"380"},{"price":"0.24","size":"380"},{"price":"0.25","size":"413.5"},{"price":"0.26","size":"380"},{"price":"0.27","size":"380"},{"price":"0.28","size":"403.14"},{"price":"0.29","size":"380"},{"price":"0.3","size":"606.69"},{"price":"0.31","size":"380"},{"price":"0.32","size":"385"},{"price":"0.33","size":"380"},{"price":"0.34","size":"385"},{"price":"0.35","size":"398.93"},{"price":"0.36","size":"394.18"},{"price":"0.37","size":"403.13"},{"price":"0.38","size":"380"},{"price":"0.39","size":"374.09"},{"price":"0.4","size":"39"},{"price":"0.41","size":"5"},{"price":"0.42","size":"28.41"},{"price":"0.43","size":"10"},{"price":"0.44","size":"16"},{"price":"0.45","size":"319.33"},{"price":"0.46","size":"10"},{"price":"0.47","size":"15"},{"price":"0.48","size":"88.05"},{"price":"0.49","size":"5"},{"price":"0.5","size":"25"},{"price":"0.51","size":"107.65"},{"price":"0.52","size":"43"},{"price":"0.53","size":"380"},{"price":"0.54","size":"380"},{"price":"0.55","size":"380"},{"price":"0.56","size":"395"},{"price":"0.57","size":"385"},{"price":"0.58","size":"385"},{"price":"0.59","size":"390"},{"price":"0.6","size":"396"},{"price":"0.61","size":"385"},{"price":"0.62","size":"380"},{"price":"0.63","size":"400.24"},{"price":"0.64","size":"516.18"},{"price":"0.65","size":"530.75"},{"price":"0.66","size":"510.37"},{"price":"0.67","size":"298.95"},{"price":"0.68","size":"490.24"},{"price":"0.69","size":"474.01"},{"price":"0.7","size":"677.5"},{"price":"0.71","size":"682.74"},{"price":"0.72","size":"582.84"},{"price":"0.73","size":"414.37"},{"price":"0.74","size":"490.67"},{"price":"0.741","size":"5"},{"price":"0.75","size":"820.01"},{"price":"0.76","size":"659.24"},{"price":"0.77","size":"470"},{"price":"0.78","size":"389.97"},{"price":"0.79","size":"385"},{"price":"0.8","size":"385"},{"price":"0.81","size":"484.75"},{"price":"0.82","size":"393"},{"price":"0.83","size":"418.78"},{"price":"0.84","size":"406.56"},{"price":"0.85","size":"406.25"},{"price":"0.86","size":"905.94"},{"price":"0.87","size":"380"},{"price":"0.88","size":"1391.36"},{"price":"0.89","size":"1390"},{"price":"0.9","size":"424.19"},{"price":"0.91","size":"380"},{"price":"0.92","size":"594.2"},{"price":"0.93","size":"464"},{"price":"0.94","size":"695.16"},{"price":"0.95","size":"329.51"},{"price":"0.96","size":"487.78"},{"price":"0.97","size":"908"},{"price":"0.98","size":"1045.53"},{"price":"0.99","size":"1164.24"},{"price":"0.991","size":"948.75"}],"asks":[{"price":"0.999","size":"140"},{"price":"0.998","size":"4.94"}],"hash":"1f9a58da1c206ca2e29affb31ac0f32d407c877f","timestamp":"1768359570661","event_type":"book"}
{"market":"0x5977c69bca02e6cc150855b0faec463b38be463f141ec37ea5c8a1a1e986e0d3","asset_id":"110222991870854778724082971333105906777328061970448875974576460135015541883929","price":"0.991","size":"11.11","fee_rate_bps":"1000","side":"SELL","timestamp":"1768359570711","event_type":"last_trade_price","transaction_hash":"0x60520a6f3ac63679ecd4d69e1a4872692c9933708a7a7dd8865e50fa892d0525"}
{"market":"0x5977c69bca02e6cc150855b0faec463b38be463f141ec37ea5c8a1a1e986e0d3","price_changes":[{"asset_id":"110222991870854778724082971333105906777328061970448875974576460135015541883929","price":"0.998","size":"10.06","side":"BUY","hash":"aa758428248ebffa3f151e19de3a2e97b67757ca","best_bid":"0.998","best_ask":"0.999"},{"asset_id":"103575991306220918671611575108050794364462782362354955892418399227289531345027","price":"0.002","size":"10.06","side":"SELL","hash":"300d249477c33f5e847a4ab06121ab41f26c9afa","best_bid":"0.001","best_ask":"0.002"}],"timestamp":"1768359570756","event_type":"price_change"}
{"market":"0x5977c69bca02e6cc150855b0faec463b38be463f141ec37ea5c8a1a1e986e0d3","price_changes":[{"asset_id":"103575991306220918671611575108050794364462782362354955892418399227289531345027","price":"0.002","size":"0","side":"BUY","hash":"300d249477c33f5e847a4ab06121ab41f26c9afa","best_bid":"0.001","best_ask":"0.002"},{"asset_id":"110222991870854778724082971333105906777328061970448875974576460135015541883929","price":"0.998","size":"0","side":"SELL","hash":"aa758428248ebffa3f151e19de3a2e97b67757ca","best_bid":"0.998","best_ask":"0.999"}],"timestamp":"1768359570756","event_type":"price_change"}
{"market":"0x5977c69bca02e6cc150855b0faec463b38be463f141ec37ea5c8a1a1e986e0d3","asset_id":"103575991306220918671611575108050794364462782362354955892418399227289531345027","bids":[{"price":"0.001","size":"140"}],"asks":[{"price":"0.999","size":"270"},{"price":"0.998","size":"60"},{"price":"0.99","size":"8146.4"},{"price":"0.98","size":"4061.8"},{"price":"0.97","size":"2960.5"},{"price":"0.96","size":"2724.52"},{"price":"0.95","size":"2640"},{"price":"0.94","size":"2505"},{"price":"0.93","size":"2505"},{"price":"0.92","size":"2505"},{"price":"0.91","size":"2505"},{"price":"0.9","size":"2515"},{"price":"0.89","size":"5"},{"price":"0.88","size":"10"},{"price":"0.87","size":"5"},{"price":"0.86","size":"5"},{"price":"0.85","size":"10"},{"price":"0.84","size":"5"},{"price":"0.83","size":"5"},{"price":"0.82","size":"5"},{"price":"0.81","size":"380"},{"price":"0.8","size":"420"},{"price":"0.79","size":"380"},{"price":"0.78","size":"380"},{"price":"0.77","size":"380"},{"price":"0.76","size":"380"},{"price":"0.75","size":"413.5"},{"price":"0.74","size":"380"},{"price":"0.73","size":"380"},{"price":"0.72","size":"403.14"},{"price":"0.71","size":"380"},{"price":"0.7","size":"606.69"},{"price":"0.69","size":"380"},{"price":"0.68","size":"385"},{"price":"0.67","size":"380"},{"price":"0.66","size":"385"},{"price":"0.65","size":"398.93"},{"price":"0.64","size":"394.18"},{"price":"0.63","size":"403.13"},{"price":"0.62","size":"380"},{"price":"0.61","size":"374.09"},{"price":"0.6","size":"39"},{"price":"0.59","size":"5"},{"price":"0.58","size":"28.41"},{"price":"0.57","size":"10"},{"price":"0.56","size":"16"},{"price":"0.55","size":"319.33"},{"price":"0.54","size":"10"},{"price":"0.53","size":"15"},{"price":"0.52","size":"88.05"},{"price":"0.51","size":"5"},{"price":"0.5","size":"25"},{"price":"0.49","size":"107.65"},{"price":"0.48","size":"43"},{"price":"0.47","size":"380"},{"price":"0.46","size":"380"},{"price":"0.45","size":"380"},{"price":"0.44","size":"395"},{"price":"0.43","size":"385"},{"price":"0.42","size":"385"},{"price":"0.41","size":"390"},{"price":"0.4","size":"396"},{"price":"0.39","size":"385"},{"price":"0.38","size":"380"},{"price":"0.37","size":"400.24"},{"price":"0.36","size":"516.18"},{"price":"0.35","size":"530.75"},{"price":"0.34","size":"510.37"},{"price":"0.33","size":"298.95"},{"price":"0.32","size":"490.24"},{"price":"0.31","size":"474.01"},{"price":"0.3","size":"677.5"},{"price":"0.29","size":"682.74"},{"price":"0.28","size":"582.84"},{"price":"0.27","size":"414.37"},{"price":"0.26","size":"490.67"},{"price":"0.259","size":"5"},{"price":"0.25","size":"820.01"},{"price":"0.24","size":"659.24"},{"price":"0.23","size":"470"},{"price":"0.22","size":"389.97"},{"price":"0.21","size":"385"},{"price":"0.2","size":"385"},{"price":"0.19","size":"484.75"},{"price":"0.18","size":"393"},{"price":"0.17","size":"418.78"},{"price":"0.16","size":"406.56"},{"price":"0.15","size":"406.25"},{"price":"0.14","size":"905.94"},{"price":"0.13","size":"380"},{"price":"0.12","size":"1391.36"},{"price":"0.11","size":"1390"},{"price":"0.1","size":"424.19"},{"price":"0.09","size":"380"},{"price":"0.08","size":"594.2"},{"price":"0.07","size":"464"},{"price":"0.06","size":"695.16"},{"price":"0.05","size":"329.51"},{"price":"0.04","size":"487.78"},{"price":"0.03","size":"908"},{"price":"0.02","size":"1045.53"},{"price":"0.01","size":"1164.24"},{"price":"0.009","size":"948.75"},{"price":"0.002","size":"10.06"}],"hash":"300d249477c33f5e847a4ab06121ab41f26c9afa","timestamp":"1768359570756","event_type":"book"}
{"market":"0x5977c69bca02e6cc150855b0faec463b38be463f141ec37ea5c8a1a1e986e0d3","asset_id":"110222991870854778724082971333105906777328061970448875974576460135015541883929","bids":[{"price":"0.001","size":"270"},{"price":"0.002","size":"60"},{"price":"0.01","size":"8146.4"},{"price":"0.02","size":"4061.8"},{"price":"0.03","size":"2960.5"},{"price":"0.04","size":"2724.52"},{"price":"0.05","size":"2640"},{"price":"0.06","size":"2505"},{"price":"0.07","size":"2505"},{"price":"0.08","size":"2505"},{"price":"0.09","size":"2505"},{"price":"0.1","size":"2515"},{"price":"0.11","size":"5"},{"price":"0.12","size":"10"},{"price":"0.13","size":"5"},{"price":"0.14","size":"5"},{"price":"0.15","size":"10"},{"price":"0.16","size":"5"},{"price":"0.17","size":"5"},{"price":"0.18","size":"5"},{"price":"0.19","size":"380"},{"price":"0.2","size":"420"},{"price":"0.21","size":"380"},{"price":"0.22","size":"380"},{"price":"0.23","size":"380"},{"price":"0.24","size":"380"},{"price":"0.25","size":"413.5"},{"price":"0.26","size":"380"},{"price":"0.27","size":"380"},{"price":"0.28","size":"403.14"},{"price":"0.29","size":"380"},{"price":"0.3","size":"606.69"},{"price":"0.31","size":"380"},{"price":"0.32","size":"385"},{"price":"0.33","size":"380"},{"price":"0.34","size":"385"},{"price":"0.35","size":"398.93"},{"price":"0.36","size":"394.18"},{"price":"0.37","size":"403.13"},{"price":"0.38","size":"380"},{"price":"0.39","size":"374.09"},{"price":"0.4","size":"39"},{"price":"0.41","size":"5"},{"price":"0.42","size":"28.41"},{"price":"0.43","size":"10"},{"price":"0.44","size":"16"},{"price":"0.45","size":"319.33"},{"price":"0.46","size":"10"},{"price":"0.47","size":"15"},{"price":"0.48","size":"88.05"},{"price":"0.49","size":"5"},{"price":"0.5","size":"25"},{"price":"0.51","size":"107.65"},{"price":"0.52","size":"43"},{"price":"0.53","size":"380"},{"price":"0.54","size":"380"},{"price":"0.55","size":"380"},{"price":"0.56","size":"395"},{"price":"0.57","size":"385"},{"price":"0.58","size":"385"},{"price":"0.59","size":"390"},{"price":"0.6","size":"396"},{"price":"0.61","size":"385"},{"price":"0.62","size":"380"},{"price":"0.63","size":"400.24"},{"price":"0.64","size":"516.18"},{"price":"0.65","size":"530.75"},{"price":"0.66","size":"510.37"},{"price":"0.67","size":"298.95"},{"price":"0.68","size":"490.24"},{"price":"0.69","size":"474.01"},{"price":"0.7","size":"677.5"},{"price":"0.71","size":"682.74"},{"price":"0.72","size":"582.84"},{"price":"0.73","size":"414.37"},{"price":"0.74","size":"490.67"},{"price":"0.741","size":"5"},{"price":"0.75","size":"820.01"},{"price":"0.76","size":"659.24"},{"price":"0.77","size":"470"},{"price":"0.78","size":"389.97"},{"price":"0.79","size":"385"},{"price":"0.8","size":"385"},{"price":"0.81","size":"484.75"},{"price":"0.82","size":"393"},{"price":"0.83","size":"418.78"},{"price":"0.84","size":"406.56"},{"price":"0.85","size":"406.25"},{"price":"0.86","size":"905.94"},{"price":"0.87","size":"380"},{"price":"0.88","size":"1391.36"},{"price":"0.89","size":"1390"},{"price":"0.9","size":"424.19"},{"price":"0.91","size":"380"},{"price":"0.92","size":"594.2"},{"price":"0.93","size":"464"},{"price":"0.94","size":"695.16"},{"price":"0.95","size":"329.51"},{"price":"0.96","size":"487.78"},{"price":"0.97","size":"908"},{"price":"0.98","size":"1045.53"},{"price":"0.99","size":"1164.24"},{"price":"0.991","size":"948.75"},{"price":"0.998","size":"10.06"}],"asks":[{"price":"0.999","size":"140"}],"hash":"aa758428248ebffa3f151e19de3a2e97b67757ca","timestamp":"1768359570756","event_type":"book"}
{"market":"0x5977c69bca02e6cc150855b0faec463b38be463f141ec37ea5c8a1a1e986e0d3","asset_id":"110222991870854778724082971333105906777328061970448875974576460135015541883929","price":"0.998","size":"4.94","fee_rate_bps":"1000","side":"BUY","timestamp":"1768359570784","event_type":"last_trade_price","transaction_hash":"0x42c732851383cd2e492ef047bb1f657c82f46a5057c7ecf3c13e6b5a4f444ffc"}
{"market":"0x5977c69bca02e6cc150855b0faec463b38be463f141ec37ea5c8a1a1e986e0d3","price_changes":[{"asset_id":"110222991870854778724082971333105906777328061970448875974576460135015541883929","price":"0.93","size":"454","side":"BUY","hash":"df6dc657fa2bdbc6df9162174f338de43fd7a3aa","best_bid":"0.998","best_ask":"0.999"},{"asset_id":"103575991306220918671611575108050794364462782362354955892418399227289531345027","price":"0.07","size":"454","side":"SELL","hash":"53c433c41e50f325167d34d51e95133b02b6427c","best_bid":"0.001","best_ask":"0.002"}],"timestamp":"1768359570789","event_type":"price_change"}
{"market":"0x5977c69bca02e6cc150855b0faec463b38be463f141ec37ea5c8a1a1e986e0d3","price_changes":[{"asset_id":"110222991870854778724082971333105906777328061970448875974576460135015541883929","price":"0.98","size":"1055.53","side":"BUY","hash":"36d98d8952d86a1153f4180ee6dfddd15a6d1da2","best_bid":"0.998","best_ask":"0.999"},{"asset_id":"103575991306220918671611575108050794364462782362354955892418399227289531345027","price":"0.02","size":"1055.53","side":"SELL","hash":"d2facba481b2f4350384c5e9efc5cd88b934bfa7","best_bid":"0.001","best_ask":"0.002"}],"timestamp":"1768359570794","event_type":"price_change"}
{"market":"0x5977c69bca02e6cc150855b0faec463b38be463f141ec37ea5c8a1a1e986e0d3","price_changes":[{"asset_id":"110222991870854778724082971333105906777328061970448875974576460135015541883929","price":"0.99","size":"1264.24","side":"BUY","hash":"16479be4bd1c274559a02865abf07000ed9e3688","best_bid":"0.998","best_ask":"0.999"},{"asset_id":"103575991306220918671611575108050794364462782362354955892418399227289531345027","price":"0.01","size":"1264.24","side":"SELL","hash":"34be3aad7a0b0d4b108a1d2fadd7a06583fa7a5f","best_bid":"0.001","best_ask":"0.002"}],"timestamp":"1768359570844","event_type":"price_change"}
{"market":"0x5977c69bca02e6cc150855b0faec463b38be463f141ec37ea5c8a1a1e986e0d3","price_changes":[{"asset_id":"110222991870854778724082971333105906777328061970448875974576460135015541883929","price":"0.97","size":"913","side":"BUY","hash":"d30c3a432e6f6d644045953727c4acee3553a87b","best_bid":"0.998","best_ask":"0.999"},{"asset_id":"103575991306220918671611575108050794364462782362354955892418399227289531345027","price":"0.03","size":"913","side":"SELL","hash":"cba17381e14da953f8d6e8e3f9b7a7d08d2290b5","best_bid":"0.001","best_ask":"0.002"}],"timestamp":"1768359570864","event_type":"price_change"}
{"market":"0x5977c69bca02e6cc150855b0faec463b38be463f141ec37ea5c8a1a1e986e0d3","price_changes":[{"asset_id":"103575991306220918671611575108050794364462782362354955892418399227289531345027","price":"0.05","size":"359.51","side":"SELL","hash":"95795f367b3377e79e705d4737c0473c02c35c35","best_bid":"0.001","best_ask":"0.002"},{"asset_id":"110222991870854778724082971333105906777328061970448875974576460135015541883929","price":"0.95","size":"359.51","side":"BUY","hash":"53f6e4db887bbc91ad41af976ffe2c14b837f274","best_bid":"0.998","best_ask":"0.999"}],"timestamp":"1768359570889","event_type":"price_change"}
{"market":"0x5977c69bca02e6cc150855b0faec463b38be463f141ec37ea5c8a1a1e986e0d3","price_changes":[{"asset_id":"110222991870854778724082971333105906777328061970448875974576460135015541883929","price":"0.97","size":"908","side":"BUY","hash":"543fe236935efcabb308d0a9a0f6ce6b3c4c3b52","best_bid":"0.998","best_ask":"0.999"},{"asset_id":"103575991306220918671611575108050794364462782362354955892418399227289531345027","price":"0.03","size":"908","side":"SELL","hash":"da7e6088bf92ddd44ce5491926d85ff6514ded83","best_bid":"0.001","best_ask":"0.002"}],"timestamp":"1768359570893","event_type":"price_change"}
{"market":"0x5977c69bca02e6cc150855b0faec463b38be463f141ec37ea5c8a1a1e986e0d3","price_changes":[{"asset_id":"110222991870854778724082971333105906777328061970448875974576460135015541883929","price":"0.979","size":"700","side":"BUY","hash":"9f300d2454f216bc17faab28b9948509a5865c35","best_bid":"0.998","best_ask":"0.999"},{"asset_id":"103575991306220918671611575108050794364462782362354955892418399227289531345027","price":"0.021","size":"700","side":"SELL","hash":"991cf0202e5d5963700bdafbfc8ee05bd7e0aada","best_bid":"0.001","best_ask":"0.002"}],"timestamp":"1768359570898","event_type":"price_change"}
{"market":"0x5977c69bca02e6cc150855b0faec463b38be463f141ec37ea5c8a1a1e986e0d3","price_changes":[{"asset_id":"110222991870854778724082971333105906777328061970448875974576460135015541883929","price":"0.94","size":"802.08","side":"BUY","hash":"4a0a5c0c1dc71a39194aab4383d1d0287a702b78","best_bid":"0.998","best_ask":"0.999"},{"asset_id":"103575991306220918671611575108050794364462782362354955892418399227289531345027","price":"0.06","size":"802.08","side":"SELL","hash":"d9febd639a52e1c45f7848311801daa3af8a9946","best_bid":"0.001","best_ask":"0.002"}],"timestamp":"1768359570900","event_type":"price_change"}
{"market":"0x5977c69bca02e6cc150855b0faec463b38be463f141ec37ea5c8a1a1e986e0d3","price_changes":[{"asset_id":"110222991870854778724082971333105906777328061970448875974576460135015541883929","price":"0.96","size":"594.7","side":"BUY","hash":"9f04eb6f972290dea58106d673f9f0d11eb7f60f","best_bid":"0.998","best_ask":"0.999"},{"asset_id":"103575991306220918671611575108050794364462782362354955892418399227289531345027","price":"0.04","size":"594.7","side":"SELL","hash":"4a192fd0cccfcbdd9d0854ec1cb31605ed4091ae","best_bid":"0.001","best_ask":"0.002"}],"timestamp":"1768359570902","event_type":"price_change"}
{"market":"0x5977c69bca02e6cc150855b0faec463b38be463f141ec37ea5c8a1a1e986e0d3","price_changes":[{"asset_id":"110222991870854778724082971333105906777328061970448875974576460135015541883929","price":"0.92","size":"701.12","side":"BUY","hash":"4abd56777162e2cbdeaa94a8deb451b8cd3c1095","best_bid":"0.998","best_ask":"0.999"},{"asset_id":"103575991306220918671611575108050794364462782362354955892418399227289531345027","price":"0.08","size":"701.12","side":"SELL","hash":"435023a53d3bd10bf38f179afdfb8d2141149465","best_bid":"0.001","best_ask":"0.002"}],"timestamp":"1768359570903","event_type":"price_change"}
{"market":"0x5977c69bca02e6cc150855b0faec463b38be463f141ec37ea5c8a1a1e986e0d3","price_changes":[{"asset_id":"110222991870854778724082971333105906777328061970448875974576460135015541883929","price":"0.93","size":"560.92","side":"BUY","hash":"da43831088ecf2cd057b6f42ca365b1706471df0","best_bid":"0.998","best_ask":"0.999"},{"asset_id":"103575991306220918671611575108050794364462782362354955892418399227289531345027","price":"0.07","size":"560.92","side":"SELL","hash":"6d2e8fbc4841023fc102b2787b009cd1026aa5a7","best_bid":"0.001","best_ask":"0.002"}],"timestamp":"1768359570906","event_type":"price_change"}
{"market":"0x5977c69bca02e6cc150855b0faec463b38be463f141ec37ea5c8a1a1e986e0d3","price_changes":[{"asset_id":"110222991870854778724082971333105906777328061970448875974576460135015541883929","price":"0.988","size":"5","side":"BUY","hash":"c5b464f5cf4ad67ce754ffd5c6d42b41df88ee00","best_bid":"0.998","best_ask":"0.999"},{"asset_id":"103575991306220918671611575108050794364462782362354955892418399227289531345027","price":"0.012","size":"5","side":"SELL","hash":"498df46d6b7eb45c67dca9214339fb7c5e3e1f18","best_bid":"0.001","best_ask":"0.002"}],"timestamp":"1768359570936","event_type":"price_change"}
{"market":"0x5977c69bca02e6cc150855b0faec463b38be463f141ec37ea5c8a1a1e986e0d3","price_changes":[{"asset_id":"110222991870854778724082971333105906777328061970448875974576460135015541883929","price":"0.998","size":"5.06","side":"BUY","hash":"7f9ef5557be0acf041821edfda9ffd9b7204e60c","best_bid":"0.998","best_ask":"0.999"},{"asset_id":"103575991306220918671611575108050794364462782362354955892418399227289531345027","price":"0.002","size":"5.06","side":"SELL","hash":"b6821c1b7975ec1835029124cfa27e4e3ed70c8f","best_bid":"0.001","best_ask":"0.002"}],"timestamp":"1768359571050","event_type":"price_change"}
{"market":"0x5977c69bca02e6cc150855b0faec463b38be463f141ec37ea5c8a1a1e986e0d3","asset_id":"103575991306220918671611575108050794364462782362354955892418399227289531345027","bids":[{"price":"0.001","size":"140"}],"asks":[{"price":"0.999","size":"270"},{"price":"0.998","size":"60"},{"price":"0.99","size":"8146.4"},{"price":"0.98","size":"4061.8"},{"price":"0.97","size":"2960.5"},{"price":"0.96","size":"2724.52"},{"price":"0.95","size":"2640"},{"price":"0.94","size":"2505"},{"price":"0.93","size":"2505"},{"price":"0.92","size":"2505"},{"price":"0.91","size":"2505"},{"price":"0.9","size":"2515"},{"price":"0.89","size":"5"},{"price":"0.88","size":"10"},{"price":"0.87","size":"5"},{"price":"0.86","size":"5"},{"price":"0.85","size":"10"},{"price":"0.84","size":"5"},{"price":"0.83","size":"5"},{"price":"0.82","size":"5"},{"price":"0.81","size":"380"},{"price":"0.8","size":"420"},{"price":"0.79","size":"380"},{"price":"0.78","size":"380"},{"price":"0.77","size":"380"},{"price":"0.76","size":"380"},{"price":"0.75","size":"413.5"},{"price":"0.74","size":"380"},{"price":"0.73","size":"380"},{"price":"0.72","size":"403.14"},{"price":"0.71","size":"380"},{"price":"0.7","size":"606.69"},{"price":"0.69","size":"380"},{"price":"0.68","size":"385"},{"price":"0.67","size":"380"},{"price":"0.66","size":"385"},{"price":"0.65","size":"398.93"},{"price":"0.64","size":"394.18"},{"price":"0.63","size":"403.13"},{"price":"0.62","size":"380"},{"price":"0.61","size":"374.09"},{"price":"0.6","size":"39"},{"price":"0.59","size":"5"},{"price":"0.58","size":"28.41"},{"price":"0.57","size":"10"},{"price":"0.56","size":"16"},{"price":"0.55","size":"319.33"},{"price":"0.54","size":"10"},{"price":"0.53","size":"15"},{"price":"0.52","size":"88.05"},{"price":"0.51","size":"5"},{"price":"0.5","size":"25"},{"price":"0.49","size":"107.65"},{"price":"0.48","size":"43"},{"price":"0.47","size":"380"},{"price":"0.46","size":"380"},{"price":"0.45","size":"380"},{"price":"0.44","size":"395"},{"price":"0.43","size":"385"},{"price":"0.42","size":"385"},{"price":"0.41","size":"390"},{"price":"0.4","size":"396"},{"price":"0.39","size":"385"},{"price":"0.38","size":"380"},{"price":"0.37","size":"400.24"},{"price":"0.36","size":"516.18"},{"price":"0.35","size":"530.75"},{"price":"0.34","size":"510.37"},{"price":"0.33","size":"298.95"},{"price":"0.32","size":"490.24"},{"price":"0.31","size":"474.01"},{"price":"0.3","size":"677.5"},{"price":"0.29","size":"682.74"},{"price":"0.28","size":"582.84"},{"price":"0.27","size":"414.37"},{"price":"0.26","size":"490.67"},{"price":"0.259","size":"5"},{"price":"0.25","size":"820.01"},{"price":"0.24","size":"659.24"},{"price":"0.23","size":"470"},{"price":"0.22","size":"389.97"},{"price":"0.21","size":"385"},{"price":"0.2","size":"385"},{"price":"0.19","size":"484.75"},{"price":"0.18","size":"393"},{"price":"0.17","size":"418.78"},{"price":"0.16","size":"406.56"},{"price":"0.15","size":"406.25"},{"price":"0.14","size":"905.94"},{"price":"0.13","size":"380"},{"price":"0.12","size":"1391.36"},{"price":"0.11","size":"1390"},{"price":"0.1","size":"424.19"},{"price":"0.09","size":"380"},{"price":"0.08","size":"701.12"},{"price":"0.07","size":"560.92"},{"price":"0.06","size":"802.08"},{"price":"0.05","size":"359.51"},{"price":"0.04","size":"594.7"},{"price":"0.03","size":"908"},{"price":"0.021","size":"700"},{"price":"0.02","size":"1055.53"},{"price":"0.012","size":"5"},{"price":"0.01","size":"1264.24"},{"price":"0.009","size":"948.75"},{"price":"0.002","size":"5.06"}],"hash":"b6821c1b7975ec1835029124cfa27e4e3ed70c8f","timestamp":"1768359571050","event_type":"book"}
{"market":"0x5977c69bca02e6cc150855b0faec463b38be463f141ec37ea5c8a1a1e986e0d3","asset_id":"110222991870854778724082971333105906777328061970448875974576460135015541883929","bids":[{"price":"0.001","size":"270"},{"price":"0.002","size":"60"},{"price":"0.01","size":"8146.4"},{"price":"0.02","size":"4061.8"},{"price":"0.03","size":"2960.5"},{"price":"0.04","size":"2724.52"},{"price":"0.05","size":"2640"},{"price":"0.06","size":"2505"},{"price":"0.07","size":"2505"},{"price":"0.08","size":"2505"},{"price":"0.09","size":"2505"},{"price":"0.1","size":"2515"},{"price":"0.11","size":"5"},{"price":"0.12","size":"10"},{"price":"0.13","size":"5"},{"price":"0.14","size":"5"},{"price":"0.15","size":"10"},{"price":"0.16","size":"5"},{"price":"0.17","size":"5"},{"price":"0.18","size":"5"},{"price":"0.19","size":"380"},{"price":"0.2","size":"420"},{"price":"0.21","size":"380"},{"price":"0.22","size":"380"},{"price":"0.23","size":"380"},{"price":"0.24","size":"380"},{"price":"0.25","size":"413.5"},{"price":"0.26","size":"380"},{"price":"0.27","size":"380"},{"price":"0.28","size":"403.14"},{"price":"0.29","size":"380"},{"price":"0.3","size":"606.69"},{"price":"0.31","size":"380"},{"price":"0.32","size":"385"},{"price":"0.33","size":"380"},{"price":"0.34","size":"385"},{"price":"0.35","size":"398.93"},{"price":"0.36","size":"394.18"},{"price":"0.37","size":"403.13"},{"price":"0.38","size":"380"},{"price":"0.39","size":"374.09"},{"price":"0.4","size":"39"},{"price":"0.41","size":"5"},{"price":"0.42","size":"28.41"},{"price":"0.43","size":"10"},{"price":"0.44","size":"16"},{"price":"0.45","size":"319.33"},{"price":"0.46","size":"10"},{"price":"0.47","size":"15"},{"price":"0.48","size":"88.05"},{"price":"0.49","size":"5"},{"price":"0.5","size":"25"},{"price":"0.51","size":"107.65"},{"price":"0.52","size":"43"},{"price":"0.53","size":"380"},{"price":"0.54","size":"380"},{"price":"0.55","size":"380"},{"price":"0.56","size":"395"},{"price":"0.57","size":"385"},{"price":"0.58","size":"385"},{"price":"0.59","size":"390"},{"price":"0.6","size":"396"},{"price":"0.61","size":"385"},{"price":"0.62","size":"380"},{"price":"0.63","size":"400.24"},{"price":"0.64","size":"516.18"},{"price":"0.65","size":"530.75"},{"price":"0.66","size":"510.37"},{"price":"0.67","size":"298.95"},{"price":"0.68","size":"490.24"},{"price":"0.69","size":"474.01"},{"price":"0.7","size":"677.5"},{"price":"0.71","size":"682.74"},{"price":"0.72","size":"582.84"},{"price":"0.73","size":"414.37"},{"price":"0.74","size":"490.67"},{"price":"0.741","size":"5"},{"price":"0.75","size":"820.01"},{"price":"0.76","size":"659.24"},{"price":"0.77","size":"470"},{"price":"0.78","size":"389.97"},{"price":"0.79","size":"385"},{"price":"0.8","size":"385"},{"price":"0.81","size":"484.75"},{"price":"0.82","size":"393"},{"price":"0.83","size":"418.78"},{"price":"0.84","size":"406.56"},{"price":"0.85","size":"406.25"},{"price":"0.86","size":"905.94"},{"price":"0.87","size":"380"},{"price":"0.88","size":"1391.36"},{"price":"0.89","size":"1390"},{"price":"0.9","size":"424.19"},{"price":"0.91","size":"380"},{"price":"0.92","size":"701.12"},{"price":"0.93","size":"560.92"},{"price":"0.94","size":"802.08"},{"price":"0.95","size":"359.51"},{"price":"0.96","size":"594.7"},{"price":"0.97","size":"908"},{"price":"0.979","size":"700"},{"price":"0.98","size":"1055.53"},{"price":"0.988","size":"5"},{"price":"0.99","size":"1264.24"},{"price":"0.991","size":"948.75"},{"price":"0.998","size":"5.06"}],"asks":[{"price":"0.999","size":"140"}],"hash":"7f9ef5557be0acf041821edfda9ffd9b7204e60c","timestamp":"1768359571050","event_type":"book"}
{"market":"0x5977c69bca02e6cc150855b0faec463b38be463f141ec37ea5c8a1a1e986e0d3","asset_id":"103575991306220918671611575108050794364462782362354955892418399227289531345027","price":"0.002","size":"5","fee_rate_bps":"1000","side":"BUY","timestamp":"1768359571079","event_type":"last_trade_price","transaction_hash":"0x83a7b2b870f9141751324e104330a4cd2a4e59d366a2a3e49d33b337cf1f3d63"}
{"market":"0x5977c69bca02e6cc150855b0faec463b38be463f141ec37ea5c8a1a1e986e0d3","price_changes":[{"asset_id":"110222991870854778724082971333105906777328061970448875974576460135015541883929","price":"0.988","size":"0","side":"BUY","hash":"73f13d383b1fcd20fa773dbb5c56ae2477b49100","best_bid":"0.998","best_ask":"0.999"},{"asset_id":"103575991306220918671611575108050794364462782362354955892418399227289531345027","price":"0.012","size":"0","side":"SELL","hash":"b76992d2ac50236c84c8942bf2ade7b8afc3c32d","best_bid":"0.001","best_ask":"0.002"}],"timestamp":"1768359571173","event_type":"price_change"}
{"market":"0x5977c69bca02e6cc150855b0faec463b38be463f141ec37ea5c8a1a1e986e0d3","price_changes":[{"asset_id":"103575991306220918671611575108050794364462782362354955892418399227289531345027","price":"0.001","size":"130","side":"BUY","hash":"fb7bdac1ea54ce903f205751d4474801ec763dc7","best_bid":"0.001","best_ask":"0.002"},{"asset_id":"110222991870854778724082971333105906777328061970448875974576460135015541883929","price":"0.999","size":"130","side":"SELL","hash":"bf4f769661bb774572e70336c5e696408e30031f","best_bid":"0.998","best_ask":"0.999"}],"timestamp":"1768359571617","event_type":"price_change"}
{"market":"0x5977c69bca02e6cc150855b0faec463b38be463f141ec37ea5c8a1a1e986e0d3","asset_id":"103575991306220918671611575108050794364462782362354955892418399227289531345027","bids":[{"price":"0.001","size":"130"}],"asks":[{"price":"0.999","size":"270"},{"price":"0.998","size":"60"},{"price":"0.99","size":"8146.4"},{"price":"0.98","size":"4061.8"},{"price":"0.97","size":"2960.5"},{"price":"0.96","size":"2724.52"},{"price":"0.95","size":"2640"},{"price":"0.94","size":"2505"},{"price":"0.93","size":"2505"},{"price":"0.92","size":"2505"},{"price":"0.91","size":"2505"},{"price":"0.9","size":"2515"},{"price":"0.89","size":"5"},{"price":"0.88","size":"10"},{"price":"0.87","size":"5"},{"price":"0.86","size":"5"},{"price":"0.85","size":"10"},{"price":"0.84","size":"5"},{"price":"0.83","size":"5"},{"price":"0.82","size":"5"},{"price":"0.81","size":"380"},{"price":"0.8","size":"420"},{"price":"0.79","size":"380"},{"price":"0.78","size":"380"},{"price":"0.77","size":"380"},{"price":"0.76","size":"380"},{"price":"0.75","size":"413.5"},{"price":"0.74","size":"380"},{"price":"0.73","size":"380"},{"price":"0.72","size":"403.14"},{"price":"0.71","size":"380"},{"price":"0.7","size":"606.69"},{"price":"0.69","size":"380"},{"price":"0.68","size":"385"},{"price":"0.67","size":"380"},{"price":"0.66","size":"385"},{"price":"0.65","size":"398.93"},{"price":"0.64","size":"394.18"},{"price":"0.63","size":"403.13"},{"price":"0.62","size":"380"},{"price":"0.61","size":"374.09"},{"price":"0.6","size":"39"},{"price":"0.59","size":"5"},{"price":"0.58","size":"28.41"},{"price":"0.57","size":"10"},{"price":"0.56","size":"16"},{"price":"0.55","size":"319.33"},{"price":"0.54","size":"10"},{"price":"0.53","size":"15"},{"price":"0.52","size":"88.05"},{"price":"0.51","size":"5"},{"price":"0.5","size":"25"},{"price":"0.49","size":"107.65"},{"price":"0.48","size":"43"},{"price":"0.47","size":"380"},{"price":"0.46","size":"380"},{"price":"0.45","size":"380"},{"price":"0.44","size":"395"},{"price":"0.43","size":"385"},{"price":"0.42","size":"385"},{"price":"0.41","size":"390"},{"price":"0.4","size":"396"},{"price":"0.39","size":"385"},{"price":"0.38","size":"380"},{"price":"0.37","size":"400.24"},{"price":"0.36","size":"516.18"},{"price":"0.35","size":"530.75"},{"price":"0.34","size":"510.37"},{"price":"0.33","size":"298.95"},{"price":"0.32","size":"490.24"},{"price":"0.31","size":"474.01"},{"price":"0.3","size":"677.5"},{"price":"0.29","size":"682.74"},{"price":"0.28","size":"582.84"},{"price":"0.27","size":"414.37"},{"price":"0.26","size":"490.67"},{"price":"0.259","size":"5"},{"price":"0.25","size":"820.01"},{"price":"0.24","size":"659.24"},{"price":"0.23","size":"470"},{"price":"0.22","size":"389.97"},{"price":"0.21","size":"385"},{"price":"0.2","size":"385"},{"price":"0.19","size":"484.75"},{"price":"0.18","size":"393"},{"price":"0.17","size":"418.78"},{"price":"0.16","size":"406.56"},{"price":"0.15","size":"406.25"},{"price":"0.14","size":"905.94"},{"price":"0.13","size":"380"},{"price":"0.12","size":"1391.36"},{"price":"0.11","size":"1390"},{"price":"0.1","size":"424.19"},{"price":"0.09","size":"380"},{"price":"0.08","size":"701.12"},{"price":"0.07","size":"560.92"},{"price":"0.06","size":"802.08"},{"price":"0.05","size":"359.51"},{"price":"0.04","size":"594.7"},{"price":"0.03","size":"908"},{"price":"0.021","size":"700"},{"price":"0.02","size":"1055.53"},{"price":"0.01","size":"1264.24"},{"price":"0.009","size":"948.75"},{"price":"0.002","size":"5.06"}],"hash":"fb7bdac1ea54ce903f205751d4474801ec763dc7","timestamp":"1768359571617","event_type":"book"}
{"market":"0x5977c69bca02e6cc150855b0faec463b38be463f141ec37ea5c8a1a1e986e0d3","asset_id":"110222991870854778724082971333105906777328061970448875974576460135015541883929","bids":[{"price":"0.001","size":"270"},{"price":"0.002","size":"60"},{"price":"0.01","size":"8146.4"},{"price":"0.02","size":"4061.8"},{"price":"0.03","size":"2960.5"},{"price":"0.04","size":"2724.52"},{"price":"0.05","size":"2640"},{"price":"0.06","size":"2505"},{"price":"0.07","size":"2505"},{"price":"0.08","size":"2505"},{"price":"0.09","size":"2505"},{"price":"0.1","size":"2515"},{"price":"0.11","size":"5"},{"price":"0.12","size":"10"},{"price":"0.13","size":"5"},{"price":"0.14","size":"5"},{"price":"0.15","size":"10"},{"price":"0.16","size":"5"},{"price":"0.17","size":"5"},{"price":"0.18","size":"5"},{"price":"0.19","size":"380"},{"price":"0.2","size":"420"},{"price":"0.21","size":"380"},{"price":"0.22","size":"380"},{"price":"0.23","size":"380"},{"price":"0.24","size":"380"},{"price":"0.25","size":"413.5"},{"price":"0.26","size":"380"},{"price":"0.27","size":"380"},{"price":"0.28","size":"403.14"},{"price":"0.29","size":"380"},{"price":"0.3","size":"606.69"},{"price":"0.31","size":"380"},{"price":"0.32","size":"385"},{"price":"0.33","size":"380"},{"price":"0.34","size":"385"},{"price":"0.35","size":"398.93"},{"price":"0.36","size":"394.18"},{"price":"0.37","size":"403.13"},{"price":"0.38","size":"380"},{"price":"0.39","size":"374.09"},{"price":"0.4","size":"39"},{"price":"0.41","size":"5"},{"price":"0.42","size":"28.41"},{"price":"0.43","size":"10"},{"price":"0.44","size":"16"},{"price":"0.45","size":"319.33"},{"price":"0.46","size":"10"},{"price":"0.47","size":"15"},{"price":"0.48","size":"88.05"},{"price":"0.49","size":"5"},{"price":"0.5","size":"25"},{"price":"0.51","size":"107.65"},{"price":"0.52","size":"43"},{"price":"0.53","size":"380"},{"price":"0.54","size":"380"},{"price":"0.55","size":"380"},{"price":"0.56","size":"395"},{"price":"0.57","size":"385"},{"price":"0.58","size":"385"},{"price":"0.59","size":"390"},{"price":"0.6","size":"396"},{"price":"0.61","size":"385"},{"price":"0.62","size":"380"},{"price":"0.63","size":"400.24"},{"price":"0.64","size":"516.18"},{"price":"0.65","size":"530.75"},{"price":"0.66","size":"510.37"},{"price":"0.67","size":"298.95"},{"price":"0.68","size":"490.24"},{"price":"0.69","size":"474.01"},{"price":"0.7","size":"677.5"},{"price":"0.71","size":"682.74"},{"price":"0.72","size":"582.84"},{"price":"0.73","size":"414.37"},{"price":"0.74","size":"490.67"},{"price":"0.741","size":"5"},{"price":"0.75","size":"820.01"},{"price":"0.76","size":"659.24"},{"price":"0.77","size":"470"},{"price":"0.78","size":"389.97"},{"price":"0.79","size":"385"},{"price":"0.8","size":"385"},{"price":"0.81","size":"484.75"},{"price":"0.82","size":"393"},{"price":"0.83","size":"418.78"},{"price":"0.84","size":"406.56"},{"price":"0.85","size":"406.25"},{"price":"0.86","size":"905.94"},{"price":"0.87","size":"380"},{"price":"0.88","size":"1391.36"},{"price":"0.89","size":"1390"},{"price":"0.9","size":"424.19"},{"price":"0.91","size":"380"},{"price":"0.92","size":"701.12"},{"price":"0.93","size":"560.92"},{"price":"0.94","size":"802.08"},{"price":"0.95","size":"359.51"},{"price":"0.96","size":"594.7"},{"price":"0.97","size":"908"},{"price":"0.979","size":"700"},{"price":"0.98","size":"1055.53"},{"price":"0.99","size":"1264.24"},{"price":"0.991","size":"948.75"},{"price":"0.998","size":"5.06"}],"asks":[{"price":"0.999","size":"130"}],"hash":"bf4f769661bb774572e70336c5e696408e30031f","timestamp":"1768359571617","event_type":"book"}
{"market":"0x5977c69bca02e6cc150855b0faec463b38be463f141ec37ea5c8a1a1e986e0d3","price_changes":[{"asset_id":"110222991870854778724082971333105906777328061970448875974576460135015541883929","price":"0.84","size":"396.56","side":"BUY","hash":"b9134c0c62fcf43dddfbe06eae7382b1fc8ad354","best_bid":"0.998","best_ask":"0.999"},{"asset_id":"103575991306220918671611575108050794364462782362354955892418399227289531345027","price":"0.16","size":"396.56","side":"SELL","hash":"214ef177b76cbfe00c7c8c0c68ecc5fbe6d313e9","best_bid":"0.001","best_ask":"0.002"}],"timestamp":"1768359571642","event_type":"price_change"}
{"market":"0x5977c69bca02e6cc150855b0faec463b38be463f141ec37ea5c8a1a1e986e0d3","asset_id":"110222991870854778724082971333105906777328061970448875974576460135015541883929","price":"0.999","size":"10","fee_rate_bps":"1000","side":"BUY","timestamp":"1768359571647","event_type":"last_trade_price","transaction_hash":"0x79e15badfec399377520a1ea14d018de25346249c9829176468183770a28bcca"}
{"market":"0x5977c69bca02e6cc150855b0faec463b38be463f141ec37ea5c8a1a1e986e0d3","price_changes":[{"asset_id":"110222991870854778724082971333105906777328061970448875974576460135015541883929","price":"0.84","size":"406.56","side":"BUY","hash":"7836628a5d6618da442210cc69937371647a5ed0","best_bid":"0.998","best_ask":"0.999"},{"asset_id":"103575991306220918671611575108050794364462782362354955892418399227289531345027","price":"0.16","size":"406.56","side":"SELL","hash":"6688a5c9fa6f262ef99ae874d7dc35140efead45","best_bid":"0.001","best_ask":"0.002"}],"timestamp":"1768359571665","event_type":"price_change"}
{"market":"0x5977c69bca02e6cc150855b0faec463b38be463f141ec37ea5c8a1a1e986e0d3","price_changes":[{"asset_id":"110222991870854778724082971333105906777328061970448875974576460135015541883929","price":"0.99","size":"1256.24","side":"BUY","hash":"2d0adbebdc9e038ac49a1cba1d7d9f80f2aa91d2","best_bid":"0.998","best_ask":"0.999"},{"asset_id":"103575991306220918671611575108050794364462782362354955892418399227289531345027","price":"0.01","size":"1256.24","side":"SELL","hash":"3df2281519e9982b4e23ab0f83ed759d53194582","best_bid":"0.001","best_ask":"0.002"}],"timestamp":"1768359572001","event_type":"price_change"}
{"market":"0x5977c69bca02e6cc150855b0faec463b38be463f141ec37ea5c8a1a1e986e0d3","price_changes":[{"asset_id":"103575991306220918671611575108050794364462782362354955892418399227289531345027","price":"0.001","size":"123.94","side":"BUY","hash":"0420c254567e9dca7defb1c59168c865c7986f9c","best_bid":"0.001","best_ask":"0.002"},{"asset_id":"110222991870854778724082971333105906777328061970448875974576460135015541883929","price":"0.999","size":"123.94","side":"SELL","hash":"384968a5f1fd9eb7a5748f32fe7e0727482ae4b9","best_bid":"0.998","best_ask":"0.999"}],"timestamp":"1768359572237","event_type":"price_change"}
{"market":"0x5977c69bca02e6cc150855b0faec463b38be463f141ec37ea5c8a1a1e986e0d3","asset_id":"103575991306220918671611575108050794364462782362354955892418399227289531345027","bids":[{"price":"0.001","size":"123.94"}],"asks":[{"price":"0.999","size":"270"},{"price":"0.998","size":"60"},{"price":"0.99","size":"8146.4"},{"price":"0.98","size":"4061.8"},{"price":"0.97","size":"2960.5"},{"price":"0.96","size":"2724.52"},{"price":"0.95","size":"2640"},{"price":"0.94","size":"2505"},{"price":"0.93","size":"2505"},{"price":"0.92","size":"2505"},{"price":"0.91","size":"2505"},{"price":"0.9","size":"2515"},{"price":"0.89","size":"5"},{"price":"0.88","size":"10"},{"price":"0.87","size":"5"},{"price":"0.86","size":"5"},{"price":"0.85","size":"10"},{"price":"0.84","size":"5"},{"price":"0.83","size":"5"},{"price":"0.82","size":"5"},{"price":"0.81","size":"380"},{"price":"0.8","size":"420"},{"price":"0.79","size":"380"},{"price":"0.78","size":"380"},{"price":"0.77","size":"380"},{"price":"0.76","size":"380"},{"price":"0.75","size":"413.5"},{"price":"0.74","size":"380"},{"price":"0.73","size":"380"},{"price":"0.72","size":"403.14"},{"price":"0.71","size":"380"},{"price":"0.7","size":"606.69"},{"price":"0.69","size":"380"},{"price":"0.68","size":"385"},{"price":"0.67","size":"380"},{"price":"0.66","size":"385"},{"price":"0.65","size":"398.93"},{"price":"0.64","size":"394.18"},{"price":"0.63","size":"403.13"},{"price":"0.62","size":"380"},{"price":"0.61","size":"374.09"},{"price":"0.6","size":"39"},{"price":"0.59","size":"5"},{"price":"0.58","size":"28.41"},{"price":"0.57","size":"10"},{"price":"0.56","size":"16"},{"price":"0.55","size":"319.33"},{"price":"0.54","size":"10"},{"price":"0.53","size":"15"},{"price":"0.52","size":"88.05"},{"price":"0.51","size":"5"},{"price":"0.5","size":"25"},{"price":"0.49","size":"107.65"},{"price":"0.48","size":"43"},{"price":"0.47","size":"380"},{"price":"0.46","size":"380"},{"price":"0.45","size":"380"},{"price":"0.44","size":"395"},{"price":"0.43","size":"385"},{"price":"0.42","size":"385"},{"price":"0.41","size":"390"},{"price":"0.4","size":"396"},{"price":"0.39","size":"385"},{"price":"0.38","size":"380"},{"price":"0.37","size":"400.24"},{"price":"0.36","size":"516.18"},{"price":"0.35","size":"530.75"},{"price":"0.34","size":"510.37"},{"price":"0.33","size":"298.95"},{"price":"0.32","size":"490.24"},{"price":"0.31","size":"474.01"},{"price":"0.3","size":"677.5"},{"price":"0.29","size":"682.74"},{"price":"0.28","size":"582.84"},{"price":"0.27","size":"414.37"},{"price":"0.26","size":"490.67"},{"price":"0.259","size":"5"},{"price":"0.25","size":"820.01"},{"price":"0.24","size":"659.24"},{"price":"0.23","size":"470"},{"price":"0.22","size":"389.97"},{"price":"0.21","size":"385"},{"price":"0.2","size":"385"},{"price":"0.19","size":"484.75"},{"price":"0.18","size":"393"},{"price":"0.17","size":"418.78"},{"price":"0.16","size":"406.56"},{"price":"0.15","size":"406.25"},{"price":"0.14","size":"905.94"},{"price":"0.13","size":"380"},{"price":"0.12","size":"1391.36"},{"price":"0.11","size":"1390"},{"price":"0.1","size":"424.19"},{"price":"0.09","size":"380"},{"price":"0.08","size":"701.12"},{"price":"0.07","size":"560.92"},{"price":"0.06","size":"802.08"},{"price":"0.05","size":"359.51"},{"price":"0.04","size":"594.7"},{"price":"0.03","size":"908"},{"price":"0.021","size":"700"},{"price":"0.02","size":"1055.53"},{"price":"0.01","size":"1256.24"},{"price":"0.009","size":"948.75"},{"price":"0.002","size":"5.06"}],"hash":"0420c254567e9dca7defb1c59168c865c7986f9c","timestamp":"1768359572237","event_type":"book"}
{"market":"0x5977c69bca02e6cc150855b0faec463b38be463f141ec37ea5c8a1a1e986e0d3","asset_id":"110222991870854778724082971333105906777328061970448875974576460135015541883929","bids":[{"price":"0.001","size":"270"},{"price":"0.002","size":"60"},{"price":"0.01","size":"8146.4"},{"price":"0.02","size":"4061.8"},{"price":"0.03","size":"2960.5"},{"price":"0.04","size":"2724.52"},{"price":"0.05","size":"2640"},{"price":"0.06","size":"2505"},{"price":"0.07","size":"2505"},{"price":"0.08","size":"2505"},{"price":"0.09","size":"2505"},{"price":"0.1","size":"2515"},{"price":"0.11","size":"5"},{"price":"0.12","size":"10"},{"price":"0.13","size":"5"},{"price":"0.14","size":"5"},{"price":"0.15","size":"10"},{"price":"0.16","size":"5"},{"price":"0.17","size":"5"},{"price":"0.18","size":"5"},{"price":"0.19","size":"380"},{"price":"0.2","size":"420"},{"price":"0.21","size":"380"},{"price":"0.22","size":"380"},{"price":"0.23","size":"380"},{"price":"0.24","size":"380"},{"price":"0.25","size":"413.5"},{"price":"0.26","size":"380"},{"price":"0.27","size":"380"},{"price":"0.28","size":"403.14"},{"price":"0.29","size":"380"},{"price":"0.3","size":"606.69"},{"price":"0.31","size":"380"},{"price":"0.32","size":"385"},{"price":"0.33","size":"380"},{"price":"0.34","size":"385"},{"price":"0.35","size":"398.93"},{"price":"0.36","size":"394.18"},{"price":"0.37","size":"403.13"},{"price":"0.38","size":"380"},{"price":"0.39","size":"374.09"},{"price":"0.4","size":"39"},{"price":"0.41","size":"5"},{"price":"0.42","size":"28.41"},{"price":"0.43","size":"10"},{"price":"0.44","size":"16"},{"price":"0.45","size":"319.33"},{"price":"0.46","size":"10"},{"price":"0.47","size":"15"},{"price":"0.48","size":"88.05"},{"price":"0.49","size":"5"},{"price":"0.5","size":"25"},{"price":"0.51","size":"107.65"},{"price":"0.52","size":"43"},{"price":"0.53","size":"380"},{"price":"0.54","size":"380"},{"price":"0.55","size":"380"},{"price":"0.56","size":"395"},{"price":"0.57","size":"385"},{"price":"0.58","size":"385"},{"price":"0.59","size":"390"},{"price":"0.6","size":"396"},{"price":"0.61","size":"385"},{"price":"0.62","size":"380"},{"price":"0.63","size":"400.24"},{"price":"0.64","size":"516.18"},{"price":"0.65","size":"530.75"},{"price":"0.66","size":"510.37"},{"price":"0.67","size":"298.95"},{"price":"0.68","size":"490.24"},{"price":"0.69","size":"474.01"},{"price":"0.7","size":"677.5"},{"price":"0.71","size":"682.74"},{"price":"0.72","size":"582.84"},{"price":"0.73","size":"414.37"},{"price":"0.74","size":"490.67"},{"price":"0.741","size":"5"},{"price":"0.75","size":"820.01"},{"price":"0.76","size":"659.24"},{"price":"0.77","size":"470"},{"price":"0.78","size":"389.97"},{"price":"0.79","size":"385"},{"price":"0.8","size":"385"},{"price":"0.81","size":"484.75"},{"price":"0.82","size":"393"},{"price":"0.83","size":"418.78"},{"price":"0.84","size":"406.56"},{"price":"0.85","size":"406.25"},{"price":"0.86","size":"905.94"},{"price":"0.87","size":"380"},{"price":"0.88","size":"1391.36"},{"price":"0.89","size":"1390"},{"price":"0.9","size":"424.19"},{"price":"0.91","size":"380"},{"price":"0.92","size":"701.12"},{"price":"0.93","size":"560.92"},{"price":"0.94","size":"802.08"},{"price":"0.95","size":"359.51"},{"price":"0.96","size":"594.7"},{"price":"0.97","size":"908"},{"price":"0.979","size":"700"},{"price":"0.98","size":"1055.53"},{"price":"0.99","size":"1256.24"},{"price":"0.991","size":"948.75"},{"price":"0.998","size":"5.06"}],"asks":[{"price":"0.999","size":"123.94"}],"hash":"384968a5f1fd9eb7a5748f32fe7e0727482ae4b9","timestamp":"1768359572237","event_type":"book"}
{"market":"0x5977c69bca02e6cc150855b0faec463b38be463f141ec37ea5c8a1a1e986e0d3","asset_id":"110222991870854778724082971333105906777328061970448875974576460135015541883929","price":"0.999","size":"6.056","fee_rate_bps":"1000","side":"BUY","timestamp":"1768359572268","event_type":"last_trade_price","transaction_hash":"0x9eef4cf0ca0ef8fc03fa5b8c7e0d7c53ae903914203160dd06ee0d1956dbc2e5"}
{"market":"0x5977c69bca02e6cc150855b0faec463b38be463f141ec37ea5c8a1a1e986e0d3","price_changes":[{"asset_id":"110222991870854778724082971333105906777328061970448875974576460135015541883929","price":"0.998","size":"0.06","side":"BUY","hash":"c1dca1f8912e9d7c7ecabcf8b8d762048c3d4a26","best_bid":"0.998","best_ask":"0.999"},{"asset_id":"103575991306220918671611575108050794364462782362354955892418399227289531345027","price":"0.002","size":"0.06","side":"SELL","hash":"c56b5833ecec4fd2af6829143cf02fb200aeb193","best_bid":"0.001","best_ask":"0.002"}],"timestamp":"1768359572370","event_type":"price_change"}
{"market":"0x5977c69bca02e6cc150855b0faec463b38be463f141ec37ea5c8a1a1e986e0d3","asset_id":"103575991306220918671611575108050794364462782362354955892418399227289531345027","bids":[{"price":"0.001","size":"123.94"}],"asks":[{"price":"0.999","size":"270"},{"price":"0.998","size":"60"},{"price":"0.99","size":"8146.4"},{"price":"0.98","size":"4061.8"},{"price":"0.97","size":"2960.5"},{"price":"0.96","size":"2724.52"},{"price":"0.95","size":"2640"},{"price":"0.94","size":"2505"},{"price":"0.93","size":"2505"},{"price":"0.92","size":"2505"},{"price":"0.91","size":"2505"},{"price":"0.9","size":"2515"},{"price":"0.89","size":"5"},{"price":"0.88","size":"10"},{"price":"0.87","size":"5"},{"price":"0.86","size":"5"},{"price":"0.85","size":"10"},{"price":"0.84","size":"5"},{"price":"0.83","size":"5"},{"price":"0.82","size":"5"},{"price":"0.81","size":"380"},{"price":"0.8","size":"420"},{"price":"0.79","size":"380"},{"price":"0.78","size":"380"},{"price":"0.77","size":"380"},{"price":"0.76","size":"380"},{"price":"0.75","size":"413.5"},{"price":"0.74","size":"380"},{"price":"0.73","size":"380"},{"price":"0.72","size":"403.14"},{"price":"0.71","size":"380"},{"price":"0.7","size":"606.69"},{"price":"0.69","size":"380"},{"price":"0.68","size":"385"},{"price":"0.67","size":"380"},{"price":"0.66","size":"385"},{"price":"0.65","size":"398.93"},{"price":"0.64","size":"394.18"},{"price":"0.63","size":"403.13"},{"price":"0.62","size":"380"},{"price":"0.61","size":"374.09"},{"price":"0.6","size":"39"},{"price":"0.59","size":"5"},{"price":"0.58","size":"28.41"},{"price":"0.57","size":"10"},{"price":"0.56","size":"16"},{"price":"0.55","size":"319.33"},{"price":"0.54","size":"10"},{"price":"0.53","size":"15"},{"price":"0.52","size":"88.05"},{"price":"0.51","size":"5"},{"price":"0.5","size":"25"},{"price":"0.49","size":"107.65"},{"price":"0.48","size":"43"},{"price":"0.47","size":"380"},{"price":"0.46","size":"380"},{"price":"0.45","size":"380"},{"price":"0.44","size":"395"},{"price":"0.43","size":"385"},{"price":"0.42","size":"385"},{"price":"0.41","size":"390"},{"price":"0.4","size":"396"},{"price":"0.39","size":"385"},{"price":"0.38","size":"380"},{"price":"0.37","size":"400.24"},{"price":"0.36","size":"516.18"},{"price":"0.35","size":"530.75"},{"price":"0.34","size":"510.37"},{"price":"0.33","size":"298.95"},{"price":"0.32","size":"490.24"},{"price":"0.31","size":"474.01"},{"price":"0.3","size":"677.5"},{"price":"0.29","size":"682.74"},{"price":"0.28","size":"582.84"},{"price":"0.27","size":"414.37"},{"price":"0.26","size":"490.67"},{"price":"0.259","size":"5"},{"price":"0.25","size":"820.01"},{"price":"0.24","size":"659.24"},{"price":"0.23","size":"470"},{"price":"0.22","size":"389.97"},{"price":"0.21","size":"385"},{"price":"0.2","size":"385"},{"price":"0.19","size":"484.75"},{"price":"0.18","size":"393"},{"price":"0.17","size":"418.78"},{"price":"0.16","size":"406.56"},{"price":"0.15","size":"406.25"},{"price":"0.14","size":"905.94"},{"price":"0.13","size":"380"},{"price":"0.12","size":"1391.36"},{"price":"0.11","size":"1390"},{"price":"0.1","size":"424.19"},{"price":"0.09","size":"380"},{"price":"0.08","size":"701.12"},{"price":"0.07","size":"560.92"},{"price":"0.06","size":"802.08"},{"price":"0.05","size":"359.51"},{"price":"0.04","size":"594.7"},{"price":"0.03","size":"908"},{"price":"0.021","size":"700"},{"price":"0.02","size":"1055.53"},{"price":"0.01","size":"1256.24"},{"price":"0.009","size":"948.75"},{"price":"0.002","size":"0.06"}],"hash":"c56b5833ecec4fd2af6829143cf02fb200aeb193","timestamp":"1768359572370","event_type":"book"}
{"market":"0x5977c69bca02e6cc150855b0faec463b38be463f141ec37ea5c8a1a1e986e0d3","asset_id":"110222991870854778724082971333105906777328061970448875974576460135015541883929","bids":[{"price":"0.001","size":"270"},{"price":"0.002","size":"60"},{"price":"0.01","size":"8146.4"},{"price":"0.02","size":"4061.8"},{"price":"0.03","size":"2960.5"},{"price":"0.04","size":"2724.52"},{"price":"0.05","size":"2640"},{"price":"0.06","size":"2505"},{"price":"0.07","size":"2505"},{"price":"0.08","size":"2505"},{"price":"0.09","size":"2505"},{"price":"0.1","size":"2515"},{"price":"0.11","size":"5"},{"price":"0.12","size":"10"},{"price":"0.13","size":"5"},{"price":"0.14","size":"5"},{"price":"0.15","size":"10"},{"price":"0.16","size":"5"},{"price":"0.17","size":"5"},{"price":"0.18","size":"5"},{"price":"0.19","size":"380"},{"price":"0.2","size":"420"},{"price":"0.21","size":"380"},{"price":"0.22","size":"380"},{"price":"0.23","size":"380"},{"price":"0.24","size":"380"},{"price":"0.25","size":"413.5"},{"price":"0.26","size":"380"},{"price":"0.27","size":"380"},{"price":"0.28","size":"403.14"},{"price":"0.29","size":"380"},{"price":"0.3","size":"606.69"},{"price":"0.31","size":"380"},{"price":"0.32","size":"385"},{"price":"0.33","size":"380"},{"price":"0.34","size":"385"},{"price":"0.35","size":"398.93"},{"price":"0.36","size":"394.18"},{"price":"0.37","size":"403.13"},{"price":"0.38","size":"380"},{"price":"0.39","size":"374.09"},{"price":"0.4","size":"39"},{"price":"0.41","size":"5"},{"price":"0.42","size":"28.41"},{"price":"0.43","size":"10"},{"price":"0.44","size":"16"},{"price":"0.45","size":"319.33"},{"price":"0.46","size":"10"},{"price":"0.47","size":"15"},{"price":"0.48","size":"88.05"},{"price":"0.49","size":"5"},{"price":"0.5","size":"25"},{"price":"0.51","size":"107.65"},{"price":"0.52","size":"43"},{"price":"0.53","size":"380"},{"price":"0.54","size":"380"},{"price":"0.55","size":"380"},{"price":"0.56","size":"395"},{"price":"0.57","size":"385"},{"price":"0.58","size":"385"},{"price":"0.59","size":"390"},{"price":"0.6","size":"396"},{"price":"0.61","size":"385"},{"price":"0.62","size":"380"},{"price":"0.63","size":"400.24"},{"price":"0.64","size":"516.18"},{"price":"0.65","size":"530.75"},{"price":"0.66","size":"510.37"},{"price":"0.67","size":"298.95"},{"price":"0.68","size":"490.24"},{"price":"0.69","size":"474.01"},{"price":"0.7","size":"677.5"},{"price":"0.71","size":"682.74"},{"price":"0.72","size":"582.84"},{"price":"0.73","size":"414.37"},{"price":"0.74","size":"490.67"},{"price":"0.741","size":"5"},{"price":"0.75","size":"820.01"},{"price":"0.76","size":"659.24"},{"price":"0.77","size":"470"},{"price":"0.78","size":"389.97"},{"price":"0.79","size":"385"},{"price":"0.8","size":"385"},{"price":"0.81","size":"484.75"},{"price":"0.82","size":"393"},{"price":"0.83","size":"418.78"},{"price":"0.84","size":"406.56"},{"price":"0.85","size":"406.25"},{"price":"0.86","size":"905.94"},{"price":"0.87","size":"380"},{"price":"0.88","size":"1391.36"},{"price":"0.89","size":"1390"},{"price":"0.9","size":"424.19"},{"price":"0.91","size":"380"},{"price":"0.92","size":"701.12"},{"price":"0.93","size":"560.92"},{"price":"0.94","size":"802.08"},{"price":"0.95","size":"359.51"},{"price":"0.96","size":"594.7"},{"price":"0.97","size":"908"},{"price":"0.979","size":"700"},{"price":"0.98","size":"1055.53"},{"price":"0.99","size":"1256.24"},{"price":"0.991","size":"948.75"},{"price":"0.998","size":"0.06"}],"asks":[{"price":"0.999","size":"123.94"}],"hash":"c1dca1f8912e9d7c7ecabcf8b8d762048c3d4a26","timestamp":"1768359572370","event_type":"book"}
{"market":"0x5977c69bca02e6cc150855b0faec463b38be463f141ec37ea5c8a1a1e986e0d3","asset_id":"103575991306220918671611575108050794364462782362354955892418399227289531345027","price":"0.002","size":"5","fee_rate_bps":"1000","side":"BUY","timestamp":"1768359572399","event_type":"last_trade_price","transaction_hash":"0x91cebe25e6b4c64792f07d5d2bff8dc6580d6fcc440e36d81e9e0de0aa793690"}
{"market":"0x5977c69bca02e6cc150855b0faec463b38be463f141ec37ea5c8a1a1e986e0d3","price_changes":[{"asset_id":"103575991306220918671611575108050794364462782362354955892418399227289531345027","price":"0.001","size":"0","side":"BUY","hash":"61a471781bbd4b23a63d3aaabf973eb261564299","best_bid":"0","best_ask":"0.002"},{"asset_id":"110222991870854778724082971333105906777328061970448875974576460135015541883929","price":"0.999","size":"0","side":"SELL","hash":"a9dc1ac6cfa7dd9976436cb05888ed7420fbae37","best_bid":"0.998","best_ask":"1"}],"timestamp":"1768359572732","event_type":"price_change"}
{"market":"0x5977c69bca02e6cc150855b0faec463b38be463f141ec37ea5c8a1a1e986e0d3","asset_id":"103575991306220918671611575108050794364462782362354955892418399227289531345027","bids":[],"asks":[{"price":"0.999","size":"270"},{"price":"0.998","size":"60"},{"price":"0.99","size":"8146.4"},{"price":"0.98","size":"4061.8"},{"price":"0.97","size":"2960.5"},{"price":"0.96","size":"2724.52"},{"price":"0.95","size":"2640"},{"price":"0.94","size":"2505"},{"price":"0.93","size":"2505"},{"price":"0.92","size":"2505"},{"price":"0.91","size":"2505"},{"price":"0.9","size":"2515"},{"price":"0.89","size":"5"},{"price":"0.88","size":"10"},{"price":"0.87","size":"5"},{"price":"0.86","size":"5"},{"price":"0.85","size":"10"},{"price":"0.84","size":"5"},{"price":"0.83","size":"5"},{"price":"0.82","size":"5"},{"price":"0.81","size":"380"},{"price":"0.8","size":"420"},{"price":"0.79","size":"380"},{"price":"0.78","size":"380"},{"price":"0.77","size":"380"},{"price":"0.76","size":"380"},{"price":"0.75","size":"413.5"},{"price":"0.74","size":"380"},{"price":"0.73","size":"380"},{"price":"0.72","size":"403.14"},{"price":"0.71","size":"380"},{"price":"0.7","size":"606.69"},{"price":"0.69","size":"380"},{"price":"0.68","size":"385"},{"price":"0.67","size":"380"},{"price":"0.66","size":"385"},{"price":"0.65","size":"398.93"},{"price":"0.64","size":"394.18"},{"price":"0.63","size":"403.13"},{"price":"0.62","size":"380"},{"price":"0.61","size":"374.09"},{"price":"0.6","size":"39"},{"price":"0.59","size":"5"},{"price":"0.58","size":"28.41"},{"price":"0.57","size":"10"},{"price":"0.56","size":"16"},{"price":"0.55","size":"319.33"},{"price":"0.54","size":"10"},{"price":"0.53","size":"15"},{"price":"0.52","size":"88.05"},{"price":"0.51","size":"5"},{"price":"0.5","size":"25"},{"price":"0.49","size":"107.65"},{"price":"0.48","size":"43"},{"price":"0.47","size":"380"},{"price":"0.46","size":"380"},{"price":"0.45","size":"380"},{"price":"0.44","size":"395"},{"price":"0.43","size":"385"},{"price":"0.42","size":"385"},{"price":"0.41","size":"390"},{"price":"0.4","size":"396"},{"price":"0.39","size":"385"},{"price":"0.38","size":"380"},{"price":"0.37","size":"400.24"},{"price":"0.36","size":"516.18"},{"price":"0.35","size":"530.75"},{"price":"0.34","size":"510.37"},{"price":"0.33","size":"298.95"},{"price":"0.32","size":"490.24"},{"price":"0.31","size":"474.01"},{"price":"0.3","size":"677.5"},{"price":"0.29","size":"682.74"},{"price":"0.28","size":"582.84"},{"price":"0.27","size":"414.37"},{"price":"0.26","size":"490.67"},{"price":"0.259","size":"5"},{"price":"0.25","size":"820.01"},{"price":"0.24","size":"659.24"},{"price":"0.23","size":"470"},{"price":"0.22","size":"389.97"},{"price":"0.21","size":"385"},{"price":"0.2","size":"385"},{"price":"0.19","size":"484.75"},{"price":"0.18","size":"393"},{"price":"0.17","size":"418.78"},{"price":"0.16","size":"406.56"},{"price":"0.15","size":"406.25"},{"price":"0.14","size":"905.94"},{"price":"0.13","size":"380"},{"price":"0.12","size":"1391.36"},{"price":"0.11","size":"1390"},{"price":"0.1","size":"424.19"},{"price":"0.09","size":"380"},{"price":"0.08","size":"701.12"},{"price":"0.07","size":"560.92"},{"price":"0.06","size":"802.08"},{"price":"0.05","size":"359.51"},{"price":"0.04","size":"594.7"},{"price":"0.03","size":"908"},{"price":"0.021","size":"700"},{"price":"0.02","size":"1055.53"},{"price":"0.01","size":"1256.24"},{"price":"0.009","size":"948.75"},{"price":"0.002","size":"0.06"}],"hash":"61a471781bbd4b23a63d3aaabf973eb261564299","timestamp":"1768359572732","event_type":"book"}
{"market":"0x5977c69bca02e6cc150855b0faec463b38be463f141ec37ea5c8a1a1e986e0d3","asset_id":"110222991870854778724082971333105906777328061970448875974576460135015541883929","bids":[{"price":"0.001","size":"270"},{"price":"0.002","size":"60"},{"price":"0.01","size":"8146.4"},{"price":"0.02","size":"4061.8"},{"price":"0.03","size":"2960.5"},{"price":"0.04","size":"2724.52"},{"price":"0.05","size":"2640"},{"price":"0.06","size":"2505"},{"price":"0.07","size":"2505"},{"price":"0.08","size":"2505"},{"price":"0.09","size":"2505"},{"price":"0.1","size":"2515"},{"price":"0.11","size":"5"},{"price":"0.12","size":"10"},{"price":"0.13","size":"5"},{"price":"0.14","size":"5"},{"price":"0.15","size":"10"},{"price":"0.16","size":"5"},{"price":"0.17","size":"5"},{"price":"0.18","size":"5"},{"price":"0.19","size":"380"},{"price":"0.2","size":"420"},{"price":"0.21","size":"380"},{"price":"0.22","size":"380"},{"price":"0.23","size":"380"},{"price":"0.24","size":"380"},{"price":"0.25","size":"413.5"},{"price":"0.26","size":"380"},{"price":"0.27","size":"380"},{"price":"0.28","size":"403.14"},{"price":"0.29","size":"380"},{"price":"0.3","size":"606.69"},{"price":"0.31","size":"380"},{"price":"0.32","size":"385"},{"price":"0.33","size":"380"},{"price":"0.34","size":"385"},{"price":"0.35","size":"398.93"},{"price":"0.36","size":"394.18"},{"price":"0.37","size":"403.13"},{"price":"0.38","size":"380"},{"price":"0.39","size":"374.09"},{"price":"0.4","size":"39"},{"price":"0.41","size":"5"},{"price":"0.42","size":"28.41"},{"price":"0.43","size":"10"},{"price":"0.44","size":"16"},{"price":"0.45","size":"319.33"},{"price":"0.46","size":"10"},{"price":"0.47","size":"15"},{"price":"0.48","size":"88.05"},{"price":"0.49","size":"5"},{"price":"0.5","size":"25"},{"price":"0.51","size":"107.65"},{"price":"0.52","size":"43"},{"price":"0.53","size":"380"},{"price":"0.54","size":"380"},{"price":"0.55","size":"380"},{"price":"0.56","size":"395"},{"price":"0.57","size":"385"},{"price":"0.58","size":"385"},{"price":"0.59","size":"390"},{"price":"0.6","size":"396"},{"price":"0.61","size":"385"},{"price":"0.62","size":"380"},{"price":"0.63","size":"400.24"},{"price":"0.64","size":"516.18"},{"price":"0.65","size":"530.75"},{"price":"0.66","size":"510.37"},{"price":"0.67","size":"298.95"},{"price":"0.68","size":"490.24"},{"price":"0.69","size":"474.01"},{"price":"0.7","size":"677.5"},{"price":"0.71","size":"682.74"},{"price":"0.72","size":"582.84"},{"price":"0.73","size":"414.37"},{"price":"0.74","size":"490.67"},{"price":"0.741","size":"5"},{"price":"0.75","size":"820.01"},{"price":"0.76","size":"659.24"},{"price":"0.77","size":"470"},{"price":"0.78","size":"389.97"},{"price":"0.79","size":"385"},{"price":"0.8","size":"385"},{"price":"0.81","size":"484.75"},{"price":"0.82","size":"393"},{"price":"0.83","size":"418.78"},{"price":"0.84","size":"406.56"},{"price":"0.85","size":"406.25"},{"price":"0.86","size":"905.94"},{"price":"0.87","size":"380"},{"price":"0.88","size":"1391.36"},{"price":"0.89","size":"1390"},{"price":"0.9","size":"424.19"},{"price":"0.91","size":"380"},{"price":"0.92","size":"701.12"},{"price":"0.93","size":"560.92"},{"price":"0.94","size":"802.08"},{"price":"0.95","size":"359.51"},{"price":"0.96","size":"594.7"},{"price":"0.97","size":"908"},{"price":"0.979","size":"700"},{"price":"0.98","size":"1055.53"},{"price":"0.99","size":"1256.24"},{"price":"0.991","size":"948.75"},{"price":"0.998","size":"0.06"}],"asks":[],"hash":"a9dc1ac6cfa7dd9976436cb05888ed7420fbae37","timestamp":"1768359572732","event_type":"book"}
{"market":"0x5977c69bca02e6cc150855b0faec463b38be463f141ec37ea5c8a1a1e986e0d3","asset_id":"110222991870854778724082971333105906777328061970448875974576460135015541883929","price":"0.999","size":"123.94","fee_rate_bps":"1000","side":"BUY","timestamp":"1768359572762","event_type":"last_trade_price","transaction_hash":"0x4c76497b4dd8cd3fa7b288d34a0eb29512d32a0c53b0fda373517ba0dbb1851e"}
{"market":"0x5977c69bca02e6cc150855b0faec463b38be463f141ec37ea5c8a1a1e986e0d3","price_changes":[{"asset_id":"110222991870854778724082971333105906777328061970448875974576460135015541883929","price":"0.84","size":"396.56","side":"BUY","hash":"2bf012bbbdf7d669cce4b248f5f457249244ef91","best_bid":"0.998","best_ask":"1"},{"asset_id":"103575991306220918671611575108050794364462782362354955892418399227289531345027","price":"0.16","size":"396.56","side":"SELL","hash":"b548c81b77976e5552e5d34c92ea9d974c71c8ed","best_bid":"0","best_ask":"0.002"}],"timestamp":"1768359572765","event_type":"price_change"}
{"market":"0x5977c69bca02e6cc150855b0faec463b38be463f141ec37ea5c8a1a1e986e0d3","price_changes":[{"asset_id":"110222991870854778724082971333105906777328061970448875974576460135015541883929","price":"0.84","size":"406.56","side":"BUY","hash":"9a71f78473f50badd56e3a6542cdd208d1c70b1c","best_bid":"0.998","best_ask":"1"},{"asset_id":"103575991306220918671611575108050794364462782362354955892418399227289531345027","price":"0.16","size":"406.56","side":"SELL","hash":"2e1f6191f2f8278a9d043765a3be1581055a1e8c","best_bid":"0","best_ask":"0.002"}],"timestamp":"1768359572791","event_type":"price_change"}
{"market":"0x5977c69bca02e6cc150855b0faec463b38be463f141ec37ea5c8a1a1e986e0d3","price_changes":[{"asset_id":"110222991870854778724082971333105906777328061970448875974576460135015541883929","price":"0.999","size":"200","side":"BUY","hash":"70d9040f5a7c481a4f39780e7a10348952247258","best_bid":"0.999","best_ask":"1"},{"asset_id":"103575991306220918671611575108050794364462782362354955892418399227289531345027","price":"0.001","size":"200","side":"SELL","hash":"4b5fd172fc18f4be1d3de74bb783b31be98b43e1","best_bid":"0","best_ask":"0.001"}],"timestamp":"1768359572811","event_type":"price_change"}
{"market":"0x5977c69bca02e6cc150855b0faec463b38be463f141ec37ea5c8a1a1e986e0d3","price_changes":[{"asset_id":"110222991870854778724082971333105906777328061970448875974576460135015541883929","price":"0.97","size":"913","side":"BUY","hash":"a5cd405c11ab5151cab041b5af24b0b1525e00cc","best_bid":"0.999","best_ask":"1"},{"asset_id":"103575991306220918671611575108050794364462782362354955892418399227289531345027","price":"0.03","size":"913","side":"SELL","hash":"aedaacd4c21da34081e3739a85df7cdd31820ef5","best_bid":"0","best_ask":"0.001"}],"timestamp":"1768359572897","event_type":"price_change"}
{"market":"0x5977c69bca02e6cc150855b0faec463b38be463f141ec37ea5c8a1a1e986e0d3","price_changes":[{"asset_id":"110222991870854778724082971333105906777328061970448875974576460135015541883929","price":"0.97","size":"908","side":"BUY","hash":"3df1252b626b8096d5e5debf5a9c4d222c9f224d","best_bid":"0.999","best_ask":"1"},{"asset_id":"103575991306220918671611575108050794364462782362354955892418399227289531345027","price":"0.03","size":"908","side":"SELL","hash":"a04b3a7ff86bfc3c95aee1b1c578e39467736e4b","best_bid":"0","best_ask":"0.001"}],"timestamp":"1768359572925","event_type":"price_change"}
{"market":"0x5977c69bca02e6cc150855b0faec463b38be463f141ec37ea5c8a1a1e986e0d3","price_changes":[{"asset_id":"110222991870854778724082971333105906777328061970448875974576460135015541883929","price":"0.999","size":"93.08","side":"BUY","hash":"04dc40ef056737999909860ed099d201696c0779","best_bid":"0.999","best_ask":"1"},{"asset_id":"103575991306220918671611575108050794364462782362354955892418399227289531345027","price":"0.001","size":"93.08","side":"SELL","hash":"408b314177089ea121061a30fb31fb9853c42a9a","best_bid":"0","best_ask":"0.001"}],"timestamp":"1768359572944","event_type":"price_change"}
{"market":"0x5977c69bca02e6cc150855b0faec463b38be463f141ec37ea5c8a1a1e986e0d3","asset_id":"103575991306220918671611575108050794364462782362354955892418399227289531345027","bids":[],"asks":[{"price":"0.999","size":"270"},{"price":"0.998","size":"60"},{"price":"0.99","size":"8146.4"},{"price":"0.98","size":"4061.8"},{"price":"0.97","size":"2960.5"},{"price":"0.96","size":"2724.52"},{"price":"0.95","size":"2640"},{"price":"0.94","size":"2505"},{"price":"0.93","size":"2505"},{"price":"0.92","size":"2505"},{"price":"0.91","size":"2505"},{"price":"0.9","size":"2515"},{"price":"0.89","size":"5"},{"price":"0.88","size":"10"},{"price":"0.87","size":"5"},{"price":"0.86","size":"5"},{"price":"0.85","size":"10"},{"price":"0.84","size":"5"},{"price":"0.83","size":"5"},{"price":"0.82","size":"5"},{"price":"0.81","size":"380"},{"price":"0.8","size":"420"},{"price":"0.79","size":"380"},{"price":"0.78","size":"380"},{"price":"0.77","size":"380"},{"price":"0.76","size":"380"},{"price":"0.75","size":"413.5"},{"price":"0.74","size":"380"},{"price":"0.73","size":"380"},{"price":"0.72","size":"403.14"},{"price":"0.71","size":"380"},{"price":"0.7","size":"606.69"},{"price":"0.69","size":"380"},{"price":"0.68","size":"385"},{"price":"0.67","size":"380"},{"price":"0.66","size":"385"},{"price":"0.65","size":"398.93"},{"price":"0.64","size":"394.18"},{"price":"0.63","size":"403.13"},{"price":"0.62","size":"380"},{"price":"0.61","size":"374.09"},{"price":"0.6","size":"39"},{"price":"0.59","size":"5"},{"price":"0.58","size":"28.41"},{"price":"0.57","size":"10"},{"price":"0.56","size":"16"},{"price":"0.55","size":"319.33"},{"price":"0.54","size":"10"},{"price":"0.53","size":"15"},{"price":"0.52","size":"88.05"},{"price":"0.51","size":"5"},{"price":"0.5","size":"25"},{"price":"0.49","size":"107.65"},{"price":"0.48","size":"43"},{"price":"0.47","size":"380"},{"price":"0.46","size":"380"},{"price":"0.45","size":"380"},{"price":"0.44","size":"395"},{"price":"0.43","size":"385"},{"price":"0.42","size":"385"},{"price":"0.41","size":"390"},{"price":"0.4","size":"396"},{"price":"0.39","size":"385"},{"price":"0.38","size":"380"},{"price":"0.37","size":"400.24"},{"price":"0.36","size":"516.18"},{"price":"0.35","size":"530.75"},{"price":"0.34","size":"510.37"},{"price":"0.33","size":"298.95"},{"price":"0.32","size":"490.24"},{"price":"0.31","size":"474.01"},{"price":"0.3","size":"677.5"},{"price":"0.29","size":"682.74"},{"price":"0.28","size":"582.84"},{"price":"0.27","size":"414.37"},{"price":"0.26","size":"490.67"},{"price":"0.259","size":"5"},{"price":"0.25","size":"820.01"},{"price":"0.24","size":"659.24"},{"price":"0.23","size":"470"},{"price":"0.22","size":"389.97"},{"price":"0.21","size":"385"},{"price":"0.2","size":"385"},{"price":"0.19","size":"484.75"},{"price":"0.18","size":"393"},{"price":"0.17","size":"418.78"},{"price":"0.16","size":"406.56"},{"price":"0.15","size":"406.25"},{"price":"0.14","size":"905.94"},{"price":"0.13","size":"380"},{"price":"0.12","size":"1391.36"},{"price":"0.11","size":"1390"},{"price":"0.1","size":"424.19"},{"price":"0.09","size":"380"},{"price":"0.08","size":"701.12"},{"price":"0.07","size":"560.92"},{"price":"0.06","size":"802.08"},{"price":"0.05","size":"359.51"},{"price":"0.04","size":"594.7"},{"price":"0.03","size":"908"},{"price":"0.021","size":"700"},{"price":"0.02","size":"1055.53"},{"price":"0.01","size":"1256.24"},{"price":"0.009","size":"948.75"},{"price":"0.002","size":"0.06"},{"price":"0.001","size":"93.08"}],"hash":"408b314177089ea121061a30fb31fb9853c42a9a","timestamp":"1768359572944","event_type":"book"}
{"market":"0x5977c69bca02e6cc150855b0faec463b38be463f141ec37ea5c8a1a1e986e0d3","asset_id":"110222991870854778724082971333105906777328061970448875974576460135015541883929","bids":[{"price":"0.001","size":"270"},{"price":"0.002","size":"60"},{"price":"0.01","size":"8146.4"},{"price":"0.02","size":"4061.8"},{"price":"0.03","size":"2960.5"},{"price":"0.04","size":"2724.52"},{"price":"0.05","size":"2640"},{"price":"0.06","size":"2505"},{"price":"0.07","size":"2505"},{"price":"0.08","size":"2505"},{"price":"0.09","size":"2505"},{"price":"0.1","size":"2515"},{"price":"0.11","size":"5"},{"price":"0.12","size":"10"},{"price":"0.13","size":"5"},{"price":"0.14","size":"5"},{"price":"0.15","size":"10"},{"price":"0.16","size":"5"},{"price":"0.17","size":"5"},{"price":"0.18","size":"5"},{"price":"0.19","size":"380"},{"price":"0.2","size":"420"},{"price":"0.21","size":"380"},{"price":"0.22","size":"380"},{"price":"0.23","size":"380"},{"price":"0.24","size":"380"},{"price":"0.25","size":"413.5"},{"price":"0.26","size":"380"},{"price":"0.27","size":"380"},{"price":"0.28","size":"403.14"},{"price":"0.29","size":"380"},{"price":"0.3","size":"606.69"},{"price":"0.31","size":"380"},{"price":"0.32","size":"385"},{"price":"0.33","size":"380"},{"price":"0.34","size":"385"},{"price":"0.35","size":"398.93"},{"price":"0.36","size":"394.18"},{"price":"0.37","size":"403.13"},{"price":"0.38","size":"380"},{"price":"0.39","size":"374.09"},{"price":"0.4","size":"39"},{"price":"0.41","size":"5"},{"price":"0.42","size":"28.41"},{"price":"0.43","size":"10"},{"price":"0.44","size":"16"},{"price":"0.45","size":"319.33"},{"price":"0.46","size":"10"},{"price":"0.47","size":"15"},{"price":"0.48","size":"88.05"},{"price":"0.49","size":"5"},{"price":"0.5","size":"25"},{"price":"0.51","size":"107.65"},{"price":"0.52","size":"43"},{"price":"0.53","size":"380"},{"price":"0.54","size":"380"},{"price":"0.55","size":"380"},{"price":"0.56","size":"395"},{"price":"0.57","size":"385"},{"price":"0.58","size":"385"},{"price":"0.59","size":"390"},{"price":"0.6","size":"396"},{"price":"0.61","size":"385"},{"price":"0.62","size":"380"},{"price":"0.63","size":"400.24"},{"price":"0.64","size":"516.18"},{"price":"0.65","size":"530.75"},{"price":"0.66","size":"510.37"},{"price":"0.67","size":"298.95"},{"price":"0.68","size":"490.24"},{"price":"0.69","size":"474.01"},{"price":"0.7","size":"677.5"},{"price":"0.71","size":"682.74"},{"price":"0.72","size":"582.84"},{"price":"0.73","size":"414.37"},{"price":"0.74","size":"490.67"},{"price":"0.741","size":"5"},{"price":"0.75","size":"820.01"},{"price":"0.76","size":"659.24"},{"price":"0.77","size":"470"},{"price":"0.78","size":"389.97"},{"price":"0.79","size":"385"},{"price":"0.8","size":"385"},{"price":"0.81","size":"484.75"},{"price":"0.82","size":"393"},{"price":"0.83","size":"418.78"},{"price":"0.84","size":"406.56"},{"price":"0.85","size":"406.25"},{"price":"0.86","size":"905.94"},{"price":"0.87","size":"380"},{"price":"0.88","size":"1391.36"},{"price":"0.89","size":"1390"},{"price":"0.9","size":"424.19"},{"price":"0.91","size":"380"},{"price":"0.92","size":"701.12"},{"price":"0.93","size":"560.92"},{"price":"0.94","size":"802.08"},{"price":"0.95","size":"359.51"},{"price":"0.96","size":"594.7"},{"price":"0.97","size":"908"},{"price":"0.979","size":"700"},{"price":"0.98","size":"1055.53"},{"price":"0.99","size":"1256.24"},{"price":"0.991","size":"948.75"},{"price":"0.998","size":"0.06"},{"price":"0.999","size":"93.08"}],"asks":[],"hash":"04dc40ef056737999909860ed099d201696c0779","timestamp":"1768359572944","event_type":"book"}
{"market":"0x5977c69bca02e6cc150855b0faec463b38be463f141ec37ea5c8a1a1e986e0d3","price_changes":[{"asset_id":"110222991870854778724082971333105906777328061970448875974576460135015541883929","price":"0.99","size":"1261.24","side":"BUY","hash":"f356bc3bb65e7bbc176e9905ddfa0e3f0359c89c","best_bid":"0.999","best_ask":"1"},{"asset_id":"103575991306220918671611575108050794364462782362354955892418399227289531345027","price":"0.01","size":"1261.24","side":"SELL","hash":"01ac1c700566c7724a936d0d090ab163242e5491","best_bid":"0","best_ask":"0.001"}],"timestamp":"1768359572961","event_type":"price_change"}
{"market":"0x5977c69bca02e6cc150855b0faec463b38be463f141ec37ea5c8a1a1e986e0d3","asset_id":"110222991870854778724082971333105906777328061970448875974576460135015541883929","price":"0.999","size":"106.92","fee_rate_bps":"1000","side":"SELL","timestamp":"1768359572970","event_type":"last_trade_price","transaction_hash":"0x0c5fd4d4b58995b35a47178eaf18ab1fcfc2083e306d684ae439a828ef85e212"}
{"market":"0x5977c69bca02e6cc150855b0faec463b38be463f141ec37ea5c8a1a1e986e0d3","price_changes":[{"asset_id":"110222991870854778724082971333105906777328061970448875974576460135015541883929","price":"0.98","size":"1031.53","side":"BUY","hash":"5cd17b2070dcfd7b56f39094e4a5c2fa2b67d378","best_bid":"0.999","best_ask":"1"},{"asset_id":"103575991306220918671611575108050794364462782362354955892418399227289531345027","price":"0.02","size":"1031.53","side":"SELL","hash":"a95a522dfa40f8a34bd32cc43b8e8d9998c49e98","best_bid":"0","best_ask":"0.001"}],"timestamp":"1768359572988","event_type":"price_change"}
{"market":"0x5977c69bca02e6cc150855b0faec463b38be463f141ec37ea5c8a1a1e986e0d3","price_changes":[{"asset_id":"110222991870854778724082971333105906777328061970448875974576460135015541883929","price":"0.99","size":"1285.24","side":"BUY","hash":"8a03da6bf4917717c8c8a3b5db78a20fcd563a90","best_bid":"0.999","best_ask":"1"},{"asset_id":"103575991306220918671611575108050794364462782362354955892418399227289531345027","price":"0.01","size":"1285.24","side":"SELL","hash":"ef34b42d6af1c3db675a3cda9397fb5bd06febb9","best_bid":"0","best_ask":"0.001"}],"timestamp":"1768359572990","event_type":"price_change"}
{"market":"0x5977c69bca02e6cc150855b0faec463b38be463f141ec37ea5c8a1a1e986e0d3","price_changes":[{"asset_id":"103575991306220918671611575108050794364462782362354955892418399227289531345027","price":"0.05","size":"329.51","side":"SELL","hash":"1d70e76990455b2876fb797ec6264d70a5c2bd33","best_bid":"0","best_ask":"0.001"},{"asset_id":"110222991870854778724082971333105906777328061970448875974576460135015541883929","price":"0.95","size":"329.51","side":"BUY","hash":"30349d5548028d5b449100399d67ae2bc6a71c07","best_bid":"0.999","best_ask":"1"}],"timestamp":"1768359572999","event_type":"price_change"}
{"market":"0x5977c69bca02e6cc150855b0faec463b38be463f141ec37ea5c8a1a1e986e0d3","price_changes":[{"asset_id":"110222991870854778724082971333105906777328061970448875974576460135015541883929","price":"0.92","size":"594.2","side":"BUY","hash":"dd92a133fa519359ecf108c1546b2597146a981c","best_bid":"0.999","best_ask":"1"},{"asset_id":"103575991306220918671611575108050794364462782362354955892418399227289531345027","price":"0.08","size":"594.2","side":"SELL","hash":"aeb7e2381a82461221631bcbef6fe29cee27bae0","best_bid":"0","best_ask":"0.001"}],"timestamp":"1768359573000","event_type":"price_change"}
{"market":"0x5977c69bca02e6cc150855b0faec463b38be463f141ec37ea5c8a1a1e986e0d3","price_changes":[{"asset_id":"110222991870854778724082971333105906777328061970448875974576460135015541883929","price":"0.93","size":"454","side":"BUY","hash":"dd92a133fa519359ecf108c1546b2597146a981c","best_bid":"0.999","best_ask":"1"},{"asset_id":"103575991306220918671611575108050794364462782362354955892418399227289531345027","price":"0.07","size":"454","side":"SELL","hash":"aeb7e2381a82461221631bcbef6fe29cee27bae0","best_bid":"0","best_ask":"0.001"}],"timestamp":"1768359573000","event_type":"price_change"}
{"market":"0x5977c69bca02e6cc150855b0faec463b38be463f141ec37ea5c8a1a1e986e0d3","price_changes":[{"asset_id":"110222991870854778724082971333105906777328061970448875974576460135015541883929","price":"0.995","size":"200","side":"BUY","hash":"9e4aa0c462958f33274164cce1bf6ebacf351893","best_bid":"0.999","best_ask":"1"},{"asset_id":"103575991306220918671611575108050794364462782362354955892418399227289531345027","price":"0.005","size":"200","side":"SELL","hash":"1fb016801716349ec7cda36341712efdd8b41425","best_bid":"0","best_ask":"0.001"}],"timestamp":"1768359573110","event_type":"price_change"}
{"market":"0x5977c69bca02e6cc150855b0faec463b38be463f141ec37ea5c8a1a1e986e0d3","price_changes":[{"asset_id":"110222991870854778724082971333105906777328061970448875974576460135015541883929","price":"0.741","size":"0","side":"BUY","hash":"63578f27e9fb3271676f014b33f03ae810b81548","best_bid":"0.999","best_ask":"1"},{"asset_id":"103575991306220918671611575108050794364462782362354955892418399227289531345027","price":"0.259","size":"0","side":"SELL","hash":"d12b9634e20b3aee065f351ede31a66b9fdc2e4a","best_bid":"0","best_ask":"0.001"}],"timestamp":"1768359573318","event_type":"price_change"}
{"market":"0x5977c69bca02e6cc150855b0faec463b38be463f141ec37ea5c8a1a1e986e0d3","price_changes":[{"asset_id":"110222991870854778724082971333105906777328061970448875974576460135015541883929","price":"0.99","size":"1485.24","side":"BUY","hash":"8338e16cff915e0026caf98ccc89e8f539f2b08a","best_bid":"0.999","best_ask":"1"},{"asset_id":"103575991306220918671611575108050794364462782362354955892418399227289531345027","price":"0.01","size":"1485.24","side":"SELL","hash":"93649268c3ebb9977e1b82f232d7750e8d8de6de","best_bid":"0","best_ask":"0.001"}],"timestamp":"1768359573437","event_type":"price_change"}
{"market":"0x5977c69bca02e6cc150855b0faec463b38be463f141ec37ea5c8a1a1e986e0d3","price_changes":[{"asset_id":"110222991870854778724082971333105906777328061970448875974576460135015541883929","price":"0.99","size":"1490.24","side":"BUY","hash":"26b348d8735c5003fb7c7f30639e79964ddbe66b","best_bid":"0.999","best_ask":"1"},{"asset_id":"103575991306220918671611575108050794364462782362354955892418399227289531345027","price":"0.01","size":"1490.24","side":"SELL","hash":"0fcaaf0516a3c8877e75e687f79c953d49e3c76a","best_bid":"0","best_ask":"0.001"}],"timestamp":"1768359573682","event_type":"price_change"}
{"market":"0x5977c69bca02e6cc150855b0faec463b38be463f141ec37ea5c8a1a1e986e0d3","price_changes":[{"asset_id":"110222991870854778724082971333105906777328061970448875974576460135015541883929","price":"0.84","size":"396.56","side":"BUY","hash":"b25158eea6517831723f075b4cd051d67569cf82","best_bid":"0.999","best_ask":"1"},{"asset_id":"103575991306220918671611575108050794364462782362354955892418399227289531345027","price":"0.16","size":"396.56","side":"SELL","hash":"e2646ec219163a8b946167099094821128bda337","best_bid":"0","best_ask":"0.001"}],"timestamp":"1768359573841","event_type":"price_change"}
{"market":"0x5977c69bca02e6cc150855b0faec463b38be463f141ec37ea5c8a1a1e986e0d3","price_changes":[{"asset_id":"110222991870854778724082971333105906777328061970448875974576460135015541883929","price":"0.84","size":"406.56","side":"BUY","hash":"c6e9c98e3dd5e420f0576b4731f4779149332666","best_bid":"0.999","best_ask":"1"},{"asset_id":"103575991306220918671611575108050794364462782362354955892418399227289531345027","price":"0.16","size":"406.56","side":"SELL","hash":"d1367c7ebfca4be69b253ce177d16a41a8fa98ab","best_bid":"0","best_ask":"0.001"}],"timestamp":"1768359573864","event_type":"price_change"}
{"market":"0x5977c69bca02e6cc150855b0faec463b38be463f141ec37ea5c8a1a1e986e0d3","price_changes":[{"asset_id":"103575991306220918671611575108050794364462782362354955892418399227289531345027","price":"0.02","size":"1043.53","side":"SELL","hash":"1bf450820a9a2c6538fb9bbb7b513e84d5b4747f","best_bid":"0","best_ask":"0.001"},{"asset_id":"110222991870854778724082971333105906777328061970448875974576460135015541883929","price":"0.98","size":"1043.53","side":"BUY","hash":"d53a143a8d3197ce277ed00a11834bca9e55ade9","best_bid":"0.999","best_ask":"1"}],"timestamp":"1768359573948","event_type":"price_change"}
{"market":"0x5977c69bca02e6cc150855b0faec463b38be463f141ec37ea5c8a1a1e986e0d3","price_changes":[{"asset_id":"103575991306220918671611575108050794364462782362354955892418399227289531345027","price":"0.02","size":"1031.53","side":"SELL","hash":"600377777d85d615299c5f67b9b93cea77517035","best_bid":"0","best_ask":"0.001"},{"asset_id":"110222991870854778724082971333105906777328061970448875974576460135015541883929","price":"0.98","size":"1031.53","side":"BUY","hash":"cf90fc7ac93edc31fa8e9a84a315e24da7f91b7b","best_bid":"0.999","best_ask":"1"}],"timestamp":"1768359574012","event_type":"price_change"}
{"market":"0x5977c69bca02e6cc150855b0faec463b38be463f141ec37ea5c8a1a1e986e0d3","price_changes":[{"asset_id":"110222991870854778724082971333105906777328061970448875974576460135015541883929","price":"0.95","size":"436.43","side":"BUY","hash":"687a5939a8485f6d09d2917aef0fb3bb83bd264f","best_bid":"0.999","best_ask":"1"},{"asset_id":"103575991306220918671611575108050794364462782362354955892418399227289531345027","price":"0.05","size":"436.43","side":"SELL","hash":"df787cac21f40f829b0d73ebda569b98ac357a06","best_bid":"0","best_ask":"0.001"}],"timestamp":"1768359574064","event_type":"price_change"}
{"market":"0x5977c69bca02e6cc150855b0faec463b38be463f141ec37ea5c8a1a1e986e0d3","price_changes":[{"asset_id":"103575991306220918671611575108050794364462782362354955892418399227289531345027","price":"0.03","size":"938","side":"SELL","hash":"b171fc3fb57467ae4eaca97d2506ca86aa8808d1","best_bid":"0","best_ask":"0.001"},{"asset_id":"110222991870854778724082971333105906777328061970448875974576460135015541883929","price":"0.97","size":"938","side":"BUY","hash":"a700ff15c708b12414f02b3a790c75ac78441ff6","best_bid":"0.999","best_ask":"1"}],"timestamp":"1768359574066","event_type":"price_change"}
{"market":"0x5977c69bca02e6cc150855b0faec463b38be463f141ec37ea5c8a1a1e986e0d3","price_changes":[{"asset_id":"110222991870854778724082971333105906777328061970448875974576460135015541883929","price":"0.98","size":"1138.45","side":"BUY","hash":"f356e1670263f4ff29ca0d7780f58d0b81c2fcc0","best_bid":"0.999","best_ask":"1"},{"asset_id":"103575991306220918671611575108050794364462782362354955892418399227289531345027","price":"0.02","size":"1138.45","side":"SELL","hash":"16265dd6d0ad794d21417d4e7ec1f6c8b7a4b103","best_bid":"0","best_ask":"0.001"}],"timestamp":"1768359574067","event_type":"price_change"}
{"market":"0x5977c69bca02e6cc150855b0faec463b38be463f141ec37ea5c8a1a1e986e0d3","price_changes":[{"asset_id":"110222991870854778724082971333105906777328061970448875974576460135015541883929","price":"0.748","size":"5","side":"BUY","hash":"644c4e7a148628b919afbc05b9e44609a1c814e2","best_bid":"0.999","best_ask":"1"},{"asset_id":"103575991306220918671611575108050794364462782362354955892418399227289531345027","price":"0.252","size":"5","side":"SELL","hash":"4a12efb204ee6df5f9b9668dde955c778d1e50b3","best_bid":"0","best_ask":"0.001"}],"timestamp":"1768359574284","event_type":"price_change"}
{"market":"0x5977c69bca02e6cc150855b0faec463b38be463f141ec37ea5c8a1a1e986e0d3","price_changes":[{"asset_id":"110222991870854778724082971333105906777328061970448875974576460135015541883929","price":"0.97","size":"950","side":"BUY","hash":"7244b702c8b6efe6f34706b5fc37940a1702dd10","best_bid":"0.999","best_ask":"1"},{"asset_id":"103575991306220918671611575108050794364462782362354955892418399227289531345027","price":"0.03","size":"950","side":"SELL","hash":"2d6cd252f2ceaf0fd1fedf122ff68d053123396d","best_bid":"0","best_ask":"0.001"}],"timestamp":"1768359574550","event_type":"price_change"}
{"market":"0x5977c69bca02e6cc150855b0faec463b38be463f141ec37ea5c8a1a1e986e0d3","price_changes":[{"asset_id":"110222991870854778724082971333105906777328061970448875974576460135015541883929","price":"0.97","size":"938","side":"BUY","hash":"d0f4266e311305b7a0055c2937cae7025cd43bf7","best_bid":"0.999","best_ask":"1"},{"asset_id":"103575991306220918671611575108050794364462782362354955892418399227289531345027","price":"0.03","size":"938","side":"SELL","hash":"ac3f4ef67e4d9ecd5bc6dc312942e0f592ee3ab8","best_bid":"0","best_ask":"0.001"}],"timestamp":"1768359574639","event_type":"price_change"}
{"market":"0x5977c69bca02e6cc150855b0faec463b38be463f141ec37ea5c8a1a1e986e0d3","price_changes":[{"asset_id":"110222991870854778724082971333105906777328061970448875974576460135015541883929","price":"0.97","size":"903","side":"BUY","hash":"391375cbe1b8fb45f19a8d354f158d9dc92eb0b6","best_bid":"0.999","best_ask":"1"},{"asset_id":"103575991306220918671611575108050794364462782362354955892418399227289531345027","price":"0.03","size":"903","side":"SELL","hash":"01c170b68355b1b5a39f926644c0a2d1d2e8d397","best_bid":"0","best_ask":"0.001"}],"timestamp":"1768359574831","event_type":"price_change"}
{"market":"0x5977c69bca02e6cc150855b0faec463b38be463f141ec37ea5c8a1a1e986e0d3","price_changes":[{"asset_id":"110222991870854778724082971333105906777328061970448875974576460135015541883929","price":"0.96","size":"634.7","side":"BUY","hash":"d9567301a922539d7bd140d2d1ff8784b1c49111","best_bid":"0.999","best_ask":"1"},{"asset_id":"103575991306220918671611575108050794364462782362354955892418399227289531345027","price":"0.04","size":"634.7","side":"SELL","hash":"4824d3127e268f690fee677caf358ac1aa5e35d2","best_bid":"0","best_ask":"0.001"}],"timestamp":"1768359574862","event_type":"price_change"}
{"market":"0x5977c69bca02e6cc150855b0faec463b38be463f141ec37ea5c8a1a1e986e0d3","price_changes":[{"asset_id":"110222991870854778724082971333105906777328061970448875974576460135015541883929","price":"0.84","size":"396.56","side":"BUY","hash":"be8a7996f057daed79ef7b91ee1778042208a471","best_bid":"0.999","best_ask":"1"},{"asset_id":"103575991306220918671611575108050794364462782362354955892418399227289531345027","price":"0.16","size":"396.56","side":"SELL","hash":"94eb48b4fa898aaef9eab4ef282ce544a2c663e3","best_bid":"0","best_ask":"0.001"}],"timestamp":"1768359574942","event_type":"price_change"}
{"market":"0x5977c69bca02e6cc150855b0faec463b38be463f141ec37ea5c8a1a1e986e0d3","price_changes":[{"asset_id":"110222991870854778724082971333105906777328061970448875974576460135015541883929","price":"0.83","size":"428.78","side":"BUY","hash":"d8cc7ffeb7ada3677ab24feedcc7c378f9be201f","best_bid":"0.999","best_ask":"1"},{"asset_id":"103575991306220918671611575108050794364462782362354955892418399227289531345027","price":"0.17","size":"428.78","side":"SELL","hash":"a40948d7fb40b85cd0bd09c61d86f6cea9dfeba4","best_bid":"0","best_ask":"0.001"}],"timestamp":"1768359574967","event_type":"price_change"}
PONG
{"market":"0x5977c69bca02e6cc150855b0faec463b38be463f141ec37ea5c8a1a1e986e0d3","price_changes":[{"asset_id":"110222991870854778724082971333105906777328061970448875974576460135015541883929","price":"0.999","size":"88.08","side":"BUY","hash":"2b35f7800f9f940f0df6978fd0566dbb95ee75b8","best_bid":"0.999","best_ask":"1"},{"asset_id":"103575991306220918671611575108050794364462782362354955892418399227289531345027","price":"0.001","size":"88.08","side":"SELL","hash":"2858873135b436d4a33b744b26905cc2d402cce2","best_bid":"0","best_ask":"0.001"}],"timestamp":"1768359575445","event_type":"price_change"}
{"market":"0x5977c69bca02e6cc150855b0faec463b38be463f141ec37ea5c8a1a1e986e0d3","asset_id":"103575991306220918671611575108050794364462782362354955892418399227289531345027","bids":[],"asks":[{"price":"0.999","size":"270"},{"price":"0.998","size":"60"},{"price":"0.99","size":"8146.4"},{"price":"0.98","size":"4061.8"},{"price":"0.97","size":"2960.5"},{"price":"0.96","size":"2724.52"},{"price":"0.95","size":"2640"},{"price":"0.94","size":"2505"},{"price":"0.93","size":"2505"},{"price":"0.92","size":"2505"},{"price":"0.91","size":"2505"},{"price":"0.9","size":"2515"},{"price":"0.89","size":"5"},{"price":"0.88","size":"10"},{"price":"0.87","size":"5"},{"price":"0.86","size":"5"},{"price":"0.85","size":"10"},{"price":"0.84","size":"5"},{"price":"0.83","size":"5"},{"price":"0.82","size":"5"},{"price":"0.81","size":"380"},{"price":"0.8","size":"420"},{"price":"0.79","size":"380"},{"price":"0.78","size":"380"},{"price":"0.77","size":"380"},{"price":"0.76","size":"380"},{"price":"0.75","size":"413.5"},{"price":"0.74","size":"380"},{"price":"0.73","size":"380"},{"price":"0.72","size":"403.14"},{"price":"0.71","size":"380"},{"price":"0.7","size":"606.69"},{"price":"0.69","size":"380"},{"price":"0.68","size":"385"},{"price":"0.67","size":"380"},{"price":"0.66","size":"385"},{"price":"0.65","size":"398.93"},{"price":"0.64","size":"394.18"},{"price":"0.63","size":"403.13"},{"price":"0.62","size":"380"},{"price":"0.61","size":"374.09"},{"price":"0.6","size":"39"},{"price":"0.59","size":"5"},{"price":"0.58","size":"28.41"},{"price":"0.57","size":"10"},{"price":"0.56","size":"16"},{"price":"0.55","size":"319.33"},{"price":"0.54","size":"10"},{"price":"0.53","size":"15"},{"price":"0.52","size":"88.05"},{"price":"0.51","size":"5"},{"price":"0.5","size":"25"},{"price":"0.49","size":"107.65"},{"price":"0.48","size":"43"},{"price":"0.47","size":"380"},{"price":"0.46","size":"380"},{"price":"0.45","size":"380"},{"price":"0.44","size":"395"},{"price":"0.43","size":"385"},{"price":"0.42","size":"385"},{"price":"0.41","size":"390"},{"price":"0.4","size":"396"},{"price":"0.39","size":"385"},{"price":"0.38","size":"380"},{"price":"0.37","size":"400.24"},{"price":"0.36","size":"516.18"},{"price":"0.35","size":"530.75"},{"price":"0.34","size":"510.37"},{"price":"0.33","size":"298.95"},{"price":"0.32","size":"490.24"},{"price":"0.31","size":"474.01"},{"price":"0.3","size":"677.5"},{"price":"0.29","size":"682.74"},{"price":"0.28","size":"582.84"},{"price":"0.27","size":"414.37"},{"price":"0.26","size":"490.67"},{"price":"0.252","size":"5"},{"price":"0.25","size":"820.01"},{"price":"0.24","size":"659.24"},{"price":"0.23","size":"470"},{"price":"0.22","size":"389.97"},{"price":"0.21","size":"385"},{"price":"0.2","size":"385"},{"price":"0.19","size":"484.75"},{"price":"0.18","size":"393"},{"price":"0.17","size":"428.78"},{"price":"0.16","size":"396.56"},{"price":"0.15","size":"406.25"},{"price":"0.14","size":"905.94"},{"price":"0.13","size":"380"},{"price":"0.12","size":"1391.36"},{"price":"0.11","size":"1390"},{"price":"0.1","size":"424.19"},{"price":"0.09","size":"380"},{"price":"0.08","size":"594.2"},{"price":"0.07","size":"454"},{"price":"0.06","size":"802.08"},{"price":"0.05","size":"436.43"},{"price":"0.04","size":"634.7"},{"price":"0.03","size":"903"},{"price":"0.021","size":"700"},{"price":"0.02","size":"1138.45"},{"price":"0.01","size":"1490.24"},{"price":"0.009","size":"948.75"},{"price":"0.005","size":"200"},{"price":"0.002","size":"0.06"},{"price":"0.001","size":"88.08"}],"hash":"2858873135b436d4a33b744b26905cc2d402cce2","timestamp":"1768359575445","event_type":"book"}
{"market":"0x5977c69bca02e6cc150855b0faec463b38be463f141ec37ea5c8a1a1e986e0d3","asset_id":"110222991870854778724082971333105906777328061970448875974576460135015541883929","bids":[{"price":"0.001","size":"270"},{"price":"0.002","size":"60"},{"price":"0.01","size":"8146.4"},{"price":"0.02","size":"4061.8"},{"price":"0.03","size":"2960.5"},{"price":"0.04","size":"2724.52"},{"price":"0.05","size":"2640"},{"price":"0.06","size":"2505"},{"price":"0.07","size":"2505"},{"price":"0.08","size":"2505"},{"price":"0.09","size":"2505"},{"price":"0.1","size":"2515"},{"price":"0.11","size":"5"},{"price":"0.12","size":"10"},{"price":"0.13","size":"5"},{"price":"0.14","size":"5"},{"price":"0.15","size":"10"},{"price":"0.16","size":"5"},{"price":"0.17","size":"5"},{"price":"0.18","size":"5"},{"price":"0.19","size":"380"},{"price":"0.2","size":"420"},{"price":"0.21","size":"380"},{"price":"0.22","size":"380"},{"price":"0.23","size":"380"},{"price":"0.24","size":"380"},{"price":"0.25","size":"413.5"},{"price":"0.26","size":"380"},{"price":"0.27","size":"380"},{"price":"0.28","size":"403.14"},{"price":"0.29","size":"380"},{"price":"0.3","size":"606.69"},{"price":"0.31","size":"380"},{"price":"0.32","size":"385"},{"price":"0.33","size":"380"},{"price":"0.34","size":"385"},{"price":"0.35","size":"398.93"},{"price":"0.36","size":"394.18"},{"price":"0.37","size":"403.13"},{"price":"0.38","size":"380"},{"price":"0.39","size":"374.09"},{"price":"0.4","size":"39"},{"price":"0.41","size":"5"},{"price":"0.42","size":"28.41"},{"price":"0.43","size":"10"},{"price":"0.44","size":"16"},{"price":"0.45","size":"319.33"},{"price":"0.46","size":"10"},{"price":"0.47","size":"15"},{"price":"0.48","size":"88.05"},{"price":"0.49","size":"5"},{"price":"0.5","size":"25"},{"price":"0.51","size":"107.65"},{"price":"0.52","size":"43"},{"price":"0.53","size":"380"},{"price":"0.54","size":"380"},{"price":"0.55","size":"380"},{"price":"0.56","size":"395"},{"price":"0.57","size":"385"},{"price":"0.58","size":"385"},{"price":"0.59","size":"390"},{"price":"0.6","size":"396"},{"price":"0.61","size":"385"},{"price":"0.62","size":"380"},{"price":"0.63","size":"400.24"},{"price":"0.64","size":"516.18"},{"price":"0.65","size":"530.75"},{"price":"0.66","size":"510.37"},{"price":"0.67","size":"298.95"},{"price":"0.68","size":"490.24"},{"price":"0.69","size":"474.01"},{"price":"0.7","size":"677.5"},{"price":"0.71","size":"682.74"},{"price":"0.72","size":"582.84"},{"price":"0.73","size":"414.37"},{"price":"0.74","size":"490.67"},{"price":"0.748","size":"5"},{"price":"0.75","size":"820.01"},{"price":"0.76","size":"659.24"},{"price":"0.77","size":"470"},{"price":"0.78","size":"389.97"},{"price":"0.79","size":"385"},{"price":"0.8","size":"385"},{"price":"0.81","size":"484.75"},{"price":"0.82","size":"393"},{"price":"0.83","size":"428.78"},{"price":"0.84","size":"396.56"},{"price":"0.85","size":"406.25"},{"price":"0.86","size":"905.94"},{"price":"0.87","size":"380"},{"price":"0.88","size":"1391.36"},{"price":"0.89","size":"1390"},{"price":"0.9","size":"424.19"},{"price":"0.91","size":"380"},{"price":"0.92","size":"594.2"},{"price":"0.93","size":"454"},{"price":"0.94","size":"802.08"},{"price":"0.95","size":"436.43"},{"price":"0.96","size":"634.7"},{"price":"0.97","size":"903"},{"price":"0.979","size":"700"},{"price":"0.98","size":"1138.45"},{"price":"0.99","size":"1490.24"},{"price":"0.991","size":"948.75"},{"price":"0.995","size":"200"},{"price":"0.998","size":"0.06"},{"price":"0.999","size":"88.08"}],"asks":[],"hash":"2b35f7800f9f940f0df6978fd0566dbb95ee75b8","timestamp":"1768359575445","event_type":"book"}
{"market":"0x5977c69bca02e6cc150855b0faec463b38be463f141ec37ea5c8a1a1e986e0d3","asset_id":"103575991306220918671611575108050794364462782362354955892418399227289531345027","price":"0.001","size":"5","fee_rate_bps":"1000","side":"BUY","timestamp":"1768359575476","event_type":"last_trade_price","transaction_hash":"0x7d9f50c18d0dd22d7c7270593c1659819a63e7d3442dca41cec4a6379a7fc40f"}
{"market":"0x5977c69bca02e6cc150855b0faec463b38be463f141ec37ea5c8a1a1e986e0d3","price_changes":[{"asset_id":"110222991870854778724082971333105906777328061970448875974576460135015541883929","price":"0.97","size":"915","side":"BUY","hash":"6d6e9f472f28da8cbf3daa0710e2437375978359","best_bid":"0.999","best_ask":"1"},{"asset_id":"103575991306220918671611575108050794364462782362354955892418399227289531345027","price":"0.03","size":"915","side":"SELL","hash":"65b20e3a229d14f4ab59e5eae277bbe05bc44d40","best_bid":"0","best_ask":"0.001"}],"timestamp":"1768359575875","event_type":"price_change"}
{"market":"0x5977c69bca02e6cc150855b0faec463b38be463f141ec37ea5c8a1a1e986e0d3","price_changes":[{"asset_id":"110222991870854778724082971333105906777328061970448875974576460135015541883929","price":"0.97","size":"903","side":"BUY","hash":"b2aa0b33f5b19e9c89ebd538c1f6501183fca0f7","best_bid":"0.999","best_ask":"1"},{"asset_id":"103575991306220918671611575108050794364462782362354955892418399227289531345027","price":"0.03","size":"903","side":"SELL","hash":"cab911d5beb8ee1dba425e243769a3cb8784171a","best_bid":"0","best_ask":"0.001"}],"timestamp":"1768359575958","event_type":"price_change"}
{"market":"0x5977c69bca02e6cc150855b0faec463b38be463f141ec37ea5c8a1a1e986e0d3","price_changes":[{"asset_id":"110222991870854778724082971333105906777328061970448875974576460135015541883929","price":"0.83","size":"418.78","side":"BUY","hash":"90f41a44fd2b6e343a4a6f6753f9826466fc9cab","best_bid":"0.999","best_ask":"1"},{"asset_id":"103575991306220918671611575108050794364462782362354955892418399227289531345027","price":"0.17","size":"418.78","side":"SELL","hash":"ff797fc177933a4ec2653b9f153b7c1508f7b1ef","best_bid":"0","best_ask":"0.001"}],"timestamp":"1768359576055","event_type":"price_change"}
{"market":"0x5977c69bca02e6cc150855b0faec463b38be463f141ec37ea5c8a1a1e986e0d3","price_changes":[{"asset_id":"110222991870854778724082971333105906777328061970448875974576460135015541883929","price":"0.83","size":"428.78","side":"BUY","hash":"7cea9aa997ead329e88683cd58f20a301df566a0","best_bid":"0.999","best_ask":"1"},{"asset_id":"103575991306220918671611575108050794364462782362354955892418399227289531345027","price":"0.17","size":"428.78","side":"SELL","hash":"01ceca0e9615099037f08aadefbd5f1c44d43343","best_bid":"0","best_ask":"0.001"}],"timestamp":"1768359576080","event_type":"price_change"}
{"market":"0x5977c69bca02e6cc150855b0faec463b38be463f141ec37ea5c8a1a1e986e0d3","price_changes":[{"asset_id":"110222991870854778724082971333105906777328061970448875974576460135015541883929","price":"0.96","size":"594.7","side":"BUY","hash":"de2eb085cdebfe2177c14d33f297e0f650c3b030","best_bid":"0.999","best_ask":"1"},{"asset_id":"103575991306220918671611575108050794364462782362354955892418399227289531345027","price":"0.04","size":"594.7","side":"SELL","hash":"7157142f30b4f70091a3acb19de9d824556741d2","best_bid":"0","best_ask":"0.001"}],"timestamp":"1768359576430","event_type":"price_change"}
{"market":"0x5977c69bca02e6cc150855b0faec463b38be463f141ec37ea5c8a1a1e986e0d3","price_changes":[{"asset_id":"110222991870854778724082971333105906777328061970448875974576460135015541883929","price":"0.999","size":"87.07","side":"BUY","hash":"873387907d306fe8a6b785cfd0a786ab8d953a39","best_bid":"0.999","best_ask":"1"},{"asset_id":"103575991306220918671611575108050794364462782362354955892418399227289531345027","price":"0.001","size":"87.07","side":"SELL","hash":"07b44ef3bbf6633b7766cd0d6a9e3281ecf2441b","best_bid":"0","best_ask":"0.001"}],"timestamp":"1768359576884","event_type":"price_change"}
