{"market":"0x5977c69bca02e6cc150855b0faec463b38be463f141ec37ea5c8a1a1e986e0d3","asset_id":"103575991306220918671611575108050794364462782362354955892418399227289531345027","bids":[],"asks":[{"price":"0.999","size":"270"},{"price":"0.998","size":"60"},{"price":"0.99","size":"5596.4"},{"price":"0.98","size":"1556.8"},{"price":"0.97","size":"455.5"},{"price":"0.96","size":"219.52"},{"price":"0.95","size":"35"},{"price":"0.9","size":"10"},{"price":"0.88","size":"5"},{"price":"0.85","size":"5"},{"price":"0.8","size":"40"},{"price":"0.75","size":"33.5"},{"price":"0.72","size":"23.14"},{"price":"0.7","size":"226.69"},{"price":"0.68","size":"5"},{"price":"0.66","size":"5"},{"price":"0.65","size":"18.93"},{"price":"0.64","size":"15"},{"price":"0.63","size":"23.13"},{"price":"0.6","size":"34"},{"price":"0.58","size":"23.41"},{"price":"0.57","size":"5"},{"price":"0.56","size":"11"},{"price":"0.55","size":"314.33"},{"price":"0.54","size":"5"},{"price":"0.53","size":"10"},{"price":"0.52","size":"83.05"},{"price":"0.5","size":"20"},{"price":"0.49","size":"102.65"},{"price":"0.48","size":"38"},{"price":"0.44","size":"15"},{"price":"0.43","size":"5"},{"price":"0.42","size":"5"},{"price":"0.41","size":"10"},{"price":"0.4","size":"16"},{"price":"0.39","size":"5"},{"price":"0.37","size":"20.24"},{"price":"0.36","size":"136.18"},{"price":"0.35","size":"150.75"},{"price":"0.34","size":"130.37"},{"price":"0.33","size":"15.12"},{"price":"0.32","size":"110.24"},{"price":"0.31","size":"94.01"},{"price":"0.3","size":"297.5"},{"price":"0.29","size":"302.74"},{"price":"0.28","size":"202.84"},{"price":"0.27","size":"34.37"},{"price":"0.26","size":"110.67"},{"price":"0.259","size":"5"},{"price":"0.25","size":"440.01"},{"price":"0.24","size":"279.24"},{"price":"0.23","size":"90"},{"price":"0.22","size":"9.97"},{"price":"0.21","size":"5"},{"price":"0.2","size":"27"},{"price":"0.19","size":"104.75"},{"price":"0.17","size":"38.78"},{"price":"0.16","size":"16.56"},{"price":"0.15","size":"26.25"},{"price":"0.14","size":"525.94"},{"price":"0.12","size":"1011.36"},{"price":"0.11","size":"1010"},{"price":"0.1","size":"44.19"},{"price":"0.08","size":"214.2"},{"price":"0.07","size":"73"},{"price":"0.06","size":"320.16"},{"price":"0.05","size":"270.38"},{"price":"0.04","size":"107.78"},{"price":"0.03","size":"504.14"},{"price":"0.02","size":"1016.53"},{"price":"0.015","size":"5"},{"price":"0.01","size":"416.83"}],"hash":"124c9c816a2bce65812bc6cc49349645d4aacd73","timestamp":"1768359592518","event_type":"book"}
{"market":"0x5977c69bca02e6cc150855b0faec463b38be463f141ec37ea5c8a1a1e986e0d3","asset_id":"110222991870854778724082971333105906777328061970448875974576460135015541883929","bids":[{"price":"0.001","size":"270"},{"price":"0.002","size":"60"},{"price":"0.01","size":"5596.4"},{"price":"0.02","size":"1556.8"},{"price":"0.03","size":"455.5"},{"price":"0.04","size":"219.52"},{"price":"0.05","size":"35"},{"price":"0.1","size":"10"},{"price":"0.12","size":"5"},{"price":"0.15","size":"5"},{"price":"0.2","size":"40"},{"price":"0.25","size":"33.5"},{"price":"0.28","size":"23.14"},{"price":"0.3","size":"226.69"},{"price":"0.32","size":"5"},{"price":"0.34","size":"5"},{"price":"0.35","size":"18.93"},{"price":"0.36","size":"15"},{"price":"0.37","size":"23.13"},{"price":"0.4","size":"34"},{"price":"0.42","size":"23.41"},{"price":"0.43","size":"5"},{"price":"0.44","size":"11"},{"price":"0.45","size":"314.33"},{"price":"0.46","size":"5"},{"price":"0.47","size":"10"},{"price":"0.48","size":"83.05"},{"price":"0.5","size":"20"},{"price":"0.51","size":"102.65"},{"price":"0.52","size":"38"},{"price":"0.56","size":"15"},{"price":"0.57","size":"5"},{"price":"0.58","size":"5"},{"price":"0.59","size":"10"},{"price":"0.6","size":"16"},{"price":"0.61","size":"5"},{"price":"0.63","size":"20.24"},{"price":"0.64","size":"136.18"},{"price":"0.65","size":"150.75"},{"price":"0.66","size":"130.37"},{"price":"0.67","size":"15.12"},{"price":"0.68","size":"110.24"},{"price":"0.69","size":"94.01"},{"price":"0.7","size":"297.5"},{"price":"0.71","size":"302.74"},{"price":"0.72","size":"202.84"},{"price":"0.73","size":"34.37"},{"price":"0.74","size":"110.67"},{"price":"0.741","size":"5"},{"price":"0.75","size":"440.01"},{"price":"0.76","size":"279.24"},{"price":"0.77","size":"90"},{"price":"0.78","size":"9.97"},{"price":"0.79","size":"5"},{"price":"0.8","size":"27"},{"price":"0.81","size":"104.75"},{"price":"0.83","size":"38.78"},{"price":"0.84","size":"16.56"},{"price":"0.85","size":"26.25"},{"price":"0.86","size":"525.94"},{"price":"0.88","size":"1011.36"},{"price":"0.89","size":"1010"},{"price":"0.9","size":"44.19"},{"price":"0.92","size":"214.2"},{"price":"0.93","size":"73"},{"price":"0.94","size":"320.16"},{"price":"0.95","size":"270.38"},{"price":"0.96","size":"107.78"},{"price":"0.97","size":"504.14"},{"price":"0.98","size":"1016.53"},{"price":"0.985","size":"5"},{"price":"0.99","size":"416.83"}],"asks":[],"hash":"ed1616a85da9a9de48e9d1173efb5f315f948dee","timestamp":"1768359592518","event_type":"book"}
{"market":"0x5977c69bca02e6cc150855b0faec463b38be463f141ec37ea5c8a1a1e986e0d3","price_changes":[{"asset_id":"110222991870854778724082971333105906777328061970448875974576460135015541883929","price":"0.8","size":"17","side":"BUY","hash":"3c1a2ed42ff57652257d0180d34d4b4e83657209","best_bid":"0.99","best_ask":"1"},{"asset_id":"103575991306220918671611575108050794364462782362354955892418399227289531345027","price":"0.2","size":"17","side":"SELL","hash":"a1df651be4ab475b9f5666b0901a5ec74eab601f","best_bid":"0","best_ask":"0.01"}],"timestamp":"1768359592541","event_type":"price_change"}
{"market":"0x5977c69bca02e6cc150855b0faec463b38be463f141ec37ea5c8a1a1e986e0d3","asset_id":"103575991306220918671611575108050794364462782362354955892418399227289531345027","price":"0.01","size":"50","fee_rate_bps":"1000","side":"BUY","timestamp":"1768359592548","event_type":"last_trade_price","transaction_hash":"0x2d44dd44ee74bd42d33f051994e6c69d58b12943c28ca78535f526e643e43e4a"}
{"market":"0x5977c69bca02e6cc150855b0faec463b38be463f141ec37ea5c8a1a1e986e0d3","price_changes":[{"asset_id":"110222991870854778724082971333105906777328061970448875974576460135015541883929","price":"0.8","size":"27","side":"BUY","hash":"f6122cd99275e8b9aa2cfaaa76c36e2ead34da9d","best_bid":"0.99","best_ask":"1"},{"asset_id":"103575991306220918671611575108050794364462782362354955892418399227289531345027","price":"0.2","size":"27","side":"SELL","hash":"fb943fb7d3487e7361bc79e3d1a002917bdec725","best_bid":"0","best_ask":"0.01"}],"timestamp":"1768359592566","event_type":"price_change"}
{"market":"0x5977c69bca02e6cc150855b0faec463b38be463f141ec37ea5c8a1a1e986e0d3","price_changes":[{"asset_id":"110222991870854778724082971333105906777328061970448875974576460135015541883929","price":"0.99","size":"421.83","side":"BUY","hash":"dbbff6a5c9f95efe5ef334e8cc21550931a1402f","best_bid":"0.99","best_ask":"1"},{"asset_id":"103575991306220918671611575108050794364462782362354955892418399227289531345027","price":"0.01","size":"421.83","side":"SELL","hash":"2b5bc1417a6c866d963805491694c26dc839bd64","best_bid":"0","best_ask":"0.01"}],"timestamp":"1768359593068","event_type":"price_change"}
{"market":"0x5977c69bca02e6cc150855b0faec463b38be463f141ec37ea5c8a1a1e986e0d3","price_changes":[{"asset_id":"110222991870854778724082971333105906777328061970448875974576460135015541883929","price":"0.741","size":"0","side":"BUY","hash":"f72f6f7d7b491c02c285e5f2633a037f2d90ccff","best_bid":"0.99","best_ask":"1"},{"asset_id":"103575991306220918671611575108050794364462782362354955892418399227289531345027","price":"0.259","size":"0","side":"SELL","hash":"6a85d57725fb8c81c1288798cb011931062f81e9","best_bid":"0","best_ask":"0.01"}],"timestamp":"1768359593193","event_type":"price_change"}
{"market":"0x5977c69bca02e6cc150855b0faec463b38be463f141ec37ea5c8a1a1e986e0d3","price_changes":[{"asset_id":"110222991870854778724082971333105906777328061970448875974576460135015541883929","price":"0.8","size":"15","side":"BUY","hash":"025736c1a80a92811c3d16548c7c0976d3f9de98","best_bid":"0.99","best_ask":"1"},{"asset_id":"103575991306220918671611575108050794364462782362354955892418399227289531345027","price":"0.2","size":"15","side":"SELL","hash":"3a8830ce6cfd06f4cec862917bbb7fbf41687a61","best_bid":"0","best_ask":"0.01"}],"timestamp":"1768359593555","event_type":"price_change"}
{"market":"0x5977c69bca02e6cc150855b0faec463b38be463f141ec37ea5c8a1a1e986e0d3","price_changes":[{"asset_id":"110222991870854778724082971333105906777328061970448875974576460135015541883929","price":"0.79","size":"17","side":"BUY","hash":"1bd407894a140f426f875f009a5fd3b0935bf0da","best_bid":"0.99","best_ask":"1"},{"asset_id":"103575991306220918671611575108050794364462782362354955892418399227289531345027","price":"0.21","size":"17","side":"SELL","hash":"a7aed768b71f86b3ded0b353262b1d14baba4c28","best_bid":"0","best_ask":"0.01"}],"timestamp":"1768359593591","event_type":"price_change"}
{"market":"0x5977c69bca02e6cc150855b0faec463b38be463f141ec37ea5c8a1a1e986e0d3","price_changes":[{"asset_id":"110222991870854778724082971333105906777328061970448875974576460135015541883929","price":"0.8","size":"5","side":"BUY","hash":"302038a9f16199ac8b26d3aece90ee3b1a185811","best_bid":"0.99","best_ask":"1"},{"asset_id":"103575991306220918671611575108050794364462782362354955892418399227289531345027","price":"0.2","size":"5","side":"SELL","hash":"518b4684c9dd596f39fffdf11348f96e2f50a470","best_bid":"0","best_ask":"0.01"}],"timestamp":"1768359593641","event_type":"price_change"}
{"market":"0x5977c69bca02e6cc150855b0faec463b38be463f141ec37ea5c8a1a1e986e0d3","price_changes":[{"asset_id":"110222991870854778724082971333105906777328061970448875974576460135015541883929","price":"0.8","size":"15","side":"BUY","hash":"ee3b41607aae9f5a795d1674d987102470a5a2dc","best_bid":"0.99","best_ask":"1"},{"asset_id":"103575991306220918671611575108050794364462782362354955892418399227289531345027","price":"0.2","size":"15","side":"SELL","hash":"fe0721f6a27914133d10717147422b0a50444316","best_bid":"0","best_ask":"0.01"}],"timestamp":"1768359593674","event_type":"price_change"}
{"market":"0x5977c69bca02e6cc150855b0faec463b38be463f141ec37ea5c8a1a1e986e0d3","price_changes":[{"asset_id":"110222991870854778724082971333105906777328061970448875974576460135015541883929","price":"0.99","size":"451.83","side":"BUY","hash":"6c063991c5e8405ea8f80a8bfa9066b782b3a9ab","best_bid":"0.99","best_ask":"1"},{"asset_id":"103575991306220918671611575108050794364462782362354955892418399227289531345027","price":"0.01","size":"451.83","side":"SELL","hash":"b0209ec4af63927023bbd70e8209d491702af1e1","best_bid":"0","best_ask":"0.01"}],"timestamp":"1768359593695","event_type":"price_change"}
{"market":"0x5977c69bca02e6cc150855b0faec463b38be463f141ec37ea5c8a1a1e986e0d3","price_changes":[{"asset_id":"103575991306220918671611575108050794364462782362354955892418399227289531345027","price":"0.01","size":"468.23","side":"SELL","hash":"4e58ad2be518b0281a71397e926be1ba19c0fd53","best_bid":"0","best_ask":"0.01"},{"asset_id":"110222991870854778724082971333105906777328061970448875974576460135015541883929","price":"0.99","size":"468.23","side":"BUY","hash":"3ebd6828711114a15c7607c52f7ca9e773258078","best_bid":"0.99","best_ask":"1"}],"timestamp":"1768359594019","event_type":"price_change"}
{"market":"0x5977c69bca02e6cc150855b0faec463b38be463f141ec37ea5c8a1a1e986e0d3","price_changes":[{"asset_id":"110222991870854778724082971333105906777328061970448875974576460135015541883929","price":"0.74","size":"115.67","side":"BUY","hash":"c6a769ace11d3432b1ea4ffd06b2a1f8ea2dd8b0","best_bid":"0.99","best_ask":"1"},{"asset_id":"103575991306220918671611575108050794364462782362354955892418399227289531345027","price":"0.26","size":"115.67","side":"SELL","hash":"a0b1a092efcbfdd698aa7521e82ce815c571ffda","best_bid":"0","best_ask":"0.01"}],"timestamp":"1768359594103","event_type":"price_change"}
{"market":"0x5977c69bca02e6cc150855b0faec463b38be463f141ec37ea5c8a1a1e986e0d3","price_changes":[{"asset_id":"110222991870854778724082971333105906777328061970448875974576460135015541883929","price":"0.99","size":"1585.23","side":"BUY","hash":"9b6a1f39365514f909b451f6db3b759ed561ec33","best_bid":"0.99","best_ask":"1"},{"asset_id":"103575991306220918671611575108050794364462782362354955892418399227289531345027","price":"0.01","size":"1585.23","side":"SELL","hash":"a156647a9c67ac080d9b55d564ea346a99212fd3","best_bid":"0","best_ask":"0.01"}],"timestamp":"1768359594254","event_type":"price_change"}
{"market":"0x5977c69bca02e6cc150855b0faec463b38be463f141ec37ea5c8a1a1e986e0d3","price_changes":[{"asset_id":"110222991870854778724082971333105906777328061970448875974576460135015541883929","price":"0.99","size":"1696.93","side":"BUY","hash":"aee9682174aab59098b84704299719c3694e4f82","best_bid":"0.99","best_ask":"1"},{"asset_id":"103575991306220918671611575108050794364462782362354955892418399227289531345027","price":"0.01","size":"1696.93","side":"SELL","hash":"0f848f868b2962edd2cfafef37153658084505b2","best_bid":"0","best_ask":"0.01"}],"timestamp":"1768359594301","event_type":"price_change"}
{"market":"0x5977c69bca02e6cc150855b0faec463b38be463f141ec37ea5c8a1a1e986e0d3","price_changes":[{"asset_id":"110222991870854778724082971333105906777328061970448875974576460135015541883929","price":"0.99","size":"1747.43","side":"BUY","hash":"a4abc878ef1bf55ba9d6412a212a1adc6b875ea0","best_bid":"0.99","best_ask":"1"},{"asset_id":"103575991306220918671611575108050794364462782362354955892418399227289531345027","price":"0.01","size":"1747.43","side":"SELL","hash":"3eba5d6a863dab9f905eea7f957dca4f32081a1d","best_bid":"0","best_ask":"0.01"}],"timestamp":"1768359594345","event_type":"price_change"}
{"market":"0x5977c69bca02e6cc150855b0faec463b38be463f141ec37ea5c8a1a1e986e0d3","price_changes":[{"asset_id":"110222991870854778724082971333105906777328061970448875974576460135015541883929","price":"0.8","size":"5","side":"BUY","hash":"7c97f2f216f75242ec965163ec2a8ef9a37a56f1","best_bid":"0.99","best_ask":"1"},{"asset_id":"103575991306220918671611575108050794364462782362354955892418399227289531345027","price":"0.2","size":"5","side":"SELL","hash":"809422c65f7167dd96c52e7c1e2176b7b8f0c187","best_bid":"0","best_ask":"0.01"}],"timestamp":"1768359594742","event_type":"price_change"}
{"market":"0x5977c69bca02e6cc150855b0faec463b38be463f141ec37ea5c8a1a1e986e0d3","price_changes":[{"asset_id":"110222991870854778724082971333105906777328061970448875974576460135015541883929","price":"0.8","size":"15","side":"BUY","hash":"3c193799ef2e42d04016afca5d63f73feb3d2c3c","best_bid":"0.99","best_ask":"1"},{"asset_id":"103575991306220918671611575108050794364462782362354955892418399227289531345027","price":"0.2","size":"15","side":"SELL","hash":"e491cbdb29b20b4cc5183ed01eab1c366efcb5da","best_bid":"0","best_ask":"0.01"}],"timestamp":"1768359594763","event_type":"price_change"}
{"market":"0x5977c69bca02e6cc150855b0faec463b38be463f141ec37ea5c8a1a1e986e0d3","price_changes":[{"asset_id":"110222991870854778724082971333105906777328061970448875974576460135015541883929","price":"0.99","size":"1731.32","side":"BUY","hash":"89938316b52f1bd90881da8804386ec293124bf9","best_bid":"0.99","best_ask":"1"},{"asset_id":"103575991306220918671611575108050794364462782362354955892418399227289531345027","price":"0.01","size":"1731.32","side":"SELL","hash":"8fbb13b70efcbe57e1cc53725f3cd5513671c892","best_bid":"0","best_ask":"0.01"}],"timestamp":"1768359595096","event_type":"price_change"}
{"market":"0x5977c69bca02e6cc150855b0faec463b38be463f141ec37ea5c8a1a1e986e0d3","asset_id":"103575991306220918671611575108050794364462782362354955892418399227289531345027","bids":[],"asks":[{"price":"0.999","size":"270"},{"price":"0.998","size":"60"},{"price":"0.99","size":"5596.4"},{"price":"0.98","size":"1556.8"},{"price":"0.97","size":"455.5"},{"price":"0.96","size":"219.52"},{"price":"0.95","size":"35"},{"price":"0.9","size":"10"},{"price":"0.88","size":"5"},{"price":"0.85","size":"5"},{"price":"0.8","size":"40"},{"price":"0.75","size":"33.5"},{"price":"0.72","size":"23.14"},{"price":"0.7","size":"226.69"},{"price":"0.68","size":"5"},{"price":"0.66","size":"5"},{"price":"0.65","size":"18.93"},{"price":"0.64","size":"15"},{"price":"0.63","size":"23.13"},{"price":"0.6","size":"34"},{"price":"0.58","size":"23.41"},{"price":"0.57","size":"5"},{"price":"0.56","size":"11"},{"price":"0.55","size":"314.33"},{"price":"0.54","size":"5"},{"price":"0.53","size":"10"},{"price":"0.52","size":"83.05"},{"price":"0.5","size":"20"},{"price":"0.49","size":"102.65"},{"price":"0.48","size":"38"},{"price":"0.44","size":"15"},{"price":"0.43","size":"5"},{"price":"0.42","size":"5"},{"price":"0.41","size":"10"},{"price":"0.4","size":"16"},{"price":"0.39","size":"5"},{"price":"0.37","size":"20.24"},{"price":"0.36","size":"136.18"},{"price":"0.35","size":"150.75"},{"price":"0.34","size":"130.37"},{"price":"0.33","size":"15.12"},{"price":"0.32","size":"110.24"},{"price":"0.31","size":"94.01"},{"price":"0.3","size":"297.5"},{"price":"0.29","size":"302.74"},{"price":"0.28","size":"202.84"},{"price":"0.27","size":"34.37"},{"price":"0.26","size":"115.67"},{"price":"0.25","size":"440.01"},{"price":"0.24","size":"279.24"},{"price":"0.23","size":"90"},{"price":"0.22","size":"9.97"},{"price":"0.21","size":"17"},{"price":"0.2","size":"15"},{"price":"0.19","size":"104.75"},{"price":"0.17","size":"38.78"},{"price":"0.16","size":"16.56"},{"price":"0.15","size":"26.25"},{"price":"0.14","size":"525.94"},{"price":"0.12","size":"1011.36"},{"price":"0.11","size":"1010"},{"price":"0.1","size":"44.19"},{"price":"0.08","size":"214.2"},{"price":"0.07","size":"73"},{"price":"0.06","size":"320.16"},{"price":"0.05","size":"270.38"},{"price":"0.04","size":"107.78"},{"price":"0.03","size":"504.14"},{"price":"0.02","size":"1016.53"},{"price":"0.015","size":"5"},{"price":"0.01","size":"1731.32"}],"hash":"8fbb13b70efcbe57e1cc53725f3cd5513671c892","timestamp":"1768359595096","event_type":"book"}
{"market":"0x5977c69bca02e6cc150855b0faec463b38be463f141ec37ea5c8a1a1e986e0d3","asset_id":"110222991870854778724082971333105906777328061970448875974576460135015541883929","bids":[{"price":"0.001","size":"270"},{"price":"0.002","size":"60"},{"price":"0.01","size":"5596.4"},{"price":"0.02","size":"1556.8"},{"price":"0.03","size":"455.5"},{"price":"0.04","size":"219.52"},{"price":"0.05","size":"35"},{"price":"0.1","size":"10"},{"price":"0.12","size":"5"},{"price":"0.15","size":"5"},{"price":"0.2","size":"40"},{"price":"0.25","size":"33.5"},{"price":"0.28","size":"23.14"},{"price":"0.3","size":"226.69"},{"price":"0.32","size":"5"},{"price":"0.34","size":"5"},{"price":"0.35","size":"18.93"},{"price":"0.36","size":"15"},{"price":"0.37","size":"23.13"},{"price":"0.4","size":"34"},{"price":"0.42","size":"23.41"},{"price":"0.43","size":"5"},{"price":"0.44","size":"11"},{"price":"0.45","size":"314.33"},{"price":"0.46","size":"5"},{"price":"0.47","size":"10"},{"price":"0.48","size":"83.05"},{"price":"0.5","size":"20"},{"price":"0.51","size":"102.65"},{"price":"0.52","size":"38"},{"price":"0.56","size":"15"},{"price":"0.57","size":"5"},{"price":"0.58","size":"5"},{"price":"0.59","size":"10"},{"price":"0.6","size":"16"},{"price":"0.61","size":"5"},{"price":"0.63","size":"20.24"},{"price":"0.64","size":"136.18"},{"price":"0.65","size":"150.75"},{"price":"0.66","size":"130.37"},{"price":"0.67","size":"15.12"},{"price":"0.68","size":"110.24"},{"price":"0.69","size":"94.01"},{"price":"0.7","size":"297.5"},{"price":"0.71","size":"302.74"},{"price":"0.72","size":"202.84"},{"price":"0.73","size":"34.37"},{"price":"0.74","size":"115.67"},{"price":"0.75","size":"440.01"},{"price":"0.76","size":"279.24"},{"price":"0.77","size":"90"},{"price":"0.78","size":"9.97"},{"price":"0.79","size":"17"},{"price":"0.8","size":"15"},{"price":"0.81","size":"104.75"},{"price":"0.83","size":"38.78"},{"price":"0.84","size":"16.56"},{"price":"0.85","size":"26.25"},{"price":"0.86","size":"525.94"},{"price":"0.88","size":"1011.36"},{"price":"0.89","size":"1010"},{"price":"0.9","size":"44.19"},{"price":"0.92","size":"214.2"},{"price":"0.93","size":"73"},{"price":"0.94","size":"320.16"},{"price":"0.95","size":"270.38"},{"price":"0.96","size":"107.78"},{"price":"0.97","size":"504.14"},{"price":"0.98","size":"1016.53"},{"price":"0.985","size":"5"},{"price":"0.99","size":"1731.32"}],"asks":[],"hash":"89938316b52f1bd90881da8804386ec293124bf9","timestamp":"1768359595096","event_type":"book"}
{"market":"0x5977c69bca02e6cc150855b0faec463b38be463f141ec37ea5c8a1a1e986e0d3","asset_id":"110222991870854778724082971333105906777328061970448875974576460135015541883929","price":"0.99","size":"16.11","fee_rate_bps":"1000","side":"SELL","timestamp":"1768359595124","event_type":"last_trade_price","transaction_hash":"0x63dd15eb7402f86533d9e624132322defda73c4e276c45e37c34561f774cd4c6"}
{"market":"0x5977c69bca02e6cc150855b0faec463b38be463f141ec37ea5c8a1a1e986e0d3","price_changes":[{"asset_id":"110222991870854778724082971333105906777328061970448875974576460135015541883929","price":"0.98","size":"1002.53","side":"BUY","hash":"254226ca1fdfc43db58f46bf2b3fd72634bc6b43","best_bid":"0.99","best_ask":"1"},{"asset_id":"103575991306220918671611575108050794364462782362354955892418399227289531345027","price":"0.02","size":"1002.53","side":"SELL","hash":"0ef2c47e249cab54f1145c4034d9cd3e59b065e6","best_bid":"0","best_ask":"0.01"}],"timestamp":"1768359595157","event_type":"price_change"}
{"market":"0x5977c69bca02e6cc150855b0faec463b38be463f141ec37ea5c8a1a1e986e0d3","price_changes":[{"asset_id":"110222991870854778724082971333105906777328061970448875974576460135015541883929","price":"0.97","size":"490.14","side":"BUY","hash":"3797c1c6355d5cb913814a7a879f9bdec50bee32","best_bid":"0.99","best_ask":"1"},{"asset_id":"103575991306220918671611575108050794364462782362354955892418399227289531345027","price":"0.03","size":"490.14","side":"SELL","hash":"74ac1d7a0dcca5445ae4603ecc0f0cf5518ff2b9","best_bid":"0","best_ask":"0.01"}],"timestamp":"1768359595159","event_type":"price_change"}
{"market":"0x5977c69bca02e6cc150855b0faec463b38be463f141ec37ea5c8a1a1e986e0d3","price_changes":[{"asset_id":"110222991870854778724082971333105906777328061970448875974576460135015541883929","price":"0.93","size":"60","side":"BUY","hash":"95da1c907ee569eeee77749d0a2534c3ebd34078","best_bid":"0.99","best_ask":"1"},{"asset_id":"103575991306220918671611575108050794364462782362354955892418399227289531345027","price":"0.07","size":"60","side":"SELL","hash":"f75408cf59a8faf4fcb83412e001c77f66292e37","best_bid":"0","best_ask":"0.01"}],"timestamp":"1768359595160","event_type":"price_change"}
{"market":"0x5977c69bca02e6cc150855b0faec463b38be463f141ec37ea5c8a1a1e986e0d3","price_changes":[{"asset_id":"110222991870854778724082971333105906777328061970448875974576460135015541883929","price":"0.97","size":"476.14","side":"BUY","hash":"ef3565398133ee6dc26ba1007845ac95b957c281","best_bid":"0.99","best_ask":"1"},{"asset_id":"103575991306220918671611575108050794364462782362354955892418399227289531345027","price":"0.03","size":"476.14","side":"SELL","hash":"5bec9b80e21490a6dfe29ef5f393b30432a3f926","best_bid":"0","best_ask":"0.01"}],"timestamp":"1768359595161","event_type":"price_change"}
{"market":"0x5977c69bca02e6cc150855b0faec463b38be463f141ec37ea5c8a1a1e986e0d3","price_changes":[{"asset_id":"110222991870854778724082971333105906777328061970448875974576460135015541883929","price":"0.98","size":"988.53","side":"BUY","hash":"f63a8a8855b07523fa48807960f7542899ab6395","best_bid":"0.99","best_ask":"1"},{"asset_id":"103575991306220918671611575108050794364462782362354955892418399227289531345027","price":"0.02","size":"988.53","side":"SELL","hash":"726bdd016dea6c150f66c2c6ce708fb3cff08922","best_bid":"0","best_ask":"0.01"}],"timestamp":"1768359595161","event_type":"price_change"}
{"market":"0x5977c69bca02e6cc150855b0faec463b38be463f141ec37ea5c8a1a1e986e0d3","price_changes":[{"asset_id":"110222991870854778724082971333105906777328061970448875974576460135015541883929","price":"0.79","size":"5","side":"BUY","hash":"ddcc1774f371ec7e0dad65d80e5c497a244821e3","best_bid":"0.99","best_ask":"1"},{"asset_id":"103575991306220918671611575108050794364462782362354955892418399227289531345027","price":"0.21","size":"5","side":"SELL","hash":"732c6031ad9826dfd6179be84b7265dc148beb56","best_bid":"0","best_ask":"0.01"}],"timestamp":"1768359595164","event_type":"price_change"}
{"market":"0x5977c69bca02e6cc150855b0faec463b38be463f141ec37ea5c8a1a1e986e0d3","price_changes":[{"asset_id":"110222991870854778724082971333105906777328061970448875974576460135015541883929","price":"0.98","size":"974.53","side":"BUY","hash":"06420949a41b44f006e8786245f47614ecad731d","best_bid":"0.99","best_ask":"1"},{"asset_id":"103575991306220918671611575108050794364462782362354955892418399227289531345027","price":"0.02","size":"974.53","side":"SELL","hash":"26ccffe383dfccd1b4db680b474330dbf76fe901","best_bid":"0","best_ask":"0.01"}],"timestamp":"1768359595166","event_type":"price_change"}
{"market":"0x5977c69bca02e6cc150855b0faec463b38be463f141ec37ea5c8a1a1e986e0d3","price_changes":[{"asset_id":"110222991870854778724082971333105906777328061970448875974576460135015541883929","price":"0.97","size":"462.14","side":"BUY","hash":"489037531e77525e0ec7fc1ad21ca31c5002cad4","best_bid":"0.99","best_ask":"1"},{"asset_id":"103575991306220918671611575108050794364462782362354955892418399227289531345027","price":"0.03","size":"462.14","side":"SELL","hash":"15e879b871144f17f0624f2349ae379e2d4c28ba","best_bid":"0","best_ask":"0.01"}],"timestamp":"1768359595168","event_type":"price_change"}
PONG
{"market":"0x5977c69bca02e6cc150855b0faec463b38be463f141ec37ea5c8a1a1e986e0d3","price_changes":[{"asset_id":"110222991870854778724082971333105906777328061970448875974576460135015541883929","price":"0.01","size":"4996.4","side":"BUY","hash":"cacec9b53d273d92119588bee92ce816e4038200","best_bid":"0.99","best_ask":"1"},{"asset_id":"103575991306220918671611575108050794364462782362354955892418399227289531345027","price":"0.99","size":"4996.4","side":"SELL","hash":"3e7895227ed70510a070c139569b1d719a134824","best_bid":"0","best_ask":"0.01"}],"timestamp":"1768359595205","event_type":"price_change"}
{"market":"0x5977c69bca02e6cc150855b0faec463b38be463f141ec37ea5c8a1a1e986e0d3","price_changes":[{"asset_id":"110222991870854778724082971333105906777328061970448875974576460135015541883929","price":"0.01","size":"4396.4","side":"BUY","hash":"48544003421647f840ace3951ba593221e70685c","best_bid":"0.99","best_ask":"1"},{"asset_id":"103575991306220918671611575108050794364462782362354955892418399227289531345027","price":"0.99","size":"4396.4","side":"SELL","hash":"ec30c83d3f125de9bbb5c3f9c0b1a4caa2536337","best_bid":"0","best_ask":"0.01"}],"timestamp":"1768359595255","event_type":"price_change"}
{"market":"0x5977c69bca02e6cc150855b0faec463b38be463f141ec37ea5c8a1a1e986e0d3","price_changes":[{"asset_id":"110222991870854778724082971333105906777328061970448875974576460135015541883929","price":"0.01","size":"4496.4","side":"BUY","hash":"added655b84daa3d8ff4771ac5fc1d70a98b7d22","best_bid":"0.99","best_ask":"1"},{"asset_id":"103575991306220918671611575108050794364462782362354955892418399227289531345027","price":"0.99","size":"4496.4","side":"SELL","hash":"ba404c36459b761ae3e79dfdb4592c1c824c2dbf","best_bid":"0","best_ask":"0.01"}],"timestamp":"1768359595456","event_type":"price_change"}
{"market":"0x5977c69bca02e6cc150855b0faec463b38be463f141ec37ea5c8a1a1e986e0d3","price_changes":[{"asset_id":"110222991870854778724082971333105906777328061970448875974576460135015541883929","price":"0.99","size":"1891.32","side":"BUY","hash":"0b6ab872868762b6c4acf43dbd738fb623e64b31","best_bid":"0.99","best_ask":"1"},{"asset_id":"103575991306220918671611575108050794364462782362354955892418399227289531345027","price":"0.01","size":"1891.32","side":"SELL","hash":"c37faa153684f5a307776ee071794adb4652d37b","best_bid":"0","best_ask":"0.01"}],"timestamp":"1768359595613","event_type":"price_change"}
{"market":"0x5977c69bca02e6cc150855b0faec463b38be463f141ec37ea5c8a1a1e986e0d3","price_changes":[{"asset_id":"110222991870854778724082971333105906777328061970448875974576460135015541883929","price":"0.999","size":"7000","side":"BUY","hash":"75a6c19147222091b46da8d8b5864b6422b51167","best_bid":"0.999","best_ask":"1"},{"asset_id":"103575991306220918671611575108050794364462782362354955892418399227289531345027","price":"0.001","size":"7000","side":"SELL","hash":"1d17391f067ca8ee3aee3dd9a915489aa251d42a","best_bid":"0","best_ask":"0.001"}],"timestamp":"1768359595753","event_type":"price_change"}
{"market":"0x5977c69bca02e6cc150855b0faec463b38be463f141ec37ea5c8a1a1e986e0d3","price_changes":[{"asset_id":"110222991870854778724082971333105906777328061970448875974576460135015541883929","price":"0.99","size":"8891.32","side":"BUY","hash":"8d6211e204d6f3eb840e292f405bbf20bfe653c3","best_bid":"0.999","best_ask":"1"},{"asset_id":"103575991306220918671611575108050794364462782362354955892418399227289531345027","price":"0.01","size":"8891.32","side":"SELL","hash":"46b022d6565832e816cd3853f8f9f58406a0ccc0","best_bid":"0","best_ask":"0.001"}],"timestamp":"1768359595758","event_type":"price_change"}
{"market":"0x5977c69bca02e6cc150855b0faec463b38be463f141ec37ea5c8a1a1e986e0d3","price_changes":[{"asset_id":"110222991870854778724082971333105906777328061970448875974576460135015541883929","price":"0.93","size":"50","side":"BUY","hash":"fb7e763935a55cd67723425d8e56fcd33b9bfa34","best_bid":"0.999","best_ask":"1"},{"asset_id":"103575991306220918671611575108050794364462782362354955892418399227289531345027","price":"0.07","size":"50","side":"SELL","hash":"951e13c682e4be96399981c205c197dbc4fc0b9d","best_bid":"0","best_ask":"0.001"}],"timestamp":"1768359595789","event_type":"price_change"}
{"market":"0x5977c69bca02e6cc150855b0faec463b38be463f141ec37ea5c8a1a1e986e0d3","price_changes":[{"asset_id":"110222991870854778724082971333105906777328061970448875974576460135015541883929","price":"0.98","size":"984.53","side":"BUY","hash":"4cb5579333c37208df30e5a42e170aa677a042e7","best_bid":"0.999","best_ask":"1"},{"asset_id":"103575991306220918671611575108050794364462782362354955892418399227289531345027","price":"0.02","size":"984.53","side":"SELL","hash":"2be46c631f93aa62aa162e4c9507204a64e350a7","best_bid":"0","best_ask":"0.001"}],"timestamp":"1768359595790","event_type":"price_change"}
{"market":"0x5977c69bca02e6cc150855b0faec463b38be463f141ec37ea5c8a1a1e986e0d3","price_changes":[{"asset_id":"110222991870854778724082971333105906777328061970448875974576460135015541883929","price":"0.8","size":"5","side":"BUY","hash":"9a07da4ec3832568df2fdfac3ed330fb0f565d6c","best_bid":"0.999","best_ask":"1"},{"asset_id":"103575991306220918671611575108050794364462782362354955892418399227289531345027","price":"0.2","size":"5","side":"SELL","hash":"20dfcbdccabda6f44b9006c3f157e36892032075","best_bid":"0","best_ask":"0.001"}],"timestamp":"1768359595841","event_type":"price_change"}
{"market":"0x5977c69bca02e6cc150855b0faec463b38be463f141ec37ea5c8a1a1e986e0d3","price_changes":[{"asset_id":"110222991870854778724082971333105906777328061970448875974576460135015541883929","price":"0.991","size":"69","side":"BUY","hash":"23af843cced95af0ce75ee22bf9b5954828ee031","best_bid":"0.999","best_ask":"1"},{"asset_id":"103575991306220918671611575108050794364462782362354955892418399227289531345027","price":"0.009","size":"69","side":"SELL","hash":"128a7a4a386d58cd98a1825268ea99026bcfed2c","best_bid":"0","best_ask":"0.001"}],"timestamp":"1768359595847","event_type":"price_change"}
{"market":"0x5977c69bca02e6cc150855b0faec463b38be463f141ec37ea5c8a1a1e986e0d3","price_changes":[{"asset_id":"110222991870854778724082971333105906777328061970448875974576460135015541883929","price":"0.999","size":"7031","side":"BUY","hash":"cded9197a013759411422c07670346a2b81ca0c2","best_bid":"0.999","best_ask":"1"},{"asset_id":"103575991306220918671611575108050794364462782362354955892418399227289531345027","price":"0.001","size":"7031","side":"SELL","hash":"9f4b415ceadda0a6aa3ece4311d1d2c62c978de7","best_bid":"0","best_ask":"0.001"}],"timestamp":"1768359595847","event_type":"price_change"}
{"market":"0x5977c69bca02e6cc150855b0faec463b38be463f141ec37ea5c8a1a1e986e0d3","price_changes":[{"asset_id":"110222991870854778724082971333105906777328061970448875974576460135015541883929","price":"0.8","size":"15","side":"BUY","hash":"c9b4503a036bef90bda261001cb545a3cfaf9d82","best_bid":"0.999","best_ask":"1"},{"asset_id":"103575991306220918671611575108050794364462782362354955892418399227289531345027","price":"0.2","size":"15","side":"SELL","hash":"ca3ec4ee1eabf9af0956ce3cecc4a13e3ad04e89","best_bid":"0","best_ask":"0.001"}],"timestamp":"1768359595863","event_type":"price_change"}
{"market":"0x5977c69bca02e6cc150855b0faec463b38be463f141ec37ea5c8a1a1e986e0d3","price_changes":[{"asset_id":"110222991870854778724082971333105906777328061970448875974576460135015541883929","price":"0.92","size":"117.9","side":"BUY","hash":"02b3601f49f877a5b5a83cfe971d73b746912852","best_bid":"0.999","best_ask":"1"},{"asset_id":"103575991306220918671611575108050794364462782362354955892418399227289531345027","price":"0.08","size":"117.9","side":"SELL","hash":"a3e58cf737897adc9d849b0d205db7de529514b6","best_bid":"0","best_ask":"0.001"}],"timestamp":"1768359596017","event_type":"price_change"}
{"market":"0x5977c69bca02e6cc150855b0faec463b38be463f141ec37ea5c8a1a1e986e0d3","price_changes":[{"asset_id":"110222991870854778724082971333105906777328061970448875974576460135015541883929","price":"0.92","size":"25","side":"BUY","hash":"b27a4a76d66c0631686f564a24878ad5e9db9a97","best_bid":"0.999","best_ask":"1"},{"asset_id":"103575991306220918671611575108050794364462782362354955892418399227289531345027","price":"0.08","size":"25","side":"SELL","hash":"38c063663f682b8d9ae00d32960df1c9a1328b47","best_bid":"0","best_ask":"0.001"}],"timestamp":"1768359596018","event_type":"price_change"}
{"market":"0x5977c69bca02e6cc150855b0faec463b38be463f141ec37ea5c8a1a1e986e0d3","price_changes":[{"asset_id":"110222991870854778724082971333105906777328061970448875974576460135015541883929","price":"0.994","size":"57","side":"BUY","hash":"2f1965750d8d133ed30f818406dd8e550f88f759","best_bid":"0.999","best_ask":"1"},{"asset_id":"103575991306220918671611575108050794364462782362354955892418399227289531345027","price":"0.006","size":"57","side":"SELL","hash":"624321b7b860df21acf728829fb8bfa2495e9d18","best_bid":"0","best_ask":"0.001"}],"timestamp":"1768359596141","event_type":"price_change"}
{"market":"0x5977c69bca02e6cc150855b0faec463b38be463f141ec37ea5c8a1a1e986e0d3","price_changes":[{"asset_id":"110222991870854778724082971333105906777328061970448875974576460135015541883929","price":"0.996","size":"44","side":"BUY","hash":"984ee8107a0446c6eeeadf8c57c3e4d40ed8635e","best_bid":"0.999","best_ask":"1"},{"asset_id":"103575991306220918671611575108050794364462782362354955892418399227289531345027","price":"0.004","size":"44","side":"SELL","hash":"dd2f2b906e3411e7ad9899489e98cbaab93784c4","best_bid":"0","best_ask":"0.001"}],"timestamp":"1768359596141","event_type":"price_change"}
{"market":"0x5977c69bca02e6cc150855b0faec463b38be463f141ec37ea5c8a1a1e986e0d3","price_changes":[{"asset_id":"110222991870854778724082971333105906777328061970448875974576460135015541883929","price":"0.99","size":"8896.32","side":"BUY","hash":"841d2582b546f5c6e3d65bf0bc3f4b21bdce168e","best_bid":"0.999","best_ask":"1"},{"asset_id":"103575991306220918671611575108050794364462782362354955892418399227289531345027","price":"0.01","size":"8896.32","side":"SELL","hash":"c76d534710984dc85fdeb2c1aa4e2b30905ce382","best_bid":"0","best_ask":"0.001"}],"timestamp":"1768359596576","event_type":"price_change"}
{"market":"0x5977c69bca02e6cc150855b0faec463b38be463f141ec37ea5c8a1a1e986e0d3","price_changes":[{"asset_id":"110222991870854778724082971333105906777328061970448875974576460135015541883929","price":"0.99","size":"8901.32","side":"BUY","hash":"9453cf683468426ab8f267143966228c34e7c507","best_bid":"0.999","best_ask":"1"},{"asset_id":"103575991306220918671611575108050794364462782362354955892418399227289531345027","price":"0.01","size":"8901.32","side":"SELL","hash":"7b60cb92908a93300df6e3fd27c8172e8b5c8573","best_bid":"0","best_ask":"0.001"}],"timestamp":"1768359596747","event_type":"price_change"}
{"market":"0x5977c69bca02e6cc150855b0faec463b38be463f141ec37ea5c8a1a1e986e0d3","price_changes":[{"asset_id":"110222991870854778724082971333105906777328061970448875974576460135015541883929","price":"0.99","size":"8906.32","side":"BUY","hash":"906338484af06ffa6b025e8809d6ed4a6f7cf060","best_bid":"0.999","best_ask":"1"},{"asset_id":"103575991306220918671611575108050794364462782362354955892418399227289531345027","price":"0.01","size":"8906.32","side":"SELL","hash":"582dc529323144dea921283d5b966707e0fdff3e","best_bid":"0","best_ask":"0.001"}],"timestamp":"1768359596804","event_type":"price_change"}
{"market":"0x5977c69bca02e6cc150855b0faec463b38be463f141ec37ea5c8a1a1e986e0d3","price_changes":[{"asset_id":"110222991870854778724082971333105906777328061970448875974576460135015541883929","price":"0.8","size":"5","side":"BUY","hash":"49629416160036da6d37e4f5d7bc3b1834d51dd1","best_bid":"0.999","best_ask":"1"},{"asset_id":"103575991306220918671611575108050794364462782362354955892418399227289531345027","price":"0.2","size":"5","side":"SELL","hash":"50a8d53ed96046b696624ae15b26bf0256a1cc5e","best_bid":"0","best_ask":"0.001"}],"timestamp":"1768359596945","event_type":"price_change"}
{"market":"0x5977c69bca02e6cc150855b0faec463b38be463f141ec37ea5c8a1a1e986e0d3","price_changes":[{"asset_id":"110222991870854778724082971333105906777328061970448875974576460135015541883929","price":"0.8","size":"15","side":"BUY","hash":"80c5e07012ee2b4ec9208bdf869679ec3e4d7f00","best_bid":"0.999","best_ask":"1"},{"asset_id":"103575991306220918671611575108050794364462782362354955892418399227289531345027","price":"0.2","size":"15","side":"SELL","hash":"6d1a5a6456a321cba64afeece62bf3665c509856","best_bid":"0","best_ask":"0.001"}],"timestamp":"1768359596971","event_type":"price_change"}
{"market":"0x5977c69bca02e6cc150855b0faec463b38be463f141ec37ea5c8a1a1e986e0d3","price_changes":[{"asset_id":"110222991870854778724082971333105906777328061970448875974576460135015541883929","price":"0.99","size":"9906.32","side":"BUY","hash":"d077beae98193fa5b144cb005e1f337243653103","best_bid":"0.999","best_ask":"1"},{"asset_id":"103575991306220918671611575108050794364462782362354955892418399227289531345027","price":"0.01","size":"9906.32","side":"SELL","hash":"448b09ed78624476d4d3b0c088bb3909af02d3ac","best_bid":"0","best_ask":"0.001"}],"timestamp":"1768359597179","event_type":"price_change"}
{"market":"0x5977c69bca02e6cc150855b0faec463b38be463f141ec37ea5c8a1a1e986e0d3","price_changes":[{"asset_id":"110222991870854778724082971333105906777328061970448875974576460135015541883929","price":"0.99","size":"10006.32","side":"BUY","hash":"0a769d61d587ca286ba3b8cbe99f218ce4b939a6","best_bid":"0.999","best_ask":"1"},{"asset_id":"103575991306220918671611575108050794364462782362354955892418399227289531345027","price":"0.01","size":"10006.32","side":"SELL","hash":"a02924a17580bf4be91966d5ef8b17535fbe1b3b","best_bid":"0","best_ask":"0.001"}],"timestamp":"1768359597234","event_type":"price_change"}
{"market":"0x5977c69bca02e6cc150855b0faec463b38be463f141ec37ea5c8a1a1e986e0d3","price_changes":[{"asset_id":"110222991870854778724082971333105906777328061970448875974576460135015541883929","price":"0.8","size":"5","side":"BUY","hash":"084e4000fe72663f033c41750ffbb800e81d9163","best_bid":"0.999","best_ask":"1"},{"asset_id":"103575991306220918671611575108050794364462782362354955892418399227289531345027","price":"0.2","size":"5","side":"SELL","hash":"5376c522de9036d6c27c9e4eafa48fb40144329b","best_bid":"0","best_ask":"0.001"}],"timestamp":"1768359598040","event_type":"price_change"}
{"market":"0x5977c69bca02e6cc150855b0faec463b38be463f141ec37ea5c8a1a1e986e0d3","price_changes":[{"asset_id":"110222991870854778724082971333105906777328061970448875974576460135015541883929","price":"0.8","size":"15","side":"BUY","hash":"7f5a4b525f868c56663f29957ee11512d9580492","best_bid":"0.999","best_ask":"1"},{"asset_id":"103575991306220918671611575108050794364462782362354955892418399227289531345027","price":"0.2","size":"15","side":"SELL","hash":"2855f0ac81643bc69ef9fcf32539e3b7af701933","best_bid":"0","best_ask":"0.001"}],"timestamp":"1768359598068","event_type":"price_change"}
{"market":"0x5977c69bca02e6cc150855b0faec463b38be463f141ec37ea5c8a1a1e986e0d3","price_changes":[{"asset_id":"110222991870854778724082971333105906777328061970448875974576460135015541883929","price":"0.99","size":"10763.32","side":"BUY","hash":"64ea96ed4b26d27c4446b1799243783145d73515","best_bid":"0.999","best_ask":"1"},{"asset_id":"103575991306220918671611575108050794364462782362354955892418399227289531345027","price":"0.01","size":"10763.32","side":"SELL","hash":"3ef27496aba091aeb63739a541f9f49ec1d5ee6c","best_bid":"0","best_ask":"0.001"}],"timestamp":"1768359598455","event_type":"price_change"}
{"market":"0x5977c69bca02e6cc150855b0faec463b38be463f141ec37ea5c8a1a1e986e0d3","price_changes":[{"asset_id":"110222991870854778724082971333105906777328061970448875974576460135015541883929","price":"0.99","size":"11201.32","side":"BUY","hash":"90e18053836a32d142ad94e83c8c350205e8a205","best_bid":"0.999","best_ask":"1"},{"asset_id":"103575991306220918671611575108050794364462782362354955892418399227289531345027","price":"0.01","size":"11201.32","side":"SELL","hash":"ce0fccc824a3545427b29eefd301a1655793689a","best_bid":"0","best_ask":"0.001"}],"timestamp":"1768359598765","event_type":"price_change"}
{"market":"0x5977c69bca02e6cc150855b0faec463b38be463f141ec37ea5c8a1a1e986e0d3","price_changes":[{"asset_id":"110222991870854778724082971333105906777328061970448875974576460135015541883929","price":"0.999","size":"7026","side":"BUY","hash":"634d8ff548e193144d7e0aef8879d321a86c9499","best_bid":"0.999","best_ask":"1"},{"asset_id":"103575991306220918671611575108050794364462782362354955892418399227289531345027","price":"0.001","size":"7026","side":"SELL","hash":"b70f576b47d4d76ce777e4d6b45cca630e511870","best_bid":"0","best_ask":"0.001"}],"timestamp":"1768359598828","event_type":"price_change"}
{"market":"0x5977c69bca02e6cc150855b0faec463b38be463f141ec37ea5c8a1a1e986e0d3","asset_id":"103575991306220918671611575108050794364462782362354955892418399227289531345027","bids":[],"asks":[{"price":"0.999","size":"270"},{"price":"0.998","size":"60"},{"price":"0.99","size":"4496.4"},{"price":"0.98","size":"1556.8"},{"price":"0.97","size":"455.5"},{"price":"0.96","size":"219.52"},{"price":"0.95","size":"35"},{"price":"0.9","size":"10"},{"price":"0.88","size":"5"},{"price":"0.85","size":"5"},{"price":"0.8","size":"40"},{"price":"0.75","size":"33.5"},{"price":"0.72","size":"23.14"},{"price":"0.7","size":"226.69"},{"price":"0.68","size":"5"},{"price":"0.66","size":"5"},{"price":"0.65","size":"18.93"},{"price":"0.64","size":"15"},{"price":"0.63","size":"23.13"},{"price":"0.6","size":"34"},{"price":"0.58","size":"23.41"},{"price":"0.57","size":"5"},{"price":"0.56","size":"11"},{"price":"0.55","size":"314.33"},{"price":"0.54","size":"5"},{"price":"0.53","size":"10"},{"price":"0.52","size":"83.05"},{"price":"0.5","size":"20"},{"price":"0.49","size":"102.65"},{"price":"0.48","size":"38"},{"price":"0.44","size":"15"},{"price":"0.43","size":"5"},{"price":"0.42","size":"5"},{"price":"0.41","size":"10"},{"price":"0.4","size":"16"},{"price":"0.39","size":"5"},{"price":"0.37","size":"20.24"},{"price":"0.36","size":"136.18"},{"price":"0.35","size":"150.75"},{"price":"0.34","size":"130.37"},{"price":"0.33","size":"15.12"},{"price":"0.32","size":"110.24"},{"price":"0.31","size":"94.01"},{"price":"0.3","size":"297.5"},{"price":"0.29","size":"302.74"},{"price":"0.28","size":"202.84"},{"price":"0.27","size":"34.37"},{"price":"0.26","size":"115.67"},{"price":"0.25","size":"440.01"},{"price":"0.24","size":"279.24"},{"price":"0.23","size":"90"},{"price":"0.22","size":"9.97"},{"price":"0.21","size":"5"},{"price":"0.2","size":"15"},{"price":"0.19","size":"104.75"},{"price":"0.17","size":"38.78"},{"price":"0.16","size":"16.56"},{"price":"0.15","size":"26.25"},{"price":"0.14","size":"525.94"},{"price":"0.12","size":"1011.36"},{"price":"0.11","size":"1010"},{"price":"0.1","size":"44.19"},{"price":"0.08","size":"25"},{"price":"0.07","size":"50"},{"price":"0.06","size":"320.16"},{"price":"0.05","size":"270.38"},{"price":"0.04","size":"107.78"},{"price":"0.03","size":"462.14"},{"price":"0.02","size":"984.53"},{"price":"0.015","size":"5"},{"price":"0.01","size":"11201.32"},{"price":"0.009","size":"69"},{"price":"0.006","size":"57"},{"price":"0.004","size":"44"},{"price":"0.001","size":"7026"}],"hash":"b70f576b47d4d76ce777e4d6b45cca630e511870","timestamp":"1768359598828","event_type":"book"}
{"market":"0x5977c69bca02e6cc150855b0faec463b38be463f141ec37ea5c8a1a1e986e0d3","asset_id":"110222991870854778724082971333105906777328061970448875974576460135015541883929","bids":[{"price":"0.001","size":"270"},{"price":"0.002","size":"60"},{"price":"0.01","size":"4496.4"},{"price":"0.02","size":"1556.8"},{"price":"0.03","size":"455.5"},{"price":"0.04","size":"219.52"},{"price":"0.05","size":"35"},{"price":"0.1","size":"10"},{"price":"0.12","size":"5"},{"price":"0.15","size":"5"},{"price":"0.2","size":"40"},{"price":"0.25","size":"33.5"},{"price":"0.28","size":"23.14"},{"price":"0.3","size":"226.69"},{"price":"0.32","size":"5"},{"price":"0.34","size":"5"},{"price":"0.35","size":"18.93"},{"price":"0.36","size":"15"},{"price":"0.37","size":"23.13"},{"price":"0.4","size":"34"},{"price":"0.42","size":"23.41"},{"price":"0.43","size":"5"},{"price":"0.44","size":"11"},{"price":"0.45","size":"314.33"},{"price":"0.46","size":"5"},{"price":"0.47","size":"10"},{"price":"0.48","size":"83.05"},{"price":"0.5","size":"20"},{"price":"0.51","size":"102.65"},{"price":"0.52","size":"38"},{"price":"0.56","size":"15"},{"price":"0.57","size":"5"},{"price":"0.58","size":"5"},{"price":"0.59","size":"10"},{"price":"0.6","size":"16"},{"price":"0.61","size":"5"},{"price":"0.63","size":"20.24"},{"price":"0.64","size":"136.18"},{"price":"0.65","size":"150.75"},{"price":"0.66","size":"130.37"},{"price":"0.67","size":"15.12"},{"price":"0.68","size":"110.24"},{"price":"0.69","size":"94.01"},{"price":"0.7","size":"297.5"},{"price":"0.71","size":"302.74"},{"price":"0.72","size":"202.84"},{"price":"0.73","size":"34.37"},{"price":"0.74","size":"115.67"},{"price":"0.75","size":"440.01"},{"price":"0.76","size":"279.24"},{"price":"0.77","size":"90"},{"price":"0.78","size":"9.97"},{"price":"0.79","size":"5"},{"price":"0.8","size":"15"},{"price":"0.81","size":"104.75"},{"price":"0.83","size":"38.78"},{"price":"0.84","size":"16.56"},{"price":"0.85","size":"26.25"},{"price":"0.86","size":"525.94"},{"price":"0.88","size":"1011.36"},{"price":"0.89","size":"1010"},{"price":"0.9","size":"44.19"},{"price":"0.92","size":"25"},{"price":"0.93","size":"50"},{"price":"0.94","size":"320.16"},{"price":"0.95","size":"270.38"},{"price":"0.96","size":"107.78"},{"price":"0.97","size":"462.14"},{"price":"0.98","size":"984.53"},{"price":"0.985","size":"5"},{"price":"0.99","size":"11201.32"},{"price":"0.991","size":"69"},{"price":"0.994","size":"57"},{"price":"0.996","size":"44"},{"price":"0.999","size":"7026"}],"asks":[],"hash":"634d8ff548e193144d7e0aef8879d321a86c9499","timestamp":"1768359598828","event_type":"book"}
{"market":"0x5977c69bca02e6cc150855b0faec463b38be463f141ec37ea5c8a1a1e986e0d3","asset_id":"103575991306220918671611575108050794364462782362354955892418399227289531345027","price":"0.001","size":"5","fee_rate_bps":"1000","side":"BUY","timestamp":"1768359598857","event_type":"last_trade_price","transaction_hash":"0x77151b63b11a5cb6094081e86ede32690fd593de41170a63468d399a1ca31a41"}
{"market":"0x5977c69bca02e6cc150855b0faec463b38be463f141ec37ea5c8a1a1e986e0d3","price_changes":[{"asset_id":"110222991870854778724082971333105906777328061970448875974576460135015541883929","price":"0.999","size":"7135.5","side":"BUY","hash":"6b7ec8a0facbabd45ade5fe5b2c2c251bcd36832","best_bid":"0.999","best_ask":"1"},{"asset_id":"103575991306220918671611575108050794364462782362354955892418399227289531345027","price":"0.001","size":"7135.5","side":"SELL","hash":"f2ce7611715bcb69907dc4dbaa08a066ff064690","best_bid":"0","best_ask":"0.001"}],"timestamp":"1768359598948","event_type":"price_change"}
{"market":"0x5977c69bca02e6cc150855b0faec463b38be463f141ec37ea5c8a1a1e986e0d3","price_changes":[{"asset_id":"110222991870854778724082971333105906777328061970448875974576460135015541883929","price":"0.8","size":"5","side":"BUY","hash":"3ce0ccbe571c9a3e807be539ae163182fd04146b","best_bid":"0.999","best_ask":"1"},{"asset_id":"103575991306220918671611575108050794364462782362354955892418399227289531345027","price":"0.2","size":"5","side":"SELL","hash":"d6730349ad28cf7f3c08e729956f1db303ab06fd","best_bid":"0","best_ask":"0.001"}],"timestamp":"1768359599141","event_type":"price_change"}
{"market":"0x5977c69bca02e6cc150855b0faec463b38be463f141ec37ea5c8a1a1e986e0d3","price_changes":[{"asset_id":"110222991870854778724082971333105906777328061970448875974576460135015541883929","price":"0.8","size":"15","side":"BUY","hash":"c527b4343445a6076ffa8442bfb0eed105467c76","best_bid":"0.999","best_ask":"1"},{"asset_id":"103575991306220918671611575108050794364462782362354955892418399227289531345027","price":"0.2","size":"15","side":"SELL","hash":"dc0080ea2a7474ae069854e00f96ccea34d1082d","best_bid":"0","best_ask":"0.001"}],"timestamp":"1768359599166","event_type":"price_change"}
{"market":"0x5977c69bca02e6cc150855b0faec463b38be463f141ec37ea5c8a1a1e986e0d3","price_changes":[{"asset_id":"110222991870854778724082971333105906777328061970448875974576460135015541883929","price":"0.99","size":"11515.74","side":"BUY","hash":"a8cd708f4b00edaeeab0fe24f5ce3f6df3c9fe6e","best_bid":"0.999","best_ask":"1"},{"asset_id":"103575991306220918671611575108050794364462782362354955892418399227289531345027","price":"0.01","size":"11515.74","side":"SELL","hash":"22b7296af1b4f425a37f0d27816a058623fdde38","best_bid":"0","best_ask":"0.001"}],"timestamp":"1768359599209","event_type":"price_change"}
{"market":"0x5977c69bca02e6cc150855b0faec463b38be463f141ec37ea5c8a1a1e986e0d3","price_changes":[{"asset_id":"110222991870854778724082971333105906777328061970448875974576460135015541883929","price":"0.99","size":"15534.87","side":"BUY","hash":"34283192e166e06a3d293979736ab7e2c1224fee","best_bid":"0.999","best_ask":"1"},{"asset_id":"103575991306220918671611575108050794364462782362354955892418399227289531345027","price":"0.01","size":"15534.87","side":"SELL","hash":"19bee4bfd0c4a60c9f11e5554189bdff51ee89f7","best_bid":"0","best_ask":"0.001"}],"timestamp":"1768359599265","event_type":"price_change"}
{"market":"0x5977c69bca02e6cc150855b0faec463b38be463f141ec37ea5c8a1a1e986e0d3","price_changes":[{"asset_id":"110222991870854778724082971333105906777328061970448875974576460135015541883929","price":"0.99","size":"15585.37","side":"BUY","hash":"d5933b2a5ab933851f8a48b623ccacf32b13bf02","best_bid":"0.999","best_ask":"1"},{"asset_id":"103575991306220918671611575108050794364462782362354955892418399227289531345027","price":"0.01","size":"15585.37","side":"SELL","hash":"53d8955b0e8d8ccd0c16c7f46674a4c448b2c200","best_bid":"0","best_ask":"0.001"}],"timestamp":"1768359599688","event_type":"price_change"}
{"market":"0x5977c69bca02e6cc150855b0faec463b38be463f141ec37ea5c8a1a1e986e0d3","price_changes":[{"asset_id":"110222991870854778724082971333105906777328061970448875974576460135015541883929","price":"0.99","size":"16412.38","side":"BUY","hash":"b79b42f654fb1b0a6f73087c25e3560f6580e0aa","best_bid":"0.999","best_ask":"1"},{"asset_id":"103575991306220918671611575108050794364462782362354955892418399227289531345027","price":"0.01","size":"16412.38","side":"SELL","hash":"ad49b4950c322b4aaf964f23147fcd8040aaff91","best_bid":"0","best_ask":"0.001"}],"timestamp":"1768359599693","event_type":"price_change"}
{"market":"0x5977c69bca02e6cc150855b0faec463b38be463f141ec37ea5c8a1a1e986e0d3","price_changes":[{"asset_id":"110222991870854778724082971333105906777328061970448875974576460135015541883929","price":"0.74","size":"110.67","side":"BUY","hash":"e6dd25050d50573c58d3befa6760941be63a8660","best_bid":"0.999","best_ask":"1"},{"asset_id":"103575991306220918671611575108050794364462782362354955892418399227289531345027","price":"0.26","size":"110.67","side":"SELL","hash":"83147341c9eef5d19cd17422742fa7a35aa46881","best_bid":"0","best_ask":"0.001"}],"timestamp":"1768359599774","event_type":"price_change"}
{"market":"0x5977c69bca02e6cc150855b0faec463b38be463f141ec37ea5c8a1a1e986e0d3","price_changes":[{"asset_id":"110222991870854778724082971333105906777328061970448875974576460135015541883929","price":"0.999","size":"12135.5","side":"BUY","hash":"ffda2a34d6ab8121c880ded469af944cc433ee0a","best_bid":"0.999","best_ask":"1"},{"asset_id":"103575991306220918671611575108050794364462782362354955892418399227289531345027","price":"0.001","size":"12135.5","side":"SELL","hash":"382f568620de48e1052bfe9c919fd1fafde8a808","best_bid":"0","best_ask":"0.001"}],"timestamp":"1768359599836","event_type":"price_change"}
{"market":"0x5977c69bca02e6cc150855b0faec463b38be463f141ec37ea5c8a1a1e986e0d3","price_changes":[{"asset_id":"110222991870854778724082971333105906777328061970448875974576460135015541883929","price":"0.999","size":"12143.32","side":"BUY","hash":"b8e7222bdf252a08787eb4e750558812fa06f254","best_bid":"0.999","best_ask":"1"},{"asset_id":"103575991306220918671611575108050794364462782362354955892418399227289531345027","price":"0.001","size":"12143.32","side":"SELL","hash":"89cbc9ef15d9474d7add677e240d3c4dca35ab8b","best_bid":"0","best_ask":"0.001"}],"timestamp":"1768359599970","event_type":"price_change"}
{"market":"0x5977c69bca02e6cc150855b0faec463b38be463f141ec37ea5c8a1a1e986e0d3","price_changes":[{"asset_id":"110222991870854778724082971333105906777328061970448875974576460135015541883929","price":"0.999","size":"19143.32","side":"BUY","hash":"676fb7750cd6b3d6d6c618eea36ffe4423f26fe9","best_bid":"0.999","best_ask":"1"},{"asset_id":"103575991306220918671611575108050794364462782362354955892418399227289531345027","price":"0.001","size":"19143.32","side":"SELL","hash":"aa382f5be41b002bb301a559088ada49958244ac","best_bid":"0","best_ask":"0.001"}],"timestamp":"1768359599994","event_type":"price_change"}
{"market":"0x5977c69bca02e6cc150855b0faec463b38be463f141ec37ea5c8a1a1e986e0d3","price_changes":[{"asset_id":"110222991870854778724082971333105906777328061970448875974576460135015541883929","price":"0.02","size":"1456.8","side":"BUY","hash":"ee5b0280f8bd29d8d31be8601630461cb66a0155","best_bid":"0.999","best_ask":"1"},{"asset_id":"103575991306220918671611575108050794364462782362354955892418399227289531345027","price":"0.98","size":"1456.8","side":"SELL","hash":"69f93398b90bf4d997db1b318d49277f27cb10de","best_bid":"0","best_ask":"0.001"}],"timestamp":"1768359600036","event_type":"price_change"}
{"market":"0x5977c69bca02e6cc150855b0faec463b38be463f141ec37ea5c8a1a1e986e0d3","price_changes":[{"asset_id":"110222991870854778724082971333105906777328061970448875974576460135015541883929","price":"0.99","size":"23412.38","side":"BUY","hash":"c012285efc46c6cf4f2a8bf2ca5e1f5e810255a2","best_bid":"0.999","best_ask":"1"},{"asset_id":"103575991306220918671611575108050794364462782362354955892418399227289531345027","price":"0.01","size":"23412.38","side":"SELL","hash":"0b66c093e31059d1b2980be64f624bc23934a0e0","best_bid":"0","best_ask":"0.001"}],"timestamp":"1768359600065","event_type":"price_change"}
{"market":"0x5977c69bca02e6cc150855b0faec463b38be463f141ec37ea5c8a1a1e986e0d3","price_changes":[{"asset_id":"110222991870854778724082971333105906777328061970448875974576460135015541883929","price":"0.8","size":"5","side":"BUY","hash":"852ae8e27d1a0743411bdaad4c2132587057f127","best_bid":"0.999","best_ask":"1"},{"asset_id":"103575991306220918671611575108050794364462782362354955892418399227289531345027","price":"0.2","size":"5","side":"SELL","hash":"7a3f01577d68a588871c5133d34d549c9e4eaba2","best_bid":"0","best_ask":"0.001"}],"timestamp":"1768359600089","event_type":"price_change"}
{"market":"0x5977c69bca02e6cc150855b0faec463b38be463f141ec37ea5c8a1a1e986e0d3","price_changes":[{"asset_id":"110222991870854778724082971333105906777328061970448875974576460135015541883929","price":"0.42","size":"33.41","side":"BUY","hash":"3feaed5c169287b8d6ff9d327db60a12f0b49fee","best_bid":"0.999","best_ask":"1"},{"asset_id":"103575991306220918671611575108050794364462782362354955892418399227289531345027","price":"0.58","size":"33.41","side":"SELL","hash":"aa84d3b26599f24524682b7d822801d3f9a2d8a5","best_bid":"0","best_ask":"0.001"}],"timestamp":"1768359600114","event_type":"price_change"}
PONG
{"market":"0x5977c69bca02e6cc150855b0faec463b38be463f141ec37ea5c8a1a1e986e0d3","price_changes":[{"asset_id":"110222991870854778724082971333105906777328061970448875974576460135015541883929","price":"0.96","size":"101.78","side":"BUY","hash":"baea4a45c3ffda35ce6d56a3a3e1ed7b2215a287","best_bid":"0.999","best_ask":"1"},{"asset_id":"103575991306220918671611575108050794364462782362354955892418399227289531345027","price":"0.04","size":"101.78","side":"SELL","hash":"86e9dbda547f8868e982227c982f165a367633c4","best_bid":"0","best_ask":"0.001"}],"timestamp":"1768359600141","event_type":"price_change"}
{"market":"0x5977c69bca02e6cc150855b0faec463b38be463f141ec37ea5c8a1a1e986e0d3","price_changes":[{"asset_id":"110222991870854778724082971333105906777328061970448875974576460135015541883929","price":"0.95","size":"262.3","side":"BUY","hash":"35061d984c6ebd72ab939789305613cd16e1dbe2","best_bid":"0.999","best_ask":"1"},{"asset_id":"103575991306220918671611575108050794364462782362354955892418399227289531345027","price":"0.05","size":"262.3","side":"SELL","hash":"3bcccb94261eabffea3193689a649e5efea37a70","best_bid":"0","best_ask":"0.001"}],"timestamp":"1768359600151","event_type":"price_change"}
{"market":"0x5977c69bca02e6cc150855b0faec463b38be463f141ec37ea5c8a1a1e986e0d3","price_changes":[{"asset_id":"103575991306220918671611575108050794364462782362354955892418399227289531345027","price":"0.48","size":"10","side":"SELL","hash":"d0255793d5c149ed4850f07a92cc52d9f772fed6","best_bid":"0","best_ask":"0.001"},{"asset_id":"110222991870854778724082971333105906777328061970448875974576460135015541883929","price":"0.52","size":"10","side":"BUY","hash":"895a7fbe52b540dc30947d46e4fd357c3327d44e","best_bid":"0.999","best_ask":"1"}],"timestamp":"1768359600787","event_type":"price_change"}
{"market":"0x5977c69bca02e6cc150855b0faec463b38be463f141ec37ea5c8a1a1e986e0d3","price_changes":[{"asset_id":"103575991306220918671611575108050794364462782362354955892418399227289531345027","price":"0.4","size":"0","side":"SELL","hash":"d0255793d5c149ed4850f07a92cc52d9f772fed6","best_bid":"0","best_ask":"0.001"},{"asset_id":"110222991870854778724082971333105906777328061970448875974576460135015541883929","price":"0.6","size":"0","side":"BUY","hash":"895a7fbe52b540dc30947d46e4fd357c3327d44e","best_bid":"0.999","best_ask":"1"}],"timestamp":"1768359600787","event_type":"price_change"}
{"market":"0x5977c69bca02e6cc150855b0faec463b38be463f141ec37ea5c8a1a1e986e0d3","price_changes":[{"asset_id":"110222991870854778724082971333105906777328061970448875974576460135015541883929","price":"0.749","size":"5","side":"BUY","hash":"c664e3deae40f413ddfc5c142d8e50c61a1fa328","best_bid":"0.999","best_ask":"1"},{"asset_id":"103575991306220918671611575108050794364462782362354955892418399227289531345027","price":"0.251","size":"5","side":"SELL","hash":"35a102f5496773de4aace6f85218100a5aa672eb","best_bid":"0","best_ask":"0.001"}],"timestamp":"1768359600790","event_type":"price_change"}
{"market":"0x5977c69bca02e6cc150855b0faec463b38be463f141ec37ea5c8a1a1e986e0d3","price_changes":[{"asset_id":"110222991870854778724082971333105906777328061970448875974576460135015541883929","price":"0.8","size":"10","side":"BUY","hash":"3fb534fb92e5dbe564991f8f5b7b2f4ca9d32115","best_bid":"0.999","best_ask":"1"},{"asset_id":"103575991306220918671611575108050794364462782362354955892418399227289531345027","price":"0.2","size":"10","side":"SELL","hash":"3554a76a7b3ed68e031a63f2a518c8c96b6e3770","best_bid":"0","best_ask":"0.001"}],"timestamp":"1768359600916","event_type":"price_change"}
{"market":"0x5977c69bca02e6cc150855b0faec463b38be463f141ec37ea5c8a1a1e986e0d3","price_changes":[{"asset_id":"103575991306220918671611575108050794364462782362354955892418399227289531345027","price":"0.06","size":"260.16","side":"SELL","hash":"e5c88fbbab90bbb6dcf540dce78889e195323061","best_bid":"0","best_ask":"0.001"},{"asset_id":"110222991870854778724082971333105906777328061970448875974576460135015541883929","price":"0.94","size":"260.16","side":"BUY","hash":"4b1f885607e5f261b0618e6780012b6a443c0a49","best_bid":"0.999","best_ask":"1"}],"timestamp":"1768359601000","event_type":"price_change"}
{"market":"0x5977c69bca02e6cc150855b0faec463b38be463f141ec37ea5c8a1a1e986e0d3","price_changes":[{"asset_id":"110222991870854778724082971333105906777328061970448875974576460135015541883929","price":"0.02","size":"1406.8","side":"BUY","hash":"5cb0df9d3d06806b61e53b171c345cc9ce3264ff","best_bid":"0.999","best_ask":"1"},{"asset_id":"103575991306220918671611575108050794364462782362354955892418399227289531345027","price":"0.98","size":"1406.8","side":"SELL","hash":"87616f103d48ed33697bc5ae06a762ba7c276433","best_bid":"0","best_ask":"0.001"}],"timestamp":"1768359601004","event_type":"price_change"}
{"market":"0x5977c69bca02e6cc150855b0faec463b38be463f141ec37ea5c8a1a1e986e0d3","price_changes":[{"asset_id":"110222991870854778724082971333105906777328061970448875974576460135015541883929","price":"0.42","size":"23.41","side":"BUY","hash":"63d6cf8ca67bd0f9bdcc8dab94f90cc31fe3a5c7","best_bid":"0.999","best_ask":"1"},{"asset_id":"103575991306220918671611575108050794364462782362354955892418399227289531345027","price":"0.58","size":"23.41","side":"SELL","hash":"6af7b0a0854222d2975e5f56075f38e0332519b3","best_bid":"0","best_ask":"0.001"}],"timestamp":"1768359601196","event_type":"price_change"}
{"market":"0x5977c69bca02e6cc150855b0faec463b38be463f141ec37ea5c8a1a1e986e0d3","price_changes":[{"asset_id":"110222991870854778724082971333105906777328061970448875974576460135015541883929","price":"0.42","size":"33.41","side":"BUY","hash":"ae35befde26233634ad5a974b9d14bb722d045a1","best_bid":"0.999","best_ask":"1"},{"asset_id":"103575991306220918671611575108050794364462782362354955892418399227289531345027","price":"0.58","size":"33.41","side":"SELL","hash":"78b1eea70d6b30d62d37851a724e416d728cade9","best_bid":"0","best_ask":"0.001"}],"timestamp":"1768359601227","event_type":"price_change"}
{"market":"0x5977c69bca02e6cc150855b0faec463b38be463f141ec37ea5c8a1a1e986e0d3","price_changes":[{"asset_id":"110222991870854778724082971333105906777328061970448875974576460135015541883929","price":"0.99","size":"28293.38","side":"BUY","hash":"77a94e57343cb13db993442ea8845594a9adb155","best_bid":"0.999","best_ask":"1"},{"asset_id":"103575991306220918671611575108050794364462782362354955892418399227289531345027","price":"0.01","size":"28293.38","side":"SELL","hash":"0dbf6606f7425e21619b7e20a330dee53525591e","best_bid":"0","best_ask":"0.001"}],"timestamp":"1768359601292","event_type":"price_change"}
{"market":"0x5977c69bca02e6cc150855b0faec463b38be463f141ec37ea5c8a1a1e986e0d3","price_changes":[{"asset_id":"110222991870854778724082971333105906777328061970448875974576460135015541883929","price":"0.999","size":"30653.32","side":"BUY","hash":"1282325a6cc1a39c2b943c69def09184c7e9784c","best_bid":"0.999","best_ask":"1"},{"asset_id":"103575991306220918671611575108050794364462782362354955892418399227289531345027","price":"0.001","size":"30653.32","side":"SELL","hash":"126723add4610379d39138a669b91ca92988779b","best_bid":"0","best_ask":"0.001"}],"timestamp":"1768359601294","event_type":"price_change"}
{"market":"0x5977c69bca02e6cc150855b0faec463b38be463f141ec37ea5c8a1a1e986e0d3","price_changes":[{"asset_id":"110222991870854778724082971333105906777328061970448875974576460135015541883929","price":"0.7","size":"5807.5","side":"BUY","hash":"7d6916b6a3e8140da39d95e904acadad98b965d2","best_bid":"0.999","best_ask":"1"},{"asset_id":"103575991306220918671611575108050794364462782362354955892418399227289531345027","price":"0.3","size":"5807.5","side":"SELL","hash":"a70d1a3fc032efa4e9e24316869f48b54b023889","best_bid":"0","best_ask":"0.001"}],"timestamp":"1768359601295","event_type":"price_change"}
{"market":"0x5977c69bca02e6cc150855b0faec463b38be463f141ec37ea5c8a1a1e986e0d3","price_changes":[{"asset_id":"110222991870854778724082971333105906777328061970448875974576460135015541883929","price":"0.99","size":"40803.38","side":"BUY","hash":"dd8455b85455bcb307364f380342d0d07a490712","best_bid":"0.999","best_ask":"1"},{"asset_id":"103575991306220918671611575108050794364462782362354955892418399227289531345027","price":"0.01","size":"40803.38","side":"SELL","hash":"cb11645c1c3a07a73a0dbd6dcfd37c4dc7d4ec38","best_bid":"0","best_ask":"0.001"}],"timestamp":"1768359601295","event_type":"price_change"}
{"market":"0x5977c69bca02e6cc150855b0faec463b38be463f141ec37ea5c8a1a1e986e0d3","price_changes":[{"asset_id":"110222991870854778724082971333105906777328061970448875974576460135015541883929","price":"0.99","size":"44114.38","side":"BUY","hash":"2e20cf7f2e89e160005be4d27b8e18bef39c43ad","best_bid":"0.999","best_ask":"1"},{"asset_id":"103575991306220918671611575108050794364462782362354955892418399227289531345027","price":"0.01","size":"44114.38","side":"SELL","hash":"c096433a88705c5448d02d508bb42dfbe2ca269f","best_bid":"0","best_ask":"0.001"}],"timestamp":"1768359601296","event_type":"price_change"}
{"market":"0x5977c69bca02e6cc150855b0faec463b38be463f141ec37ea5c8a1a1e986e0d3","price_changes":[{"asset_id":"110222991870854778724082971333105906777328061970448875974576460135015541883929","price":"0.99","size":"46636.38","side":"BUY","hash":"3789956d0508ea2c73cc7c0d94922dd22e6388a3","best_bid":"0.999","best_ask":"1"},{"asset_id":"103575991306220918671611575108050794364462782362354955892418399227289531345027","price":"0.01","size":"46636.38","side":"SELL","hash":"6ed65b0f3f9121a4e85bc2eeeb32f3c8fb7055c3","best_bid":"0","best_ask":"0.001"}],"timestamp":"1768359601297","event_type":"price_change"}
{"market":"0x5977c69bca02e6cc150855b0faec463b38be463f141ec37ea5c8a1a1e986e0d3","price_changes":[{"asset_id":"110222991870854778724082971333105906777328061970448875974576460135015541883929","price":"0.99","size":"50071.38","side":"BUY","hash":"6f2ce935ee47bc45b053af738167d590a4e5a8a4","best_bid":"0.999","best_ask":"1"},{"asset_id":"103575991306220918671611575108050794364462782362354955892418399227289531345027","price":"0.01","size":"50071.38","side":"SELL","hash":"0c8f885c2ad49c8bd432fd61c9e1b1eec3cf4b3c","best_bid":"0","best_ask":"0.001"}],"timestamp":"1768359601298","event_type":"price_change"}
{"market":"0x5977c69bca02e6cc150855b0faec463b38be463f141ec37ea5c8a1a1e986e0d3","price_changes":[{"asset_id":"110222991870854778724082971333105906777328061970448875974576460135015541883929","price":"0.99","size":"56439.38","side":"BUY","hash":"2f609d03f956d2d963ad9358bd7f2d86eed48b68","best_bid":"0.999","best_ask":"1"},{"asset_id":"103575991306220918671611575108050794364462782362354955892418399227289531345027","price":"0.01","size":"56439.38","side":"SELL","hash":"94b53519a3816c9bde5b5e6333c7bf0858db619b","best_bid":"0","best_ask":"0.001"}],"timestamp":"1768359601299","event_type":"price_change"}
{"market":"0x5977c69bca02e6cc150855b0faec463b38be463f141ec37ea5c8a1a1e986e0d3","price_changes":[{"asset_id":"110222991870854778724082971333105906777328061970448875974576460135015541883929","price":"0.99","size":"59436.38","side":"BUY","hash":"86bfed412d5e7f013f6cf4c1139eaf9e9a495daf","best_bid":"0.999","best_ask":"1"},{"asset_id":"103575991306220918671611575108050794364462782362354955892418399227289531345027","price":"0.01","size":"59436.38","side":"SELL","hash":"10e8e31453b649fba1458bcaf24f340af5d77ff0","best_bid":"0","best_ask":"0.001"}],"timestamp":"1768359601300","event_type":"price_change"}
{"market":"0x5977c69bca02e6cc150855b0faec463b38be463f141ec37ea5c8a1a1e986e0d3","price_changes":[{"asset_id":"110222991870854778724082971333105906777328061970448875974576460135015541883929","price":"0.9","size":"5554.19","side":"BUY","hash":"d076b49c74c0730948a8f41dc0bb264722b891f0","best_bid":"0.999","best_ask":"1"},{"asset_id":"103575991306220918671611575108050794364462782362354955892418399227289531345027","price":"0.1","size":"5554.19","side":"SELL","hash":"4300f4321cd210cd1d8547bb33ee38dcab781a61","best_bid":"0","best_ask":"0.001"}],"timestamp":"1768359601301","event_type":"price_change"}
{"market":"0x5977c69bca02e6cc150855b0faec463b38be463f141ec37ea5c8a1a1e986e0d3","price_changes":[{"asset_id":"110222991870854778724082971333105906777328061970448875974576460135015541883929","price":"0.99","size":"66946.38","side":"BUY","hash":"9684b6c5719e9f8cab9311e07e283a5869a84393","best_bid":"0.999","best_ask":"1"},{"asset_id":"103575991306220918671611575108050794364462782362354955892418399227289531345027","price":"0.01","size":"66946.38","side":"SELL","hash":"27f947dcb66cc60f294a27f9fab206b2ab55e939","best_bid":"0","best_ask":"0.001"}],"timestamp":"1768359601302","event_type":"price_change"}
{"market":"0x5977c69bca02e6cc150855b0faec463b38be463f141ec37ea5c8a1a1e986e0d3","price_changes":[{"asset_id":"110222991870854778724082971333105906777328061970448875974576460135015541883929","price":"0.999","size":"37163.32","side":"BUY","hash":"27a3213c645b45ffbb54d67d3a34616506019ff1","best_bid":"0.999","best_ask":"1"},{"asset_id":"103575991306220918671611575108050794364462782362354955892418399227289531345027","price":"0.001","size":"37163.32","side":"SELL","hash":"56527b1c826b3c3937af0afe499acca14110a3ec","best_bid":"0","best_ask":"0.001"}],"timestamp":"1768359601303","event_type":"price_change"}
{"market":"0x5977c69bca02e6cc150855b0faec463b38be463f141ec37ea5c8a1a1e986e0d3","price_changes":[{"asset_id":"110222991870854778724082971333105906777328061970448875974576460135015541883929","price":"0.99","size":"71126.38","side":"BUY","hash":"1def262b4fdce66d63abdcca77e69c223cacaddc","best_bid":"0.999","best_ask":"1"},{"asset_id":"103575991306220918671611575108050794364462782362354955892418399227289531345027","price":"0.01","size":"71126.38","side":"SELL","hash":"0743dbea6dd5a44c114869e4b855125ffbbb37e7","best_bid":"0","best_ask":"0.001"}],"timestamp":"1768359601304","event_type":"price_change"}
{"market":"0x5977c69bca02e6cc150855b0faec463b38be463f141ec37ea5c8a1a1e986e0d3","price_changes":[{"asset_id":"110222991870854778724082971333105906777328061970448875974576460135015541883929","price":"0.99","size":"75572.38","side":"BUY","hash":"82349e947d3c490df6f3f4731defc8ae564d76d6","best_bid":"0.999","best_ask":"1"},{"asset_id":"103575991306220918671611575108050794364462782362354955892418399227289531345027","price":"0.01","size":"75572.38","side":"SELL","hash":"7e12320e47bd06fc74acbf4ef7f6216e9c4c43d1","best_bid":"0","best_ask":"0.001"}],"timestamp":"1768359601305","event_type":"price_change"}
{"market":"0x5977c69bca02e6cc150855b0faec463b38be463f141ec37ea5c8a1a1e986e0d3","price_changes":[{"asset_id":"110222991870854778724082971333105906777328061970448875974576460135015541883929","price":"0.99","size":"81953.38","side":"BUY","hash":"f414e76a250b88a0390eda92f5a0bfb1317cae31","best_bid":"0.999","best_ask":"1"},{"asset_id":"103575991306220918671611575108050794364462782362354955892418399227289531345027","price":"0.01","size":"81953.38","side":"SELL","hash":"ad976a9590e02061567589873acc1a398364d4eb","best_bid":"0","best_ask":"0.001"}],"timestamp":"1768359601306","event_type":"price_change"}
{"market":"0x5977c69bca02e6cc150855b0faec463b38be463f141ec37ea5c8a1a1e986e0d3","price_changes":[{"asset_id":"110222991870854778724082971333105906777328061970448875974576460135015541883929","price":"0.99","size":"86352.38","side":"BUY","hash":"e091fcdf16e8a9f4ef24ac82d25ed10242efd4e2","best_bid":"0.999","best_ask":"1"},{"asset_id":"103575991306220918671611575108050794364462782362354955892418399227289531345027","price":"0.01","size":"86352.38","side":"SELL","hash":"83b50bb76022865aa42fcb22b1bf9bab2388f1ba","best_bid":"0","best_ask":"0.001"}],"timestamp":"1768359601307","event_type":"price_change"}
{"market":"0x5977c69bca02e6cc150855b0faec463b38be463f141ec37ea5c8a1a1e986e0d3","price_changes":[{"asset_id":"110222991870854778724082971333105906777328061970448875974576460135015541883929","price":"0.99","size":"92638.38","side":"BUY","hash":"294d6955dd7d39d89669773ef02958f954e5764d","best_bid":"0.999","best_ask":"1"},{"asset_id":"103575991306220918671611575108050794364462782362354955892418399227289531345027","price":"0.01","size":"92638.38","side":"SELL","hash":"a5922ab127fa52f3e80ec56fa7ae64837ef81a93","best_bid":"0","best_ask":"0.001"}],"timestamp":"1768359601308","event_type":"price_change"}
{"market":"0x5977c69bca02e6cc150855b0faec463b38be463f141ec37ea5c8a1a1e986e0d3","price_changes":[{"asset_id":"110222991870854778724082971333105906777328061970448875974576460135015541883929","price":"0.999","size":"46673.32","side":"BUY","hash":"c5de26072cd681e58d9dca309fe073e3060a1c82","best_bid":"0.999","best_ask":"1"},{"asset_id":"103575991306220918671611575108050794364462782362354955892418399227289531345027","price":"0.001","size":"46673.32","side":"SELL","hash":"df48aae20fc583545990503561ee46bb61992389","best_bid":"0","best_ask":"0.001"}],"timestamp":"1768359601309","event_type":"price_change"}
{"market":"0x5977c69bca02e6cc150855b0faec463b38be463f141ec37ea5c8a1a1e986e0d3","price_changes":[{"asset_id":"110222991870854778724082971333105906777328061970448875974576460135015541883929","price":"0.99","size":"103148.38","side":"BUY","hash":"f18f9881e1009313dc9c9198544825323f70d581","best_bid":"0.999","best_ask":"1"},{"asset_id":"103575991306220918671611575108050794364462782362354955892418399227289531345027","price":"0.01","size":"103148.38","side":"SELL","hash":"eefe92cca794555418f1c6413f94d6f7479fdaae","best_bid":"0","best_ask":"0.001"}],"timestamp":"1768359601310","event_type":"price_change"}
{"market":"0x5977c69bca02e6cc150855b0faec463b38be463f141ec37ea5c8a1a1e986e0d3","price_changes":[{"asset_id":"110222991870854778724082971333105906777328061970448875974576460135015541883929","price":"0.8","size":"5520","side":"BUY","hash":"917e0a6f956e449a9c8bc4bc397718e069791b90","best_bid":"0.999","best_ask":"1"},{"asset_id":"103575991306220918671611575108050794364462782362354955892418399227289531345027","price":"0.2","size":"5520","side":"SELL","hash":"79affb9e70ab31a61f39506298d187ca351e555d","best_bid":"0","best_ask":"0.001"}],"timestamp":"1768359601311","event_type":"price_change"}
{"market":"0x5977c69bca02e6cc150855b0faec463b38be463f141ec37ea5c8a1a1e986e0d3","price_changes":[{"asset_id":"110222991870854778724082971333105906777328061970448875974576460135015541883929","price":"0.999","size":"60183.32","side":"BUY","hash":"8f5292810747ddd62af126513e4ede587eae2d87","best_bid":"0.999","best_ask":"1"},{"asset_id":"103575991306220918671611575108050794364462782362354955892418399227289531345027","price":"0.001","size":"60183.32","side":"SELL","hash":"eb49dea4b8144ee42933dac3615802c2c0654ea9","best_bid":"0","best_ask":"0.001"}],"timestamp":"1768359601311","event_type":"price_change"}
{"market":"0x5977c69bca02e6cc150855b0faec463b38be463f141ec37ea5c8a1a1e986e0d3","price_changes":[{"asset_id":"110222991870854778724082971333105906777328061970448875974576460135015541883929","price":"0.4","size":"5544","side":"BUY","hash":"9e8edf2e837a67224338e921b0a16a3918eaf854","best_bid":"0.999","best_ask":"1"},{"asset_id":"103575991306220918671611575108050794364462782362354955892418399227289531345027","price":"0.6","size":"5544","side":"SELL","hash":"02a127d1e03c3e1285a287d290ecbe3543902fff","best_bid":"0","best_ask":"0.001"}],"timestamp":"1768359601312","event_type":"price_change"}
{"market":"0x5977c69bca02e6cc150855b0faec463b38be463f141ec37ea5c8a1a1e986e0d3","price_changes":[{"asset_id":"110222991870854778724082971333105906777328061970448875974576460135015541883929","price":"0.99","size":"117658.38","side":"BUY","hash":"cb8f49cbb0e094cc900f1527225b38e9d67fc15d","best_bid":"0.999","best_ask":"1"},{"asset_id":"103575991306220918671611575108050794364462782362354955892418399227289531345027","price":"0.01","size":"117658.38","side":"SELL","hash":"79c5e36568de0acd16db392399129c5ae8930043","best_bid":"0","best_ask":"0.001"}],"timestamp":"1768359601313","event_type":"price_change"}
{"market":"0x5977c69bca02e6cc150855b0faec463b38be463f141ec37ea5c8a1a1e986e0d3","price_changes":[{"asset_id":"110222991870854778724082971333105906777328061970448875974576460135015541883929","price":"0.99","size":"120175.38","side":"BUY","hash":"06d66254d1e502de2aa293064241dfec5956f702","best_bid":"0.999","best_ask":"1"},{"asset_id":"103575991306220918671611575108050794364462782362354955892418399227289531345027","price":"0.01","size":"120175.38","side":"SELL","hash":"8c0ab1522dae36f122c566098505f4a6d6d7741c","best_bid":"0","best_ask":"0.001"}],"timestamp":"1768359601314","event_type":"price_change"}
{"market":"0x5977c69bca02e6cc150855b0faec463b38be463f141ec37ea5c8a1a1e986e0d3","price_changes":[{"asset_id":"110222991870854778724082971333105906777328061970448875974576460135015541883929","price":"0.9","size":"6054.19","side":"BUY","hash":"c4a50206f5aeea19c4d605e21964c67ba92557ea","best_bid":"0.999","best_ask":"1"},{"asset_id":"103575991306220918671611575108050794364462782362354955892418399227289531345027","price":"0.1","size":"6054.19","side":"SELL","hash":"b30556e507d02ef031a62061fb9b7494c3faa6c8","best_bid":"0","best_ask":"0.001"}],"timestamp":"1768359601315","event_type":"price_change"}
{"market":"0x5977c69bca02e6cc150855b0faec463b38be463f141ec37ea5c8a1a1e986e0d3","price_changes":[{"asset_id":"110222991870854778724082971333105906777328061970448875974576460135015541883929","price":"0.99","size":"120675.38","side":"BUY","hash":"369e86e609255c045e6a2dfddf666e4dd4997c80","best_bid":"0.999","best_ask":"1"},{"asset_id":"103575991306220918671611575108050794364462782362354955892418399227289531345027","price":"0.01","size":"120675.38","side":"SELL","hash":"2c52540c28574ab56d1403d918f6685e98c6c696","best_bid":"0","best_ask":"0.001"}],"timestamp":"1768359601316","event_type":"price_change"}
{"market":"0x5977c69bca02e6cc150855b0faec463b38be463f141ec37ea5c8a1a1e986e0d3","price_changes":[{"asset_id":"110222991870854778724082971333105906777328061970448875974576460135015541883929","price":"0.99","size":"123420.38","side":"BUY","hash":"2d1f95eb78800878c96c6e7c891078bff32d6f08","best_bid":"0.999","best_ask":"1"},{"asset_id":"103575991306220918671611575108050794364462782362354955892418399227289531345027","price":"0.01","size":"123420.38","side":"SELL","hash":"5e29f61c0ea55d079a40480e48dd4300cdc0224f","best_bid":"0","best_ask":"0.001"}],"timestamp":"1768359601317","event_type":"price_change"}
{"market":"0x5977c69bca02e6cc150855b0faec463b38be463f141ec37ea5c8a1a1e986e0d3","price_changes":[{"asset_id":"110222991870854778724082971333105906777328061970448875974576460135015541883929","price":"0.99","size":"125906.38","side":"BUY","hash":"a6ff5522622a50568972f5db62a1e2a81c6b268b","best_bid":"0.999","best_ask":"1"},{"asset_id":"103575991306220918671611575108050794364462782362354955892418399227289531345027","price":"0.01","size":"125906.38","side":"SELL","hash":"dece0a6fac92cda9ec62f130a0b39735af1510b0","best_bid":"0","best_ask":"0.001"}],"timestamp":"1768359601318","event_type":"price_change"}
{"market":"0x5977c69bca02e6cc150855b0faec463b38be463f141ec37ea5c8a1a1e986e0d3","price_changes":[{"asset_id":"110222991870854778724082971333105906777328061970448875974576460135015541883929","price":"0.99","size":"142416.38","side":"BUY","hash":"423f4b49059c652cb0c1cbe5ff260512f0afd57d","best_bid":"0.999","best_ask":"1"},{"asset_id":"103575991306220918671611575108050794364462782362354955892418399227289531345027","price":"0.01","size":"142416.38","side":"SELL","hash":"d624052fd8bcc3473feb5183cfb5572c43f1661f","best_bid":"0","best_ask":"0.001"}],"timestamp":"1768359601319","event_type":"price_change"}
{"market":"0x5977c69bca02e6cc150855b0faec463b38be463f141ec37ea5c8a1a1e986e0d3","price_changes":[{"asset_id":"110222991870854778724082971333105906777328061970448875974576460135015541883929","price":"0.999","size":"75693.32","side":"BUY","hash":"2799cbfd83a9a7fa85b72a51f8dfc948ff3aaa1b","best_bid":"0.999","best_ask":"1"},{"asset_id":"103575991306220918671611575108050794364462782362354955892418399227289531345027","price":"0.001","size":"75693.32","side":"SELL","hash":"4f211c3460989c5b3d353ed7409ca102b37b2edb","best_bid":"0","best_ask":"0.001"}],"timestamp":"1768359601320","event_type":"price_change"}
{"market":"0x5977c69bca02e6cc150855b0faec463b38be463f141ec37ea5c8a1a1e986e0d3","price_changes":[{"asset_id":"110222991870854778724082971333105906777328061970448875974576460135015541883929","price":"0.1","size":"5520","side":"BUY","hash":"0a0da330ff8635fa30303d5b837a543775cce2d3","best_bid":"0.999","best_ask":"1"},{"asset_id":"103575991306220918671611575108050794364462782362354955892418399227289531345027","price":"0.9","size":"5520","side":"SELL","hash":"06b7ccd499ba8ba1d082988a8c5a45644f7c4067","best_bid":"0","best_ask":"0.001"}],"timestamp":"1768359601321","event_type":"price_change"}
{"market":"0x5977c69bca02e6cc150855b0faec463b38be463f141ec37ea5c8a1a1e986e0d3","price_changes":[{"asset_id":"110222991870854778724082971333105906777328061970448875974576460135015541883929","price":"0.99","size":"144490.38","side":"BUY","hash":"2efebf309357739a4c47f9d7ad0e889a39b79f48","best_bid":"0.999","best_ask":"1"},{"asset_id":"103575991306220918671611575108050794364462782362354955892418399227289531345027","price":"0.01","size":"144490.38","side":"SELL","hash":"41010fa830853505579739d45f3953e0b83653a6","best_bid":"0","best_ask":"0.001"}],"timestamp":"1768359601322","event_type":"price_change"}
{"market":"0x5977c69bca02e6cc150855b0faec463b38be463f141ec37ea5c8a1a1e986e0d3","price_changes":[{"asset_id":"110222991870854778724082971333105906777328061970448875974576460135015541883929","price":"0.99","size":"147572.38","side":"BUY","hash":"79148aa2483d633147b5ff00847110ef1d984ea4","best_bid":"0.999","best_ask":"1"},{"asset_id":"103575991306220918671611575108050794364462782362354955892418399227289531345027","price":"0.01","size":"147572.38","side":"SELL","hash":"a6cdbd2907625a511ceb8cabef4fd9d40648e89a","best_bid":"0","best_ask":"0.001"}],"timestamp":"1768359601323","event_type":"price_change"}
{"market":"0x5977c69bca02e6cc150855b0faec463b38be463f141ec37ea5c8a1a1e986e0d3","price_changes":[{"asset_id":"110222991870854778724082971333105906777328061970448875974576460135015541883929","price":"0.99","size":"151738.38","side":"BUY","hash":"395298157212ef7bd1da05a94eb16e76b29997c0","best_bid":"0.999","best_ask":"1"},{"asset_id":"103575991306220918671611575108050794364462782362354955892418399227289531345027","price":"0.01","size":"151738.38","side":"SELL","hash":"b0df0cca2beff70d82228aaf44904bd0f964a10c","best_bid":"0","best_ask":"0.001"}],"timestamp":"1768359601325","event_type":"price_change"}
{"market":"0x5977c69bca02e6cc150855b0faec463b38be463f141ec37ea5c8a1a1e986e0d3","price_changes":[{"asset_id":"110222991870854778724082971333105906777328061970448875974576460135015541883929","price":"0.99","size":"155078.38","side":"BUY","hash":"fa09078e09d82e3512af399c789ecbf0f82e8cdd","best_bid":"0.999","best_ask":"1"},{"asset_id":"103575991306220918671611575108050794364462782362354955892418399227289531345027","price":"0.01","size":"155078.38","side":"SELL","hash":"fffb383b1cafa20e147e3a1ed99fa3bb91bd3c19","best_bid":"0","best_ask":"0.001"}],"timestamp":"1768359601326","event_type":"price_change"}
{"market":"0x5977c69bca02e6cc150855b0faec463b38be463f141ec37ea5c8a1a1e986e0d3","price_changes":[{"asset_id":"110222991870854778724082971333105906777328061970448875974576460135015541883929","price":"0.99","size":"165082.38","side":"BUY","hash":"40ae1ce18753d29f69aeda1886ac4b4c66def2ea","best_bid":"0.999","best_ask":"1"},{"asset_id":"103575991306220918671611575108050794364462782362354955892418399227289531345027","price":"0.01","size":"165082.38","side":"SELL","hash":"b47058ca1baa272b8e6fb4dc0ef77ee915438d3d","best_bid":"0","best_ask":"0.001"}],"timestamp":"1768359601327","event_type":"price_change"}
{"market":"0x5977c69bca02e6cc150855b0faec463b38be463f141ec37ea5c8a1a1e986e0d3","price_changes":[{"asset_id":"110222991870854778724082971333105906777328061970448875974576460135015541883929","price":"0.99","size":"166682.38","side":"BUY","hash":"e1d3220d576e4c142ef80ca5dd488877ab36afe7","best_bid":"0.999","best_ask":"1"},{"asset_id":"103575991306220918671611575108050794364462782362354955892418399227289531345027","price":"0.01","size":"166682.38","side":"SELL","hash":"b8ebc84410c21a4e8dcf6710be3d7c7f5e87dbdb","best_bid":"0","best_ask":"0.001"}],"timestamp":"1768359601328","event_type":"price_change"}
{"market":"0x5977c69bca02e6cc150855b0faec463b38be463f141ec37ea5c8a1a1e986e0d3","price_changes":[{"asset_id":"110222991870854778724082971333105906777328061970448875974576460135015541883929","price":"0.99","size":"169989.38","side":"BUY","hash":"8bdb4fef8e66018dffdd8750e7e4f74ba7c40640","best_bid":"0.999","best_ask":"1"},{"asset_id":"103575991306220918671611575108050794364462782362354955892418399227289531345027","price":"0.01","size":"169989.38","side":"SELL","hash":"fe289951f7764a107cb067b2d2d08a42f6dce1f7","best_bid":"0","best_ask":"0.001"}],"timestamp":"1768359601328","event_type":"price_change"}
{"market":"0x5977c69bca02e6cc150855b0faec463b38be463f141ec37ea5c8a1a1e986e0d3","price_changes":[{"asset_id":"110222991870854778724082971333105906777328061970448875974576460135015541883929","price":"0.99","size":"174021.38","side":"BUY","hash":"e7de65a7c2a8edda472b18dc4587602a0f4412ac","best_bid":"0.999","best_ask":"1"},{"asset_id":"103575991306220918671611575108050794364462782362354955892418399227289531345027","price":"0.01","size":"174021.38","side":"SELL","hash":"412d8b3980c360d413ae96592ed887502f3c1c80","best_bid":"0","best_ask":"0.001"}],"timestamp":"1768359601330","event_type":"price_change"}
{"market":"0x5977c69bca02e6cc150855b0faec463b38be463f141ec37ea5c8a1a1e986e0d3","price_changes":[{"asset_id":"110222991870854778724082971333105906777328061970448875974576460135015541883929","price":"0.99","size":"178353.38","side":"BUY","hash":"654204d89232736b71e68aea9a7b0d0930f3ba87","best_bid":"0.999","best_ask":"1"},{"asset_id":"103575991306220918671611575108050794364462782362354955892418399227289531345027","price":"0.01","size":"178353.38","side":"SELL","hash":"3cb90c5337a3f7e622cabf9babd95bdc5b88bb8a","best_bid":"0","best_ask":"0.001"}],"timestamp":"1768359601331","event_type":"price_change"}
{"market":"0x5977c69bca02e6cc150855b0faec463b38be463f141ec37ea5c8a1a1e986e0d3","price_changes":[{"asset_id":"110222991870854778724082971333105906777328061970448875974576460135015541883929","price":"0.99","size":"178369.38","side":"BUY","hash":"e65efd01c5792157535df9adf1ed5053bb2d4b7b","best_bid":"0.999","best_ask":"1"},{"asset_id":"103575991306220918671611575108050794364462782362354955892418399227289531345027","price":"0.01","size":"178369.38","side":"SELL","hash":"32f974a06e2f8f7064c1bfe4cd7623d071e9f4be","best_bid":"0","best_ask":"0.001"}],"timestamp":"1768359601340","event_type":"price_change"}
{"market":"0x5977c69bca02e6cc150855b0faec463b38be463f141ec37ea5c8a1a1e986e0d3","price_changes":[{"asset_id":"110222991870854778724082971333105906777328061970448875974576460135015541883929","price":"0.99","size":"183866.38","side":"BUY","hash":"295a948ba595ac47e1c92ab07f76442a5b3ab3a9","best_bid":"0.999","best_ask":"1"},{"asset_id":"103575991306220918671611575108050794364462782362354955892418399227289531345027","price":"0.01","size":"183866.38","side":"SELL","hash":"00608f9e47593bccb8fe92053d90b7deb91c457d","best_bid":"0","best_ask":"0.001"}],"timestamp":"1768359601343","event_type":"price_change"}
{"market":"0x5977c69bca02e6cc150855b0faec463b38be463f141ec37ea5c8a1a1e986e0d3","price_changes":[{"asset_id":"110222991870854778724082971333105906777328061970448875974576460135015541883929","price":"0.999","size":"76145.8","side":"BUY","hash":"61641915a7f9271a08931457ede62fd2a22e920c","best_bid":"0.999","best_ask":"1"},{"asset_id":"103575991306220918671611575108050794364462782362354955892418399227289531345027","price":"0.001","size":"76145.8","side":"SELL","hash":"1c9e01fd41af1fabf0c9cbd344dde455d9957587","best_bid":"0","best_ask":"0.001"}],"timestamp":"1768359601344","event_type":"price_change"}
{"market":"0x5977c69bca02e6cc150855b0faec463b38be463f141ec37ea5c8a1a1e986e0d3","price_changes":[{"asset_id":"110222991870854778724082971333105906777328061970448875974576460135015541883929","price":"0.99","size":"189394.38","side":"BUY","hash":"742728563cd7dd0e679ae81537e6fc5a66f13cdc","best_bid":"0.999","best_ask":"1"},{"asset_id":"103575991306220918671611575108050794364462782362354955892418399227289531345027","price":"0.01","size":"189394.38","side":"SELL","hash":"5406e36768e5a11a969c44a3017e50d27f0d4484","best_bid":"0","best_ask":"0.001"}],"timestamp":"1768359601345","event_type":"price_change"}
{"market":"0x5977c69bca02e6cc150855b0faec463b38be463f141ec37ea5c8a1a1e986e0d3","price_changes":[{"asset_id":"110222991870854778724082971333105906777328061970448875974576460135015541883929","price":"0.99","size":"193445.38","side":"BUY","hash":"4726d32ec066833cbeaccb70859b15ea42db00e6","best_bid":"0.999","best_ask":"1"},{"asset_id":"103575991306220918671611575108050794364462782362354955892418399227289531345027","price":"0.01","size":"193445.38","side":"SELL","hash":"57aa2e99013a40be0c3963bd8a0bee7fe03c0426","best_bid":"0","best_ask":"0.001"}],"timestamp":"1768359601357","event_type":"price_change"}
{"market":"0x5977c69bca02e6cc150855b0faec463b38be463f141ec37ea5c8a1a1e986e0d3","price_changes":[{"asset_id":"110222991870854778724082971333105906777328061970448875974576460135015541883929","price":"0.99","size":"199861.38","side":"BUY","hash":"7c53bf36e0f3b1e3d6ecfbacc482caef704e7a32","best_bid":"0.999","best_ask":"1"},{"asset_id":"103575991306220918671611575108050794364462782362354955892418399227289531345027","price":"0.01","size":"199861.38","side":"SELL","hash":"19f7308342d03b51f268b00ce69b596942e217f0","best_bid":"0","best_ask":"0.001"}],"timestamp":"1768359601359","event_type":"price_change"}
{"market":"0x5977c69bca02e6cc150855b0faec463b38be463f141ec37ea5c8a1a1e986e0d3","price_changes":[{"asset_id":"110222991870854778724082971333105906777328061970448875974576460135015541883929","price":"0.99","size":"209866.38","side":"BUY","hash":"7caa323114338ff3625306e23a03b0802a832f29","best_bid":"0.999","best_ask":"1"},{"asset_id":"103575991306220918671611575108050794364462782362354955892418399227289531345027","price":"0.01","size":"209866.38","side":"SELL","hash":"c0a2dab20ceebac0a77ee1451f40e8ac995f8aaf","best_bid":"0","best_ask":"0.001"}],"timestamp":"1768359601362","event_type":"price_change"}
{"market":"0x5977c69bca02e6cc150855b0faec463b38be463f141ec37ea5c8a1a1e986e0d3","price_changes":[{"asset_id":"110222991870854778724082971333105906777328061970448875974576460135015541883929","price":"0.99","size":"214866.38","side":"BUY","hash":"c263713ff054c25fbddd89e22a43dbe042b64c29","best_bid":"0.999","best_ask":"1"},{"asset_id":"103575991306220918671611575108050794364462782362354955892418399227289531345027","price":"0.01","size":"214866.38","side":"SELL","hash":"c1cd4814dcbeba01e062a1eadc38bf3995edab05","best_bid":"0","best_ask":"0.001"}],"timestamp":"1768359601364","event_type":"price_change"}
{"market":"0x5977c69bca02e6cc150855b0faec463b38be463f141ec37ea5c8a1a1e986e0d3","price_changes":[{"asset_id":"110222991870854778724082971333105906777328061970448875974576460135015541883929","price":"0.99","size":"218894.38","side":"BUY","hash":"eed9de72bb381afaf4dc00b88dd4c1873e7b5cc7","best_bid":"0.999","best_ask":"1"},{"asset_id":"103575991306220918671611575108050794364462782362354955892418399227289531345027","price":"0.01","size":"218894.38","side":"SELL","hash":"10eb6c5e803227a8e388ea27f6ae82957c2b9025","best_bid":"0","best_ask":"0.001"}],"timestamp":"1768359601369","event_type":"price_change"}
{"market":"0x5977c69bca02e6cc150855b0faec463b38be463f141ec37ea5c8a1a1e986e0d3","price_changes":[{"asset_id":"110222991870854778724082971333105906777328061970448875974576460135015541883929","price":"0.99","size":"228897.38","side":"BUY","hash":"d560ce0206de821172b867fbd4223846b374faf4","best_bid":"0.999","best_ask":"1"},{"asset_id":"103575991306220918671611575108050794364462782362354955892418399227289531345027","price":"0.01","size":"228897.38","side":"SELL","hash":"62731c244b5b9ee2609609e8f947f7de97c1cabd","best_bid":"0","best_ask":"0.001"}],"timestamp":"1768359601376","event_type":"price_change"}
{"market":"0x5977c69bca02e6cc150855b0faec463b38be463f141ec37ea5c8a1a1e986e0d3","price_changes":[{"asset_id":"110222991870854778724082971333105906777328061970448875974576460135015541883929","price":"0.99","size":"238902.38","side":"BUY","hash":"a5940994ac885411086d0a1ad8705cc614c24c40","best_bid":"0.999","best_ask":"1"},{"asset_id":"103575991306220918671611575108050794364462782362354955892418399227289531345027","price":"0.01","size":"238902.38","side":"SELL","hash":"c3ad23badb6faebf401e57cc22a844622fa9f253","best_bid":"0","best_ask":"0.001"}],"timestamp":"1768359601379","event_type":"price_change"}
{"market":"0x5977c69bca02e6cc150855b0faec463b38be463f141ec37ea5c8a1a1e986e0d3","price_changes":[{"asset_id":"110222991870854778724082971333105906777328061970448875974576460135015541883929","price":"0.99","size":"248905.38","side":"BUY","hash":"804f07d0b0e8fe644dd0cc71534b5cf6d6ae3ed5","best_bid":"0.999","best_ask":"1"},{"asset_id":"103575991306220918671611575108050794364462782362354955892418399227289531345027","price":"0.01","size":"248905.38","side":"SELL","hash":"133f0100717565fb9f7f9c40a7daa130d64302d9","best_bid":"0","best_ask":"0.001"}],"timestamp":"1768359601380","event_type":"price_change"}
{"market":"0x5977c69bca02e6cc150855b0faec463b38be463f141ec37ea5c8a1a1e986e0d3","price_changes":[{"asset_id":"110222991870854778724082971333105906777328061970448875974576460135015541883929","price":"0.99","size":"249157.58","side":"BUY","hash":"7c469ae62287f3ec4ca02bdd2dfd945df4a2159c","best_bid":"0.999","best_ask":"1"},{"asset_id":"103575991306220918671611575108050794364462782362354955892418399227289531345027","price":"0.01","size":"249157.58","side":"SELL","hash":"461a6d6eba6ab28ec7379b3e8e12231f8ab3b204","best_bid":"0","best_ask":"0.001"}],"timestamp":"1768359601384","event_type":"price_change"}
{"market":"0x5977c69bca02e6cc150855b0faec463b38be463f141ec37ea5c8a1a1e986e0d3","price_changes":[{"asset_id":"110222991870854778724082971333105906777328061970448875974576460135015541883929","price":"0.99","size":"253329.58","side":"BUY","hash":"e641770007ec8426e40e4c30ae4d3910ba1ffa47","best_bid":"0.999","best_ask":"1"},{"asset_id":"103575991306220918671611575108050794364462782362354955892418399227289531345027","price":"0.01","size":"253329.58","side":"SELL","hash":"d39adf3fd33ebd6640ffba951c5e7cbfd8ef9ef1","best_bid":"0","best_ask":"0.001"}],"timestamp":"1768359601407","event_type":"price_change"}
{"market":"0x5977c69bca02e6cc150855b0faec463b38be463f141ec37ea5c8a1a1e986e0d3","price_changes":[{"asset_id":"110222991870854778724082971333105906777328061970448875974576460135015541883929","price":"0.99","size":"278329.58","side":"BUY","hash":"a5779a8563a838e1efd69bf35a550791cf5b08e3","best_bid":"0.999","best_ask":"1"},{"asset_id":"103575991306220918671611575108050794364462782362354955892418399227289531345027","price":"0.01","size":"278329.58","side":"SELL","hash":"ec5ed44eefdb0c66a693826540698f12f35bc223","best_bid":"0","best_ask":"0.001"}],"timestamp":"1768359601413","event_type":"price_change"}
{"market":"0x5977c69bca02e6cc150855b0faec463b38be463f141ec37ea5c8a1a1e986e0d3","price_changes":[{"asset_id":"110222991870854778724082971333105906777328061970448875974576460135015541883929","price":"0.99","size":"280177.58","side":"BUY","hash":"16557e4f4577e465a5acd13d3a5c736e542e5d2a","best_bid":"0.999","best_ask":"1"},{"asset_id":"103575991306220918671611575108050794364462782362354955892418399227289531345027","price":"0.01","size":"280177.58","side":"SELL","hash":"939c5c8abdd20dd73fca14d54b14b1be4d96ad15","best_bid":"0","best_ask":"0.001"}],"timestamp":"1768359601425","event_type":"price_change"}
{"market":"0x5977c69bca02e6cc150855b0faec463b38be463f141ec37ea5c8a1a1e986e0d3","price_changes":[{"asset_id":"110222991870854778724082971333105906777328061970448875974576460135015541883929","price":"0.99","size":"281684.65","side":"BUY","hash":"4ae42bbc34c3331f2cfc15bfeaa31c32e87c7849","best_bid":"0.999","best_ask":"1"},{"asset_id":"103575991306220918671611575108050794364462782362354955892418399227289531345027","price":"0.01","size":"281684.65","side":"SELL","hash":"1775e5570ee579c4f2d7a71dbf7dba226b1054e1","best_bid":"0","best_ask":"0.001"}],"timestamp":"1768359601436","event_type":"price_change"}
{"market":"0x5977c69bca02e6cc150855b0faec463b38be463f141ec37ea5c8a1a1e986e0d3","price_changes":[{"asset_id":"110222991870854778724082971333105906777328061970448875974576460135015541883929","price":"0.999","size":"76151.8","side":"BUY","hash":"42433e75180416c8b78b65740a346c2721fb9448","best_bid":"0.999","best_ask":"1"},{"asset_id":"103575991306220918671611575108050794364462782362354955892418399227289531345027","price":"0.001","size":"76151.8","side":"SELL","hash":"003b804c8848334ff4e912382405f1c84dbd720a","best_bid":"0","best_ask":"0.001"}],"timestamp":"1768359601457","event_type":"price_change"}
{"market":"0x5977c69bca02e6cc150855b0faec463b38be463f141ec37ea5c8a1a1e986e0d3","price_changes":[{"asset_id":"110222991870854778724082971333105906777328061970448875974576460135015541883929","price":"0.999","size":"76157.8","side":"BUY","hash":"d6230eb93a083aa30b757674e8524628be4dd7ca","best_bid":"0.999","best_ask":"1"},{"asset_id":"103575991306220918671611575108050794364462782362354955892418399227289531345027","price":"0.001","size":"76157.8","side":"SELL","hash":"6caf48d3c8afb905488173627b57fa2bc0f9c36a","best_bid":"0","best_ask":"0.001"}],"timestamp":"1768359601465","event_type":"price_change"}
{"market":"0x5977c69bca02e6cc150855b0faec463b38be463f141ec37ea5c8a1a1e986e0d3","price_changes":[{"asset_id":"110222991870854778724082971333105906777328061970448875974576460135015541883929","price":"0.99","size":"288846.74","side":"BUY","hash":"93a9be7f0115249707842e3d554c835a5cfd042e","best_bid":"0.999","best_ask":"1"},{"asset_id":"103575991306220918671611575108050794364462782362354955892418399227289531345027","price":"0.01","size":"288846.74","side":"SELL","hash":"cedbafc35bb9314389c8a5469c150511440fc97d","best_bid":"0","best_ask":"0.001"}],"timestamp":"1768359601469","event_type":"price_change"}
{"market":"0x5977c69bca02e6cc150855b0faec463b38be463f141ec37ea5c8a1a1e986e0d3","price_changes":[{"asset_id":"110222991870854778724082971333105906777328061970448875974576460135015541883929","price":"0.99","size":"298846.74","side":"BUY","hash":"c039cbe303544edc90cc36a61d799a96e56c7948","best_bid":"0.999","best_ask":"1"},{"asset_id":"103575991306220918671611575108050794364462782362354955892418399227289531345027","price":"0.01","size":"298846.74","side":"SELL","hash":"1f4fdb8442695550bf9339e50aef9ea850216778","best_bid":"0","best_ask":"0.001"}],"timestamp":"1768359601473","event_type":"price_change"}
{"market":"0x5977c69bca02e6cc150855b0faec463b38be463f141ec37ea5c8a1a1e986e0d3","price_changes":[{"asset_id":"110222991870854778724082971333105906777328061970448875974576460135015541883929","price":"0.999","size":"76207.8","side":"BUY","hash":"b330e8496247c0d891ce7b8ea9047fb2c0a1d744","best_bid":"0.999","best_ask":"1"},{"asset_id":"103575991306220918671611575108050794364462782362354955892418399227289531345027","price":"0.001","size":"76207.8","side":"SELL","hash":"3257021440ebc7379d7a0b29beda467d4680d037","best_bid":"0","best_ask":"0.001"}],"timestamp":"1768359601476","event_type":"price_change"}
{"market":"0x5977c69bca02e6cc150855b0faec463b38be463f141ec37ea5c8a1a1e986e0d3","price_changes":[{"asset_id":"110222991870854778724082971333105906777328061970448875974576460135015541883929","price":"0.999","size":"96207.8","side":"BUY","hash":"ad70758baaf9ac2180b79f71356838dba5221598","best_bid":"0.999","best_ask":"1"},{"asset_id":"103575991306220918671611575108050794364462782362354955892418399227289531345027","price":"0.001","size":"96207.8","side":"SELL","hash":"bc287bc681a8a7939c740b2ffabfc5c658dbca11","best_bid":"0","best_ask":"0.001"}],"timestamp":"1768359601485","event_type":"price_change"}
{"market":"0x5977c69bca02e6cc150855b0faec463b38be463f141ec37ea5c8a1a1e986e0d3","price_changes":[{"asset_id":"110222991870854778724082971333105906777328061970448875974576460135015541883929","price":"0.999","size":"97207.8","side":"BUY","hash":"d82f2b8f8975815b02285ac84a6a056ea2f54eef","best_bid":"0.999","best_ask":"1"},{"asset_id":"103575991306220918671611575108050794364462782362354955892418399227289531345027","price":"0.001","size":"97207.8","side":"SELL","hash":"476535218df1a5374ac5caea858c363014c73c23","best_bid":"0","best_ask":"0.001"}],"timestamp":"1768359601490","event_type":"price_change"}
{"market":"0x5977c69bca02e6cc150855b0faec463b38be463f141ec37ea5c8a1a1e986e0d3","price_changes":[{"asset_id":"110222991870854778724082971333105906777328061970448875974576460135015541883929","price":"0.999","size":"105207.8","side":"BUY","hash":"7e402f872233775b7af6b1ff964371a9b302c014","best_bid":"0.999","best_ask":"1"},{"asset_id":"103575991306220918671611575108050794364462782362354955892418399227289531345027","price":"0.001","size":"105207.8","side":"SELL","hash":"28d774ebc0b41c9f89b1cdcd133949f7632d34c2","best_bid":"0","best_ask":"0.001"}],"timestamp":"1768359601501","event_type":"price_change"}
{"market":"0x5977c69bca02e6cc150855b0faec463b38be463f141ec37ea5c8a1a1e986e0d3","price_changes":[{"asset_id":"110222991870854778724082971333105906777328061970448875974576460135015541883929","price":"0.9","size":"8554.19","side":"BUY","hash":"58b01c3463f956b3c17cae7a0600d05ad22a7301","best_bid":"0.999","best_ask":"1"},{"asset_id":"103575991306220918671611575108050794364462782362354955892418399227289531345027","price":"0.1","size":"8554.19","side":"SELL","hash":"bc7dc7ef344623b0496b0a6b01c24d288794e230","best_bid":"0","best_ask":"0.001"}],"timestamp":"1768359601530","event_type":"price_change"}
{"market":"0x5977c69bca02e6cc150855b0faec463b38be463f141ec37ea5c8a1a1e986e0d3","price_changes":[{"asset_id":"110222991870854778724082971333105906777328061970448875974576460135015541883929","price":"0.05","size":"3035","side":"BUY","hash":"09fa2ef66d9f54ef03c77b2f61925b042ee79fa3","best_bid":"0.999","best_ask":"1"},{"asset_id":"103575991306220918671611575108050794364462782362354955892418399227289531345027","price":"0.95","size":"3035","side":"SELL","hash":"9fa722630db2f98ba9e79b94bc49682bd5415360","best_bid":"0","best_ask":"0.001"}],"timestamp":"1768359601578","event_type":"price_change"}
{"market":"0x5977c69bca02e6cc150855b0faec463b38be463f141ec37ea5c8a1a1e986e0d3","price_changes":[{"asset_id":"110222991870854778724082971333105906777328061970448875974576460135015541883929","price":"0.8","size":"5515","side":"BUY","hash":"2da38e799f8516c018cdf4635de13aad6511e898","best_bid":"0.999","best_ask":"1"},{"asset_id":"103575991306220918671611575108050794364462782362354955892418399227289531345027","price":"0.2","size":"5515","side":"SELL","hash":"59740966e43c34089fbd424b9e5883033d0f3697","best_bid":"0","best_ask":"0.001"}],"timestamp":"1768359601650","event_type":"price_change"}
{"market":"0x5977c69bca02e6cc150855b0faec463b38be463f141ec37ea5c8a1a1e986e0d3","price_changes":[{"asset_id":"110222991870854778724082971333105906777328061970448875974576460135015541883929","price":"0.99","size":"298851.74","side":"BUY","hash":"edbcf934c2bdae747282d08e89dbdca92bdb63ec","best_bid":"0.999","best_ask":"1"},{"asset_id":"103575991306220918671611575108050794364462782362354955892418399227289531345027","price":"0.01","size":"298851.74","side":"SELL","hash":"db38b453792f7fcd2b6b46a2b2a09e9661603224","best_bid":"0","best_ask":"0.001"}],"timestamp":"1768359601665","event_type":"price_change"}
{"market":"0x5977c69bca02e6cc150855b0faec463b38be463f141ec37ea5c8a1a1e986e0d3","price_changes":[{"asset_id":"110222991870854778724082971333105906777328061970448875974576460135015541883929","price":"0.999","size":"105257.8","side":"BUY","hash":"accf08d6e14e16fdb7cbc5e87eed2a105771a8c3","best_bid":"0.999","best_ask":"1"},{"asset_id":"103575991306220918671611575108050794364462782362354955892418399227289531345027","price":"0.001","size":"105257.8","side":"SELL","hash":"7ddd7ed49eee62dec9f1c893073d3831834fe32f","best_bid":"0","best_ask":"0.001"}],"timestamp":"1768359602362","event_type":"price_change"}
{"market":"0x5977c69bca02e6cc150855b0faec463b38be463f141ec37ea5c8a1a1e986e0d3","price_changes":[{"asset_id":"110222991870854778724082971333105906777328061970448875974576460135015541883929","price":"0.99","size":"298024.73","side":"BUY","hash":"de3b7cc0a7b982e24992a49fcfa02bd76348ea7e","best_bid":"0.999","best_ask":"1"},{"asset_id":"103575991306220918671611575108050794364462782362354955892418399227289531345027","price":"0.01","size":"298024.73","side":"SELL","hash":"763283153c4f1ec1610d79917caf5dc8071ca3ae","best_bid":"0","best_ask":"0.001"}],"timestamp":"1768359602854","event_type":"price_change"}
{"market":"0x5977c69bca02e6cc150855b0faec463b38be463f141ec37ea5c8a1a1e986e0d3","price_changes":[{"asset_id":"110222991870854778724082971333105906777328061970448875974576460135015541883929","price":"0.02","size":"1391.8","side":"BUY","hash":"bad41800f693b860838865fa660beea439e86b53","best_bid":"0.999","best_ask":"1"},{"asset_id":"103575991306220918671611575108050794364462782362354955892418399227289531345027","price":"0.98","size":"1391.8","side":"SELL","hash":"eff904e51ed87dd4abdf083002d5b301f4915bdd","best_bid":"0","best_ask":"0.001"}],"timestamp":"1768359603676","event_type":"price_change"}
{"market":"0x5977c69bca02e6cc150855b0faec463b38be463f141ec37ea5c8a1a1e986e0d3","price_changes":[{"asset_id":"110222991870854778724082971333105906777328061970448875974576460135015541883929","price":"0.02","size":"1291.8","side":"BUY","hash":"5c1c454d973902b09f515de7ff46bb04fb10a614","best_bid":"0.999","best_ask":"1"},{"asset_id":"103575991306220918671611575108050794364462782362354955892418399227289531345027","price":"0.98","size":"1291.8","side":"SELL","hash":"0b96e551f39ceab4b64286e30c0a2b7c8f486b30","best_bid":"0","best_ask":"0.001"}],"timestamp":"1768359603877","event_type":"price_change"}
{"market":"0x5977c69bca02e6cc150855b0faec463b38be463f141ec37ea5c8a1a1e986e0d3","price_changes":[{"asset_id":"110222991870854778724082971333105906777328061970448875974576460135015541883929","price":"0.03","size":"405.5","side":"BUY","hash":"5c1c454d973902b09f515de7ff46bb04fb10a614","best_bid":"0.999","best_ask":"1"},{"asset_id":"103575991306220918671611575108050794364462782362354955892418399227289531345027","price":"0.97","size":"405.5","side":"SELL","hash":"0b96e551f39ceab4b64286e30c0a2b7c8f486b30","best_bid":"0","best_ask":"0.001"}],"timestamp":"1768359603877","event_type":"price_change"}
{"market":"0x5977c69bca02e6cc150855b0faec463b38be463f141ec37ea5c8a1a1e986e0d3","price_changes":[{"asset_id":"110222991870854778724082971333105906777328061970448875974576460135015541883929","price":"0.01","size":"4296.4","side":"BUY","hash":"5c1c454d973902b09f515de7ff46bb04fb10a614","best_bid":"0.999","best_ask":"1"},{"asset_id":"103575991306220918671611575108050794364462782362354955892418399227289531345027","price":"0.99","size":"4296.4","side":"SELL","hash":"0b96e551f39ceab4b64286e30c0a2b7c8f486b30","best_bid":"0","best_ask":"0.001"}],"timestamp":"1768359603877","event_type":"price_change"}
{"market":"0x5977c69bca02e6cc150855b0faec463b38be463f141ec37ea5c8a1a1e986e0d3","price_changes":[{"asset_id":"110222991870854778724082971333105906777328061970448875974576460135015541883929","price":"0.03","size":"355.5","side":"BUY","hash":"27f90f9a54586e771b057b8aa9e43010a22b7ab3","best_bid":"0.999","best_ask":"1"},{"asset_id":"103575991306220918671611575108050794364462782362354955892418399227289531345027","price":"0.97","size":"355.5","side":"SELL","hash":"54c9225e54c6b364400acc98c30e7f48913d1495","best_bid":"0","best_ask":"0.001"}],"timestamp":"1768359604737","event_type":"price_change"}
{"market":"0x5977c69bca02e6cc150855b0faec463b38be463f141ec37ea5c8a1a1e986e0d3","price_changes":[{"asset_id":"110222991870854778724082971333105906777328061970448875974576460135015541883929","price":"0.02","size":"1191.8","side":"BUY","hash":"27f90f9a54586e771b057b8aa9e43010a22b7ab3","best_bid":"0.999","best_ask":"1"},{"asset_id":"103575991306220918671611575108050794364462782362354955892418399227289531345027","price":"0.98","size":"1191.8","side":"SELL","hash":"54c9225e54c6b364400acc98c30e7f48913d1495","best_bid":"0","best_ask":"0.001"}],"timestamp":"1768359604737","event_type":"price_change"}
{"market":"0x5977c69bca02e6cc150855b0faec463b38be463f141ec37ea5c8a1a1e986e0d3","price_changes":[{"asset_id":"110222991870854778724082971333105906777328061970448875974576460135015541883929","price":"0.01","size":"4146.4","side":"BUY","hash":"27f90f9a54586e771b057b8aa9e43010a22b7ab3","best_bid":"0.999","best_ask":"1"},{"asset_id":"103575991306220918671611575108050794364462782362354955892418399227289531345027","price":"0.99","size":"4146.4","side":"SELL","hash":"54c9225e54c6b364400acc98c30e7f48913d1495","best_bid":"0","best_ask":"0.001"}],"timestamp":"1768359604737","event_type":"price_change"}
PONG
{"market":"0x5977c69bca02e6cc150855b0faec463b38be463f141ec37ea5c8a1a1e986e0d3","price_changes":[{"asset_id":"110222991870854778724082971333105906777328061970448875974576460135015541883929","price":"0.93","size":"45","side":"BUY","hash":"510dad00487c125bf2237aa64013c7dbbd4dbad1","best_bid":"0.999","best_ask":"1"},{"asset_id":"103575991306220918671611575108050794364462782362354955892418399227289531345027","price":"0.07","size":"45","side":"SELL","hash":"5d43bf519aaca6310e540f0e50f90f9589f54dcc","best_bid":"0","best_ask":"0.001"}],"timestamp":"1768359605605","event_type":"price_change"}
{"market":"0x5977c69bca02e6cc150855b0faec463b38be463f141ec37ea5c8a1a1e986e0d3","price_changes":[{"asset_id":"110222991870854778724082971333105906777328061970448875974576460135015541883929","price":"0.99","size":"298125.74","side":"BUY","hash":"d82f84ed7f1e3af325c7248d5d1458924a0c23de","best_bid":"0.999","best_ask":"1"},{"asset_id":"103575991306220918671611575108050794364462782362354955892418399227289531345027","price":"0.01","size":"298125.74","side":"SELL","hash":"431ca7f9ff4f669896d83479d3f077a149ac3414","best_bid":"0","best_ask":"0.001"}],"timestamp":"1768359605619","event_type":"price_change"}
{"market":"0x5977c69bca02e6cc150855b0faec463b38be463f141ec37ea5c8a1a1e986e0d3","price_changes":[{"asset_id":"110222991870854778724082971333105906777328061970448875974576460135015541883929","price":"0.99","size":"273125.74","side":"BUY","hash":"a36ad57eae66ca470e89f71026a18bcc185f6482","best_bid":"0.999","best_ask":"1"},{"asset_id":"103575991306220918671611575108050794364462782362354955892418399227289531345027","price":"0.01","size":"273125.74","side":"SELL","hash":"39d137c878321aa1928999f8e1336f18f398830e","best_bid":"0","best_ask":"0.001"}],"timestamp":"1768359606483","event_type":"price_change"}
{"market":"0x5977c69bca02e6cc150855b0faec463b38be463f141ec37ea5c8a1a1e986e0d3","price_changes":[{"asset_id":"110222991870854778724082971333105906777328061970448875974576460135015541883929","price":"0.97","size":"457.14","side":"BUY","hash":"1b22b2df59bd31cda59451df19de5e659d52c074","best_bid":"0.999","best_ask":"1"},{"asset_id":"103575991306220918671611575108050794364462782362354955892418399227289531345027","price":"0.03","size":"457.14","side":"SELL","hash":"971a0cc66ca231e655240d8ac1e07c144661f5e0","best_bid":"0","best_ask":"0.001"}],"timestamp":"1768359606610","event_type":"price_change"}
{"market":"0x5977c69bca02e6cc150855b0faec463b38be463f141ec37ea5c8a1a1e986e0d3","price_changes":[{"asset_id":"110222991870854778724082971333105906777328061970448875974576460135015541883929","price":"0.01","size":"4141.4","side":"BUY","hash":"1b22b2df59bd31cda59451df19de5e659d52c074","best_bid":"0.999","best_ask":"1"},{"asset_id":"103575991306220918671611575108050794364462782362354955892418399227289531345027","price":"0.99","size":"4141.4","side":"SELL","hash":"971a0cc66ca231e655240d8ac1e07c144661f5e0","best_bid":"0","best_ask":"0.001"}],"timestamp":"1768359606610","event_type":"price_change"}
{"market":"0x5977c69bca02e6cc150855b0faec463b38be463f141ec37ea5c8a1a1e986e0d3","price_changes":[{"asset_id":"110222991870854778724082971333105906777328061970448875974576460135015541883929","price":"0.749","size":"0","side":"BUY","hash":"1c44ce21757a5e520ab023cdc370ea1253b41bfe","best_bid":"0.999","best_ask":"1"},{"asset_id":"103575991306220918671611575108050794364462782362354955892418399227289531345027","price":"0.251","size":"0","side":"SELL","hash":"06873a754b842948781f7ded7a60afb094347cda","best_bid":"0","best_ask":"0.001"}],"timestamp":"1768359606731","event_type":"price_change"}
{"market":"0x5977c69bca02e6cc150855b0faec463b38be463f141ec37ea5c8a1a1e986e0d3","price_changes":[{"asset_id":"110222991870854778724082971333105906777328061970448875974576460135015541883929","price":"0.999","size":"104971.03","side":"BUY","hash":"edd309603a70620127a6a1304aa6fcb6d6c140f0","best_bid":"0.999","best_ask":"1"},{"asset_id":"103575991306220918671611575108050794364462782362354955892418399227289531345027","price":"0.001","size":"104971.03","side":"SELL","hash":"45f955faa574848ca21cc2dfdcbf5f0f9a643f88","best_bid":"0","best_ask":"0.001"}],"timestamp":"1768359607566","event_type":"price_change"}
{"market":"0x5977c69bca02e6cc150855b0faec463b38be463f141ec37ea5c8a1a1e986e0d3","asset_id":"103575991306220918671611575108050794364462782362354955892418399227289531345027","bids":[],"asks":[{"price":"0.999","size":"270"},{"price":"0.998","size":"60"},{"price":"0.99","size":"4141.4"},{"price":"0.98","size":"1191.8"},{"price":"0.97","size":"355.5"},{"price":"0.96","size":"219.52"},{"price":"0.95","size":"3035"},{"price":"0.9","size":"5520"},{"price":"0.88","size":"5"},{"price":"0.85","size":"5"},{"price":"0.8","size":"40"},{"price":"0.75","size":"33.5"},{"price":"0.72","size":"23.14"},{"price":"0.7","size":"226.69"},{"price":"0.68","size":"5"},{"price":"0.66","size":"5"},{"price":"0.65","size":"18.93"},{"price":"0.64","size":"15"},{"price":"0.63","size":"23.13"},{"price":"0.6","size":"5544"},{"price":"0.58","size":"33.41"},{"price":"0.57","size":"5"},{"price":"0.56","size":"11"},{"price":"0.55","size":"314.33"},{"price":"0.54","size":"5"},{"price":"0.53","size":"10"},{"price":"0.52","size":"83.05"},{"price":"0.5","size":"20"},{"price":"0.49","size":"102.65"},{"price":"0.48","size":"10"},{"price":"0.44","size":"15"},{"price":"0.43","size":"5"},{"price":"0.42","size":"5"},{"price":"0.41","size":"10"},{"price":"0.39","size":"5"},{"price":"0.37","size":"20.24"},{"price":"0.36","size":"136.18"},{"price":"0.35","size":"150.75"},{"price":"0.34","size":"130.37"},{"price":"0.33","size":"15.12"},{"price":"0.32","size":"110.24"},{"price":"0.31","size":"94.01"},{"price":"0.3","size":"5807.5"},{"price":"0.29","size":"302.74"},{"price":"0.28","size":"202.84"},{"price":"0.27","size":"34.37"},{"price":"0.26","size":"110.67"},{"price":"0.25","size":"440.01"},{"price":"0.24","size":"279.24"},{"price":"0.23","size":"90"},{"price":"0.22","size":"9.97"},{"price":"0.21","size":"5"},{"price":"0.2","size":"5515"},{"price":"0.19","size":"104.75"},{"price":"0.17","size":"38.78"},{"price":"0.16","size":"16.56"},{"price":"0.15","size":"26.25"},{"price":"0.14","size":"525.94"},{"price":"0.12","size":"1011.36"},{"price":"0.11","size":"1010"},{"price":"0.1","size":"8554.19"},{"price":"0.08","size":"25"},{"price":"0.07","size":"45"},{"price":"0.06","size":"260.16"},{"price":"0.05","size":"262.3"},{"price":"0.04","size":"101.78"},{"price":"0.03","size":"457.14"},{"price":"0.02","size":"984.53"},{"price":"0.015","size":"5"},{"price":"0.01","size":"273125.74"},{"price":"0.009","size":"69"},{"price":"0.006","size":"57"},{"price":"0.004","size":"44"},{"price":"0.001","size":"104971.03"}],"hash":"45f955faa574848ca21cc2dfdcbf5f0f9a643f88","timestamp":"1768359607566","event_type":"book"}
{"market":"0x5977c69bca02e6cc150855b0faec463b38be463f141ec37ea5c8a1a1e986e0d3","asset_id":"110222991870854778724082971333105906777328061970448875974576460135015541883929","bids":[{"price":"0.001","size":"270"},{"price":"0.002","size":"60"},{"price":"0.01","size":"4141.4"},{"price":"0.02","size":"1191.8"},{"price":"0.03","size":"355.5"},{"price":"0.04","size":"219.52"},{"price":"0.05","size":"3035"},{"price":"0.1","size":"5520"},{"price":"0.12","size":"5"},{"price":"0.15","size":"5"},{"price":"0.2","size":"40"},{"price":"0.25","size":"33.5"},{"price":"0.28","size":"23.14"},{"price":"0.3","size":"226.69"},{"price":"0.32","size":"5"},{"price":"0.34","size":"5"},{"price":"0.35","size":"18.93"},{"price":"0.36","size":"15"},{"price":"0.37","size":"23.13"},{"price":"0.4","size":"5544"},{"price":"0.42","size":"33.41"},{"price":"0.43","size":"5"},{"price":"0.44","size":"11"},{"price":"0.45","size":"314.33"},{"price":"0.46","size":"5"},{"price":"0.47","size":"10"},{"price":"0.48","size":"83.05"},{"price":"0.5","size":"20"},{"price":"0.51","size":"102.65"},{"price":"0.52","size":"10"},{"price":"0.56","size":"15"},{"price":"0.57","size":"5"},{"price":"0.58","size":"5"},{"price":"0.59","size":"10"},{"price":"0.61","size":"5"},{"price":"0.63","size":"20.24"},{"price":"0.64","size":"136.18"},{"price":"0.65","size":"150.75"},{"price":"0.66","size":"130.37"},{"price":"0.67","size":"15.12"},{"price":"0.68","size":"110.24"},{"price":"0.69","size":"94.01"},{"price":"0.7","size":"5807.5"},{"price":"0.71","size":"302.74"},{"price":"0.72","size":"202.84"},{"price":"0.73","size":"34.37"},{"price":"0.74","size":"110.67"},{"price":"0.75","size":"440.01"},{"price":"0.76","size":"279.24"},{"price":"0.77","size":"90"},{"price":"0.78","size":"9.97"},{"price":"0.79","size":"5"},{"price":"0.8","size":"5515"},{"price":"0.81","size":"104.75"},{"price":"0.83","size":"38.78"},{"price":"0.84","size":"16.56"},{"price":"0.85","size":"26.25"},{"price":"0.86","size":"525.94"},{"price":"0.88","size":"1011.36"},{"price":"0.89","size":"1010"},{"price":"0.9","size":"8554.19"},{"price":"0.92","size":"25"},{"price":"0.93","size":"45"},{"price":"0.94","size":"260.16"},{"price":"0.95","size":"262.3"},{"price":"0.96","size":"101.78"},{"price":"0.97","size":"457.14"},{"price":"0.98","size":"984.53"},{"price":"0.985","size":"5"},{"price":"0.99","size":"273125.74"},{"price":"0.991","size":"69"},{"price":"0.994","size":"57"},{"price":"0.996","size":"44"},{"price":"0.999","size":"104971.03"}],"asks":[],"hash":"edd309603a70620127a6a1304aa6fcb6d6c140f0","timestamp":"1768359607566","event_type":"book"}
{"market":"0x5977c69bca02e6cc150855b0faec463b38be463f141ec37ea5c8a1a1e986e0d3","price_changes":[{"asset_id":"110222991870854778724082971333105906777328061970448875974576460135015541883929","price":"0.999","size":"105976.77","side":"BUY","hash":"d707b649eb4e68642ec740b7a0cdd92e93557c08","best_bid":"0.999","best_ask":"1"},{"asset_id":"103575991306220918671611575108050794364462782362354955892418399227289531345027","price":"0.001","size":"105976.77","side":"SELL","hash":"23984fdec1f707e0c4b9a52ec6dae992f4a1e0ca","best_bid":"0","best_ask":"0.001"}],"timestamp":"1768359607568","event_type":"price_change"}
{"market":"0x5977c69bca02e6cc150855b0faec463b38be463f141ec37ea5c8a1a1e986e0d3","asset_id":"110222991870854778724082971333105906777328061970448875974576460135015541883929","price":"0.999","size":"286.77","fee_rate_bps":"1000","side":"SELL","timestamp":"1768359607593","event_type":"last_trade_price","transaction_hash":"0x15c885a045d3223bfbee154d36eeda115d58434e77caea71c187e1f13ba1dead"}
{"market":"0x5977c69bca02e6cc150855b0faec463b38be463f141ec37ea5c8a1a1e986e0d3","price_changes":[{"asset_id":"110222991870854778724082971333105906777328061970448875974576460135015541883929","price":"0.999","size":"105926.77","side":"BUY","hash":"d223e1586c94c27656f8f7e0d88bf6b0227cee72","best_bid":"0.999","best_ask":"1"},{"asset_id":"103575991306220918671611575108050794364462782362354955892418399227289531345027","price":"0.001","size":"105926.77","side":"SELL","hash":"b297ae4af35f2dd3525df2d034eb32080cb293ce","best_bid":"0","best_ask":"0.001"}],"timestamp":"1768359609081","event_type":"price_change"}
{"market":"0x5977c69bca02e6cc150855b0faec463b38be463f141ec37ea5c8a1a1e986e0d3","asset_id":"103575991306220918671611575108050794364462782362354955892418399227289531345027","bids":[],"asks":[{"price":"0.999","size":"270"},{"price":"0.998","size":"60"},{"price":"0.99","size":"4141.4"},{"price":"0.98","size":"1191.8"},{"price":"0.97","size":"355.5"},{"price":"0.96","size":"219.52"},{"price":"0.95","size":"3035"},{"price":"0.9","size":"5520"},{"price":"0.88","size":"5"},{"price":"0.85","size":"5"},{"price":"0.8","size":"40"},{"price":"0.75","size":"33.5"},{"price":"0.72","size":"23.14"},{"price":"0.7","size":"226.69"},{"price":"0.68","size":"5"},{"price":"0.66","size":"5"},{"price":"0.65","size":"18.93"},{"price":"0.64","size":"15"},{"price":"0.63","size":"23.13"},{"price":"0.6","size":"5544"},{"price":"0.58","size":"33.41"},{"price":"0.57","size":"5"},{"price":"0.56","size":"11"},{"price":"0.55","size":"314.33"},{"price":"0.54","size":"5"},{"price":"0.53","size":"10"},{"price":"0.52","size":"83.05"},{"price":"0.5","size":"20"},{"price":"0.49","size":"102.65"},{"price":"0.48","size":"10"},{"price":"0.44","size":"15"},{"price":"0.43","size":"5"},{"price":"0.42","size":"5"},{"price":"0.41","size":"10"},{"price":"0.39","size":"5"},{"price":"0.37","size":"20.24"},{"price":"0.36","size":"136.18"},{"price":"0.35","size":"150.75"},{"price":"0.34","size":"130.37"},{"price":"0.33","size":"15.12"},{"price":"0.32","size":"110.24"},{"price":"0.31","size":"94.01"},{"price":"0.3","size":"5807.5"},{"price":"0.29","size":"302.74"},{"price":"0.28","size":"202.84"},{"price":"0.27","size":"34.37"},{"price":"0.26","size":"110.67"},{"price":"0.25","size":"440.01"},{"price":"0.24","size":"279.24"},{"price":"0.23","size":"90"},{"price":"0.22","size":"9.97"},{"price":"0.21","size":"5"},{"price":"0.2","size":"5515"},{"price":"0.19","size":"104.75"},{"price":"0.17","size":"38.78"},{"price":"0.16","size":"16.56"},{"price":"0.15","size":"26.25"},{"price":"0.14","size":"525.94"},{"price":"0.12","size":"1011.36"},{"price":"0.11","size":"1010"},{"price":"0.1","size":"8554.19"},{"price":"0.08","size":"25"},{"price":"0.07","size":"45"},{"price":"0.06","size":"260.16"},{"price":"0.05","size":"262.3"},{"price":"0.04","size":"101.78"},{"price":"0.03","size":"457.14"},{"price":"0.02","size":"984.53"},{"price":"0.015","size":"5"},{"price":"0.01","size":"273125.74"},{"price":"0.009","size":"69"},{"price":"0.006","size":"57"},{"price":"0.004","size":"44"},{"price":"0.001","size":"105926.77"}],"hash":"b297ae4af35f2dd3525df2d034eb32080cb293ce","timestamp":"1768359609081","event_type":"book"}
{"market":"0x5977c69bca02e6cc150855b0faec463b38be463f141ec37ea5c8a1a1e986e0d3","asset_id":"110222991870854778724082971333105906777328061970448875974576460135015541883929","bids":[{"price":"0.001","size":"270"},{"price":"0.002","size":"60"},{"price":"0.01","size":"4141.4"},{"price":"0.02","size":"1191.8"},{"price":"0.03","size":"355.5"},{"price":"0.04","size":"219.52"},{"price":"0.05","size":"3035"},{"price":"0.1","size":"5520"},{"price":"0.12","size":"5"},{"price":"0.15","size":"5"},{"price":"0.2","size":"40"},{"price":"0.25","size":"33.5"},{"price":"0.28","size":"23.14"},{"price":"0.3","size":"226.69"},{"price":"0.32","size":"5"},{"price":"0.34","size":"5"},{"price":"0.35","size":"18.93"},{"price":"0.36","size":"15"},{"price":"0.37","size":"23.13"},{"price":"0.4","size":"5544"},{"price":"0.42","size":"33.41"},{"price":"0.43","size":"5"},{"price":"0.44","size":"11"},{"price":"0.45","size":"314.33"},{"price":"0.46","size":"5"},{"price":"0.47","size":"10"},{"price":"0.48","size":"83.05"},{"price":"0.5","size":"20"},{"price":"0.51","size":"102.65"},{"price":"0.52","size":"10"},{"price":"0.56","size":"15"},{"price":"0.57","size":"5"},{"price":"0.58","size":"5"},{"price":"0.59","size":"10"},{"price":"0.61","size":"5"},{"price":"0.63","size":"20.24"},{"price":"0.64","size":"136.18"},{"price":"0.65","size":"150.75"},{"price":"0.66","size":"130.37"},{"price":"0.67","size":"15.12"},{"price":"0.68","size":"110.24"},{"price":"0.69","size":"94.01"},{"price":"0.7","size":"5807.5"},{"price":"0.71","size":"302.74"},{"price":"0.72","size":"202.84"},{"price":"0.73","size":"34.37"},{"price":"0.74","size":"110.67"},{"price":"0.75","size":"440.01"},{"price":"0.76","size":"279.24"},{"price":"0.77","size":"90"},{"price":"0.78","size":"9.97"},{"price":"0.79","size":"5"},{"price":"0.8","size":"5515"},{"price":"0.81","size":"104.75"},{"price":"0.83","size":"38.78"},{"price":"0.84","size":"16.56"},{"price":"0.85","size":"26.25"},{"price":"0.86","size":"525.94"},{"price":"0.88","size":"1011.36"},{"price":"0.89","size":"1010"},{"price":"0.9","size":"8554.19"},{"price":"0.92","size":"25"},{"price":"0.93","size":"45"},{"price":"0.94","size":"260.16"},{"price":"0.95","size":"262.3"},{"price":"0.96","size":"101.78"},{"price":"0.97","size":"457.14"},{"price":"0.98","size":"984.53"},{"price":"0.985","size":"5"},{"price":"0.99","size":"273125.74"},{"price":"0.991","size":"69"},{"price":"0.994","size":"57"},{"price":"0.996","size":"44"},{"price":"0.999","size":"105926.77"}],"asks":[],"hash":"d223e1586c94c27656f8f7e0d88bf6b0227cee72","timestamp":"1768359609081","event_type":"book"}
{"market":"0x5977c69bca02e6cc150855b0faec463b38be463f141ec37ea5c8a1a1e986e0d3","asset_id":"110222991870854778724082971333105906777328061970448875974576460135015541883929","price":"0.999","size":"50","fee_rate_bps":"1000","side":"SELL","timestamp":"1768359609110","event_type":"last_trade_price","transaction_hash":"0x9dd2c1a1acca346fd2ceabc720ecb63b5b5fce13a205d5956fec68ad3847e068"}
{"market":"0x5977c69bca02e6cc150855b0faec463b38be463f141ec37ea5c8a1a1e986e0d3","price_changes":[{"asset_id":"110222991870854778724082971333105906777328061970448875974576460135015541883929","price":"0.94","size":"90.16","side":"BUY","hash":"a615e25d9b6d515f49ceca7e76ff96c9de9f27fc","best_bid":"0.999","best_ask":"1"},{"asset_id":"103575991306220918671611575108050794364462782362354955892418399227289531345027","price":"0.06","size":"90.16","side":"SELL","hash":"576271bb065512639eedf6daccc6ac6679ff6c35","best_bid":"0","best_ask":"0.001"}],"timestamp":"1768359609644","event_type":"price_change"}
PONG
{"market":"0x5977c69bca02e6cc150855b0faec463b38be463f141ec37ea5c8a1a1e986e0d3","price_changes":[{"asset_id":"110222991870854778724082971333105906777328061970448875974576460135015541883929","price":"0.01","size":"4040.4","side":"BUY","hash":"e76737d2ec54c9f425cd6f2597db4c27bc718508","best_bid":"0.999","best_ask":"1"},{"asset_id":"103575991306220918671611575108050794364462782362354955892418399227289531345027","price":"0.99","size":"4040.4","side":"SELL","hash":"94fb8134e4f0e5f8cd471203c4f768923c683f7b","best_bid":"0","best_ask":"0.001"}],"timestamp":"1768359614588","event_type":"price_change"}
PONG
{"market":"0x5977c69bca02e6cc150855b0faec463b38be463f141ec37ea5c8a1a1e986e0d3","price_changes":[{"asset_id":"110222991870854778724082971333105906777328061970448875974576460135015541883929","price":"0.999","size":"104918.52","side":"BUY","hash":"b7ebe3b6caaeaaccb77bc98f09da4d60d3aae19e","best_bid":"0.999","best_ask":"1"},{"asset_id":"103575991306220918671611575108050794364462782362354955892418399227289531345027","price":"0.001","size":"104918.52","side":"SELL","hash":"e35a4097d360ab1dbf8deec341ef40134ed8a07e","best_bid":"0","best_ask":"0.001"}],"timestamp":"1768359615551","event_type":"price_change"}
{"market":"0x5977c69bca02e6cc150855b0faec463b38be463f141ec37ea5c8a1a1e986e0d3","asset_id":"103575991306220918671611575108050794364462782362354955892418399227289531345027","bids":[],"asks":[{"price":"0.999","size":"270"},{"price":"0.998","size":"60"},{"price":"0.99","size":"4040.4"},{"price":"0.98","size":"1191.8"},{"price":"0.97","size":"355.5"},{"price":"0.96","size":"219.52"},{"price":"0.95","size":"3035"},{"price":"0.9","size":"5520"},{"price":"0.88","size":"5"},{"price":"0.85","size":"5"},{"price":"0.8","size":"40"},{"price":"0.75","size":"33.5"},{"price":"0.72","size":"23.14"},{"price":"0.7","size":"226.69"},{"price":"0.68","size":"5"},{"price":"0.66","size":"5"},{"price":"0.65","size":"18.93"},{"price":"0.64","size":"15"},{"price":"0.63","size":"23.13"},{"price":"0.6","size":"5544"},{"price":"0.58","size":"33.41"},{"price":"0.57","size":"5"},{"price":"0.56","size":"11"},{"price":"0.55","size":"314.33"},{"price":"0.54","size":"5"},{"price":"0.53","size":"10"},{"price":"0.52","size":"83.05"},{"price":"0.5","size":"20"},{"price":"0.49","size":"102.65"},{"price":"0.48","size":"10"},{"price":"0.44","size":"15"},{"price":"0.43","size":"5"},{"price":"0.42","size":"5"},{"price":"0.41","size":"10"},{"price":"0.39","size":"5"},{"price":"0.37","size":"20.24"},{"price":"0.36","size":"136.18"},{"price":"0.35","size":"150.75"},{"price":"0.34","size":"130.37"},{"price":"0.33","size":"15.12"},{"price":"0.32","size":"110.24"},{"price":"0.31","size":"94.01"},{"price":"0.3","size":"5807.5"},{"price":"0.29","size":"302.74"},{"price":"0.28","size":"202.84"},{"price":"0.27","size":"34.37"},{"price":"0.26","size":"110.67"},{"price":"0.25","size":"440.01"},{"price":"0.24","size":"279.24"},{"price":"0.23","size":"90"},{"price":"0.22","size":"9.97"},{"price":"0.21","size":"5"},{"price":"0.2","size":"5515"},{"price":"0.19","size":"104.75"},{"price":"0.17","size":"38.78"},{"price":"0.16","size":"16.56"},{"price":"0.15","size":"26.25"},{"price":"0.14","size":"525.94"},{"price":"0.12","size":"1011.36"},{"price":"0.11","size":"1010"},{"price":"0.1","size":"8554.19"},{"price":"0.08","size":"25"},{"price":"0.07","size":"45"},{"price":"0.06","size":"90.16"},{"price":"0.05","size":"262.3"},{"price":"0.04","size":"101.78"},{"price":"0.03","size":"457.14"},{"price":"0.02","size":"984.53"},{"price":"0.015","size":"5"},{"price":"0.01","size":"273125.74"},{"price":"0.009","size":"69"},{"price":"0.006","size":"57"},{"price":"0.004","size":"44"},{"price":"0.001","size":"104918.52"}],"hash":"e35a4097d360ab1dbf8deec341ef40134ed8a07e","timestamp":"1768359615551","event_type":"book"}
{"market":"0x5977c69bca02e6cc150855b0faec463b38be463f141ec37ea5c8a1a1e986e0d3","asset_id":"110222991870854778724082971333105906777328061970448875974576460135015541883929","bids":[{"price":"0.001","size":"270"},{"price":"0.002","size":"60"},{"price":"0.01","size":"4040.4"},{"price":"0.02","size":"1191.8"},{"price":"0.03","size":"355.5"},{"price":"0.04","size":"219.52"},{"price":"0.05","size":"3035"},{"price":"0.1","size":"5520"},{"price":"0.12","size":"5"},{"price":"0.15","size":"5"},{"price":"0.2","size":"40"},{"price":"0.25","size":"33.5"},{"price":"0.28","size":"23.14"},{"price":"0.3","size":"226.69"},{"price":"0.32","size":"5"},{"price":"0.34","size":"5"},{"price":"0.35","size":"18.93"},{"price":"0.36","size":"15"},{"price":"0.37","size":"23.13"},{"price":"0.4","size":"5544"},{"price":"0.42","size":"33.41"},{"price":"0.43","size":"5"},{"price":"0.44","size":"11"},{"price":"0.45","size":"314.33"},{"price":"0.46","size":"5"},{"price":"0.47","size":"10"},{"price":"0.48","size":"83.05"},{"price":"0.5","size":"20"},{"price":"0.51","size":"102.65"},{"price":"0.52","size":"10"},{"price":"0.56","size":"15"},{"price":"0.57","size":"5"},{"price":"0.58","size":"5"},{"price":"0.59","size":"10"},{"price":"0.61","size":"5"},{"price":"0.63","size":"20.24"},{"price":"0.64","size":"136.18"},{"price":"0.65","size":"150.75"},{"price":"0.66","size":"130.37"},{"price":"0.67","size":"15.12"},{"price":"0.68","size":"110.24"},{"price":"0.69","size":"94.01"},{"price":"0.7","size":"5807.5"},{"price":"0.71","size":"302.74"},{"price":"0.72","size":"202.84"},{"price":"0.73","size":"34.37"},{"price":"0.74","size":"110.67"},{"price":"0.75","size":"440.01"},{"price":"0.76","size":"279.24"},{"price":"0.77","size":"90"},{"price":"0.78","size":"9.97"},{"price":"0.79","size":"5"},{"price":"0.8","size":"5515"},{"price":"0.81","size":"104.75"},{"price":"0.83","size":"38.78"},{"price":"0.84","size":"16.56"},{"price":"0.85","size":"26.25"},{"price":"0.86","size":"525.94"},{"price":"0.88","size":"1011.36"},{"price":"0.89","size":"1010"},{"price":"0.9","size":"8554.19"},{"price":"0.92","size":"25"},{"price":"0.93","size":"45"},{"price":"0.94","size":"90.16"},{"price":"0.95","size":"262.3"},{"price":"0.96","size":"101.78"},{"price":"0.97","size":"457.14"},{"price":"0.98","size":"984.53"},{"price":"0.985","size":"5"},{"price":"0.99","size":"273125.74"},{"price":"0.991","size":"69"},{"price":"0.994","size":"57"},{"price":"0.996","size":"44"},{"price":"0.999","size":"104918.52"}],"asks":[],"hash":"b7ebe3b6caaeaaccb77bc98f09da4d60d3aae19e","timestamp":"1768359615551","event_type":"book"}
{"market":"0x5977c69bca02e6cc150855b0faec463b38be463f141ec37ea5c8a1a1e986e0d3","asset_id":"110222991870854778724082971333105906777328061970448875974576460135015541883929","price":"0.999","size":"1008.25","fee_rate_bps":"1000","side":"SELL","timestamp":"1768359615585","event_type":"last_trade_price","transaction_hash":"0x6f6c4692f906a567e4fbe58c771b117c0fe6d80435899a52a7a9f34bfa4b70a4"}
PONG
{"market":"0x5977c69bca02e6cc150855b0faec463b38be463f141ec37ea5c8a1a1e986e0d3","price_changes":[{"asset_id":"110222991870854778724082971333105906777328061970448875974576460135015541883929","price":"0.51","size":"95.43","side":"BUY","hash":"7e76d61df29ee20b520ee8705512c620a7a65512","best_bid":"0.999","best_ask":"1"},{"asset_id":"103575991306220918671611575108050794364462782362354955892418399227289531345027","price":"0.49","size":"95.43","side":"SELL","hash":"b32758d6705b26469a27aaa64eac78315bd6ccce","best_bid":"0","best_ask":"0.001"}],"timestamp":"1768359620586","event_type":"price_change"}
{"market":"0x5977c69bca02e6cc150855b0faec463b38be463f141ec37ea5c8a1a1e986e0d3","price_changes":[{"asset_id":"110222991870854778724082971333105906777328061970448875974576460135015541883929","price":"0.001","size":"1260","side":"BUY","hash":"d64b493a566c2624029e8a80b98d72e84100c610","best_bid":"0.999","best_ask":"1"},{"asset_id":"103575991306220918671611575108050794364462782362354955892418399227289531345027","price":"0.999","size":"1260","side":"SELL","hash":"44ab4a1bba8bc2d88993b2b0c6042dda1a94cbb3","best_bid":"0","best_ask":"0.001"}],"timestamp":"1768359621556","event_type":"price_change"}
PONG
{"market":"0x5977c69bca02e6cc150855b0faec463b38be463f141ec37ea5c8a1a1e986e0d3","price_changes":[{"asset_id":"110222991870854778724082971333105906777328061970448875974576460135015541883929","price":"0.999","size":"105947.43","side":"BUY","hash":"a8536c73871651c8b941bbc1c7217688157473bb","best_bid":"0.999","best_ask":"1"},{"asset_id":"103575991306220918671611575108050794364462782362354955892418399227289531345027","price":"0.001","size":"105947.43","side":"SELL","hash":"c3c3a891ecb07ffb2b0f9b1118416eaa6e55192a","best_bid":"0","best_ask":"0.001"}],"timestamp":"1768359626917","event_type":"price_change"}
PONG
{"market":"0x5977c69bca02e6cc150855b0faec463b38be463f141ec37ea5c8a1a1e986e0d3","price_changes":[{"asset_id":"110222991870854778724082971333105906777328061970448875974576460135015541883929","price":"0.68","size":"120.31","side":"BUY","hash":"c333f9e02897599f6e1395281ef19ef6184ce702","best_bid":"0.999","best_ask":"1"},{"asset_id":"103575991306220918671611575108050794364462782362354955892418399227289531345027","price":"0.32","size":"120.31","side":"SELL","hash":"666e9153379b0c72056db6f46881c412bffbf732","best_bid":"0","best_ask":"0.001"}],"timestamp":"1768359630990","event_type":"price_change"}
{"market":"0x5977c69bca02e6cc150855b0faec463b38be463f141ec37ea5c8a1a1e986e0d3","price_changes":[{"asset_id":"110222991870854778724082971333105906777328061970448875974576460135015541883929","price":"0.999","size":"105937.36","side":"BUY","hash":"20fe307fab76b092421fd52c5f3777a9bed595ba","best_bid":"0.999","best_ask":"1"},{"asset_id":"103575991306220918671611575108050794364462782362354955892418399227289531345027","price":"0.001","size":"105937.36","side":"SELL","hash":"b05584a546abc9b326280e9c533725cae05ead41","best_bid":"0","best_ask":"0.001"}],"timestamp":"1768359631400","event_type":"price_change"}
{"market":"0x5977c69bca02e6cc150855b0faec463b38be463f141ec37ea5c8a1a1e986e0d3","asset_id":"103575991306220918671611575108050794364462782362354955892418399227289531345027","bids":[],"asks":[{"price":"0.999","size":"1260"},{"price":"0.998","size":"60"},{"price":"0.99","size":"4040.4"},{"price":"0.98","size":"1191.8"},{"price":"0.97","size":"355.5"},{"price":"0.96","size":"219.52"},{"price":"0.95","size":"3035"},{"price":"0.9","size":"5520"},{"price":"0.88","size":"5"},{"price":"0.85","size":"5"},{"price":"0.8","size":"40"},{"price":"0.75","size":"33.5"},{"price":"0.72","size":"23.14"},{"price":"0.7","size":"226.69"},{"price":"0.68","size":"5"},{"price":"0.66","size":"5"},{"price":"0.65","size":"18.93"},{"price":"0.64","size":"15"},{"price":"0.63","size":"23.13"},{"price":"0.6","size":"5544"},{"price":"0.58","size":"33.41"},{"price":"0.57","size":"5"},{"price":"0.56","size":"11"},{"price":"0.55","size":"314.33"},{"price":"0.54","size":"5"},{"price":"0.53","size":"10"},{"price":"0.52","size":"83.05"},{"price":"0.5","size":"20"},{"price":"0.49","size":"95.43"},{"price":"0.48","size":"10"},{"price":"0.44","size":"15"},{"price":"0.43","size":"5"},{"price":"0.42","size":"5"},{"price":"0.41","size":"10"},{"price":"0.39","size":"5"},{"price":"0.37","size":"20.24"},{"price":"0.36","size":"136.18"},{"price":"0.35","size":"150.75"},{"price":"0.34","size":"130.37"},{"price":"0.33","size":"15.12"},{"price":"0.32","size":"120.31"},{"price":"0.31","size":"94.01"},{"price":"0.3","size":"5807.5"},{"price":"0.29","size":"302.74"},{"price":"0.28","size":"202.84"},{"price":"0.27","size":"34.37"},{"price":"0.26","size":"110.67"},{"price":"0.25","size":"440.01"},{"price":"0.24","size":"279.24"},{"price":"0.23","size":"90"},{"price":"0.22","size":"9.97"},{"price":"0.21","size":"5"},{"price":"0.2","size":"5515"},{"price":"0.19","size":"104.75"},{"price":"0.17","size":"38.78"},{"price":"0.16","size":"16.56"},{"price":"0.15","size":"26.25"},{"price":"0.14","size":"525.94"},{"price":"0.12","size":"1011.36"},{"price":"0.11","size":"1010"},{"price":"0.1","size":"8554.19"},{"price":"0.08","size":"25"},{"price":"0.07","size":"45"},{"price":"0.06","size":"90.16"},{"price":"0.05","size":"262.3"},{"price":"0.04","size":"101.78"},{"price":"0.03","size":"457.14"},{"price":"0.02","size":"984.53"},{"price":"0.015","size":"5"},{"price":"0.01","size":"273125.74"},{"price":"0.009","size":"69"},{"price":"0.006","size":"57"},{"price":"0.004","size":"44"},{"price":"0.001","size":"105937.36"}],"hash":"b05584a546abc9b326280e9c533725cae05ead41","timestamp":"1768359631400","event_type":"book"}
{"market":"0x5977c69bca02e6cc150855b0faec463b38be463f141ec37ea5c8a1a1e986e0d3","asset_id":"110222991870854778724082971333105906777328061970448875974576460135015541883929","bids":[{"price":"0.001","size":"1260"},{"price":"0.002","size":"60"},{"price":"0.01","size":"4040.4"},{"price":"0.02","size":"1191.8"},{"price":"0.03","size":"355.5"},{"price":"0.04","size":"219.52"},{"price":"0.05","size":"3035"},{"price":"0.1","size":"5520"},{"price":"0.12","size":"5"},{"price":"0.15","size":"5"},{"price":"0.2","size":"40"},{"price":"0.25","size":"33.5"},{"price":"0.28","size":"23.14"},{"price":"0.3","size":"226.69"},{"price":"0.32","size":"5"},{"price":"0.34","size":"5"},{"price":"0.35","size":"18.93"},{"price":"0.36","size":"15"},{"price":"0.37","size":"23.13"},{"price":"0.4","size":"5544"},{"price":"0.42","size":"33.41"},{"price":"0.43","size":"5"},{"price":"0.44","size":"11"},{"price":"0.45","size":"314.33"},{"price":"0.46","size":"5"},{"price":"0.47","size":"10"},{"price":"0.48","size":"83.05"},{"price":"0.5","size":"20"},{"price":"0.51","size":"95.43"},{"price":"0.52","size":"10"},{"price":"0.56","size":"15"},{"price":"0.57","size":"5"},{"price":"0.58","size":"5"},{"price":"0.59","size":"10"},{"price":"0.61","size":"5"},{"price":"0.63","size":"20.24"},{"price":"0.64","size":"136.18"},{"price":"0.65","size":"150.75"},{"price":"0.66","size":"130.37"},{"price":"0.67","size":"15.12"},{"price":"0.68","size":"120.31"},{"price":"0.69","size":"94.01"},{"price":"0.7","size":"5807.5"},{"price":"0.71","size":"302.74"},{"price":"0.72","size":"202.84"},{"price":"0.73","size":"34.37"},{"price":"0.74","size":"110.67"},{"price":"0.75","size":"440.01"},{"price":"0.76","size":"279.24"},{"price":"0.77","size":"90"},{"price":"0.78","size":"9.97"},{"price":"0.79","size":"5"},{"price":"0.8","size":"5515"},{"price":"0.81","size":"104.75"},{"price":"0.83","size":"38.78"},{"price":"0.84","size":"16.56"},{"price":"0.85","size":"26.25"},{"price":"0.86","size":"525.94"},{"price":"0.88","size":"1011.36"},{"price":"0.89","size":"1010"},{"price":"0.9","size":"8554.19"},{"price":"0.92","size":"25"},{"price":"0.93","size":"45"},{"price":"0.94","size":"90.16"},{"price":"0.95","size":"262.3"},{"price":"0.96","size":"101.78"},{"price":"0.97","size":"457.14"},{"price":"0.98","size":"984.53"},{"price":"0.985","size":"5"},{"price":"0.99","size":"273125.74"},{"price":"0.991","size":"69"},{"price":"0.994","size":"57"},{"price":"0.996","size":"44"},{"price":"0.999","size":"105937.36"}],"asks":[],"hash":"20fe307fab76b092421fd52c5f3777a9bed595ba","timestamp":"1768359631400","event_type":"book"}
{"market":"0x5977c69bca02e6cc150855b0faec463b38be463f141ec37ea5c8a1a1e986e0d3","asset_id":"103575991306220918671611575108050794364462782362354955892418399227289531345027","price":"0.001","size":"10.07","fee_rate_bps":"1000","side":"BUY","timestamp":"1768359631448","event_type":"last_trade_price","transaction_hash":"0x46d1487e8f606ec3d88db7bd49327ede25112b896e9ddc3959a29227941a723e"}
PONG
PONG
PONG
{"market":"0x5977c69bca02e6cc150855b0faec463b38be463f141ec37ea5c8a1a1e986e0d3","price_changes":[{"asset_id":"110222991870854778724082971333105906777328061970448875974576460135015541883929","price":"0.51","size":"88.01","side":"BUY","hash":"c8ec9bc24d3ae48117b9090f193a0a90ce6381df","best_bid":"0.999","best_ask":"1"},{"asset_id":"103575991306220918671611575108050794364462782362354955892418399227289531345027","price":"0.49","size":"88.01","side":"SELL","hash":"e2c04236e71d124ef1699f48ce20b6c94abdde78","best_bid":"0","best_ask":"0.001"}],"timestamp":"1768359646631","event_type":"price_change"}
PONG
{"market":"0x5977c69bca02e6cc150855b0faec463b38be463f141ec37ea5c8a1a1e986e0d3","price_changes":[{"asset_id":"110222991870854778724082971333105906777328061970448875974576460135015541883929","price":"0.001","size":"270","side":"BUY","hash":"559b65030066c2cd9dfe50ddcfce73aa74fcd6e6","best_bid":"0.999","best_ask":"1"},{"asset_id":"103575991306220918671611575108050794364462782362354955892418399227289531345027","price":"0.999","size":"270","side":"SELL","hash":"92f780563f216008fee859aeaf649cc2501f1b3a","best_bid":"0","best_ask":"0.001"}],"timestamp":"1768359651000","event_type":"price_change"}
PONG
{"market":"0x5977c69bca02e6cc150855b0faec463b38be463f141ec37ea5c8a1a1e986e0d3","price_changes":[{"asset_id":"110222991870854778724082971333105906777328061970448875974576460135015541883929","price":"0.94","size":"85.16","side":"BUY","hash":"2cff64b49ad70c582305deb08eae70a12c7f3fb6","best_bid":"0.999","best_ask":"1"},{"asset_id":"103575991306220918671611575108050794364462782362354955892418399227289531345027","price":"0.06","size":"85.16","side":"SELL","hash":"c56f36f97323b25bd9bc7bc9b3a69a6444debcba","best_bid":"0","best_ask":"0.001"}],"timestamp":"1768359658651","event_type":"price_change"}
PONG
{"market":"0x5977c69bca02e6cc150855b0faec463b38be463f141ec37ea5c8a1a1e986e0d3","price_changes":[{"asset_id":"103575991306220918671611575108050794364462782362354955892418399227289531345027","price":"0.27","size":"0","side":"SELL","hash":"e52b130f364b80c03bab08702ca82ce88db8391b","best_bid":"0","best_ask":"1"},{"asset_id":"110222991870854778724082971333105906777328061970448875974576460135015541883929","price":"0.73","size":"0","side":"BUY","hash":"37b8ccb799c95692ea5fdc0dec47f324ae8c79a0","best_bid":"0","best_ask":"1"}],"timestamp":"1768359662151","event_type":"price_change"}
{"market":"0x5977c69bca02e6cc150855b0faec463b38be463f141ec37ea5c8a1a1e986e0d3","price_changes":[{"asset_id":"103575991306220918671611575108050794364462782362354955892418399227289531345027","price":"0.25","size":"0","side":"SELL","hash":"e52b130f364b80c03bab08702ca82ce88db8391b","best_bid":"0","best_ask":"1"},{"asset_id":"110222991870854778724082971333105906777328061970448875974576460135015541883929","price":"0.75","size":"0","side":"BUY","hash":"37b8ccb799c95692ea5fdc0dec47f324ae8c79a0","best_bid":"0","best_ask":"1"}],"timestamp":"1768359662151","event_type":"price_change"}
{"market":"0x5977c69bca02e6cc150855b0faec463b38be463f141ec37ea5c8a1a1e986e0d3","price_changes":[{"asset_id":"103575991306220918671611575108050794364462782362354955892418399227289531345027","price":"0.96","size":"0","side":"SELL","hash":"e52b130f364b80c03bab08702ca82ce88db8391b","best_bid":"0","best_ask":"1"},{"asset_id":"110222991870854778724082971333105906777328061970448875974576460135015541883929","price":"0.04","size":"0","side":"BUY","hash":"37b8ccb799c95692ea5fdc0dec47f324ae8c79a0","best_bid":"0","best_ask":"1"}],"timestamp":"1768359662151","event_type":"price_change"}
{"market":"0x5977c69bca02e6cc150855b0faec463b38be463f141ec37ea5c8a1a1e986e0d3","price_changes":[{"asset_id":"103575991306220918671611575108050794364462782362354955892418399227289531345027","price":"0.01","size":"0","side":"SELL","hash":"e52b130f364b80c03bab08702ca82ce88db8391b","best_bid":"0","best_ask":"1"},{"asset_id":"110222991870854778724082971333105906777328061970448875974576460135015541883929","price":"0.99","size":"0","side":"BUY","hash":"37b8ccb799c95692ea5fdc0dec47f324ae8c79a0","best_bid":"0","best_ask":"1"}],"timestamp":"1768359662151","event_type":"price_change"}
{"market":"0x5977c69bca02e6cc150855b0faec463b38be463f141ec37ea5c8a1a1e986e0d3","price_changes":[{"asset_id":"103575991306220918671611575108050794364462782362354955892418399227289531345027","price":"0.26","size":"0","side":"SELL","hash":"e52b130f364b80c03bab08702ca82ce88db8391b","best_bid":"0","best_ask":"1"},{"asset_id":"110222991870854778724082971333105906777328061970448875974576460135015541883929","price":"0.74","size":"0","side":"BUY","hash":"37b8ccb799c95692ea5fdc0dec47f324ae8c79a0","best_bid":"0","best_ask":"1"}],"timestamp":"1768359662151","event_type":"price_change"}
{"market":"0x5977c69bca02e6cc150855b0faec463b38be463f141ec37ea5c8a1a1e986e0d3","price_changes":[{"asset_id":"103575991306220918671611575108050794364462782362354955892418399227289531345027","price":"0.72","size":"0","side":"SELL","hash":"e52b130f364b80c03bab08702ca82ce88db8391b","best_bid":"0","best_ask":"1"},{"asset_id":"110222991870854778724082971333105906777328061970448875974576460135015541883929","price":"0.28","size":"0","side":"BUY","hash":"37b8ccb799c95692ea5fdc0dec47f324ae8c79a0","best_bid":"0","best_ask":"1"}],"timestamp":"1768359662151","event_type":"price_change"}
{"market":"0x5977c69bca02e6cc150855b0faec463b38be463f141ec37ea5c8a1a1e986e0d3","price_changes":[{"asset_id":"103575991306220918671611575108050794364462782362354955892418399227289531345027","price":"0.24","size":"0","side":"SELL","hash":"e52b130f364b80c03bab08702ca82ce88db8391b","best_bid":"0","best_ask":"1"},{"asset_id":"110222991870854778724082971333105906777328061970448875974576460135015541883929","price":"0.76","size":"0","side":"BUY","hash":"37b8ccb799c95692ea5fdc0dec47f324ae8c79a0","best_bid":"0","best_ask":"1"}],"timestamp":"1768359662151","event_type":"price_change"}
{"market":"0x5977c69bca02e6cc150855b0faec463b38be463f141ec37ea5c8a1a1e986e0d3","price_changes":[{"asset_id":"103575991306220918671611575108050794364462782362354955892418399227289531345027","price":"0.97","size":"0","side":"SELL","hash":"e52b130f364b80c03bab08702ca82ce88db8391b","best_bid":"0","best_ask":"1"},{"asset_id":"110222991870854778724082971333105906777328061970448875974576460135015541883929","price":"0.03","size":"0","side":"BUY","hash":"37b8ccb799c95692ea5fdc0dec47f324ae8c79a0","best_bid":"0","best_ask":"1"}],"timestamp":"1768359662151","event_type":"price_change"}
{"market":"0x5977c69bca02e6cc150855b0faec463b38be463f141ec37ea5c8a1a1e986e0d3","price_changes":[{"asset_id":"103575991306220918671611575108050794364462782362354955892418399227289531345027","price":"0.28","size":"0","side":"SELL","hash":"e52b130f364b80c03bab08702ca82ce88db8391b","best_bid":"0","best_ask":"1"},{"asset_id":"110222991870854778724082971333105906777328061970448875974576460135015541883929","price":"0.72","size":"0","side":"BUY","hash":"37b8ccb799c95692ea5fdc0dec47f324ae8c79a0","best_bid":"0","best_ask":"1"}],"timestamp":"1768359662151","event_type":"price_change"}
{"market":"0x5977c69bca02e6cc150855b0faec463b38be463f141ec37ea5c8a1a1e986e0d3","price_changes":[{"asset_id":"103575991306220918671611575108050794364462782362354955892418399227289531345027","price":"0.04","size":"0","side":"SELL","hash":"e52b130f364b80c03bab08702ca82ce88db8391b","best_bid":"0","best_ask":"1"},{"asset_id":"110222991870854778724082971333105906777328061970448875974576460135015541883929","price":"0.96","size":"0","side":"BUY","hash":"37b8ccb799c95692ea5fdc0dec47f324ae8c79a0","best_bid":"0","best_ask":"1"}],"timestamp":"1768359662151","event_type":"price_change"}
{"market":"0x5977c69bca02e6cc150855b0faec463b38be463f141ec37ea5c8a1a1e986e0d3","price_changes":[{"asset_id":"103575991306220918671611575108050794364462782362354955892418399227289531345027","price":"0.31","size":"0","side":"SELL","hash":"e52b130f364b80c03bab08702ca82ce88db8391b","best_bid":"0","best_ask":"1"},{"asset_id":"110222991870854778724082971333105906777328061970448875974576460135015541883929","price":"0.69","size":"0","side":"BUY","hash":"37b8ccb799c95692ea5fdc0dec47f324ae8c79a0","best_bid":"0","best_ask":"1"}],"timestamp":"1768359662151","event_type":"price_change"}
{"market":"0x5977c69bca02e6cc150855b0faec463b38be463f141ec37ea5c8a1a1e986e0d3","price_changes":[{"asset_id":"103575991306220918671611575108050794364462782362354955892418399227289531345027","price":"0.1","size":"0","side":"SELL","hash":"e52b130f364b80c03bab08702ca82ce88db8391b","best_bid":"0","best_ask":"1"},{"asset_id":"110222991870854778724082971333105906777328061970448875974576460135015541883929","price":"0.9","size":"0","side":"BUY","hash":"37b8ccb799c95692ea5fdc0dec47f324ae8c79a0","best_bid":"0","best_ask":"1"}],"timestamp":"1768359662151","event_type":"price_change"}
{"market":"0x5977c69bca02e6cc150855b0faec463b38be463f141ec37ea5c8a1a1e986e0d3","price_changes":[{"asset_id":"103575991306220918671611575108050794364462782362354955892418399227289531345027","price":"0.03","size":"0","side":"SELL","hash":"e52b130f364b80c03bab08702ca82ce88db8391b","best_bid":"0","best_ask":"1"},{"asset_id":"110222991870854778724082971333105906777328061970448875974576460135015541883929","price":"0.97","size":"0","side":"BUY","hash":"37b8ccb799c95692ea5fdc0dec47f324ae8c79a0","best_bid":"0","best_ask":"1"}],"timestamp":"1768359662151","event_type":"price_change"}
{"market":"0x5977c69bca02e6cc150855b0faec463b38be463f141ec37ea5c8a1a1e986e0d3","price_changes":[{"asset_id":"103575991306220918671611575108050794364462782362354955892418399227289531345027","price":"0.99","size":"0","side":"SELL","hash":"e52b130f364b80c03bab08702ca82ce88db8391b","best_bid":"0","best_ask":"1"},{"asset_id":"110222991870854778724082971333105906777328061970448875974576460135015541883929","price":"0.01","size":"0","side":"BUY","hash":"37b8ccb799c95692ea5fdc0dec47f324ae8c79a0","best_bid":"0","best_ask":"1"}],"timestamp":"1768359662151","event_type":"price_change"}
{"market":"0x5977c69bca02e6cc150855b0faec463b38be463f141ec37ea5c8a1a1e986e0d3","price_changes":[{"asset_id":"103575991306220918671611575108050794364462782362354955892418399227289531345027","price":"0.75","size":"0","side":"SELL","hash":"e52b130f364b80c03bab08702ca82ce88db8391b","best_bid":"0","best_ask":"1"},{"asset_id":"110222991870854778724082971333105906777328061970448875974576460135015541883929","price":"0.25","size":"0","side":"BUY","hash":"37b8ccb799c95692ea5fdc0dec47f324ae8c79a0","best_bid":"0","best_ask":"1"}],"timestamp":"1768359662151","event_type":"price_change"}
{"market":"0x5977c69bca02e6cc150855b0faec463b38be463f141ec37ea5c8a1a1e986e0d3","price_changes":[{"asset_id":"103575991306220918671611575108050794364462782362354955892418399227289531345027","price":"0.98","size":"0","side":"SELL","hash":"e52b130f364b80c03bab08702ca82ce88db8391b","best_bid":"0","best_ask":"1"},{"asset_id":"110222991870854778724082971333105906777328061970448875974576460135015541883929","price":"0.02","size":"0","side":"BUY","hash":"37b8ccb799c95692ea5fdc0dec47f324ae8c79a0","best_bid":"0","best_ask":"1"}],"timestamp":"1768359662151","event_type":"price_change"}
{"market":"0x5977c69bca02e6cc150855b0faec463b38be463f141ec37ea5c8a1a1e986e0d3","price_changes":[{"asset_id":"103575991306220918671611575108050794364462782362354955892418399227289531345027","price":"0.22","size":"0","side":"SELL","hash":"e52b130f364b80c03bab08702ca82ce88db8391b","best_bid":"0","best_ask":"1"},{"asset_id":"110222991870854778724082971333105906777328061970448875974576460135015541883929","price":"0.78","size":"0","side":"BUY","hash":"37b8ccb799c95692ea5fdc0dec47f324ae8c79a0","best_bid":"0","best_ask":"1"}],"timestamp":"1768359662151","event_type":"price_change"}
{"market":"0x5977c69bca02e6cc150855b0faec463b38be463f141ec37ea5c8a1a1e986e0d3","price_changes":[{"asset_id":"103575991306220918671611575108050794364462782362354955892418399227289531345027","price":"0.16","size":"0","side":"SELL","hash":"e52b130f364b80c03bab08702ca82ce88db8391b","best_bid":"0","best_ask":"1"},{"asset_id":"110222991870854778724082971333105906777328061970448875974576460135015541883929","price":"0.84","size":"0","side":"BUY","hash":"37b8ccb799c95692ea5fdc0dec47f324ae8c79a0","best_bid":"0","best_ask":"1"}],"timestamp":"1768359662151","event_type":"price_change"}
{"market":"0x5977c69bca02e6cc150855b0faec463b38be463f141ec37ea5c8a1a1e986e0d3","price_changes":[{"asset_id":"103575991306220918671611575108050794364462782362354955892418399227289531345027","price":"0.65","size":"0","side":"SELL","hash":"e52b130f364b80c03bab08702ca82ce88db8391b","best_bid":"0","best_ask":"1"},{"asset_id":"110222991870854778724082971333105906777328061970448875974576460135015541883929","price":"0.35","size":"0","side":"BUY","hash":"37b8ccb799c95692ea5fdc0dec47f324ae8c79a0","best_bid":"0","best_ask":"1"}],"timestamp":"1768359662151","event_type":"price_change"}
{"market":"0x5977c69bca02e6cc150855b0faec463b38be463f141ec37ea5c8a1a1e986e0d3","price_changes":[{"asset_id":"103575991306220918671611575108050794364462782362354955892418399227289531345027","price":"0.63","size":"0","side":"SELL","hash":"e52b130f364b80c03bab08702ca82ce88db8391b","best_bid":"0","best_ask":"1"},{"asset_id":"110222991870854778724082971333105906777328061970448875974576460135015541883929","price":"0.37","size":"0","side":"BUY","hash":"37b8ccb799c95692ea5fdc0dec47f324ae8c79a0","best_bid":"0","best_ask":"1"}],"timestamp":"1768359662151","event_type":"price_change"}
{"market":"0x5977c69bca02e6cc150855b0faec463b38be463f141ec37ea5c8a1a1e986e0d3","price_changes":[{"asset_id":"110222991870854778724082971333105906777328061970448875974576460135015541883929","price":"0.68","size":"0","side":"BUY","hash":"37b8ccb799c95692ea5fdc0dec47f324ae8c79a0","best_bid":"0","best_ask":"1"},{"asset_id":"103575991306220918671611575108050794364462782362354955892418399227289531345027","price":"0.32","size":"0","side":"SELL","hash":"e52b130f364b80c03bab08702ca82ce88db8391b","best_bid":"0","best_ask":"1"}],"timestamp":"1768359662151","event_type":"price_change"}
{"market":"0x5977c69bca02e6cc150855b0faec463b38be463f141ec37ea5c8a1a1e986e0d3","price_changes":[{"asset_id":"110222991870854778724082971333105906777328061970448875974576460135015541883929","price":"0.05","size":"0","side":"BUY","hash":"37b8ccb799c95692ea5fdc0dec47f324ae8c79a0","best_bid":"0","best_ask":"1"},{"asset_id":"103575991306220918671611575108050794364462782362354955892418399227289531345027","price":"0.95","size":"0","side":"SELL","hash":"e52b130f364b80c03bab08702ca82ce88db8391b","best_bid":"0","best_ask":"1"}],"timestamp":"1768359662151","event_type":"price_change"}
{"market":"0x5977c69bca02e6cc150855b0faec463b38be463f141ec37ea5c8a1a1e986e0d3","price_changes":[{"asset_id":"110222991870854778724082971333105906777328061970448875974576460135015541883929","price":"0.02","size":"0","side":"BUY","hash":"37b8ccb799c95692ea5fdc0dec47f324ae8c79a0","best_bid":"0","best_ask":"1"},{"asset_id":"103575991306220918671611575108050794364462782362354955892418399227289531345027","price":"0.98","size":"0","side":"SELL","hash":"e52b130f364b80c03bab08702ca82ce88db8391b","best_bid":"0","best_ask":"1"}],"timestamp":"1768359662151","event_type":"price_change"}
{"market":"0x5977c69bca02e6cc150855b0faec463b38be463f141ec37ea5c8a1a1e986e0d3","price_changes":[{"asset_id":"110222991870854778724082971333105906777328061970448875974576460135015541883929","price":"0.59","size":"0","side":"BUY","hash":"37b8ccb799c95692ea5fdc0dec47f324ae8c79a0","best_bid":"0","best_ask":"1"},{"asset_id":"103575991306220918671611575108050794364462782362354955892418399227289531345027","price":"0.41","size":"0","side":"SELL","hash":"e52b130f364b80c03bab08702ca82ce88db8391b","best_bid":"0","best_ask":"1"}],"timestamp":"1768359662151","event_type":"price_change"}
{"market":"0x5977c69bca02e6cc150855b0faec463b38be463f141ec37ea5c8a1a1e986e0d3","price_changes":[{"asset_id":"110222991870854778724082971333105906777328061970448875974576460135015541883929","price":"0.81","size":"0","side":"BUY","hash":"37b8ccb799c95692ea5fdc0dec47f324ae8c79a0","best_bid":"0","best_ask":"1"},{"asset_id":"103575991306220918671611575108050794364462782362354955892418399227289531345027","price":"0.19","size":"0","side":"SELL","hash":"e52b130f364b80c03bab08702ca82ce88db8391b","best_bid":"0","best_ask":"1"}],"timestamp":"1768359662151","event_type":"price_change"}
{"market":"0x5977c69bca02e6cc150855b0faec463b38be463f141ec37ea5c8a1a1e986e0d3","price_changes":[{"asset_id":"110222991870854778724082971333105906777328061970448875974576460135015541883929","price":"0.64","size":"0","side":"BUY","hash":"37b8ccb799c95692ea5fdc0dec47f324ae8c79a0","best_bid":"0","best_ask":"1"},{"asset_id":"103575991306220918671611575108050794364462782362354955892418399227289531345027","price":"0.36","size":"0","side":"SELL","hash":"e52b130f364b80c03bab08702ca82ce88db8391b","best_bid":"0","best_ask":"1"}],"timestamp":"1768359662151","event_type":"price_change"}
{"market":"0x5977c69bca02e6cc150855b0faec463b38be463f141ec37ea5c8a1a1e986e0d3","price_changes":[{"asset_id":"110222991870854778724082971333105906777328061970448875974576460135015541883929","price":"0.99","size":"0","side":"BUY","hash":"37b8ccb799c95692ea5fdc0dec47f324ae8c79a0","best_bid":"0","best_ask":"1"},{"asset_id":"103575991306220918671611575108050794364462782362354955892418399227289531345027","price":"0.01","size":"0","side":"SELL","hash":"e52b130f364b80c03bab08702ca82ce88db8391b","best_bid":"0","best_ask":"1"}],"timestamp":"1768359662151","event_type":"price_change"}
{"market":"0x5977c69bca02e6cc150855b0faec463b38be463f141ec37ea5c8a1a1e986e0d3","price_changes":[{"asset_id":"110222991870854778724082971333105906777328061970448875974576460135015541883929","price":"0.42","size":"0","side":"BUY","hash":"37b8ccb799c95692ea5fdc0dec47f324ae8c79a0","best_bid":"0","best_ask":"1"},{"asset_id":"103575991306220918671611575108050794364462782362354955892418399227289531345027","price":"0.58","size":"0","side":"SELL","hash":"e52b130f364b80c03bab08702ca82ce88db8391b","best_bid":"0","best_ask":"1"}],"timestamp":"1768359662151","event_type":"price_change"}
{"market":"0x5977c69bca02e6cc150855b0faec463b38be463f141ec37ea5c8a1a1e986e0d3","price_changes":[{"asset_id":"110222991870854778724082971333105906777328061970448875974576460135015541883929","price":"0.01","size":"0","side":"BUY","hash":"37b8ccb799c95692ea5fdc0dec47f324ae8c79a0","best_bid":"0","best_ask":"1"},{"asset_id":"103575991306220918671611575108050794364462782362354955892418399227289531345027","price":"0.99","size":"0","side":"SELL","hash":"e52b130f364b80c03bab08702ca82ce88db8391b","best_bid":"0","best_ask":"1"}],"timestamp":"1768359662151","event_type":"price_change"}
{"market":"0x5977c69bca02e6cc150855b0faec463b38be463f141ec37ea5c8a1a1e986e0d3","price_changes":[{"asset_id":"110222991870854778724082971333105906777328061970448875974576460135015541883929","price":"0.76","size":"0","side":"BUY","hash":"37b8ccb799c95692ea5fdc0dec47f324ae8c79a0","best_bid":"0","best_ask":"1"},{"asset_id":"103575991306220918671611575108050794364462782362354955892418399227289531345027","price":"0.24","size":"0","side":"SELL","hash":"e52b130f364b80c03bab08702ca82ce88db8391b","best_bid":"0","best_ask":"1"}],"timestamp":"1768359662151","event_type":"price_change"}
{"market":"0x5977c69bca02e6cc150855b0faec463b38be463f141ec37ea5c8a1a1e986e0d3","price_changes":[{"asset_id":"110222991870854778724082971333105906777328061970448875974576460135015541883929","price":"0.47","size":"0","side":"BUY","hash":"37b8ccb799c95692ea5fdc0dec47f324ae8c79a0","best_bid":"0","best_ask":"1"},{"asset_id":"103575991306220918671611575108050794364462782362354955892418399227289531345027","price":"0.53","size":"0","side":"SELL","hash":"e52b130f364b80c03bab08702ca82ce88db8391b","best_bid":"0","best_ask":"1"}],"timestamp":"1768359662151","event_type":"price_change"}
{"market":"0x5977c69bca02e6cc150855b0faec463b38be463f141ec37ea5c8a1a1e986e0d3","price_changes":[{"asset_id":"110222991870854778724082971333105906777328061970448875974576460135015541883929","price":"0.9","size":"0","side":"BUY","hash":"37b8ccb799c95692ea5fdc0dec47f324ae8c79a0","best_bid":"0","best_ask":"1"},{"asset_id":"103575991306220918671611575108050794364462782362354955892418399227289531345027","price":"0.1","size":"0","side":"SELL","hash":"e52b130f364b80c03bab08702ca82ce88db8391b","best_bid":"0","best_ask":"1"}],"timestamp":"1768359662151","event_type":"price_change"}
{"market":"0x5977c69bca02e6cc150855b0faec463b38be463f141ec37ea5c8a1a1e986e0d3","price_changes":[{"asset_id":"110222991870854778724082971333105906777328061970448875974576460135015541883929","price":"0.69","size":"0","side":"BUY","hash":"37b8ccb799c95692ea5fdc0dec47f324ae8c79a0","best_bid":"0","best_ask":"1"},{"asset_id":"103575991306220918671611575108050794364462782362354955892418399227289531345027","price":"0.31","size":"0","side":"SELL","hash":"e52b130f364b80c03bab08702ca82ce88db8391b","best_bid":"0","best_ask":"1"}],"timestamp":"1768359662151","event_type":"price_change"}
{"market":"0x5977c69bca02e6cc150855b0faec463b38be463f141ec37ea5c8a1a1e986e0d3","price_changes":[{"asset_id":"110222991870854778724082971333105906777328061970448875974576460135015541883929","price":"0.4","size":"0","side":"BUY","hash":"37b8ccb799c95692ea5fdc0dec47f324ae8c79a0","best_bid":"0","best_ask":"1"},{"asset_id":"103575991306220918671611575108050794364462782362354955892418399227289531345027","price":"0.6","size":"0","side":"SELL","hash":"e52b130f364b80c03bab08702ca82ce88db8391b","best_bid":"0","best_ask":"1"}],"timestamp":"1768359662151","event_type":"price_change"}
{"market":"0x5977c69bca02e6cc150855b0faec463b38be463f141ec37ea5c8a1a1e986e0d3","price_changes":[{"asset_id":"110222991870854778724082971333105906777328061970448875974576460135015541883929","price":"0.45","size":"0","side":"BUY","hash":"37b8ccb799c95692ea5fdc0dec47f324ae8c79a0","best_bid":"0","best_ask":"1"},{"asset_id":"103575991306220918671611575108050794364462782362354955892418399227289531345027","price":"0.55","size":"0","side":"SELL","hash":"e52b130f364b80c03bab08702ca82ce88db8391b","best_bid":"0","best_ask":"1"}],"timestamp":"1768359662151","event_type":"price_change"}
{"market":"0x5977c69bca02e6cc150855b0faec463b38be463f141ec37ea5c8a1a1e986e0d3","price_changes":[{"asset_id":"110222991870854778724082971333105906777328061970448875974576460135015541883929","price":"0.98","size":"0","side":"BUY","hash":"37b8ccb799c95692ea5fdc0dec47f324ae8c79a0","best_bid":"0","best_ask":"1"},{"asset_id":"103575991306220918671611575108050794364462782362354955892418399227289531345027","price":"0.02","size":"0","side":"SELL","hash":"e52b130f364b80c03bab08702ca82ce88db8391b","best_bid":"0","best_ask":"1"}],"timestamp":"1768359662151","event_type":"price_change"}
{"market":"0x5977c69bca02e6cc150855b0faec463b38be463f141ec37ea5c8a1a1e986e0d3","price_changes":[{"asset_id":"110222991870854778724082971333105906777328061970448875974576460135015541883929","price":"0.999","size":"0","side":"BUY","hash":"37b8ccb799c95692ea5fdc0dec47f324ae8c79a0","best_bid":"0","best_ask":"1"},{"asset_id":"103575991306220918671611575108050794364462782362354955892418399227289531345027","price":"0.001","size":"0","side":"SELL","hash":"e52b130f364b80c03bab08702ca82ce88db8391b","best_bid":"0","best_ask":"1"}],"timestamp":"1768359662151","event_type":"price_change"}
{"market":"0x5977c69bca02e6cc150855b0faec463b38be463f141ec37ea5c8a1a1e986e0d3","price_changes":[{"asset_id":"110222991870854778724082971333105906777328061970448875974576460135015541883929","price":"0.75","size":"0","side":"BUY","hash":"37b8ccb799c95692ea5fdc0dec47f324ae8c79a0","best_bid":"0","best_ask":"1"},{"asset_id":"103575991306220918671611575108050794364462782362354955892418399227289531345027","price":"0.25","size":"0","side":"SELL","hash":"e52b130f364b80c03bab08702ca82ce88db8391b","best_bid":"0","best_ask":"1"}],"timestamp":"1768359662151","event_type":"price_change"}
{"market":"0x5977c69bca02e6cc150855b0faec463b38be463f141ec37ea5c8a1a1e986e0d3","price_changes":[{"asset_id":"110222991870854778724082971333105906777328061970448875974576460135015541883929","price":"0.93","size":"0","side":"BUY","hash":"37b8ccb799c95692ea5fdc0dec47f324ae8c79a0","best_bid":"0","best_ask":"1"},{"asset_id":"103575991306220918671611575108050794364462782362354955892418399227289531345027","price":"0.07","size":"0","side":"SELL","hash":"e52b130f364b80c03bab08702ca82ce88db8391b","best_bid":"0","best_ask":"1"}],"timestamp":"1768359662151","event_type":"price_change"}
{"market":"0x5977c69bca02e6cc150855b0faec463b38be463f141ec37ea5c8a1a1e986e0d3","price_changes":[{"asset_id":"110222991870854778724082971333105906777328061970448875974576460135015541883929","price":"0.03","size":"0","side":"BUY","hash":"37b8ccb799c95692ea5fdc0dec47f324ae8c79a0","best_bid":"0","best_ask":"1"},{"asset_id":"103575991306220918671611575108050794364462782362354955892418399227289531345027","price":"0.97","size":"0","side":"SELL","hash":"e52b130f364b80c03bab08702ca82ce88db8391b","best_bid":"0","best_ask":"1"}],"timestamp":"1768359662151","event_type":"price_change"}
{"market":"0x5977c69bca02e6cc150855b0faec463b38be463f141ec37ea5c8a1a1e986e0d3","price_changes":[{"asset_id":"110222991870854778724082971333105906777328061970448875974576460135015541883929","price":"0.996","size":"0","side":"BUY","hash":"37b8ccb799c95692ea5fdc0dec47f324ae8c79a0","best_bid":"0","best_ask":"1"},{"asset_id":"103575991306220918671611575108050794364462782362354955892418399227289531345027","price":"0.004","size":"0","side":"SELL","hash":"e52b130f364b80c03bab08702ca82ce88db8391b","best_bid":"0","best_ask":"1"}],"timestamp":"1768359662151","event_type":"price_change"}
{"market":"0x5977c69bca02e6cc150855b0faec463b38be463f141ec37ea5c8a1a1e986e0d3","price_changes":[{"asset_id":"110222991870854778724082971333105906777328061970448875974576460135015541883929","price":"0.66","size":"0","side":"BUY","hash":"37b8ccb799c95692ea5fdc0dec47f324ae8c79a0","best_bid":"0","best_ask":"1"},{"asset_id":"103575991306220918671611575108050794364462782362354955892418399227289531345027","price":"0.34","size":"0","side":"SELL","hash":"e52b130f364b80c03bab08702ca82ce88db8391b","best_bid":"0","best_ask":"1"}],"timestamp":"1768359662151","event_type":"price_change"}
{"market":"0x5977c69bca02e6cc150855b0faec463b38be463f141ec37ea5c8a1a1e986e0d3","price_changes":[{"asset_id":"110222991870854778724082971333105906777328061970448875974576460135015541883929","price":"0.96","size":"0","side":"BUY","hash":"37b8ccb799c95692ea5fdc0dec47f324ae8c79a0","best_bid":"0","best_ask":"1"},{"asset_id":"103575991306220918671611575108050794364462782362354955892418399227289531345027","price":"0.04","size":"0","side":"SELL","hash":"e52b130f364b80c03bab08702ca82ce88db8391b","best_bid":"0","best_ask":"1"}],"timestamp":"1768359662151","event_type":"price_change"}
{"market":"0x5977c69bca02e6cc150855b0faec463b38be463f141ec37ea5c8a1a1e986e0d3","price_changes":[{"asset_id":"110222991870854778724082971333105906777328061970448875974576460135015541883929","price":"0.51","size":"0","side":"BUY","hash":"37b8ccb799c95692ea5fdc0dec47f324ae8c79a0","best_bid":"0","best_ask":"1"},{"asset_id":"103575991306220918671611575108050794364462782362354955892418399227289531345027","price":"0.49","size":"0","side":"SELL","hash":"e52b130f364b80c03bab08702ca82ce88db8391b","best_bid":"0","best_ask":"1"}],"timestamp":"1768359662151","event_type":"price_change"}
{"market":"0x5977c69bca02e6cc150855b0faec463b38be463f141ec37ea5c8a1a1e986e0d3","price_changes":[{"asset_id":"110222991870854778724082971333105906777328061970448875974576460135015541883929","price":"0.94","size":"0","side":"BUY","hash":"37b8ccb799c95692ea5fdc0dec47f324ae8c79a0","best_bid":"0","best_ask":"1"},{"asset_id":"103575991306220918671611575108050794364462782362354955892418399227289531345027","price":"0.06","size":"0","side":"SELL","hash":"e52b130f364b80c03bab08702ca82ce88db8391b","best_bid":"0","best_ask":"1"}],"timestamp":"1768359662151","event_type":"price_change"}
{"market":"0x5977c69bca02e6cc150855b0faec463b38be463f141ec37ea5c8a1a1e986e0d3","price_changes":[{"asset_id":"110222991870854778724082971333105906777328061970448875974576460135015541883929","price":"0.65","size":"0","side":"BUY","hash":"37b8ccb799c95692ea5fdc0dec47f324ae8c79a0","best_bid":"0","best_ask":"1"},{"asset_id":"103575991306220918671611575108050794364462782362354955892418399227289531345027","price":"0.35","size":"0","side":"SELL","hash":"e52b130f364b80c03bab08702ca82ce88db8391b","best_bid":"0","best_ask":"1"}],"timestamp":"1768359662151","event_type":"price_change"}
{"market":"0x5977c69bca02e6cc150855b0faec463b38be463f141ec37ea5c8a1a1e986e0d3","price_changes":[{"asset_id":"110222991870854778724082971333105906777328061970448875974576460135015541883929","price":"0.83","size":"0","side":"BUY","hash":"37b8ccb799c95692ea5fdc0dec47f324ae8c79a0","best_bid":"0","best_ask":"1"},{"asset_id":"103575991306220918671611575108050794364462782362354955892418399227289531345027","price":"0.17","size":"0","side":"SELL","hash":"e52b130f364b80c03bab08702ca82ce88db8391b","best_bid":"0","best_ask":"1"}],"timestamp":"1768359662151","event_type":"price_change"}
{"market":"0x5977c69bca02e6cc150855b0faec463b38be463f141ec37ea5c8a1a1e986e0d3","price_changes":[{"asset_id":"110222991870854778724082971333105906777328061970448875974576460135015541883929","price":"0.67","size":"0","side":"BUY","hash":"37b8ccb799c95692ea5fdc0dec47f324ae8c79a0","best_bid":"0","best_ask":"1"},{"asset_id":"103575991306220918671611575108050794364462782362354955892418399227289531345027","price":"0.33","size":"0","side":"SELL","hash":"e52b130f364b80c03bab08702ca82ce88db8391b","best_bid":"0","best_ask":"1"}],"timestamp":"1768359662151","event_type":"price_change"}
{"market":"0x5977c69bca02e6cc150855b0faec463b38be463f141ec37ea5c8a1a1e986e0d3","price_changes":[{"asset_id":"110222991870854778724082971333105906777328061970448875974576460135015541883929","price":"0.95","size":"0","side":"BUY","hash":"37b8ccb799c95692ea5fdc0dec47f324ae8c79a0","best_bid":"0","best_ask":"1"},{"asset_id":"103575991306220918671611575108050794364462782362354955892418399227289531345027","price":"0.05","size":"0","side":"SELL","hash":"e52b130f364b80c03bab08702ca82ce88db8391b","best_bid":"0","best_ask":"1"}],"timestamp":"1768359662151","event_type":"price_change"}
{"market":"0x5977c69bca02e6cc150855b0faec463b38be463f141ec37ea5c8a1a1e986e0d3","price_changes":[{"asset_id":"110222991870854778724082971333105906777328061970448875974576460135015541883929","price":"0.92","size":"0","side":"BUY","hash":"37b8ccb799c95692ea5fdc0dec47f324ae8c79a0","best_bid":"0","best_ask":"1"},{"asset_id":"103575991306220918671611575108050794364462782362354955892418399227289531345027","price":"0.08","size":"0","side":"SELL","hash":"e52b130f364b80c03bab08702ca82ce88db8391b","best_bid":"0","best_ask":"1"}],"timestamp":"1768359662151","event_type":"price_change"}
{"market":"0x5977c69bca02e6cc150855b0faec463b38be463f141ec37ea5c8a1a1e986e0d3","price_changes":[{"asset_id":"110222991870854778724082971333105906777328061970448875974576460135015541883929","price":"0.1","size":"0","side":"BUY","hash":"37b8ccb799c95692ea5fdc0dec47f324ae8c79a0","best_bid":"0","best_ask":"1"},{"asset_id":"103575991306220918671611575108050794364462782362354955892418399227289531345027","price":"0.9","size":"0","side":"SELL","hash":"e52b130f364b80c03bab08702ca82ce88db8391b","best_bid":"0","best_ask":"1"}],"timestamp":"1768359662151","event_type":"price_change"}
{"market":"0x5977c69bca02e6cc150855b0faec463b38be463f141ec37ea5c8a1a1e986e0d3","price_changes":[{"asset_id":"110222991870854778724082971333105906777328061970448875974576460135015541883929","price":"0.32","size":"0","side":"BUY","hash":"37b8ccb799c95692ea5fdc0dec47f324ae8c79a0","best_bid":"0","best_ask":"1"},{"asset_id":"103575991306220918671611575108050794364462782362354955892418399227289531345027","price":"0.68","size":"0","side":"SELL","hash":"e52b130f364b80c03bab08702ca82ce88db8391b","best_bid":"0","best_ask":"1"}],"timestamp":"1768359662151","event_type":"price_change"}
{"market":"0x5977c69bca02e6cc150855b0faec463b38be463f141ec37ea5c8a1a1e986e0d3","price_changes":[{"asset_id":"110222991870854778724082971333105906777328061970448875974576460135015541883929","price":"0.991","size":"0","side":"BUY","hash":"37b8ccb799c95692ea5fdc0dec47f324ae8c79a0","best_bid":"0","best_ask":"1"},{"asset_id":"103575991306220918671611575108050794364462782362354955892418399227289531345027","price":"0.009","size":"0","side":"SELL","hash":"e52b130f364b80c03bab08702ca82ce88db8391b","best_bid":"0","best_ask":"1"}],"timestamp":"1768359662151","event_type":"price_change"}
{"market":"0x5977c69bca02e6cc150855b0faec463b38be463f141ec37ea5c8a1a1e986e0d3","price_changes":[{"asset_id":"110222991870854778724082971333105906777328061970448875974576460135015541883929","price":"0.79","size":"0","side":"BUY","hash":"37b8ccb799c95692ea5fdc0dec47f324ae8c79a0","best_bid":"0","best_ask":"1"},{"asset_id":"103575991306220918671611575108050794364462782362354955892418399227289531345027","price":"0.21","size":"0","side":"SELL","hash":"e52b130f364b80c03bab08702ca82ce88db8391b","best_bid":"0","best_ask":"1"}],"timestamp":"1768359662151","event_type":"price_change"}
{"market":"0x5977c69bca02e6cc150855b0faec463b38be463f141ec37ea5c8a1a1e986e0d3","price_changes":[{"asset_id":"110222991870854778724082971333105906777328061970448875974576460135015541883929","price":"0.04","size":"0","side":"BUY","hash":"37b8ccb799c95692ea5fdc0dec47f324ae8c79a0","best_bid":"0","best_ask":"1"},{"asset_id":"103575991306220918671611575108050794364462782362354955892418399227289531345027","price":"0.96","size":"0","side":"SELL","hash":"e52b130f364b80c03bab08702ca82ce88db8391b","best_bid":"0","best_ask":"1"}],"timestamp":"1768359662151","event_type":"price_change"}
{"market":"0x5977c69bca02e6cc150855b0faec463b38be463f141ec37ea5c8a1a1e986e0d3","price_changes":[{"asset_id":"110222991870854778724082971333105906777328061970448875974576460135015541883929","price":"0.97","size":"0","side":"BUY","hash":"37b8ccb799c95692ea5fdc0dec47f324ae8c79a0","best_bid":"0","best_ask":"1"},{"asset_id":"103575991306220918671611575108050794364462782362354955892418399227289531345027","price":"0.03","size":"0","side":"SELL","hash":"e52b130f364b80c03bab08702ca82ce88db8391b","best_bid":"0","best_ask":"1"}],"timestamp":"1768359662151","event_type":"price_change"}
{"market":"0x5977c69bca02e6cc150855b0faec463b38be463f141ec37ea5c8a1a1e986e0d3","price_changes":[{"asset_id":"110222991870854778724082971333105906777328061970448875974576460135015541883929","price":"0.36","size":"0","side":"BUY","hash":"37b8ccb799c95692ea5fdc0dec47f324ae8c79a0","best_bid":"0","best_ask":"1"},{"asset_id":"103575991306220918671611575108050794364462782362354955892418399227289531345027","price":"0.64","size":"0","side":"SELL","hash":"e52b130f364b80c03bab08702ca82ce88db8391b","best_bid":"0","best_ask":"1"}],"timestamp":"1768359662151","event_type":"price_change"}
{"market":"0x5977c69bca02e6cc150855b0faec463b38be463f141ec37ea5c8a1a1e986e0d3","price_changes":[{"asset_id":"110222991870854778724082971333105906777328061970448875974576460135015541883929","price":"0.52","size":"0","side":"BUY","hash":"37b8ccb799c95692ea5fdc0dec47f324ae8c79a0","best_bid":"0","best_ask":"1"},{"asset_id":"103575991306220918671611575108050794364462782362354955892418399227289531345027","price":"0.48","size":"0","side":"SELL","hash":"e52b130f364b80c03bab08702ca82ce88db8391b","best_bid":"0","best_ask":"1"}],"timestamp":"1768359662151","event_type":"price_change"}
{"market":"0x5977c69bca02e6cc150855b0faec463b38be463f141ec37ea5c8a1a1e986e0d3","price_changes":[{"asset_id":"110222991870854778724082971333105906777328061970448875974576460135015541883929","price":"0.71","size":"0","side":"BUY","hash":"37b8ccb799c95692ea5fdc0dec47f324ae8c79a0","best_bid":"0","best_ask":"1"},{"asset_id":"103575991306220918671611575108050794364462782362354955892418399227289531345027","price":"0.29","size":"0","side":"SELL","hash":"e52b130f364b80c03bab08702ca82ce88db8391b","best_bid":"0","best_ask":"1"}],"timestamp":"1768359662151","event_type":"price_change"}
{"market":"0x5977c69bca02e6cc150855b0faec463b38be463f141ec37ea5c8a1a1e986e0d3","price_changes":[{"asset_id":"110222991870854778724082971333105906777328061970448875974576460135015541883929","price":"0.2","size":"0","side":"BUY","hash":"37b8ccb799c95692ea5fdc0dec47f324ae8c79a0","best_bid":"0","best_ask":"1"},{"asset_id":"103575991306220918671611575108050794364462782362354955892418399227289531345027","price":"0.8","size":"0","side":"SELL","hash":"e52b130f364b80c03bab08702ca82ce88db8391b","best_bid":"0","best_ask":"1"}],"timestamp":"1768359662151","event_type":"price_change"}
{"market":"0x5977c69bca02e6cc150855b0faec463b38be463f141ec37ea5c8a1a1e986e0d3","price_changes":[{"asset_id":"110222991870854778724082971333105906777328061970448875974576460135015541883929","price":"0.56","size":"0","side":"BUY","hash":"37b8ccb799c95692ea5fdc0dec47f324ae8c79a0","best_bid":"0","best_ask":"1"},{"asset_id":"103575991306220918671611575108050794364462782362354955892418399227289531345027","price":"0.44","size":"0","side":"SELL","hash":"e52b130f364b80c03bab08702ca82ce88db8391b","best_bid":"0","best_ask":"1"}],"timestamp":"1768359662151","event_type":"price_change"}
{"market":"0x5977c69bca02e6cc150855b0faec463b38be463f141ec37ea5c8a1a1e986e0d3","price_changes":[{"asset_id":"110222991870854778724082971333105906777328061970448875974576460135015541883929","price":"0.74","size":"0","side":"BUY","hash":"37b8ccb799c95692ea5fdc0dec47f324ae8c79a0","best_bid":"0","best_ask":"1"},{"asset_id":"103575991306220918671611575108050794364462782362354955892418399227289531345027","price":"0.26","size":"0","side":"SELL","hash":"e52b130f364b80c03bab08702ca82ce88db8391b","best_bid":"0","best_ask":"1"}],"timestamp":"1768359662151","event_type":"price_change"}
{"market":"0x5977c69bca02e6cc150855b0faec463b38be463f141ec37ea5c8a1a1e986e0d3","price_changes":[{"asset_id":"110222991870854778724082971333105906777328061970448875974576460135015541883929","price":"0.89","size":"0","side":"BUY","hash":"37b8ccb799c95692ea5fdc0dec47f324ae8c79a0","best_bid":"0","best_ask":"1"},{"asset_id":"103575991306220918671611575108050794364462782362354955892418399227289531345027","price":"0.11","size":"0","side":"SELL","hash":"e52b130f364b80c03bab08702ca82ce88db8391b","best_bid":"0","best_ask":"1"}],"timestamp":"1768359662151","event_type":"price_change"}
{"market":"0x5977c69bca02e6cc150855b0faec463b38be463f141ec37ea5c8a1a1e986e0d3","price_changes":[{"asset_id":"110222991870854778724082971333105906777328061970448875974576460135015541883929","price":"0.34","size":"0","side":"BUY","hash":"37b8ccb799c95692ea5fdc0dec47f324ae8c79a0","best_bid":"0","best_ask":"1"},{"asset_id":"103575991306220918671611575108050794364462782362354955892418399227289531345027","price":"0.66","size":"0","side":"SELL","hash":"e52b130f364b80c03bab08702ca82ce88db8391b","best_bid":"0","best_ask":"1"}],"timestamp":"1768359662151","event_type":"price_change"}
{"market":"0x5977c69bca02e6cc150855b0faec463b38be463f141ec37ea5c8a1a1e986e0d3","price_changes":[{"asset_id":"110222991870854778724082971333105906777328061970448875974576460135015541883929","price":"0.7","size":"0","side":"BUY","hash":"37b8ccb799c95692ea5fdc0dec47f324ae8c79a0","best_bid":"0","best_ask":"1"},{"asset_id":"103575991306220918671611575108050794364462782362354955892418399227289531345027","price":"0.3","size":"0","side":"SELL","hash":"e52b130f364b80c03bab08702ca82ce88db8391b","best_bid":"0","best_ask":"1"}],"timestamp":"1768359662151","event_type":"price_change"}
{"market":"0x5977c69bca02e6cc150855b0faec463b38be463f141ec37ea5c8a1a1e986e0d3","price_changes":[{"asset_id":"110222991870854778724082971333105906777328061970448875974576460135015541883929","price":"0.002","size":"0","side":"BUY","hash":"37b8ccb799c95692ea5fdc0dec47f324ae8c79a0","best_bid":"0","best_ask":"1"},{"asset_id":"103575991306220918671611575108050794364462782362354955892418399227289531345027","price":"0.998","size":"0","side":"SELL","hash":"e52b130f364b80c03bab08702ca82ce88db8391b","best_bid":"0","best_ask":"1"}],"timestamp":"1768359662151","event_type":"price_change"}
{"market":"0x5977c69bca02e6cc150855b0faec463b38be463f141ec37ea5c8a1a1e986e0d3","price_changes":[{"asset_id":"110222991870854778724082971333105906777328061970448875974576460135015541883929","price":"0.63","size":"0","side":"BUY","hash":"37b8ccb799c95692ea5fdc0dec47f324ae8c79a0","best_bid":"0","best_ask":"1"},{"asset_id":"103575991306220918671611575108050794364462782362354955892418399227289531345027","price":"0.37","size":"0","side":"SELL","hash":"e52b130f364b80c03bab08702ca82ce88db8391b","best_bid":"0","best_ask":"1"}],"timestamp":"1768359662151","event_type":"price_change"}
{"market":"0x5977c69bca02e6cc150855b0faec463b38be463f141ec37ea5c8a1a1e986e0d3","price_changes":[{"asset_id":"110222991870854778724082971333105906777328061970448875974576460135015541883929","price":"0.73","size":"0","side":"BUY","hash":"37b8ccb799c95692ea5fdc0dec47f324ae8c79a0","best_bid":"0","best_ask":"1"},{"asset_id":"103575991306220918671611575108050794364462782362354955892418399227289531345027","price":"0.27","size":"0","side":"SELL","hash":"e52b130f364b80c03bab08702ca82ce88db8391b","best_bid":"0","best_ask":"1"}],"timestamp":"1768359662151","event_type":"price_change"}
{"market":"0x5977c69bca02e6cc150855b0faec463b38be463f141ec37ea5c8a1a1e986e0d3","price_changes":[{"asset_id":"110222991870854778724082971333105906777328061970448875974576460135015541883929","price":"0.5","size":"0","side":"BUY","hash":"37b8ccb799c95692ea5fdc0dec47f324ae8c79a0","best_bid":"0","best_ask":"1"},{"asset_id":"103575991306220918671611575108050794364462782362354955892418399227289531345027","price":"0.5","size":"0","side":"SELL","hash":"e52b130f364b80c03bab08702ca82ce88db8391b","best_bid":"0","best_ask":"1"}],"timestamp":"1768359662151","event_type":"price_change"}
{"market":"0x5977c69bca02e6cc150855b0faec463b38be463f141ec37ea5c8a1a1e986e0d3","price_changes":[{"asset_id":"110222991870854778724082971333105906777328061970448875974576460135015541883929","price":"0.88","size":"0","side":"BUY","hash":"37b8ccb799c95692ea5fdc0dec47f324ae8c79a0","best_bid":"0","best_ask":"1"},{"asset_id":"103575991306220918671611575108050794364462782362354955892418399227289531345027","price":"0.12","size":"0","side":"SELL","hash":"e52b130f364b80c03bab08702ca82ce88db8391b","best_bid":"0","best_ask":"1"}],"timestamp":"1768359662151","event_type":"price_change"}
{"market":"0x5977c69bca02e6cc150855b0faec463b38be463f141ec37ea5c8a1a1e986e0d3","price_changes":[{"asset_id":"110222991870854778724082971333105906777328061970448875974576460135015541883929","price":"0.8","size":"0","side":"BUY","hash":"37b8ccb799c95692ea5fdc0dec47f324ae8c79a0","best_bid":"0","best_ask":"1"},{"asset_id":"103575991306220918671611575108050794364462782362354955892418399227289531345027","price":"0.2","size":"0","side":"SELL","hash":"e52b130f364b80c03bab08702ca82ce88db8391b","best_bid":"0","best_ask":"1"}],"timestamp":"1768359662151","event_type":"price_change"}
{"market":"0x5977c69bca02e6cc150855b0faec463b38be463f141ec37ea5c8a1a1e986e0d3","price_changes":[{"asset_id":"110222991870854778724082971333105906777328061970448875974576460135015541883929","price":"0.48","size":"0","side":"BUY","hash":"37b8ccb799c95692ea5fdc0dec47f324ae8c79a0","best_bid":"0","best_ask":"1"},{"asset_id":"103575991306220918671611575108050794364462782362354955892418399227289531345027","price":"0.52","size":"0","side":"SELL","hash":"e52b130f364b80c03bab08702ca82ce88db8391b","best_bid":"0","best_ask":"1"}],"timestamp":"1768359662151","event_type":"price_change"}
{"market":"0x5977c69bca02e6cc150855b0faec463b38be463f141ec37ea5c8a1a1e986e0d3","price_changes":[{"asset_id":"110222991870854778724082971333105906777328061970448875974576460135015541883929","price":"0.46","size":"0","side":"BUY","hash":"37b8ccb799c95692ea5fdc0dec47f324ae8c79a0","best_bid":"0","best_ask":"1"},{"asset_id":"103575991306220918671611575108050794364462782362354955892418399227289531345027","price":"0.54","size":"0","side":"SELL","hash":"e52b130f364b80c03bab08702ca82ce88db8391b","best_bid":"0","best_ask":"1"}],"timestamp":"1768359662151","event_type":"price_change"}
{"market":"0x5977c69bca02e6cc150855b0faec463b38be463f141ec37ea5c8a1a1e986e0d3","price_changes":[{"asset_id":"110222991870854778724082971333105906777328061970448875974576460135015541883929","price":"0.72","size":"0","side":"BUY","hash":"37b8ccb799c95692ea5fdc0dec47f324ae8c79a0","best_bid":"0","best_ask":"1"},{"asset_id":"103575991306220918671611575108050794364462782362354955892418399227289531345027","price":"0.28","size":"0","side":"SELL","hash":"e52b130f364b80c03bab08702ca82ce88db8391b","best_bid":"0","best_ask":"1"}],"timestamp":"1768359662151","event_type":"price_change"}
{"market":"0x5977c69bca02e6cc150855b0faec463b38be463f141ec37ea5c8a1a1e986e0d3","price_changes":[{"asset_id":"110222991870854778724082971333105906777328061970448875974576460135015541883929","price":"0.86","size":"0","side":"BUY","hash":"37b8ccb799c95692ea5fdc0dec47f324ae8c79a0","best_bid":"0","best_ask":"1"},{"asset_id":"103575991306220918671611575108050794364462782362354955892418399227289531345027","price":"0.14","size":"0","side":"SELL","hash":"e52b130f364b80c03bab08702ca82ce88db8391b","best_bid":"0","best_ask":"1"}],"timestamp":"1768359662151","event_type":"price_change"}
{"market":"0x5977c69bca02e6cc150855b0faec463b38be463f141ec37ea5c8a1a1e986e0d3","price_changes":[{"asset_id":"110222991870854778724082971333105906777328061970448875974576460135015541883929","price":"0.3","size":"0","side":"BUY","hash":"37b8ccb799c95692ea5fdc0dec47f324ae8c79a0","best_bid":"0","best_ask":"1"},{"asset_id":"103575991306220918671611575108050794364462782362354955892418399227289531345027","price":"0.7","size":"0","side":"SELL","hash":"e52b130f364b80c03bab08702ca82ce88db8391b","best_bid":"0","best_ask":"1"}],"timestamp":"1768359662151","event_type":"price_change"}
{"market":"0x5977c69bca02e6cc150855b0faec463b38be463f141ec37ea5c8a1a1e986e0d3","price_changes":[{"asset_id":"110222991870854778724082971333105906777328061970448875974576460135015541883929","price":"0.15","size":"0","side":"BUY","hash":"37b8ccb799c95692ea5fdc0dec47f324ae8c79a0","best_bid":"0","best_ask":"1"},{"asset_id":"103575991306220918671611575108050794364462782362354955892418399227289531345027","price":"0.85","size":"0","side":"SELL","hash":"e52b130f364b80c03bab08702ca82ce88db8391b","best_bid":"0","best_ask":"1"}],"timestamp":"1768359662151","event_type":"price_change"}
{"market":"0x5977c69bca02e6cc150855b0faec463b38be463f141ec37ea5c8a1a1e986e0d3","price_changes":[{"asset_id":"110222991870854778724082971333105906777328061970448875974576460135015541883929","price":"0.001","size":"0","side":"BUY","hash":"37b8ccb799c95692ea5fdc0dec47f324ae8c79a0","best_bid":"0","best_ask":"1"},{"asset_id":"103575991306220918671611575108050794364462782362354955892418399227289531345027","price":"0.999","size":"0","side":"SELL","hash":"e52b130f364b80c03bab08702ca82ce88db8391b","best_bid":"0","best_ask":"1"}],"timestamp":"1768359662151","event_type":"price_change"}
{"market":"0x5977c69bca02e6cc150855b0faec463b38be463f141ec37ea5c8a1a1e986e0d3","price_changes":[{"asset_id":"110222991870854778724082971333105906777328061970448875974576460135015541883929","price":"0.994","size":"0","side":"BUY","hash":"37b8ccb799c95692ea5fdc0dec47f324ae8c79a0","best_bid":"0","best_ask":"1"},{"asset_id":"103575991306220918671611575108050794364462782362354955892418399227289531345027","price":"0.006","size":"0","side":"SELL","hash":"e52b130f364b80c03bab08702ca82ce88db8391b","best_bid":"0","best_ask":"1"}],"timestamp":"1768359662151","event_type":"price_change"}
{"market":"0x5977c69bca02e6cc150855b0faec463b38be463f141ec37ea5c8a1a1e986e0d3","price_changes":[{"asset_id":"110222991870854778724082971333105906777328061970448875974576460135015541883929","price":"0.43","size":"0","side":"BUY","hash":"37b8ccb799c95692ea5fdc0dec47f324ae8c79a0","best_bid":"0","best_ask":"1"},{"asset_id":"103575991306220918671611575108050794364462782362354955892418399227289531345027","price":"0.57","size":"0","side":"SELL","hash":"e52b130f364b80c03bab08702ca82ce88db8391b","best_bid":"0","best_ask":"1"}],"timestamp":"1768359662151","event_type":"price_change"}
{"market":"0x5977c69bca02e6cc150855b0faec463b38be463f141ec37ea5c8a1a1e986e0d3","price_changes":[{"asset_id":"110222991870854778724082971333105906777328061970448875974576460135015541883929","price":"0.77","size":"0","side":"BUY","hash":"37b8ccb799c95692ea5fdc0dec47f324ae8c79a0","best_bid":"0","best_ask":"1"},{"asset_id":"103575991306220918671611575108050794364462782362354955892418399227289531345027","price":"0.23","size":"0","side":"SELL","hash":"e52b130f364b80c03bab08702ca82ce88db8391b","best_bid":"0","best_ask":"1"}],"timestamp":"1768359662151","event_type":"price_change"}
{"market":"0x5977c69bca02e6cc150855b0faec463b38be463f141ec37ea5c8a1a1e986e0d3","price_changes":[{"asset_id":"110222991870854778724082971333105906777328061970448875974576460135015541883929","price":"0.61","size":"0","side":"BUY","hash":"37b8ccb799c95692ea5fdc0dec47f324ae8c79a0","best_bid":"0","best_ask":"1"},{"asset_id":"103575991306220918671611575108050794364462782362354955892418399227289531345027","price":"0.39","size":"0","side":"SELL","hash":"e52b130f364b80c03bab08702ca82ce88db8391b","best_bid":"0","best_ask":"1"}],"timestamp":"1768359662151","event_type":"price_change"}
{"market":"0x5977c69bca02e6cc150855b0faec463b38be463f141ec37ea5c8a1a1e986e0d3","price_changes":[{"asset_id":"110222991870854778724082971333105906777328061970448875974576460135015541883929","price":"0.44","size":"0","side":"BUY","hash":"37b8ccb799c95692ea5fdc0dec47f324ae8c79a0","best_bid":"0","best_ask":"1"},{"asset_id":"103575991306220918671611575108050794364462782362354955892418399227289531345027","price":"0.56","size":"0","side":"SELL","hash":"e52b130f364b80c03bab08702ca82ce88db8391b","best_bid":"0","best_ask":"1"}],"timestamp":"1768359662151","event_type":"price_change"}
{"market":"0x5977c69bca02e6cc150855b0faec463b38be463f141ec37ea5c8a1a1e986e0d3","price_changes":[{"asset_id":"110222991870854778724082971333105906777328061970448875974576460135015541883929","price":"0.57","size":"0","side":"BUY","hash":"37b8ccb799c95692ea5fdc0dec47f324ae8c79a0","best_bid":"0","best_ask":"1"},{"asset_id":"103575991306220918671611575108050794364462782362354955892418399227289531345027","price":"0.43","size":"0","side":"SELL","hash":"e52b130f364b80c03bab08702ca82ce88db8391b","best_bid":"0","best_ask":"1"}],"timestamp":"1768359662151","event_type":"price_change"}
{"market":"0x5977c69bca02e6cc150855b0faec463b38be463f141ec37ea5c8a1a1e986e0d3","price_changes":[{"asset_id":"110222991870854778724082971333105906777328061970448875974576460135015541883929","price":"0.85","size":"0","side":"BUY","hash":"37b8ccb799c95692ea5fdc0dec47f324ae8c79a0","best_bid":"0","best_ask":"1"},{"asset_id":"103575991306220918671611575108050794364462782362354955892418399227289531345027","price":"0.15","size":"0","side":"SELL","hash":"e52b130f364b80c03bab08702ca82ce88db8391b","best_bid":"0","best_ask":"1"}],"timestamp":"1768359662151","event_type":"price_change"}
{"market":"0x5977c69bca02e6cc150855b0faec463b38be463f141ec37ea5c8a1a1e986e0d3","price_changes":[{"asset_id":"110222991870854778724082971333105906777328061970448875974576460135015541883929","price":"0.58","size":"0","side":"BUY","hash":"37b8ccb799c95692ea5fdc0dec47f324ae8c79a0","best_bid":"0","best_ask":"1"},{"asset_id":"103575991306220918671611575108050794364462782362354955892418399227289531345027","price":"0.42","size":"0","side":"SELL","hash":"e52b130f364b80c03bab08702ca82ce88db8391b","best_bid":"0","best_ask":"1"}],"timestamp":"1768359662151","event_type":"price_change"}
{"market":"0x5977c69bca02e6cc150855b0faec463b38be463f141ec37ea5c8a1a1e986e0d3","price_changes":[{"asset_id":"110222991870854778724082971333105906777328061970448875974576460135015541883929","price":"0.12","size":"0","side":"BUY","hash":"37b8ccb799c95692ea5fdc0dec47f324ae8c79a0","best_bid":"0","best_ask":"1"},{"asset_id":"103575991306220918671611575108050794364462782362354955892418399227289531345027","price":"0.88","size":"0","side":"SELL","hash":"e52b130f364b80c03bab08702ca82ce88db8391b","best_bid":"0","best_ask":"1"}],"timestamp":"1768359662151","event_type":"price_change"}
{"market":"0x5977c69bca02e6cc150855b0faec463b38be463f141ec37ea5c8a1a1e986e0d3","price_changes":[{"asset_id":"110222991870854778724082971333105906777328061970448875974576460135015541883929","price":"0.985","size":"0","side":"BUY","hash":"37b8ccb799c95692ea5fdc0dec47f324ae8c79a0","best_bid":"0","best_ask":"1"},{"asset_id":"103575991306220918671611575108050794364462782362354955892418399227289531345027","price":"0.015","size":"0","side":"SELL","hash":"e52b130f364b80c03bab08702ca82ce88db8391b","best_bid":"0","best_ask":"1"}],"timestamp":"1768359662151","event_type":"price_change"}
PONG
PONG
PONG
PONG

